Workbook

Sheet 종합
B8: 구분 | E8: 2401 | F8: 2402 | G8: 2403 | H8: 2404 | I8: 2405 | J8: 2406 | K8: 2407 | L8: 2408 | M8: 2409 | N8: 2410 | O8: 2411 | P8: 2412 | Q8: 2501 | R8: 2502 | S8: 2503 | T8: 2504 | U8: 2505 | V8: 2506 | W8: 2507 | X8: 2508 | Y8: 2509 | Z8: 2510 | AA8: 2511 | AB8: 2512 | AC8: 25년 누적 | AD8: 25년 월평균
B9: 관리수수료 | D9: 계 | Q9: =Q10+Q11+Q12+Q13 -> 46.936707 | R9: =R10+R11+R12+R13 -> 50.212828 | S9: =S10+S11+S12+S13 -> 46.993549 | T9: =T10+T11+T12+T13 -> 54.612779 | U9: =U10+U11+U12+U13 -> 44.629061 | AC9: =SUM(D9:T9) -> 198.75586 | AD9: =AVERAGE(Q9:U9) -> 48.676985
D10: 무선 | Q10: =Q15+Q18+Q24+Q27+Q31+Q32 -> 32.117026 | R10: =R15+R18+R24+R27+R31+R32 -> 32.819003 | S10: =S15+S18+S24+S27+S31+S32 -> 31.966464 | T10: =T15+T18+T24+T27+T31+T32 -> 31.148299 | U10: =U15+U18+U24+U27+U31+U32 -> 30.550866 | AC10: =SUM(D10:T10) -> 128.05079 | AD10: =AVERAGE(Q10:U10) -> 31.720332
D11: 유선 | Q11: =Q16+Q20+Q25+Q28 -> 6.577184 | R11: =R16+R20+R25+R28 -> 7.1815229 | S11: =S16+S20+S25+S28 -> 7.5357089 | T11: =T16+T20+T25+T28 -> 6.59036 | U11: =U16+U20+U25+U28 -> 6.4865683 | AC11: =SUM(D11:T11) -> 27.884776 | AD11: =AVERAGE(Q11:U11) -> 6.8742688
D12: H.C | Q12: =Q22+Q29 -> 2.1884938 | R12: =R22+R29 -> 2.4766145 | S12: =S22+S29 -> 2.7696575 | T12: =T22+T29 -> 2.9780212 | U12: =U22+U29 -> 3.2158703 | AC12: =SUM(D12:T12) -> 10.412787 | AD12: =AVERAGE(Q12:U12) -> 2.7257315
D13: 기타 | Q13: =Q33 -> 6.0540026 | R13: =R33 -> 7.735688 | S13: =S33 -> 4.721718 | T13: =T33 -> 13.896099 | U13: =U33 -> 4.3757565 | AC13: =SUM(D13:T13) -> 32.407507 | AD13: =AVERAGE(Q13:U13) -> 7.3566528
B14: 소매 | D14: 계 | E14: 27 | F14: 27.4 | G14: 26.9 | H14: 27.1 | I14: 26.8 | J14: 27.1 | K14: 27 | L14: 26.8 | M14: 26.9 | N14: 26.6 | O14: 26.4 | P14: 26 | Q14: =Q15+Q16 -> 23.890354 | R14: =R15+R16 -> 24.701307 | S14: =S15+S16 -> 25.050896 | T14: =T15+T16 -> 23.809409 | U14: =U15+U16 -> 23.57592 | AC14: =SUM(D14:T14) -> 419.45197 | AD14: =AVERAGE(Q14:U14) -> 24.205577
D15: 무선 | E15: 23.232542 | F15: 23.638276 | G15: 23.080875 | H15: 23.254129 | I15: 23.032484 | J15: 23.332455 | K15: 23.242898 | L15: 23.10626 | M15: 23.190662 | N15: 22.880206 | O15: 22.721914 | P15: 22.313857 | Q15: ='(참고) 연결용'!F6 -> 20.402818 | R15: ='(참고) 연결용'!G6 -> 20.814096 | S15: ='(참고) 연결용'!H6 -> 20.926437 | T15: ='(참고) 연결용'!I6 -> 20.153446 | U15: ='(참고) 연결용'!J6 -> 19.901026 | AC15: =SUM(D15:T15) -> 359.32335 | AD15: =AVERAGE(Q15:U15) -> 20.439564
D16: 유선 | E16: 3.7674583 | F16: 3.7617237 | G16: 3.8191253 | H16: 3.8458707 | I16: 3.7675159 | J16: 3.7675454 | K16: 3.7571025 | L16: 3.6937402 | M16: 3.7093376 | N16: 3.7197939 | O16: 3.6780862 | P16: 3.6861434 | Q16: ='(참고) 연결용'!F22 -> 3.4875361 | R16: ='(참고) 연결용'!G22 -> 3.8872114 | S16: ='(참고) 연결용'!H22 -> 4.1244591 | T16: ='(참고) 연결용'!I22 -> 3.6559634 | U16: ='(참고) 연결용'!J22 -> 3.6748937 | AC16: =SUM(D16:T16) -> 60.128613 | AD16: =AVERAGE(Q16:U16) -> 3.7660127
B17: 도매 | D17: 계 | E17: 13.1 | F17: 12.6 | G17: 12.4 | H17: 12.1 | I17: 11.6 | J17: 11.3 | K17: 11.1 | L17: 10.8 | M17: 10.6 | N17: 10.4 | O17: 9.9 | P17: 9.6 | Q17: 9.1 | R17: 9.0830929 | S17: 8.5529126 | T17: 8.0079655 | U17: 7.6013216 | AC17: =SUM(D17:T17) -> 170.24397 | AD17: =AVERAGE(Q17:U17) -> 8.4690585
D18: 무선 | E18: =E17-E19-E20-E21 -> 0.201186 | F18: =F17-F19-F20-F21 -> 0.064343049 | G18: =G17-G19-G20-G21 -> 0.25349453 | H18: =H17-H19-H20-H21 -> 0.36028347 | I18: =I17-I19-I20-I21 -> 0.25776804 | J18: =J17-J19-J20-J21 -> 0.35737908 | K18: =K17-K19-K20-K21 -> 0.42163681 | L18: =L17-L19-L20-L21 -> 0.51237423 | ... P18: =P17-P19-P20-P21 -> 0.81376202 | Q18: ='(참고) 연결용'!F5 -> 2.9624661 | R18: ='(참고) 연결용'!G5 -> 2.91333 | S18: ='(참고) 연결용'!H5 -> 2.4573264 | T18: ='(참고) 연결용'!I5 -> 2.526277 | U18: ='(참고) 연결용'!J5 -> 2.3802389 | AC18: =SUM(D18:T18) -> 16.410074 | AD18: =AVERAGE(Q18:U18) -> 2.6479277
D19: 점프업 | E19: 4.5555838 | F19: 4.2798038 | G19: 3.9510572 | H19: 3.6747115 | I19: 3.4186966 | J19: 3.2155809 | K19: 3.0333787 | L19: 2.842718 | M19: 2.6700881 | N19: 2.4984012 | O19: 2.3461477 | P19: 2.2111794
D20: 유선 | E20: 2.775657 | F20: 2.7472658 | G20: 2.7423491 | H20: 2.697131 | I20: 2.6393608 | J20: 2.5545065 | K20: 2.5248521 | L20: 2.4420311 | M20: 2.3737327 | N20: 2.3304191 | O20: 2.2147525 | P20: 2.1650585 | Q20: ='(참고) 연결용'!F21 -> 1.9975339 | R20: ='(참고) 연결용'!G21 -> 2.0294241 | S20: ='(참고) 연결용'!H21 -> 2.2323665 | T20: ='(참고) 연결용'!I21 -> 1.8044475 | U20: ='(참고) 연결용'!J21 -> 1.7026086 | AC20: =SUM(D20:T20) -> 38.270888 | AD20: =AVERAGE(Q20:U20) -> 1.9532761
D21: H.C | E21: 5.5675732 | F21: 5.5085874 | G21: 5.4530992 | H21: 5.367874 | I21: 5.2841746 | J21: 5.1725335 | K21: 5.1201324 | L21: 5.0028767 | M21: 4.867749 | N21: 4.7402626 | O21: 4.55 | P21: 4.41 | Q21: 4.14 | R21: 4.1403388 | S21: 3.8632196 | T21: 3.6772409 | U21: 3.5184741 | AC21: 76.865662 | AD21: 3.8678547
D22: Win-Win H.C | E22: 0.0087965286 | F22: 0.036799681 | G22: 0.11150798 | H22: 0.19265921 | I22: 0.27808436 | J22: 0.36137504 | K22: 0.45979166 | L22: 0.56598657 | M22: 0.71547984 | N22: 0.87183651 | O22: 1.0436457 | P22: 1.1684938 | Q22: 1.1684938 | R22: 1.3666145 | S22: 1.5696575 | T22: 1.7213212 | U22: 1.8914007 | V22: 2.1825411
B23: 소상공인 | D23: 계 | Q23: =Q24+Q25 -> 1.2109914 | R23: =R24+R25 -> 1.364172 | S23: =S24+S25 -> 1.2723795 | T23: =T24+T25 -> 1.2368363 | U23: =U24+U25 -> 1.2193463 | AC23: =SUM(D23:T23) -> 5.0843791 | AD23: =AVERAGE(Q23:U23) -> 1.2607451
D24: 무선 | Q24: ='(참고) 연결용'!F7 -> 0.47383373 | R24: ='(참고) 연결용'!G7 -> 0.48559427 | S24: ='(참고) 연결용'!H7 -> 0.45793709 | T24: ='(참고) 연결용'!I7 -> 0.44099936 | U24: ='(참고) 연결용'!J7 -> 0.42470564 | AC24: =SUM(D24:T24) -> 1.8583645 | AD24: =AVERAGE(Q24:U24) -> 0.45661402
D25: 유선 | Q25: ='(참고) 연결용'!F23 -> 0.73715764 | R25: ='(참고) 연결용'!G23 -> 0.87857773 | S25: ='(참고) 연결용'!H23 -> 0.81444236 | T25: ='(참고) 연결용'!I23 -> 0.79583691 | U25: ='(참고) 연결용'!J23 -> 0.79464064 | AC25: =SUM(D25:T25) -> 3.2260146 | AD25: =AVERAGE(Q25:U25) -> 0.80413105
B26: 디지털 | D26: 계 | E26: 6 | F26: 5.7 | G26: 5.9 | H26: 5.8 | I26: 5.8 | J26: 5.7 | K26: 5.8 | L26: 5.7 | M26: 5.7 | N26: 5.7 | O26: 5.6 | P26: 5.5 | Q26: =Q27+Q28+Q29 -> 5.2 | R26: =R27+R28+R29 -> 5.3671954 | S26: =S27+S28+S29 -> 5.1954726 | T26: =T27+T28+T29 -> 5.066248 | U26: =U27+U28+U29 -> 4.9718197 | AC26: =SUM(D26:T26) -> 89.728916 | AD26: =AVERAGE(Q26:U26) -> 5.1601471
D27: 무선 | E27: =E26-E28-E29 -> 5.433244 | F27: =F26-F28-F29 -> 5.1382724 | G27: =G26-G28-G29 -> 4.9912975 | H27: =H26-H28-H29 -> 4.8656638 | I27: =I26-I28-I29 -> 4.8242472 | J27: =J26-J28-J29 -> 4.704188 | K27: =K26-K28-K29 -> 4.7789876 | L27: =L26-L28-L29 -> 4.6154407 | ... P27: =P26-P28-P29 -> 4.11623 | Q27: ='(참고) 연결용'!F9 -> 3.8250436 | R27: ='(참고) 연결용'!G9 -> 3.8708857 | S27: ='(참고) 연결용'!H9 -> 3.6310316 | T27: ='(참고) 연결용'!I9 -> 3.4754358 | U27: ='(참고) 연결용'!J9 -> 3.3329248 | AC27: =SUM(D27:T27) -> 71.553467 | AD27: =AVERAGE(Q27:U27) -> 3.6270643
D28: 유선 | E28: 0.566756 | F28: 0.56172764 | G28: 0.54870245 | H28: 0.52433618 | I28: 0.50575282 | J28: 0.485812 | K28: 0.47101236 | L28: 0.45455927 | M28: 0.43477627 | N28: 0.42295245 | O28: 0.39877282 | P28: 0.38377 | Q28: 0.35495636 | R28: ='(참고) 연결용'!G25 -> 0.3863097 | S28: ='(참고) 연결용'!H25 -> 0.36444095 | T28: ='(참고) 연결용'!I25 -> 0.3341122 | U28: ='(참고) 연결용'!J25 -> 0.3144253 | AC28: =SUM(D28:T28) -> 7.1987495 | AD28: =AVERAGE(Q28:U28) -> 0.3508489
D29: H.C | G29: 0.36 | H29: 0.41 | I29: 0.47 | J29: 0.51 | K29: 0.55 | L29: 0.63 | M29: 0.68 | N29: 0.84 | O29: 0.94 | P29: 1 | Q29: ='(참고) 연결용'!F15 -> 1.02 | R29: ='(참고) 연결용'!G15 -> 1.11 | S29: ='(참고) 연결용'!H15 -> 1.2 | T29: ='(참고) 연결용'!I15 -> 1.2567 | U29: ='(참고) 연결용'!J15 -> 1.3244696 | AC29: =SUM(D29:T29) -> 10.9767 | AD29: =AVERAGE(Q29:U29) -> 1.1822339
B30: B2B | D30: 계 | E30: =E31+E32 -> 5.3595323 | F30: =F31+F32 -> 5.0397463 | G30: =G31+G32 -> 4.9948352 | H30: =H31+H32 -> 5.5564696 | I30: =I31+I32 -> 5.0182843 | J30: =J31+J32 -> 4.693901 | K30: =K31+K32 -> 5.1975374 | L30: =L31+L32 -> 4.7080901 | ... U30: =U31+U32 -> 4.511971 | AC30: =SUM(D30:T30) -> 78.236972 | AD30: =AVERAGE(Q30:U30) -> 4.5491613
D31: 무선(기업) | E31: 2.2321313 | F31: 2.2146565 | G31: 2.1495214 | H31: 2.482852 | I31: 2.2195729 | J31: 2.0524255 | K31: 2.3254245 | L31: 2.0815853 | M31: 2.2659388 | N31: 2.3115774 | O31: 1.830619 | P31: 2.278 | Q31: ='(참고) 연결용'!F11 -> 1.9728654 | R31: ='(참고) 연결용'!G11 -> 2.0155581 | S31: ='(참고) 연결용'!H11 -> 1.9641957 | T31: ='(참고) 연결용'!I11 -> 2.0361414 | U31: ='(참고) 연결용'!J11 -> 2.138469 | AC31: =SUM(D31:T31) -> 34.433065 | AD31: =AVERAGE(Q31:U31) -> 2.0254459
D32: 무선(Biz) | E32: 3.127401 | F32: 2.8250899 | G32: 2.8453138 | H32: 3.0736176 | I32: 2.7987114 | J32: 2.6414755 | K32: 2.872113 | L32: 2.6265048 | M32: 2.7846919 | N32: 2.7036336 | O32: 2.60638 | P32: 2.6539 | Q32: ='(참고) 연결용'!F12 -> 2.48 | R32: ='(참고) 연결용'!G12 -> 2.7195389 | S32: ='(참고) 연결용'!H12 -> 2.529536 | T32: ='(참고) 연결용'!I12 -> 2.516 | U32: ='(참고) 연결용'!J12 -> 2.373502 | AC32: =SUM(D32:T32) -> 43.803907 | AD32: =AVERAGE(Q32:U32) -> 2.5237154
B33: 기타 | D33: 계 | Q33: =Q34+Q36+Q35 -> 6.0540026 | R33: =R34+R36+R35 -> 7.735688 | S33: =S34+S36+S35 -> 4.721718 | T33: =T34+T36+T35 -> 13.896099 | U33: =U34+U36+U35 -> 4.3757565 | AC33: =SUM(D33:T33) -> 32.407507 | AD33: =AVERAGE(Q33:U33) -> 7.3566528
D34: P3.0 | Q34: ='(참고) 연결용'!F16 -> 7.9 | R34: ='(참고) 연결용'!G16 -> 7.9716096 | S34: ='(참고) 연결용'!H16 -> 7.4216384 | T34: ='(참고) 연결용'!I16 -> 7.6139128 | U34: ='(참고) 연결용'!J16 -> 7.622857 | AC34: =SUM(D34:T34) -> 30.907161 | AD34: =AVERAGE(Q34:U34) -> 7.7060036
D35: 매장성수수료 | Q35: ='(참고) 연결용'!F17 -> 0.60595882 | R35: ='(참고) 연결용'!G17 -> 0.66603878 | S35: ='(참고) 연결용'!H17 -> 0.63645968 | T35: ='(참고) 연결용'!I17 -> 0.57387266 | U35: ='(참고) 연결용'!J17 -> 0.69777633 | AC35: =SUM(D35:T35) -> 2.4823299 | AD35: =AVERAGE(Q35:U35) -> 0.63602125
D36: 본사공통 | Q36: ='(참고) 연결용'!F13 -> -2.4519562 | R36: ='(참고) 연결용'!G13 -> -0.90196034 | S36: ='(참고) 연결용'!H13 -> -3.3363801 | T36: ='(참고) 연결용'!I13 -> 5.7083132 | U36: ='(참고) 연결용'!J13 -> -3.9448768 | AC36: =SUM(D36:T36) -> -0.98198339 | AD36: =AVERAGE(Q36:U36) -> -0.98537205
B38: 구분 | Q38: 2501 | R38: 2502 | S38: 2503 | T38: 2504 | U38: 2505 | V38: 2506 | W38: 2507 | X38: 2508 | Y38: 2509 | Z38: 2510 | AA38: 2511 | AB38: 2512 | AC38: 25년 누적 | AD38: 25년 월평균
B39: 가입자 | D39: 계 | Q39: =Q40+Q41+Q42 -> 2437221 | R39: =R40+R41+R42 -> 2418438 | S39: =S40+S41+S42 -> 2394811 | T39: =T40+T41+T42 -> 2388658 | U39: =U40+U41+U42 -> 2406955 | AC39: =SUM(D39:T39) -> 9639128
D40: 무선 | Q40: =Q45+Q49+Q54+Q58+Q63+Q64 -> 1438997 | R40: =R45+R49+R54+R58+R63+R64 -> 1428238 | S40: =S45+S49+S54+S58+S63+S64 -> 1417929 | T40: =T45+T49+T54+T58+T63+T64 -> 1419139 | U40: =U45+U49+U54+U58+U63+U64 -> 1428753 | AC40: =SUM(D40:T40) -> 5704303
D41: 유선 | Q41: =Q46+Q47+Q50+Q51+Q55+Q56+Q59+Q60 -> 276106 | R41: =R46+R47+R50+R51+R55+R56+R59+R60 -> 274037 | S41: =S46+S47+S50+S51+S55+S56+S59+S60 -> 270709 | T41: =T46+T47+T50+T51+T55+T56+T59+T60 -> 269132 | U41: =U46+U47+U50+U51+U55+U56+U59+U60 -> 268690 | AC41: =SUM(D41:T41) -> 1089984
D42: H.C | Q42: =Q52+Q61 -> 722118 | R42: =R52+R61 -> 716163 | S42: =S52+S61 -> 706173 | T42: =T52+T61 -> 700387 | U42: =U52+U61 -> 709512 | AC42: =SUM(D42:T42) -> 2844841
D43: 기타 | AC43: =SUM(D43:T43) -> 0
B44: 소매 | D44: 계 | E44: 894405 | F44: 893011 | G44: 892673 | H44: 890727 | I44: 889722 | J44: 890125 | K44: 890893 | L44: 892043 | M44: 890763 | N44: 883936 | O44: 887759 | P44: 886188 | Q44: =Q45+Q47+Q46 -> 863927 | R44: =R45+R47+R46 -> 867687 | S44: =S45+S47+S46 -> 868817 | T44: =T45+T47+T46 -> 873806 | U44: =U45+U47+U46 -> 891478 | AC44: =SUM(D44:T44) -> 14156482
D45: 무선 | E45: 749129 | F45: 748834 | G45: 748987 | H45: 747221 | I45: 747650 | J45: 750317 | K45: 752257 | L45: 755901 | M45: 756168 | N45: 751500 | O45: 756006 | P45: 755811 | Q45: ='(참고) 연결용 (가입자 무선)'!F22 -> 751971 | R45: ='(참고) 연결용 (가입자 무선)'!G22 -> 752950 | S45: ='(참고) 연결용 (가입자 무선)'!H22 -> 752266 | T45: ='(참고) 연결용 (가입자 무선)'!I22 -> 754111 | U45: ='(참고) 연결용 (가입자 무선)'!J22 -> 766608 | AC45: =SUM(D45:T45) -> 12031079
D46: 유선(I) | Q46: 69550 | R46: 69467 | S46: 68835 | T46: 68722 | U46: 69025 | AC46: =SUM(D46:T46) -> 276574
D47: 유선(TV) | Q47: 42406 | R47: 45270 | S47: 47716 | T47: 50973 | U47: 55845 | V47: 59349 | AC47: =SUM(D47:T47) -> 186365
B48: 도매 | D48: 계 | Q48: =Q49+Q51+Q50+Q52 -> 738464 | R48: =R49+R51+R50+R52 -> 709587 | S48: =S49+S51+S50+S52 -> 686178 | T48: =T49+T51+T50+T52 -> 662458 | U48: =U49+U51+U50+U52 -> 639166 | AC48: =SUM(D48:T48) -> 2796687
...

Sheet 종합(E)
B2: 구분 | C2: 종합 | D2: 소매 | E2: 도매 | F2: 디지털 | G2: B2B | H2: 소상공인 | I2: 기타
B3: 18년 | C3: =D3+E3+F3 -> 494.9314 | D3: =SUM('관리수수료 트렌드 정리'!D3:D14) -> 154.63153 | E3: =SUM('관리수수료 트렌드 정리'!C3:C14) -> 298.69881 | F3: =SUM('관리수수료 트렌드 정리'!E3:E14) -> 41.601056
B4: 19년 | C4: =D4+E4+F4 -> 346.97322 | D4: =SUM('관리수수료 트렌드 정리'!D15:D26) -> 132.08526 | E4: =SUM('관리수수료 트렌드 정리'!C15:C26) -> 180.35234 | F4: 34.535629
B5: 20년 | C5: =D5+E5+F5 -> 304.08588 | D5: =SUM('관리수수료 트렌드 정리'!D27:D38) -> 174.63156 | E5: =SUM('관리수수료 트렌드 정리'!C27:C38) -> 91.460928 | F5: 37.993394
B6: 21년 | C6: =D6+E6+F6 -> 415.79902 | D6: 238.0231 | E6: 127.87815 | F6: 49.897776
B7: 22년 | C7: =D7+E7+F7+G7+I7 -> 481.46282 | D7: =SUM('관리수수료 트렌드 정리'!D51:D62) -> 264.94001 | E7: =SUM('관리수수료 트렌드 정리'!C51:C62) -> 157.1894 | F7: =SUM('관리수수료 트렌드 정리'!E51:E62) -> 59.333402
B8: 23년 | C8: =D8+E8+F8+G8+I8 -> 614.87758 | D8: =SUM('관리수수료 트렌드 정리'!D63:D74) -> 311.06232 | E8: =SUM('관리수수료 트렌드 정리'!C63:C74) -> 170.37648 | F8: =SUM('관리수수료 트렌드 정리'!E63:E74) -> 69.930816 | G8: =SUM('관리수수료 트렌드 정리'!J63:M74) -> 63.507968
B9: 24년 | C9: =D9+E9+F9+G9+I9 -> 717.87909 | D9: ='소매 (E)'!C4 -> 322 | E9: ='도매(E)'!C4 -> 141.31446 | F9: ='디지털(E)'!C3 -> 68.9 | G9: =SUM('관리수수료 트렌드 정리'!J75:M86) -> 86.448426 | H9: ='소상공인(E)'!C3 -> 16.325662 | I9: ='소매 (E)'!C10 -> 99.216209
B10: 25년 | C10: =D10+E10+F10+G10+H10+I10 -> 650.10979 | D10: ='소매 (E)'!C5 -> 290.27045 | E10: ='도매(E)'!C5 -> 136.43485 | F10: ='디지털(E)'!C4 -> 60.040496 | G10: ='B2B(E)'!AQ5 -> 54.121058 | H10: ='소상공인(E)'!C4 -> 14.47016 | I10: ='소매 (E)'!C11 -> 94.772779
B11: 26년 (E) | C11: =D11+E11+F11+G11+H11+I11 -> 604.56068 | D11: ='소매 (E)'!C6 -> 283.04189 | E11: ='도매(E)'!C6 -> 109.63097 | F11: ='디지털(E)'!C5 -> 52.915119 | G11: 54.519284 | H11: 14.47016 | I11: 89.983264
B12: 27년 (E) | C12: =D12+E12+F12+G12+H12+I12 -> 55.381674 | F12: ='디지털(E)'!C6 -> 55.381674 | H12: ='소상공인(E)'!C6 -> 0 | I12: ='소매 (E)'!C13 -> 0 | K12: 130 | L12: 22 | M12: 76 | N12: 130
K13: 200 | L13: 23 | M13: 90 | N13: 150
D14: 100 | F14: 60 | G14: 30 | H14: -50 | I14: 50 | K14: 200 | L14: 24 | M14: 144 | N14: 210
D15: 100 | E15: 30 | F15: 50 | G15: 30 | H15: -50 | I15: 50 | K15: 210 | L15: 25 | M15: 13 | N15: 210
D16: 40 | K16: 260 | L16: 26
K17: 20 | L17: 27
B18: 200억
B19: 160 | D19: 100 | E19: 30 | F19: 50 | G19: 30 | H19: 0 | I19: 50 | K19: 200
B20: 210 | K20: 200

Sheet 소매
E62: 75 | F62: 76 | G62: 77 | H62: 78 | I62: 79 | J62: 80 | K62: 81 | L62: 82 | M62: 83 | N62: 84 | O62: 85 | P62: 86
B63: 구분 | E63: 2401 | F63: 2402 | G63: 2403 | H63: 2404 | I63: 2405 | J63: 2406 | K63: 2407 | L63: 2408 | M63: 2409 | N63: 2410 | O63: 2411 | P63: 2412 | Q63: 2501 | R63: 2502 | S63: 2503 | T63: 2504 | U63: 2505 | V63: 2506 | W63: 2507 | X63: 2508 | Y63: 2509 | Z63: 2510 | AA63: 2511 | AB63: 2512 | AC63: 25년 누적 | AD63: 25년 월평균
B64: 소매 | D64: 계 | E64: 27 | F64: 27.4 | G64: 26.9 | H64: 27.1 | I64: 26.8 | J64: 27.1 | K64: 27 | L64: 26.8 | M64: 26.9 | N64: 26.6 | O64: 26.4 | P64: 26 | Q64: 23.890354 | R64: 24.701307 | S64: 25.050896 | T64: 23.809409 | U64: 23.57592 | V64: =V65+V66 -> 24.228225 | W64: =W65+W66 -> 29.31502 | X64: =X65+X66 -> 27.780371 | Y64: =Y65+Y66 -> 28.513278 | Z64: =Z65+Z66 -> 28.406531
D65: 무선 | E65: =E64-E66 -> 23.232542 | F65: =F64-F66 -> 23.638276 | G65: =G64-G66 -> 23.080875 | H65: =H64-H66 -> 23.254129 | I65: =I64-I66 -> 23.032484 | J65: =J64-J66 -> 23.332455 | K65: =K64-K66 -> 23.242898 | L65: =L64-L66 -> 23.10626 | ... P65: =P64-P66 -> 22.313857 | Q65: 20.402818 | R65: 20.814096 | S65: 20.926437 | T65: 20.153446 | U65: 19.901026 | V65: 20.510782 | W65: 25.571297 | X65: 23.97615 | Y65: 24.691904 | Z65: 24.564483
D66: 유선 | E66: 3.7674583 | F66: 3.7617237 | G66: 3.8191253 | H66: 3.8458707 | I66: 3.7675159 | J66: 3.7675454 | K66: 3.7571025 | L66: 3.6937402 | M66: 3.7093376 | N66: 3.7197939 | O66: 3.6780862 | P66: 3.6861434 | Q66: 3.4875361 | R66: 3.8872114 | S66: 4.1244591 | T66: 3.6559634 | U66: 3.6748937 | V66: 3.717443 | W66: 3.7437236 | X66: 3.8042217 | Y66: 3.8213735 | Z66: 3.8420484
B67: 구분 | E67: 2401 | F67: 2402 | G67: 2403 | H67: 2404 | I67: 2405 | J67: 2406 | K67: 2407 | L67: 2408 | M67: 2409 | N67: 2410 | O67: 2411 | P67: 2412 | Q67: 2501 | R67: 2502 | S67: 2503 | T67: 2504 | U67: 2505 | V67: 2506 | W67: 2507 | X67: 2508 | Y67: 2509 | Z67: 2510 | AA67: 2511 | AB67: 2512 | AC67: 25년 누적 | AD67: 25년 월평균
B68: 기타 | D68: 계 | E68: =SUM(E69:E71) -> 8.3630735 | F68: =SUM(F69:F71) -> 7.4613188 | G68: =SUM(G69:G71) -> 7.5899538 | H68: =SUM(H69:H71) -> 4.8425968 | I68: =SUM(I69:I71) -> 6.1175147 | J68: =SUM(J69:J71) -> 6.3733313 | K68: =SUM(K69:K71) -> 7.9993811 | L68: =SUM(L69:L71) -> 7.1907803 | ... P68: =SUM(P69:P71) -> 21.060126 | Q68: 6.0540026 | R68: 7.735688 | S68: 4.721718 | T68: 13.896099 | U68: 4.3757565 | V68: =V69+V70+V71 -> 13.000696 | W68: =W69+W70+W71 -> 7.4690453 | X68: =X69+X70+X71 -> 6.4659674 | Y68: =Y69+Y70+Y71 -> 8.0688769 | Z68: =Z69+Z70+Z71 -> 7.2972452
D69: P3.0 | E69: 6.9 | F69: 7.3 | G69: 7.3 | H69: 7.35 | I69: 7.3868889 | J69: 7.3146808 | K69: 7.6354255 | L69: 7.4 | M69: 7.6538857 | N69: 7.8686388 | O69: 7.6142395 | P69: 7.94 | Q69: 7.9 | R69: 7.9716096 | S69: 7.4216384 | T69: 7.6139128 | U69: 7.622857 | V69: ='관리수수료 트렌드 정리'!Q92 -> 7.772182 | W69: 7.4912717 | X69: 6.6766701 | Y69: 6.9000007 | Z69: 6.872728
D70: 매장성수수료 | E70: 0.69062104 | F70: 0.67475181 | G70: 0.65596743 | H70: 0.66106861 | I70: 0.66754688 | J70: 0.64455618 | K70: 0.709512 | L70: 0.7051672 | M70: 0.62985633 | N70: 0.65229932 | O70: 0.63941378 | P70: 0.61422585 | Q70: 0.60595882 | R70: 0.66603878 | S70: 0.63645968 | T70: 0.57387266 | U70: 0.69777633 | V70: ='관리수수료 트렌드 정리'!R92 -> 0.75951674 | W70: 0.68965745 | X70: 0.63667796 | Y70: 0.63216598 | Z70: 0.58205908
D71: 본사공통 | E71: 0.77245242 | F71: -0.51343305 | G71: -0.36601364 | H71: -3.1684718 | I71: -1.9369211 | J71: -1.5859057 | K71: -0.34555639 | L71: -0.91438691 | M71: -2.7508403 | N71: 4.2134669 | O71: -4.3028273 | P71: 12.5059 | Q71: -2.4519562 | R71: -0.90196034 | S71: -3.3363801 | T71: 5.7083132 | U71: -3.9448768 | V71: ='관리수수료 트렌드 정리'!P92 -> 4.4689971 | W71: -0.7118838 | X71: -0.84738071 | Y71: 0.53671021 | Z71: -0.1575418
B72: 구분 | E72: 2401 | F72: 2402 | G72: 2403 | H72: 2404 | I72: 2405 | J72: 2406 | K72: 2407 | L72: 2408 | M72: 2409 | N72: 2410 | O72: 2411 | P72: 2412 | Q72: 2501 | R72: 2502 | S72: 2503 | T72: 2504 | U72: 2505 | V72: 2506 | W72: 2507 | X72: 2508 | Y72: 2509 | Z72: 2510 | AA72: 2511 | AB72: 2512 | AC72: 25년 누적 | AD72: 25년 월평균
B73: 소매 가입자 | D73: 계 | E73: =E74+E77 -> 894405 | F73: =F74+F77 -> 893011 | G73: =G74+G77 -> 892673 | H73: =H74+H77 -> 890727 | I73: =I74+I77 -> 889722 | J73: =J74+J77 -> 890125 | K73: =K74+K77 -> 890893 | L73: =L74+L77 -> 892043 | ... P73: =P74+P77 -> 886188 | Q73: 863927 | R73: 867687 | S73: 868817 | T73: 873806 | U73: 891478 | V73: =V74+V77 -> 829860 | W73: =W74+W77 -> 829106 | X73: =X74+X77 -> 825302 | Y73: =Y74+Y77 -> 820999 | Z73: =Z74+Z77 -> 815114
D74: 무선 | E74: 749129 | F74: 748834 | G74: 748987 | H74: 747221 | I74: 747650 | J74: 750317 | K74: 752257 | L74: 755901 | M74: 756168 | N74: 751500 | O74: 756006 | P74: 755811 | Q74: 751971 | R74: 752950 | S74: 752266 | T74: 754111 | U74: 766608 | V74: 764910 | W74: 762687 | X74: 758312 | Y74: 753607 | Z74: 748268
D75: 유선 | E75: 145276 | F75: 144177 | G75: 143686 | H75: 143506 | I75: 142072 | J75: 139808 | K75: 138636 | L75: 136142 | M75: 134595 | N75: 132436 | O75: 131753 | P75: 130377 | Q75: =Q76+Q77 -> 128645 | R75: =R76+R77 -> 129575 | S75: =S76+S77 -> 129166 | T75: =T76+T77 -> 129992 | U75: =U76+U77 -> 134949 | V75: =V76+V77 -> 135217 | W75: =W76+W77 -> 137095 | X75: =X76+X77 -> 137024 | ... Z75: =Z76+Z77 -> 135234
D76: 인터넷 | E76: 145276 | F76: 144177 | G76: 143686 | H76: 143506 | I76: 142072 | J76: 139808 | K76: 138636 | L76: 136142 | M76: 134595 | N76: 132436 | O76: 131753 | P76: 130377 | Q76: 69550 | R76: 69467 | S76: 68835 | T76: 68722 | U76: 70687 | V76: 70267 | W76: 70676 | X76: 70034 | Y76: 69511 | Z76: 68388
D77: TV | E77: 145276 | F77: 144177 | G77: 143686 | H77: 143506 | I77: 142072 | J77: 139808 | K77: 138636 | L77: 136142 | M77: 134595 | N77: 132436 | O77: 131753 | P77: 130377 | Q77: 59095 | R77: 60108 | S77: 60331 | T77: 61270 | U77: 64262 | V77: 64950 | W77: 66419 | X77: 66990 | Y77: 67392 | Z77: 66846
B78: 구분 | E78: 2401 | F78: 2402 | G78: 2403 | H78: 2404 | I78: 2405 | J78: 2406 | K78: 2407 | L78: 2408 | M78: 2409 | N78: 2410 | O78: 2411 | P78: 2412 | Q78: 2501 | R78: 2502 | S78: 2503 | T78: 2504 | U78: 2505 | V78: 2506 | W78: 2507 | X78: 2508 | Y78: 2509 | Z78: 2510 | AA78: 2511 | AB78: 2512 | AC78: 25년 누적 | AD78: 25년 월평균
B79: 소매 capa | D79: 계 | E79: =E80+E83 -> 26997 | F79: =F80+F83 -> 17538 | G79: =G80+G83 -> 19530 | H79: =H80+H83 -> 19429 | I79: =I80+I83 -> 19761 | J79: =J80+J83 -> 17706 | K79: =K80+K83 -> 25829 | L79: =L80+L83 -> 19335 | ... P79: =P80+P83 -> 16088 | Q79: 14423 | R79: 29919 | S79: 20890 | T79: 26775 | U79: 36758 | V79: =V80+V83 -> 20258 | W79: =W80+W83 -> 32204 | X79: =X80+X83 -> 19962 | Y79: =Y80+Y83 -> 25261 | Z79: =Z80+Z83 -> 16884
D80: 무선 | E80: 23395 | F80: 14757 | G80: 16162 | H80: 15877 | I80: 16156 | J80: 14591 | K80: 21830 | L80: 16249 | M80: 20549 | N80: 16254 | O80: 15024 | P80: 13168 | Q80: 11930 | R80: 25000 | S80: 17145 | T80: 22354 | U80: 29195 | V80: 18050 | W80: 29155 | X80: 17775 | Y80: 23129 | Z80: 15351
D81: 유선 | E81: 3602 | F81: 2781 | G81: 3368 | H81: 3552 | I81: 3605 | J81: 3115 | K81: 3999 | L81: 3086 | M81: 3272 | N81: 3263 | O81: 3254 | P81: 2920 | Q81: =Q82+Q83 -> 2493 | R81: =R82+R83 -> 4919 | S81: =S82+S83 -> 3745 | T81: =T82+T83 -> 4421 | U81: =U82+U83 -> 7563 | V81: =V82+V83 -> 4089 | W81: =W82+W83 -> 5722 | X81: =X82+X83 -> 3850 | ... Z81: =Z82+Z83 -> 2765
D82: 인터넷 | E82: 3602 | F82: 2781 | G82: 3368 | H82: 3552 | I82: 3605 | J82: 3115 | K82: 3999 | L82: 3086 | M82: 3272 | N82: 3263 | O82: 3254 | P82: 2920 | Q82: 1166 | R82: 2200 | S82: 1692 | T82: 2007 | U82: 3634 | V82: 1881 | W82: 2673 | X82: 1663 | Y82: 1839 | Z82: 1232
D83: TV | E83: 3602 | F83: 2781 | G83: 3368 | H83: 3552 | I83: 3605 | J83: 3115 | K83: 3999 | L83: 3086 | M83: 3272 | N83: 3263 | O83: 3254 | P83: 2920 | Q83: 1327 | R83: 2719 | S83: 2053 | T83: 2414 | U83: 3929 | V83: 2208 | W83: 3049 | X83: 2187 | Y83: 2132 | Z83: 1533
B84: 구분 | E84: 2401 | F84: 2402 | G84: 2403 | H84: 2404 | I84: 2405 | J84: 2406 | K84: 2407 | L84: 2408 | M84: 2409 | N84: 2410 | O84: 2411 | P84: 2412 | Q84: 2501 | R84: 2502 | S84: 2503 | T84: 2504 | U84: 2505 | V84: 2506 | W84: 2507 | X84: 2508 | Y84: 2509 | Z84: 2510 | AA84: 2511 | AB84: 2512 | AC84: 25년 누적 | AD84: 25년 월평균
B85: 소매 순증 | D85: 무선 | E85: 62 | F85: -295 | G85: 153 | H85: -1766 | I85: 429 | J85: 2667 | K85: 1940 | L85: 3644 | M85: 267 | N85: -4668 | O85: 4506 | P85: -195 | Q85: -3840 | R85: 979 | S85: -684 | T85: 1845 | U85: 12497 | V85: -1698 | W85: -2223 | X85: -4375 | Y85: -4705 | Z85: -5339
D86: 유선 | Q86: =Q87+Q88 -> -1732 | R86: =R87+R88 -> 930 | S86: =S87+S88 -> -409 | T86: =T87+T88 -> 826 | U86: =U87+U88 -> 4957 | V86: =V87+V88 -> 268 | W86: =W87+W88 -> 1878 | X86: =X87+X88 -> -71 | ... Z86: =Z87+Z88 -> -1669
D87: 인터넷 | Q87: -1254 | R87: -83 | S87: -632 | T87: -113 | U87: 1965 | V87: -420 | W87: 409 | X87: -642 | Y87: -523 | Z87: -1123
D88: TV | E88: 598 | F88: -1099 | G88: -491 | H88: -180 | I88: -1434 | J88: -2264 | K88: -1172 | L88: -2494 | M88: -1547 | N88: -2159 | O88: -683 | P88: -1190 | Q88: -478 | R88: 1013 | S88: 223 | T88: 939 | U88: 2992 | V88: 688 | W88: 1469 | X88: 571 | Y88: 402 | Z88: -546
B89: 구분 | E89: 2401 | F89: 2402 | G89: 2403 | H89: 2404 | I89: 2405 | J89: 2406 | K89: 2407 | L89: 2408 | M89: 2409 | N89: 2410 | O89: 2411 | P89: 2412 | Q89: 2501 | R89: 2502 | S89: 2503 | T89: 2504 | U89: 2505 | V89: 2506 | W89: 2507 | X89: 2508 | Y89: 2509 | Z89: 2510 | AA89: 2511 | AB89: 2512 | AC89: 25년 누적 | AD89: 25년 월평균
B90: 소매 유지 arpu | D90: 무선 | E90: =E65*100000000/E74/0.085*1.1/(1-E93) -> 40134.132 | F90: =F65*100000000/F74/0.085*1.1/(1-F93) -> 40851.124 | G90: =G65*100000000/G74/0.085*1.1/(1-G93) -> 39879.687 | H90: =H65*100000000/H74/0.085*1.1/(1-H93) -> 40274.001 | I90: =I65*100000000/I74/0.085*1.1/(1-I93) -> 39867.243 | J90: =J65*100000000/J74/0.085*1.1/(1-J93) -> 40242.912 | K90: =K65*100000000/K74/0.085*1.1/(1-K93) -> 39985.063 | L90: =L65*100000000/L74/0.085*1.1/(1-L93) -> 39558.38 | ... Y90: =Y65*100000000/Y74/0.085*1.1/(1-Y93) -> 42401.715
B91: 객관리 수수료 | D91: 유선 객관리수수료 | E91: =E66*100000000/E77*(1-E94) -> 2593.3109 | F91: =F66*100000000/F77*(1-F94) -> 2609.1011 | G91: =G66*100000000/G77*(1-G94) -> 2657.9662 | H91: =H66*100000000/H77*(1-H94) -> 2679.9372 | I91: =I66*100000000/I77*(1-I94) -> 2651.8356 | J91: =J66*100000000/J77*(1-J94) -> 2694.7996 | K91: =K66*100000000/K77*(1-K94) -> 2710.0482 | L91: =L66*100000000/L77*(1-L94) -> 2713.1526 | ... P91: =P66*100000000/P77*(1-P94) -> 2827.2957 | Q91: =Q66*100000000/Q75*(1-Q94) -> 2614.7771 | R91: =R66*100000000/R75*(1-R94) -> 2884.3193 | S91: =S66*100000000/S75*(1-S94) -> 3074.8556 | T91: =T66*100000000/T75*(1-T94) -> 2725.6914 | U91: =U66*100000000/U75*(1-U94) -> 2591.7577 | V91: =V66*100000000/V75*(1-V94) -> 2749.2423 | W91: =W66*100000000/W75*(1-W94) -> 2730.7514 | X91: =X66*100000000/X75*(1-X94) -> 2776.3178 | Y91: =Y66*100000000/Y75*(1-Y94) -> 2791.3
B92: 소매 해지율 | D92: 계 | Q92: 0.0184379 | R92: 0.033946573 | S92: 0.024767011 | T92: 0.027042616 | U92: 0.035423196
D93: 무선 | Q93: 0.015864974 | R93: 0.033189455 | S93: 0.022781835 | T93: 0.029641525 | U93: 0.038078131 | V93: =V85/V74 -> -0.002219869
D94: 유선(I) | Q94: 0.035485262 | R94: 0.038550679 | S94: 0.037045108 | T94: 0.030848928 | U94: 0.048257878
D95: 유선(TV) | Q95: 0.036103382 | R95: 0.039474266 | S95: 0.038351916 | T95: -0.016538167 | U95: -0.016886024 | V95: 0.016101074
D97: 무선CAPA | Q97: =Q74*Q93 -> 11930 | R97: =R74*R93 -> 24990 | S97: =S74*S93 -> 17138 | T97: =T74*T93 -> 22353 | U97: =U74*U93 -> 29191 | V97: =AVERAGE(Q97:U97) -> 21120.4
D98: 유선CAPA | Q98: 2493 | R98: 4919 | S98: 3745 | T98: 4421 | U98: 7563 | V98: =AVERAGE(Q98:U98) -> 4628.2
R99: =R66/Q66-1 -> 0.11460104 | S99: =S66/R66-1 -> 0.061032884 | T99: =T66/S66-1 -> -0.11358962 | U99: =U66/T66-1 -> 0.0051779463 | V99: =V66/U66-1 -> 0.011578363

Sheet 소매 (E)
B2: □ 소매 관리수수료
B3: 구분 | C3: 소매 | D3: 무선 | E3: 유선 | F3: 비고 | H3: 구분 | I3: 무선 CAPA | J3: 유선 CAPA | K3: 무선 CAPA 월평균 | L3: 유선 CAPA 월평균
B4: 24년 | C4: =SUM(E54:P54) -> 322 | D4: =SUM(E55:P55) -> 277.02656 | E4: =SUM(E56:P56) -> 44.973443 | H4: 24년 | I4: =SUM(E70:P70) -> 204012 | J4: =SUM(E71:P71) -> 39817 | K4: =I4/12 -> 17001 | L4: =J4/12 -> 3318.0833
B5: 25년 | C5: =SUM(R54:AC54) -> 290.27045 | D5: =SUM(R55:AC55) -> 244.88387 | E5: =SUM(R56:AC56) -> 45.386576 | H5: 25년 (E) | I5: =SUM(R70:AC70) -> 235577 | J5: =SUM(R71:AC71) -> 50993.2 | K5: =I5/12 -> 19631.417 | L5: =J5/12 -> 4249.4333
B6: 26년 (E) | C6: =SUM(AE54:AP54) -> 283.04189 | D6: =SUM(AE55:AP55) -> 238.64189 | E6: =SUM(AE56:AP56) -> 44.4 | H6: 26년 (E) | I6: =SUM(AE70:AP70) -> 235577 | J6: =SUM(R72:AC72) -> 30078 | K6: =I6/12 -> 19631.417 | L6: =J6/12 -> 2506.5
B7: 27년 (E) | H7: 27년 (E) | K7: =I7/12 -> 0 | L7: =J7/12 -> 0
B9: 구분 | C9: 기타 | D9: P3.0 | E9: 매장성 | F9: 본사 공통
B10: 24년 | C10: =D10+E10+F10 -> 99.216209 | D10: =SUM(E59:P59) -> 89.663759 | E10: =SUM(E60:P60) -> 7.9449864 | F10: =SUM(E61:P61) -> 1.6074637
B11: 25년 | C11: =D11+E11+F11 -> 94.772779 | D11: =SUM(R59:AC59) -> 87.933781 | E11: =SUM(R60:AC60) -> 8.1954289 | F11: =SUM(R61:AC61) -> -1.3564302
B12: 26년 (E)
B13: 27년 (E)
E52: 75 | F52: 76 | G52: 77 | H52: 78 | I52: 79 | J52: 80 | K52: 81 | L52: 82 | M52: 83 | N52: 84 | O52: 85 | P52: 86
B53: 구분 | E53: 2401 | F53: 2402 | G53: 2403 | H53: 2404 | I53: 2405 | J53: 2406 | K53: 2407 | L53: 2408 | M53: 2409 | N53: 2410 | O53: 2411 | P53: 2412 | R53: 2501 | S53: 2502 | T53: 2503 | U53: 2504 | V53: 2505 | W53: 2506 | X53: 2507 | Y53: 2508 | Z53: 2509 | AA53: 2510 | AB53: 2511 | AC53: 2512 | AE53: 2601 | AF53: 2602 | AG53: 2603 | AH53: 2604 | AI53: 2605 | AJ53: 2606 | AK53: 2607 | AL53: 2608 | AM53: 2609 | AN53: 2610 | AO53: 2611 | AP53: 2612 | AQ53: 25년 누적 | AR53: 25년 월평균
B54: 소매 | D54: 계 | E54: 27 | F54: 27.4 | G54: 26.9 | H54: 27.1 | I54: 26.8 | J54: 27.1 | K54: 27 | L54: 26.8 | M54: 26.9 | N54: 26.6 | O54: 26.4 | P54: 26 | R54: 23.890354 | S54: 24.701307 | T54: 25.050896 | U54: 23.809409 | V54: 23.57592 | W54: 24.228225 | X54: 25.571297 | Y54: 23.97615 | Z54: 24.059738 | AA54: 23.890146 | AB54: 23.781975 | AC54: 23.735033 | AE54: =AE55+AE56 -> 23.636791 | AF54: =AF55+AF56 -> 23.906079 | AG54: =AG55+AG56 -> 24.061123 | AH54: =AH55+AH56 -> 23.242945 | AI54: =AI55+AI56 -> 22.731501 | AJ54: =AJ55+AJ56 -> 23.693367 | AK54: =AK55+AK56 -> 24.990446 | AL54: =AL55+AL56 -> 23.429924 | ... AP54: =AP55+AP56 -> 23.251226 | AQ54: 97.451966 | AR54: 24.205577
D55: 무선 | E55: =E54-E56 -> 23.232542 | F55: =F54-F56 -> 23.638276 | G55: =G54-G56 -> 23.080875 | H55: =H54-H56 -> 23.254129 | I55: =I54-I56 -> 23.032484 | J55: =J54-J56 -> 23.332455 | K55: =K54-K56 -> 23.242898 | L55: =L54-L56 -> 23.10626 | ... P55: =P54-P56 -> 22.313857 | R55: 20.402818 | S55: 20.814096 | T55: 20.926437 | U55: 20.153446 | V55: 19.901026 | W55: =W54-W56 -> 20.510782 | X55: =X54-X56 -> 21.827573 | Y55: =Y54-Y56 -> 20.171928 | Z55: =Z54-Z56 -> 20.238365 | AA55: =AA54-AA56 -> 20.048097 | AB55: =AB54-AB56 -> 19.990058 | AC55: =AC54-AC56 -> 19.899248 | AE55: =AC64*0.085/1.1/100000000*AE76*(1-R79) -> 19.936791 | AF55: =AE64*0.085/1.1/100000000*AF76*(1-S79) -> 20.206079 | AG55: =AF64*0.085/1.1/100000000*AG76*(1-T79) -> 20.361123 | AH55: =AG64*0.085/1.1/100000000*AH76*(1-U79) -> 19.542945 | AI55: =AH64*0.085/1.1/100000000*AI76*(1-V79) -> 19.031501 | AJ55: =AI64*0.085/1.1/100000000*AJ76*(1-W79) -> 19.993367 | AK55: =AJ64*0.085/1.1/100000000*AK76*(1-X79) -> 21.290446 | AL55: =AK64*0.085/1.1/100000000*AL76*(1-Y79) -> 19.729924 | AM55: =AL64*0.085/1.1/100000000*AM76*(1-Z79) -> 19.800999 | ... AP55: =AO64*0.085/1.1/100000000*AP76*(1-AC79) -> 19.551226 | AQ55: =SUM(R55:AC55) -> 244.88387 | AR55: 20.439564
D56: 유선 | E56: 3.7674583 | F56: 3.7617237 | G56: 3.8191253 | H56: 3.8458707 | I56: 3.7675159 | J56: 3.7675454 | K56: 3.7571025 | L56: 3.6937402 | M56: 3.7093376 | N56: 3.7197939 | O56: 3.6780862 | P56: 3.6861434 | R56: 3.4875361 | S56: 3.8872114 | T56: 4.1244591 | U56: 3.6559634 | V56: 3.6748937 | W56: 3.717443 | X56: 3.7437236 | Y56: 3.8042217 | Z56: 3.8213735 | AA56: 3.8420484 | AB56: 3.7919169 | AC56: 3.8357851 | AE56: 3.7 | AF56: 3.7 | AG56: 3.7 | AH56: 3.7 | AI56: 3.7 | AJ56: 3.7 | AK56: 3.7 | AL56: 3.7 | AM56: 3.7 | AN56: 3.7 | AO56: 3.7 | AP56: 3.7 | AQ56: 15.15517 | AR56: 3.7660127
B57: 구분 | E57: 2401 | F57: 2402 | G57: 2403 | H57: 2404 | I57: 2405 | J57: 2406 | K57: 2407 | L57: 2408 | M57: 2409 | N57: 2410 | O57: 2411 | P57: 2412 | R57: 2501 | S57: 2502 | T57: 2503 | U57: 2504 | V57: 2505 | W57: 2506 | X57: 2507 | Y57: 2508 | Z57: 2509 | AA57: 2510 | AB57: 2511 | AC57: 2512 | AE57: 2601 | AF57: 2602 | AG57: 2603 | AH57: 2604 | AI57: 2605 | AJ57: 2606 | AK57: 2607 | AL57: 2608 | AM57: 2609 | AN57: 2610 | AO57: 2611 | AP57: 2612 | AQ57: 25년 누적 | AR57: 25년 월평균
B58: 기타 | D58: 계 | E58: =SUM(E59:E61) -> 8.3630735 | F58: =SUM(F59:F61) -> 7.4613188 | G58: =SUM(G59:G61) -> 7.5899538 | H58: =SUM(H59:H61) -> 4.8425968 | I58: =SUM(I59:I61) -> 6.1175147 | J58: =SUM(J59:J61) -> 6.3733313 | K58: =SUM(K59:K61) -> 7.9993811 | L58: =SUM(L59:L61) -> 7.1907803 | ... P58: =SUM(P59:P61) -> 21.060126 | R58: 6.0540026 | S58: 7.735688 | T58: 4.721718 | U58: 13.896099 | V58: 4.3757565 | W58: =W59+W60+W61 -> 13.000696 | X58: =X59+X60+X61 -> 7.4690453 | Y58: =Y59+Y60+Y61 -> 6.4659674 | Z58: =Z59+Z60+Z61 -> 8.0688769 | AA58: =AA59+AA60+AA61 -> 7.2972452 | AB58: =AB59+AB60+AB61 -> 7.4603885 | AC58: =AC59+AC60+AC61 -> 8.2272964 | AE58: =AE59+AE60+AE61 -> 7.6 | AF58: =AF59+AF60+AF61 -> 7.6 | AG58: =AG59+AG60+AG61 -> 7.6 | AH58: =AH59+AH60+AH61 -> 7.6 | AI58: =AI59+AI60+AI61 -> 7.6 | AJ58: =AJ59+AJ60+AJ61 -> 7.6 | AK58: =AK59+AK60+AK61 -> 7.6 | AL58: =AL59+AL60+AL61 -> 7.6 | ... AP58: =AP59+AP60+AP61 -> 7.6 | AQ58: 32.407507 | AR58: 7.3566528
D59: P3.0 | E59: 6.9 | F59: 7.3 | G59: 7.3 | H59: 7.35 | I59: 7.3868889 | J59: 7.3146808 | K59: 7.6354255 | L59: 7.4 | M59: 7.6538857 | N59: 7.8686388 | O59: 7.6142395 | P59: 7.94 | R59: 7.9 | S59: 7.9716096 | T59: 7.4216384 | U59: 7.6139128 | V59: 7.622857 | W59: 7.772182 | X59: 7.4912717 | Y59: 6.6766701 | Z59: 6.9000007 | AA59: 6.872728 | AB59: 6.8454552 | AC59: 6.8454552 | AE59: 7.5 | AF59: 7.5 | AG59: 7.5 | AH59: 7.5 | AI59: 7.5 | AJ59: 7.5 | AK59: 7.5 | AL59: 7.5 | AM59: 7.5 | AN59: 7.5 | AO59: 7.5 | AP59: 7.5 | AQ59: 30.907161 | AR59: 7.7060036
D60: 매장성수수료 | E60: 0.69062104 | F60: 0.67475181 | G60: 0.65596743 | H60: 0.66106861 | I60: 0.66754688 | J60: 0.64455618 | K60: 0.709512 | L60: 0.7051672 | M60: 0.62985633 | N60: 0.65229932 | O60: 0.63941378 | P60: 0.61422585 | R60: 0.60595882 | S60: 0.66603878 | T60: 0.63645968 | U60: 0.57387266 | V60: 0.69777633 | W60: 0.75951674 | X60: 0.68965745 | Y60: 0.63667796 | Z60: 0.63216598 | AA60: 0.58205908 | AB60: 0.81182807 | AC60: 0.90341731 | AE60: 0.6 | AF60: 0.6 | AG60: 0.6 | AH60: 0.6 | AI60: 0.6 | AJ60: 0.6 | AK60: 0.6 | AL60: 0.6 | AM60: 0.6 | AN60: 0.6 | AO60: 0.6 | AP60: 0.6 | AQ60: 2.4823299 | AR60: 0.63602125
D61: 본사공통 | E61: 0.77245242 | F61: -0.51343305 | G61: -0.36601364 | H61: -3.1684718 | I61: -1.9369211 | J61: -1.5859057 | K61: -0.34555639 | L61: -0.91438691 | M61: -2.7508403 | N61: 4.2134669 | O61: -4.3028273 | P61: 12.5059 | R61: -2.4519562 | S61: -0.90196034 | T61: -3.3363801 | U61: 5.7083132 | V61: -3.9448768 | W61: 4.4689971 | X61: -0.7118838 | Y61: -0.84738071 | Z61: 0.53671021 | AA61: -0.1575418 | AB61: -0.1968948 | AC61: ='관리수수료 트렌드 정리'!P98 -> 0.47842386 | AE61: -0.5 | AF61: -0.5 | AG61: -0.5 | AH61: -0.5 | AI61: -0.5 | AJ61: -0.5 | AK61: -0.5 | AL61: -0.5 | AM61: -0.5 | AN61: -0.5 | AO61: -0.5 | AP61: -0.5 | AQ61: -0.98198339 | AR61: -0.98537205
B62: 구분 | E62: 2401 | F62: 2402 | G62: 2403 | H62: 2404 | I62: 2405 | J62: 2406 | K62: 2407 | L62: 2408 | M62: 2409 | N62: 2410 | O62: 2411 | P62: 2412 | R62: 2501 | S62: 2502 | T62: 2503 | U62: 2504 | V62: 2505 | W62: 2506 | X62: 2507 | Y62: 2508 | Z62: 2509 | AA62: 2510 | AB62: 2511 | AC62: 2512 | AE62: 2601 | AF62: 2602 | AG62: 2603 | AH62: 2604 | AI62: 2605 | AJ62: 2606 | AK62: 2607 | AL62: 2608 | AM62: 2609 | AN62: 2610 | AO62: 2611 | AP62: 2612 | AQ62: 25년 누적 | AR62: 25년 월평균
B63: 소매 가입자 | D63: 계 | E63: =E64+E65 -> 894405 | F63: =F64+F65 -> 893011 | G63: =G64+G65 -> 892673 | H63: =H64+H65 -> 890727 | I63: =I64+I65 -> 889722 | J63: =J64+J65 -> 890125 | K63: =K64+K65 -> 890893 | L63: =L64+L65 -> 892043 | ... P63: =P64+P65 -> 886188 | R63: 863927 | S63: 867687 | T63: 868817 | U63: 873806 | V63: 891478 | W63: =W64+W65 -> 900127 | X63: =X64+X65 -> 899782 | Y63: =Y64+Y65 -> 895336 | Z63: =Z64+Z65 -> 890510 | AA63: =AA64+AA65 -> 883502 | AB63: =AB64+AB65 -> 876733 | AC63: =AC64+AC65 -> 867471 | AQ63: 3474237
D64: 무선 | E64: 749129 | F64: 748834 | G64: 748987 | H64: 747221 | I64: 747650 | J64: 750317 | K64: 752257 | L64: 755901 | M64: 756168 | N64: 751500 | O64: 756006 | P64: 755811 | R64: 751971 | S64: 752950 | T64: 752266 | U64: 754111 | V64: 766608 | W64: 764910 | X64: 762687 | Y64: 758312 | Z64: 753607 | AA64: 748268 | AB64: 742935 | AC64: 734795 | AE64: =AC64+AE73 -> 730955 | AF64: =AE64+AF73 -> 731944 | AG64: =AF64+AG73 -> 731267 | AH64: =AG64+AH73 -> 733113 | AI64: =AH64+AI73 -> 745614 | AJ64: =AI64+AJ73 -> 743919 | AK64: =AJ64+AK73 -> 741696 | AL64: =AK64+AL73 -> 737321 | AM64: =AL64+AM73 -> 732616 | ... AP64: =AO64+AP73 -> 713804 | AQ64: 3011298
D65: 유선 | E65: 145276 | F65: 144177 | G65: 143686 | H65: 143506 | I65: 142072 | J65: 139808 | K65: 138636 | L65: 136142 | M65: 134595 | N65: 132436 | O65: 131753 | P65: 130377 | R65: 128645 | S65: 129575 | T65: 129166 | U65: 129992 | V65: 134949 | W65: 135217 | X65: 137095 | Y65: 137024 | Z65: 136903 | AA65: 135234 | AB65: 133798 | AC65: 132676 | AQ65: 462939
R66: 69550 | S66: 69467 | T66: 68835 | U66: 68722 | V66: 70687 | W66: 70267 | X66: 70676 | Y66: 70034 | Z66: 69511 | AA66: 68388 | AB66: 67227 | AC66: 66318
R67: 59095 | S67: 60108 | T67: 60331 | U67: 61270 | V67: 64262 | W67: 64950 | X67: 66419 | Y67: 66990 | Z67: 67392 | AA67: 66846 | AB67: 66571 | AC67: 66358
B68: 구분 | E68: 2401 | F68: 2402 | G68: 2403 | H68: 2404 | I68: 2405 | J68: 2406 | K68: 2407 | L68: 2408 | M68: 2409 | N68: 2410 | O68: 2411 | P68: 2412 | R68: 2501 | S68: 2502 | T68: 2503 | U68: 2504 | V68: 2505 | W68: 2506 | X68: 2507 | Y68: 2508 | Z68: 2509 | AA68: 2510 | AB68: 2511 | AC68: 2512 | AE68: 2601 | AF68: 2602 | AG68: 2603 | AH68: 2604 | AI68: 2605 | AJ68: 2606 | AK68: 2607 | AL68: 2608 | AM68: 2609 | AN68: 2610 | AO68: 2611 | AP68: 2612 | AQ68: 25년 누적 | AR68: 25년 월평균
B69: 소매 capa | D69: 계 | E69: =E70+E71 -> 26997 | F69: =F70+F71 -> 17538 | G69: =G70+G71 -> 19530 | H69: =H70+H71 -> 19429 | I69: =I70+I71 -> 19761 | J69: =J70+J71 -> 17706 | K69: =K70+K71 -> 25829 | L69: =L70+L71 -> 19335 | ... P69: =P70+P71 -> 16088 | R69: 14423 | S69: 29919 | T69: 20890 | U69: 26775 | V69: 36758 | W69: =W70+W71 -> 22139 | X69: 22139 | Y69: 22139 | Z69: 22139 | AA69: 22139 | AB69: 22139 | AC69: 22139 | AQ69: 92007
D70: 무선 | E70: 23395 | F70: 14757 | G70: 16162 | H70: 15877 | I70: 16156 | J70: 14591 | K70: 21830 | L70: 16249 | M70: 20549 | N70: 16254 | O70: 15024 | P70: 13168 | R70: 11930 | S70: 25000 | T70: 17145 | U70: 22356 | V70: 29195 | W70: 18050 | X70: 29155 | Y70: 17775 | Z70: 23129 | AA70: 15351 | AB70: 13674 | AC70: 12817 | AE70: 11930 | AF70: 25000 | AG70: 17145 | AH70: 22356 | AI70: 29195 | AJ70: 18050 | AK70: 29155 | AL70: 17775 | AM70: 23129 | AN70: 15351 | AO70: 13674 | AP70: 12817 | AQ70: 76429
D71: 유선 | E71: 3602 | F71: 2781 | G71: 3368 | H71: 3552 | I71: 3605 | J71: 3115 | K71: 3999 | L71: 3086 | M71: 3272 | N71: 3263 | O71: 3254 | P71: 2920 | R71: 2493 | S71: 4919 | T71: 3745 | U71: 4421 | V71: 7563 | W71: 4089 | X71: 5722 | Y71: 3850 | Z71: 3971 | AA71: 2765 | AB71: 2827 | AC71: 4628.2 | AE71: 2493 | AF71: 4919 | AG71: 3745 | AH71: 4421 | AI71: 7563 | AJ71: 4089 | AK71: 5722 | AL71: 3850 | AM71: 3971 | AN71: 2765 | AO71: 2827 | AP71: 4628.2 | AQ71: 15578
B72: 구분 | E72: 2401 | F72: 2402 | G72: 2403 | H72: 2404 | I72: 2405 | J72: 2406 | K72: 2407 | L72: 2408 | M72: 2409 | N72: 2410 | O72: 2411 | P72: 2412 | R72: 2501 | S72: 2502 | T72: 2503 | U72: 2504 | V72: 2505 | W72: 2506 | X72: 2507 | Y72: 2508 | Z72: 2509 | AA72: 2510 | AB72: 2511 | AC72: 2512 | AE72: 2601 | AF72: 2602 | AG72: 2603 | AH72: 2604 | AI72: 2605 | AJ72: 2606 | AK72: 2607 | AL72: 2608 | AM72: 2609 | AN72: 2610 | AO72: 2611 | AP72: 2612 | AQ72: 25년 누적 | AR72: 25년 월평균
B73: 소매 순증 | D73: 무선 | E73: 62 | F73: -295 | G73: 153 | H73: -1766 | I73: 429 | J73: 2667 | K73: 1940 | L73: 3644 | M73: 267 | N73: -4668 | O73: 4506 | P73: -195 | R73: -3840 | S73: 979 | T73: -684 | U73: 1845 | V73: 12497 | W73: -1698 | X73: -2223 | Y73: -4375 | Z73: -4705 | AA73: -5339 | AB73: =AB64-AA64 -> -5333 | AC73: =AC64-AB64 -> -8140 | AE73: =AE70-(R82+R83+R84) -> -3840 | AF73: =AF70-(S82+S83+S84) -> 989 | AG73: =AG70-(T82+T83+T84) -> -677 | AH73: =AH70-(U82+U83+U84) -> 1846 | AI73: =AI70-(V82+V83+V84) -> 12501 | AJ73: =AJ70-(W82+W83+W84) -> -1695 | AK73: =AK70-(X82+X83+X84) -> -2223 | AL73: =AL70-(Y82+Y83+Y84) -> -4375 | ... AP73: =AP70-(AC82+AC83+AC84) -> -8140 | AQ73: 22
D74: 유선 | E74: 598 | F74: -1099 | G74: -491 | H74: -180 | I74: -1434 | J74: -2264 | K74: -1172 | L74: -2494 | M74: -1547 | N74: -2159 | O74: -683 | P74: -1190 | R74: -1732 | S74: 930 | T74: -409 | U74: 826 | V74: 4957 | W74: 268 | X74: 1878 | Y74: -71 | Z74: -121 | AA74: -1669 | AB74: -1436 | AC74: =AC65-AB65 -> -1122 | AQ74: 6632
B75: 구분 | E75: 2401 | F75: 2402 | G75: 2403 | H75: 2404 | I75: 2405 | J75: 2406 | K75: 2407 | L75: 2408 | M75: 2409 | N75: 2410 | O75: 2411 | P75: 2412 | R75: 2501 | S75: 2502 | T75: 2503 | U75: 2504 | V75: 2505 | W75: 2506 | X75: 2507 | Y75: 2508 | Z75: 2509 | AA75: 2510 | AB75: 2511 | AC75: 2512 | AE75: 2601 | AF75: 2602 | AG75: 2603 | AH75: 2604 | AI75: 2605 | AJ75: 2606 | AK75: 2607 | AL75: 2608 | AM75: 2609 | AN75: 2610 | AO75: 2611 | AP75: 2612 | AQ75: 25년 누적 | AR75: 25년 월평균
B76: 소매 유지 arpu | D76: 무선 | E76: =E55*100000000/E64/0.085*1.1/(1-E79) -> 40134.132 | F76: =F55*100000000/F64/0.085*1.1/(1-F79) -> 40851.124 | G76: =G55*100000000/G64/0.085*1.1/(1-G79) -> 39879.687 | H76: =H55*100000000/H64/0.085*1.1/(1-H79) -> 40274.001 | I76: =I55*100000000/I64/0.085*1.1/(1-I79) -> 39867.243 | J76: =J55*100000000/J64/0.085*1.1/(1-J79) -> 40242.912 | K76: =K55*100000000/K64/0.085*1.1/(1-K79) -> 39985.063 | L76: =L55*100000000/L64/0.085*1.1/(1-L79) -> 39558.38 | ... P76: =P55*100000000/P64/0.085*1.1/(1-P79) -> 38206.318 | R76: =R55*100000000/R64/0.085*1.1/(1-R79) -> 35864.725 | S76: =S55*100000000/S64/0.085*1.1/(1-S79) -> 36952.185 | T76: =T55*100000000/T64/0.085*1.1/(1-T79) -> 36873.161 | U76: =U55*100000000/U64/0.085*1.1/(1-U79) -> 35551.928 | V76: =V55*100000000/V64/0.085*1.1/(1-V79) -> 34342.963 | W76: =W55*100000000/W64/0.085*1.1/(1-W79) -> 35620.789 | X76: =X55*100000000/X64/0.085*1.1/(1-X79) -> 38625.871 | Y76: =Y55*100000000/Y64/0.085*1.1/(1-Y79) -> 35460.738 | ... AC76: =AC55*100000000/AC64/0.085*1.1/(1-AC79) -> 36075.368 | AE76: 35864.725 | AF76: 36952.185 | AG76: 36873.161 | AH76: 35551.928 | AI76: 34342.963 | AJ76: 35620.789 | AK76: 38625.871 | AL76: 35460.738 | AM76: 36086.8 | AN76: 35658.852 | AO76: 35734.889 | AP76: 36075.368
B77: 객관리 수수료 | D77: 유선 객관리수수료 | E77: =E56*100000000/E65*(1-E80) -> 2593.3109 | F77: =F56*100000000/F65*(1-F80) -> 2609.1011 | G77: =G56*100000000/G65*(1-G80) -> 2657.9662 | H77: =H56*100000000/H65*(1-H80) -> 2679.9372 | I77: =I56*100000000/I65*(1-I80) -> 2651.8356 | J77: =J56*100000000/J65*(1-J80) -> 2694.7996 | K77: =K56*100000000/K65*(1-K80) -> 2710.0482 | L77: =L56*100000000/L65*(1-L80) -> 2713.1526 | ... P77: =P56*100000000/P65*(1-P80) -> 2827.2957 | R77: =R56*100000000/(R66*(1-R80)+R67*(1-R81)) -> 2803.035 | S77: =S56*100000000/(S66*(1-S80)+S67*(1-S81)) -> 3095.2585 | T77: =T56*100000000/(T66*(1-T80)+T67*(1-T81)) -> 3299.2505 | U77: =U56*100000000/(U66*(1-U80)+U67*(1-U81)) -> 2892.4447 | V77: =V56*100000000/(V66*(1-V80)+V67*(1-V81)) -> 2776.7949 | W77: =W56*100000000/(W66*(1-W80)+W67*(1-W81)) -> 2829.1904 | X77: =X56*100000000/(X66*(1-X80)+X67*(1-X81)) -> 2809.5276 | Y77: =Y56*100000000/(Y66*(1-Y80)+Y67*(1-Y81)) -> 2858.1036 | ... AC77: =AC56*100000000/(AC66*(1-AC80)+AC67*(1-AC81)) -> 2976.4995
B78: 소매 해지율 | D78: 계 | R78: 0.0184379 | S78: 0.033946573 | T78: 0.024767011 | U78: 0.027042616 | V78: 0.035423196 | AQ78: 0.1041941
D79: 무선 | R79: 0.020971553 | S79: 0.031889236 | T79: 0.023691088 | U79: 0.027197588 | V79: 0.021776449 | W79: 0.025813494 | X79: 0.041141386 | Y79: 0.029209613 | Z79: 0.03693437 | AA79: 0.027650521 | AB79: 0.025583665 | AC79: 0.02852088 | AQ79: 0.10147779
D80: 유선(I) | R80: =R90 -> 0.034795111 | S80: =S90 -> 0.032864526 | T80: =T90 -> 0.033761894 | U80: =U90 -> 0.030848928 | V80: =V90 -> 0.023611131 | W80: =W90 -> 0.032746524 | X80: =X90 -> 0.032033505 | Y80: =Y90 -> 0.032912585 | ... AC80: =AC90 -> 0.031831479 | AQ80: 0.14192998
...

Sheet 도매
B28: 구분 | E28: 2501 | F28: 2502 | G28: 2503 | H28: 2504 | I28: 2505 | J28: 2506 | K28: 2507 | L28: 2508 | M28: 2509 | N28: 2510 | O28: 2511 | P28: 2512 | Q28: 25년 누적 | R28: 25년 월평균
B29: 도매 관리수수료 | D29: 계(win-win 포함) | E29: =E30+E35 -> 10.268494 | F29: =F30+F35+E35 -> 11.618201 | G29: =G30+G35 -> 10.12257 | H29: =H30+H35 -> 9.7292867 | I29: =I30+I35 -> 9.4927223 | J29: =J30 -> 11.278029 | Q29: 34.743971 | R29: 8.4690585
D30: 계 | E30: 9.1 | F30: 9.0830929 | G30: 8.5529126 | H30: 8.0079655 | I30: 7.6013216 | J30: ='관리수수료 트렌드 정리'!C92 -> 11.278029 | K30: 9.470221 | L30: 9.1583625 | M30: 9.0471217 | N30: 8.8861889 | Q30: 34.743971 | R30: 8.4690585
D31: 무선 | E31: =E30-E32-E33-E34 -> 1.6986729 | F31: =F30-F32-F33-F34 -> 1.7475366 | G31: =G30-G32-G33-G34 -> 1.4124376 | H31: =H30-H32-H33-H34 -> 1.5719565 | I31: =I30-I32-I33-I34 -> 1.5193557 | J31: =J30-J32-J33-J34-J35-I35 -> 1.4699261 | K31: =K30-K32-K33-K34-K35 -> 1.5963926 | L31: =L30-L32-L33-L34-L35 -> 1.387607 | M31: =M30-M32-M33-M34-M35 -> 1.3495309 | N31: =N30-N32-N33-N34-N35 -> 1.2755036 | Q31: 10.8594 | R31: 2.6479277
D32: 점프업 | E32: 1.2637932 | F32: 1.1657934 | G32: 1.0448888 | H32: 0.95432054 | I32: 0.86088327 | J32: 0.7662568 | K32: 0.66542558 | L32: 0.58167732 | M32: 0.50999542 | N32: 0.42652902
D33: 유선 | E33: 1.9975339 | F33: 2.0294241 | G33: 2.2323665 | H33: 1.8044475 | I33: 1.7026086 | J33: 1.5949692 | K33: 1.4921995 | L33: 1.4055083 | M33: 1.3104795 | N33: 1.2273193 | Q33: 8.0637721 | R33: 1.9532761
D34: H.C | E34: 4.14 | F34: 4.1403388 | G34: 3.8632196 | H34: 3.6772409 | I34: 3.5184741 | J34: 3.3729352 | K34: 3.2175035 | L34: 3.0304162 | M34: 2.8506906 | N34: 2.6879537 | Q34: 15.820799 | R34: 3.8678547
D35: Win-Win H.C | E35: 1.1684938 | F35: 1.3666145 | G35: 1.5696575 | H35: 1.7213212 | I35: 1.8914007 | J35: 2.1825411 | K35: 2.4986998 | L35: 2.7531537 | M35: 3.0264253 | N35: 3.2688833
B36: 도매 가입자 | D36: 계 | E36: 738464 | F36: 709587 | G36: 686178 | H36: 662458 | I36: 639166 | J36: =J37+J38+J41 -> 614364 | K36: =K37+K38+K41 -> 583185 | L36: =L37+L38+L41 -> 556731 | M36: =M37+M38+M41 -> 531164 | N36: =N37+N38+N41 -> 507552 | Q36: 2796687
D37: 무선(점프업포함) | E37: 66322 | F37: 64615 | G37: 63539 | H37: 62009 | I37: 61102 | J37: 59733 | K37: 57967 | L37: 56554 | M37: 54874 | N37: 53548 | Q37: 256485
D38: 유선 | E38: =E39+E40 -> 89486 | F38: =F39+F40 -> 85565 | G38: =G39+G40 -> 81161 | H38: =H39+H40 -> 76871 | I38: =I39+I40 -> 72596 | J38: =J39+J40 -> 68144 | K38: =K39+K40 -> 63626 | L38: =L39+L40 -> 59480 | ... N38: =N39+N40 -> 52411 | Q38: 333083
D39: 유선(I) | E39: 44891 | F39: 42582 | G39: 40286 | H39: 38053 | I39: 35974 | J39: 33891 | K39: 31645 | L39: 29508 | M39: 27707 | N39: 25748
D40: 유선(TV) | E40: 44595 | F40: 42983 | G40: 40875 | H40: 38818 | I40: 36622 | J40: 34253 | K40: 31981 | L40: 29972 | M40: 28369 | N40: 26663
D41: H.C | E41: 582656 | F41: 559407 | G41: 541478 | H41: 523578 | I41: 505468 | J41: 486487 | K41: 461592 | L41: 440697 | M41: 420214 | N41: 401593 | Q41: 2207119
B42: 도매 CAPA | D42: 계 | E42: 20704 | F42: 30404 | G42: 23182 | H42: 28296 | I42: 44209 | J42: =J44+J45+J46 -> 34432 | K42: =K44+K45+K46 -> 38252 | L42: =L44+L45+L46 -> 30197 | M42: =M44+M45+M46 -> 32574 | N42: =N44+N45+N46 -> 30662 | Q42: 102586
D43: 무선 | Q43: 0
D44: 유선(I) | E44: 1637 | F44: 2086 | G44: 1810 | H44: 1896 | I44: 3639 | J44: 2896 | K44: 2548 | L44: 2549 | M44: 2550 | N44: 1819 | Q44: 7429
D45: 유선(TV) | E45: 1828 | F45: 2334 | G45: 2074 | H45: 2120 | I45: 4113 | J45: 3180 | K45: 2864 | L45: 2865 | M45: 2866 | N45: 1989 | Q45: 8356
D46: H.C | E46: 17239 | F46: 25984 | G46: 19298 | H46: 24280 | I46: 36457 | J46: 28356 | K46: 32840 | L46: 24783 | M46: 27158 | N46: 26854 | Q46: 86801
B47: 도매 해지 | D47: 계 | E47: 31918 | F47: 48864 | G47: 36511 | H47: 41775 | I47: 53023 | Q47: 159068
D48: 무선 | E48: 1268 | F48: 1707 | G48: 1076 | H48: 1530 | I48: 907 | Q48: 4520
D49: 유선(I) | E49: 3785 | F49: 4013 | G49: 4106 | H49: 4129 | I49: 5718 | Q49: 2488
D50: 유선(TV) | E50: 3309 | F50: 3517 | G50: 4182 | H50: 4177 | I50: 6309 | Q50: 3232
D51: H.C | E51: 33142 | F51: 49233 | G51: 37227 | H51: 42180 | I51: 54567 | Q51: 148828
B52: 도매 순증 | D52: 무선 | E52: -1268 | F52: -1707 | G52: -1076 | H52: -1530 | I52: -907 | J52: -1369 | K52: -1766 | L52: -1413 | M52: -1680 | N52: -1326 | Q52: -6488
D53: 유선(I) | E53: -2148 | F53: -2309 | G53: -2296 | H53: -2233 | I53: -2079 | J53: -2083 | K53: -2246 | L53: -2137 | M53: -1801 | N53: -1959 | Q53: -10683
D54: 유선(TV) | E54: -1481 | F54: -1183 | G54: -2108 | H54: -2057 | I54: -2196 | J54: -2369 | K54: -2272 | L54: -2009 | M54: -1603 | N54: -1706 | Q54: -9025
D55: H.C | E55: -15903 | F55: -23249 | G55: -17929 | H55: -17900 | I55: -18110 | J55: -18981 | K55: -24895 | L55: -20895 | M55: -20483 | N55: -18621 | Q55: -93091
B56: 도매 유지 ARPU | D56: 계 | E56: 0 | F56: 0 | G56: 0 | H56: 0 | I56: 0 | Q56: 0
D57: 무선 | E57: 70247.456 | F57: 74027.255 | G57: 73429.653 | H57: 72599.898 | I57: 68871.078 | J57: 66653.977 | K57: 61458.373 | L57: 64705.321 | M57: 65039.173 | N57: 64879.445 | Q57: 0
B58: 도매 객관리수수료 | D58: 계 | E58: 0 | F58: 0 | G58: 0 | H58: 0 | I58: 0 | Q58: 0
D59: 무선 | Q59: 0
B60: 도매 해지율 | D60: 계 | Q60: 0
D61: 무선 | Q61: 0

Sheet 도매(E)
B3: 구분 | C3: 도매 | D3: 무선 | E3: 점프업 | F3: 유선 | G3: h.c | H3: win-win
B4: 24년 | C4: =SUM(E12:P12) -> 141.31446 | D4: =SUM(E14:P14) -> 21.774058 | E4: =SUM(E15:P15) -> 22.473963 | F4: =SUM(E16:P16) -> 30.207116 | G4: =SUM(E17:P17) -> 61.044862 | H4: =SUM(E18:P18) -> 5.8144568
B5: 25년 (E) | C5: =SUM(R12:AC12) -> 136.43485 | D5: =SUM(R14:AC14) -> 17.767806 | E5: =SUM(R15:AC15) -> 8.9822564 | F5: =SUM(R16:AC16) -> 19.032817 | G5: =SUM(R17:AC17) -> 39.413327 | H5: =SUM(R18:AC18) -> 28.731601
B6: 26년 (E) | C6: =D6+E6+F6+G6+H6 -> 109.63097 | D6: =SUM(AE14:AP14) -> 13.994499 | E6: =SUM(AE15:AP15) -> 2.4104169 | F6: =SUM(AE16:AP16) -> 9.3201677 | G6: =SUM(AE17:AP17) -> 21.087357 | H6: =SUM(AE18:AP18) -> 62.818529
B7: 27년 (E) | C7: =SUM(AR12:BC12) -> 122.52639
E9: =E20*E39*0.085 -> 5.2324468e+08
F10: =F18/E18-1 -> 3.1834322 | G10: =G18/F18-1 -> 2.0301344 | H10: =H18/G18-1 -> 0.72776157 | I10: =I18/H18-1 -> 0.44340034 | J10: =J18/I18-1 -> 0.29951585 | K10: =K18/J18-1 -> 0.27233931 | L10: =L18/K18-1 -> 0.23096311 | M10: =M18/L18-1 -> 0.26412865 | ... P10: =P18/O18-1 -> 0.11962691 | R10: =R18/P18-1 -> 0 | S10: =S18/R18-1 -> 0.16955225 | T10: =T18/S18-1 -> 0.14857368 | U10: =U18/T18-1 -> 0.096622193 | V10: =V18/U18-1 -> 0.098807509
B11: 구분 | E11: 2401 | F11: 2402 | G11: 2403 | H11: 2404 | I11: 2405 | J11: 2406 | K11: 2407 | L11: 2408 | M11: 2409 | N11: 2410 | O11: 2411 | P11: 2412 | R11: 2501 | S11: 2502 | T11: 2503 | U11: 2504 | V11: 2505 | W11: 2506 | X11: 2507 | Y11: 2508 | Z11: 2509 | AA11: 2510 | AB11: 2511 | AC11: 2512 | AE11: 2601 | AF11: 2602 | AG11: 2603 | AH11: 2604 | AI11: 2605 | AJ11: 2606 | AK11: 2607 | AL11: 2608 | AM11: 2609 | AN11: 2610 | AO11: 2611 | AP11: 2612 | AR11: 2701 | AS11: 2702 | AT11: 2703 | AU11: 2704 | AV11: 2705 | AW11: 2706 | AX11: 2707 | AY11: 2708 | AZ11: 2709 | BA11: 2710 | BB11: 2711 | BC11: 2712
B12: 도매 관리수수료 | D12: 계(win-win 포함) | E12: =E13+E18 -> 13.108797 | F12: =F13+F18 -> 12.6368 | G12: =G13+G18 -> 12.511508 | H12: =H13+H18 -> 12.292659 | I12: =I13+I18 -> 11.878084 | J12: =J13+J18 -> 11.661375 | K12: =K13+K18 -> 11.559792 | L12: =L13+L18 -> 11.365987 | ... P12: =P13+P18 -> 10.768494 | R12: =R13+R18 -> 10.268494 | S12: =S13+S18 -> 10.449707 | T12: =T13+T18 -> 10.12257 | U12: =U13+U18 -> 9.7292867 | V12: =V13+V18 -> 9.4927223 | W12: =W13+W18 -> 13.46057 | X12: =X13+X18 -> 11.968921 | Y12: =Y13+Y18 -> 11.911516 | ... AC12: =AC13+AC18 -> 12.473373 | AE12: =AE13+AE18 -> 8.9732998 | AF12: =AF13+AF18 -> 8.9672177 | AG12: =AG13+AG18 -> 8.9733716 | AH12: =AH13+AH18 -> 8.990997 | AI12: =AI13+AI18 -> 9.0193838 | AJ12: =AJ13+AJ18 -> 9.0578716 | AK12: =AK13+AK18 -> 9.1058463 | AL12: =AL13+AL18 -> 9.1627363 | ... AP12: =AP13+AP18 -> 9.4693206 | AR12: =AR13+AR18 -> 9.5634795 | AS12: =AS13+AS18 -> 9.6638478 | AT12: =AT13+AT18 -> 9.7700727 | AU12: =AU13+AU18 -> 9.8818239 | AV12: =AV13+AV18 -> 9.9987922 | AW12: =AW13+AW18 -> 10.120688 | AX12: =AX13+AX18 -> 10.24724 | AY12: =AY13+AY18 -> 10.378192 | ... BC12: =BC13+BC18 -> 10.941447
D13: 계 | E13: 13.1 | F13: 12.6 | G13: 12.4 | H13: 12.1 | I13: 11.6 | J13: 11.3 | K13: 11.1 | L13: 10.8 | M13: 10.6 | N13: 10.4 | O13: 9.9 | P13: 9.6 | R13: 9.1 | S13: 9.0830929 | T13: 8.5529126 | U13: 8.0079655 | V13: 7.6013216 | W13: 11.278029 | X13: 9.470221 | Y13: 9.1583625 | Z13: 9.0471217 | AA13: 8.8861889 | AB13: 8.8098992 | AC13: 8.7081341 | AE13: =AE14+AE15+AE16+AE17 -> 4.9447129 | AF13: =AF14+AF15+AF16+AF17 -> 4.7193053 | AG13: =AG14+AG15+AG16+AG17 -> 4.5061336 | AH13: =AH14+AH15+AH16+AH17 -> 4.3044335 | AI13: =AI14+AI15+AI16+AI17 -> 4.1134946 | AJ13: =AJ14+AJ15+AJ16+AJ17 -> 3.9326569 | AK13: =AK14+AK15+AK16+AK17 -> 3.7613061 | AL13: =AL14+AL15+AL16+AL17 -> 3.5988705 | ... AP13: =AP14+AP15+AP16+AP17 -> 3.0281526 | AR13: =AR14+AR15+AR16+AR17 -> 2.9029859 | AS13: =AS14+AS15+AS16+AS17 -> 2.7840287 | AT13: =AT14+AT15+AT16+AT17 -> 2.670928 | AU13: =AU14+AU15+AU16+AU17 -> 2.5633537 | AV13: =AV14+AV15+AV16+AV17 -> 2.4609965 | AW13: =AW14+AW15+AW16+AW17 -> 2.3635667 | AX13: =AX14+AX15+AX16+AX17 -> 2.2707927 | AY13: =AY14+AY15+AY16+AY17 -> 2.1824199 | ... BC13: =BC14+BC15+BC16+BC17 -> 1.8683723
D14: 무선 | E14: 2.0940601 | F14: 1.8819668 | G14: 1.9234486 | H14: 1.9246826 | I14: 1.7133767 | J14: 1.7550199 | K14: 1.6882306 | L14: 1.7061712 | M14: 1.8324907 | N14: 1.8238246 | O14: 1.7224815 | P14: 1.7083045 | R14: =2.96246609090909-R15 -> 1.6986729 | S14: 1.7475366 | T14: 1.4124376 | U14: 1.5719565 | V14: 1.5193557 | W14: =V14*0.98 -> 1.4889686 | X14: =W14*0.98 -> 1.4591892 | Y14: =X14*0.98 -> 1.4300054 | Z14: =Y14*0.98 -> 1.4014053 | AA14: =Z14*0.98 -> 1.3733772 | AB14: =AA14*0.98 -> 1.3459096 | AC14: =AB14*0.98 -> 1.3189914 | AE14: =AC14*(1+AVERAGE($R$47:$AC$47)) -> 1.2938041 | AF14: =AE14*(1+AVERAGE($R$47:$AC$47)) -> 1.2690978 | AG14: =AF14*(1+AVERAGE($R$47:$AC$47)) -> 1.2448633 | AH14: =AG14*(1+AVERAGE($R$47:$AC$47)) -> 1.2210915 | AI14: =AH14*(1+AVERAGE($R$47:$AC$47)) -> 1.1977737 | AJ14: =AI14*(1+AVERAGE($R$47:$AC$47)) -> 1.1749011 | AK14: =AJ14*(1+AVERAGE($R$47:$AC$47)) -> 1.1524653 | AL14: =AK14*(1+AVERAGE($R$47:$AC$47)) -> 1.130458 | AM14: =AL14*(1+AVERAGE($R$47:$AC$47)) -> 1.1088709 | ... AP14: =AO14*(1+AVERAGE($R$47:$AC$47)) -> 1.0465516 | AR14: =AP14*(1+AVERAGE($R$47:$AC$47)) -> 1.0265668 | AS14: =AR14*(1+AVERAGE($R$47:$AC$47)) -> 1.0069636 | AT14: =AS14*(1+AVERAGE($R$47:$AC$47)) -> 0.9877347 | AU14: =AT14*(1+AVERAGE($R$47:$AC$47)) -> 0.96887303 | AV14: =AU14*(1+AVERAGE($R$47:$AC$47)) -> 0.95037154 | AW14: =AV14*(1+AVERAGE($R$47:$AC$47)) -> 0.93222336 | AX14: =AW14*(1+AVERAGE($R$47:$AC$47)) -> 0.91442172 | AY14: =AX14*(1+AVERAGE($R$47:$AC$47)) -> 0.89696003 | AZ14: =AY14*(1+AVERAGE($R$47:$AC$47)) -> 0.87983178 | ... BC14: =BB14*(1+AVERAGE($R$47:$AC$47)) -> 0.83038465
D15: 점프업 | E15: 2.6627098 | F15: 2.46218 | G15: 2.2811031 | H15: 2.1103124 | I15: 1.9630879 | J15: 1.8179401 | K15: 1.7667849 | L15: 1.648921 | M15: 1.5260275 | N15: 1.5054937 | O15: 1.4127659 | P15: 1.316637 | R15: 1.2637932 | S15: 1.1657934 | T15: 1.0448888 | U15: 0.95432054 | V15: 0.86088327 | W15: 0.7662568 | X15: 0.66542558 | Y15: 0.58167732 | Z15: 0.50999542 | AA15: 0.42652902 | AB15: 0.37134652 | AC15: 0.37134652 | AE15: =AC15*(1+AVERAGE($R$48:$AC$48)) -> 0.33453337 | AF15: =AE15*(1+AVERAGE($R$48:$AD$48)) -> 0.30136966 | AG15: =AF15*(1+AVERAGE($R$48:$AD$48)) -> 0.27149362 | AH15: =AG15*(1+AVERAGE($R$48:$AD$48)) -> 0.24457931 | AI15: =AH15*(1+AVERAGE($R$48:$AD$48)) -> 0.22033313 | AJ15: =AI15*(1+AVERAGE($R$48:$AD$48)) -> 0.19849057 | AK15: =AJ15*(1+AVERAGE($R$48:$AD$48)) -> 0.17881337 | AL15: =AK15*(1+AVERAGE($R$48:$AD$48)) -> 0.16108684 | AM15: =AL15*(1+AVERAGE($R$48:$AD$48)) -> 0.14511762 | ... AP15: =AO15*(1+AVERAGE($R$48:$AD$48)) -> 0.10609634 | AR15: =AP15*(1+AVERAGE($R$48:$AC$48)) -> 0.095578565 | AS15: =AR15*(1+AVERAGE($R$48:$AD$48)) -> 0.086103459 | AT15: =AS15*(1+AVERAGE($R$48:$AD$48)) -> 0.077567659 | AU15: =AT15*(1+AVERAGE($R$48:$AD$48)) -> 0.069878049 | AV15: =AU15*(1+AVERAGE($R$48:$AD$48)) -> 0.062950743 | AW15: =AV15*(1+AVERAGE($R$48:$AD$48)) -> 0.05671017 | AX15: =AW15*(1+AVERAGE($R$48:$AD$48)) -> 0.051088251 | AY15: =AX15*(1+AVERAGE($R$48:$AD$48)) -> 0.046023657 | AZ15: =AY15*(1+AVERAGE($R$48:$AD$48)) -> 0.041461138 | ... BC15: =BB15*(1+AVERAGE($R$48:$AD$48)) -> 0.030312481
D16: 유선 | E16: 2.775657 | F16: 2.7472658 | G16: 2.7423491 | H16: 2.697131 | I16: 2.6393608 | J16: 2.5545065 | K16: 2.5248521 | L16: 2.4420311 | M16: 2.3737327 | N16: 2.3304191 | O16: 2.2147525 | P16: 2.1650585 | R16: 1.9975339 | S16: 2.0294241 | T16: 2.2323665 | U16: 1.8044475 | V16: 1.7026086 | W16: 1.5949692 | X16: 1.4921995 | Y16: 1.4055083 | Z16: 1.3104795 | AA16: 1.2273193 | AB16: 1.1457579 | AC16: 1.0902025 | AE16: =AC16*(1+AVERAGE($R$49:$AC$49)) -> 1.0319402 | AF16: =AE16*(1+AVERAGE($R$49:$AC$49)) -> 0.97679152 | AG16: =AF16*(1+AVERAGE($R$49:$AC$49)) -> 0.92459011 | AH16: =AG16*(1+AVERAGE($R$49:$AC$49)) -> 0.87517843 | AI16: =AH16*(1+AVERAGE($R$49:$AC$49)) -> 0.8284074 | AJ16: =AI16*(1+AVERAGE($R$49:$AC$49)) -> 0.78413589 | AK16: =AJ16*(1+AVERAGE($R$49:$AC$49)) -> 0.74223033 | AL16: =AK16*(1+AVERAGE($R$49:$AC$49)) -> 0.70256427 | AM16: =AL16*(1+AVERAGE($R$49:$AC$49)) -> 0.66501803 | ... AP16: =AO16*(1+AVERAGE($R$49:$AC$49)) -> 0.56399533 | AR16: =AP16*(1+AVERAGE($R$49:$AC$49)) -> 0.53385446 | AS16: =AR16*(1+AVERAGE($R$49:$AC$49)) -> 0.50532436 | AT16: =AS16*(1+AVERAGE($R$49:$AC$49)) -> 0.47831896 | AU16: =AT16*(1+AVERAGE($R$49:$AC$49)) -> 0.45275678 | AV16: =AU16*(1+AVERAGE($R$49:$AC$49)) -> 0.42856068 | AW16: =AV16*(1+AVERAGE($R$49:$AC$49)) -> 0.40565767 | AX16: =AW16*(1+AVERAGE($R$49:$AC$49)) -> 0.38397863 | AY16: =AX16*(1+AVERAGE($R$49:$AC$49)) -> 0.36345815 | AZ16: =AY16*(1+AVERAGE($R$49:$AC$49)) -> 0.34403433 | ... BC16: =BB16*(1+AVERAGE($R$49:$AC$49)) -> 0.29177217
D17: H.C | E17: 5.5675732 | F17: 5.5085874 | G17: 5.4530992 | H17: 5.367874 | I17: 5.2841746 | J17: 5.1725335 | K17: 5.1201324 | L17: 5.0028767 | M17: 4.867749 | N17: 4.7402626 | O17: 4.55 | P17: 4.41 | R17: 4.14 | S17: 4.1403388 | T17: 3.8632196 | U17: 3.6772409 | V17: 3.5184741 | W17: 3.3729352 | X17: 3.2175035 | Y17: 3.0304162 | Z17: 2.8506906 | AA17: 2.6879537 | AB17: 2.5119147 | AC17: 2.4026395 | AE17: =AC17*(1+AVERAGE($R$50:$AC$50)) -> 2.2844352 | AF17: =AE17*(1+AVERAGE($R$50:$AC$50)) -> 2.1720463 | AG17: =AF17*(1+AVERAGE($R$50:$AC$50)) -> 2.0651866 | AH17: =AG17*(1+AVERAGE($R$50:$AC$50)) -> 1.9635842 | AI17: =AH17*(1+AVERAGE($R$50:$AC$50)) -> 1.8669805 | AJ17: =AI17*(1+AVERAGE($R$50:$AC$50)) -> 1.7751293 | AK17: =AJ17*(1+AVERAGE($R$50:$AC$50)) -> 1.6877971 | AL17: =AK17*(1+AVERAGE($R$50:$AC$50)) -> 1.6047614 | AM17: =AL17*(1+AVERAGE($R$50:$AC$50)) -> 1.5258109 | ... AP17: =AO17*(1+AVERAGE($R$50:$AC$50)) -> 1.3115094 | AR17: =AP17*(1+AVERAGE($R$50:$AC$50)) -> 1.2469861 | AS17: =AR17*(1+AVERAGE($R$50:$AC$50)) -> 1.1856373 | AT17: =AS17*(1+AVERAGE($R$50:$AC$50)) -> 1.1273067 | AU17: =AT17*(1+AVERAGE($R$50:$AC$50)) -> 1.0718458 | AV17: =AU17*(1+AVERAGE($R$50:$AC$50)) -> 1.0191135 | AW17: =AV17*(1+AVERAGE($R$50:$AC$50)) -> 0.96897548 | AX17: =AW17*(1+AVERAGE($R$50:$AC$50)) -> 0.92130414 | AY17: =AX17*(1+AVERAGE($R$50:$AC$50)) -> 0.87597811 | AZ17: =AY17*(1+AVERAGE($R$50:$AC$50)) -> 0.83288202 | ... BC17: =BB17*(1+AVERAGE($R$50:$AC$50)) -> 0.715903
