Workbook

Sheet 0. 목차
A2: '25년 전사 경영 FactBook
A4: 0. 목차
A6: 순번 | C6: 구분 | F6: 상세 내용 | P6: 마감일시 | Z6: 페이지
A7: 1 | C7: 재무 | F7: ① 매출 (통신매출, 유통플랫폼사업매출) | K7: ② 판매비와 일반관리비 | P7: 21일 ~ 26일 (회계 결산 마감 이후 반영) | T7: • • • • • • • • • • • • • • • • • • • • • • • • • • • • • • • • • • | Z7: 1 ~ 3
F8: ③ 채널별 영업이익 | K8: ④ 주요 채널 상세 재무지표 요약
A9: 2 | C9: 무선가입자 | F9: ① 일반 후불 (전체) 가입자(CAPA) | K9: ② 운영 후불 (전체) 가입자(CAPA) | P9: ~ 16일 | T9: • • • • • • • • • • • • • • • • • • • • • • • • • • • • • • • • • • | Z9: 4 ~ 5
F10: ③ 도소매 조직별 가입자(CAPA) | K10: ④ 채널별 판매 ARPU / 무선 증분 매출
A11: 2-(1) | C11: 무선가입자 (상세) | F11: ① 관리수수료 8.5% 대상 가입자(CAPA) | K11: ② 위탁 H/C 2.2% 대상 가입자(CAPA) | P11: ~ 16일 | T11: • • • • • • • • • • • • • • • • • • • • • • • • • • • • • • • • • • | Z11: 6 ~ 7
F12: ③ 채널별 일반 후불 (전체) 가입자(CAPA) | K12: ④ 채널별 무선 관리수수료
A13: 3 | C13: 유선가입자 | F13: ① 유선 전체 (I+TV) 가입자 | K13: ② 유선 순신규 (I+TV) 가입자 | P13: ~ 16일 | T13: • • • • • • • • • • • • • • • • • • • • • • • • • • • • • • • • • • | Z13: 8 ~ 9
F14: ③ 도소매 조직별 (I+TV) 가입자 | K14: ④ 유선 Quality 채널별 비중
A15: 3-(1) | C15: 유선가입자(상세) | F15: ① 채널별 인터넷 (I) 가입자 상세 | K15: ② 채널별 TV 가입자 상세 | P15: ~ 16일 | T15: • • • • • • • • • • • • • • • • • • • • • • • • • • • • • • • • • • | Z15: 10 ~ 11
F16: ③ 채널별 유선 관리수수료
A17: 4 | C17: 디지털 | F17: ① KT닷컴 운영 후불/ 유선 순신규 가입자 | K17: ② KT닷컴 전용 요고 요금제 실적 | P17: ~ 13일 (전월 가입자 / 인력 마감 이후) | T17: • • • • • • • • • • • • • • • • • • • • • • • • • • • • • • • • • • | Z17: 12
F18: ③ 라이브 방송 실적 | K18: ④ 영업센터 파트별 인력 현황
A19: 5 | C19: 소상공인 | F19: ① 전체 무선 후불 / 유선 순신규 가입자 | K19: ② 본부별 무선 후불 / 유선 순신규 가입자 | P19: ~ 13일 (전월 가입자 / 인력 마감 이후) | T19: • • • • • • • • • • • • • • • • • • • • • • • • • • • • • • • • • • | Z19: 13 ~ 14
F20: ③ 소상공인 전체 인력 현황 | K20: ④ 본부별 인력 충원 / 등급 / 포인트
A21: 6 | C21: B2B | F21: ① B2B 전체 유무선 가입자 실적 | K21: ② 기업영업 / 법인 영업 유무선 가입자 실적 | P21: ~ 13일 | T21: • • • • • • • • • • • • • • • • • • • • • • • • • • • • • • • • • • | Z21: 15
A22: 7 | C22: 유통플랫폼사업 | F22: ① 시연폰 사업 매입 / 매각 현황 | K22: ② 중고폰 사업 매입 / 매각 현황 | P22: 13일 ~ 18일 (전월 가입자 / 매출액 마감 이후) | T22: • • • • • • • • • • • • • • • • • • • • • • • • • • • • • • • • • • | Z22: 16
F23: ③ 코코넛 허브 가입 및 출고 현황 | K23: ④ 코코넛 Mall 이용자 및 매출액
A24: 8 | C24: 인프라 | F24: ① 소매 매장 조직별 인프라 현황 | K24: ② 매장 생산성 (후불 + 유선 순신규) | P24: ~ 16일 | T24: • • • • • • • • • • • • • • • • • • • • • • • • • • • • • • • • • • | Z24: 17
F25: ③ 도매센터 조직별 인프라 현황
A26: 9 | C26: 인력 | F26: ① 전사 인력 현황 | K26: ② 직급별 인력 현황 | P26: ~ 16일 | T26: • • • • • • • • • • • • • • • • • • • • • • • • • • • • • • • • • • | Z26: 18 ~ 20
F27: ③ 도소매 조직별 인력 현황
A28: 10 | C28: 영업품질 | F28: ① 도소매 R-VOC 인입 현황 | K28: ② 도소매 대외 민원 접수 / 귀책 건수 | P28: ~ 16일 (대외 민원 / 음성적 재가입은 익익월 산출) | T28: • • • • • • • • • • • • • • • • • • • • • • • • • • • • • • • • • • | Z28: 21 ~ 22
F29: ③ 도소매 불완전 판매 현황 | K29: ④ 도소매 음성적 재가입 현황
A30: 11 | C30: 재고 | F30: ① 단말 / 유선 재고 현황 | K30: ② 제조사별 직매입 현황 | P30: ~ 16일 | T30: • • • • • • • • • • • • • • • • • • • • • • • • • • • • • • • • • • | Z30: 23
F31: ③ 제조사별 판매 현황 (KT 내 비중) | K31: ④ 엣지프로젝트 수량 및 마진 현황
A32: 12 | C32: 기타지표 | F32: ① 지사별 TCSI 점수 현황 | K32: ② 전략 상품 판매 현황 | P32: ~ 16일 | T32: • • • • • • • • • • • • • • • • • • • • • • • • • • • • • • • • • • | Z32: 24

Sheet 1.재무
F1: BC | G1: BP | H1: BQ | I1: BR | J1: BS | K1: BT | L1: BU | M1: BV | N1: BW | O1: BX | P1: BY | Q1: Bz | R1: CA | S1: CB | T1: CX | U1: CC | V1: CD | W1: CE | X1: CF | Y1: CG | Z1: CH | AA1: CI | AB1: CJ | AC1: CK | AD1: 실적 | BG1: AQ | BH1: BC | BI1: AW | BJ1: BI | BK1: AY
A2: 1. 재무 | BG2: 프리미엄 모델 출시년월
E4: ※ 내부 도전목표 | H4: '25년 실적 | Z4: 연간누적실적 | AE4: 전년 | AS4: 내부목표 | BG4: 갤럭시s | BI4: 폴더블 | BK4: 아이폰
A5: 구분 | E5: 설명 | F5: '23년 계 | G5: '24년 계 | H5: {=INDIRECT("'※ 재무_세부시트'!"&H$1&$AD5, TRUE)} -> '25.1월 | I5: {=INDIRECT("'※ 재무_세부시트'!"&I$1&$AD5, TRUE)} -> '25.2월 | J5: {=INDIRECT("'※ 재무_세부시트'!"&J$1&$AD5, TRUE)} -> '25.3월 | K5: {=INDIRECT("'※ 재무_세부시트'!"&K$1&$AD5, TRUE)} -> '25.4월 | L5: {=INDIRECT("'※ 재무_세부시트'!"&L$1&$AD5, TRUE)} -> '25.5월 | M5: {=INDIRECT("'※ 재무_세부시트'!"&M$1&$AD5, TRUE)} -> '25.6월 | N5: {=INDIRECT("'※ 재무_세부시트'!"&N$1&$AD5, TRUE)} -> '25.7월 | O5: {=INDIRECT("'※ 재무_세부시트'!"&O$1&$AD5, TRUE)} -> '25.8월 | ... S5: {=INDIRECT("'※ 재무_세부시트'!"&S$1&$AD5, TRUE)} -> '25.12월 | T5: 목표 | U5: 목표대비 | V5: 달성률 | W5: 전월대비 | X5: 전년 동월대비 | Y5: 전작 출시대비 | Z5: 누적 | AA5: 목표대비 | AB5: 달성률 | AC5: 전년 동기대비 | AD5: 4 | AE5: 23.1월 | AF5: 23.2월 | AG5: 23.3월 | AH5: 23.4월 | AI5: 23.5월 | AJ5: 23.6월 | AK5: 23.7월 | AL5: 23.8월 | AM5: 23.9월 | AN5: 23.10월 | AO5: 23.11월 | AP5: 23.12월 | AQ5: 계 | AS5: 24.1월 | AT5: 24.2월 | AU5: 24.3월 | AV5: 24.4월 | AW5: 24.5월 | AX5: 24.6월 | AY5: 24.7월 | AZ5: 24.8월 | BA5: 24.9월 | BB5: 24.10월 | BC5: 24.11월 | BD5: 24.12월 | BE5: 계 | BG5: 23.02 | BH5: 24.01 | BI5: 23.08 | BJ5: 24.07 | BK5: 23.1
A6: 총매출 (ⓐ+ⓑ+ⓒ+ⓓ) | F6: {=INDIRECT("'※ 재무_세부시트'!"&F$1&$AD6, TRUE)} -> 6951.3447 | G6: {=INDIRECT("'※ 재무_세부시트'!"&G$1&$AD6, TRUE)} -> 8073.0711 | H6: {=INDIRECT("'※ 재무_세부시트'!"&H$1&$AD6, TRUE)} -> 560.63833 | I6: {=INDIRECT("'※ 재무_세부시트'!"&I$1&$AD6, TRUE)} -> 1003.2939 | J6: {=INDIRECT("'※ 재무_세부시트'!"&J$1&$AD6, TRUE)} -> 569.23055 | K6: {=INDIRECT("'※ 재무_세부시트'!"&K$1&$AD6, TRUE)} -> 449.51814 | L6: {=INDIRECT("'※ 재무_세부시트'!"&L$1&$AD6, TRUE)} -> 517.36254 | M6: {=INDIRECT("'※ 재무_세부시트'!"&M$1&$AD6, TRUE)} -> 544.95947 | ... AC6: {=INDIRECT("'※ 재무_세부시트'!"&AC$1&$AD6, TRUE)} -> -538.49012 | AD6: 5 | AE6: =AE7+AE13+AE51 -> 474.37248 | AF6: =AF7+AF13+AF51 -> 736.97131 | AG6: =AG7+AG13+AG51 -> 520.49606 | AH6: =AH7+AH13+AH51 -> 489.87118 | AI6: =AI7+AI13+AI51 -> 510.89928 | AJ6: =AJ7+AJ13+AJ51 -> 472.27082 | AK6: =AK7+AK13+AK51 -> 412.06067 | AL6: =AL7+AL13+AL51 -> 845.34421 | ... AP6: =AP7+AP13+AP51 -> 488.55515 | AQ6: =SUM(AE6:AP6) -> 6951.3447 | AS6: =AS7+AS13+AS51 -> 1002.2017 | AT6: =AT7+AT13+AT51 -> 838.15168 | AU6: =AU7+AU13+AU51 -> 667.59223 | AV6: =AV7+AV13+AV51 -> 652.13202 | AW6: =AW7+AW13+AW51 -> 699.40269 | AX6: =AX7+AX13+AX51 -> 605.97812 | AY6: =AY7+AY13+AY51 -> 1040.6455 | AZ6: =AZ7+AZ13+AZ51 -> 585.97321 | ... BD6: =BD7+BD13+BD51 -> 733.89434 | BE6: =SUM(AS6:BD6) -> 9335.0967 | BG6: {=INDIRECT("'※ 재무_세부시트'!"&BG$1&$AD6, TRUE)} -> 474.37248 | BH6: {=INDIRECT("'※ 재무_세부시트'!"&BH$1&$AD6, TRUE)} -> 6951.3447 | BI6: {=INDIRECT("'※ 재무_세부시트'!"&BI$1&$AD6, TRUE)} -> 412.06067 | BJ6: {=INDIRECT("'※ 재무_세부시트'!"&BJ$1&$AD6, TRUE)} -> 619.57999 | BK6: {=INDIRECT("'※ 재무_세부시트'!"&BK$1&$AD6, TRUE)} -> 469.75417
B7: 상품매출 (ⓐ+ⓓ) | F7: {=INDIRECT("'※ 재무_세부시트'!"&F$1&$AD7, TRUE)} -> 4527.9375 | G7: {=INDIRECT("'※ 재무_세부시트'!"&G$1&$AD7, TRUE)} -> 5452.5105 | H7: {=INDIRECT("'※ 재무_세부시트'!"&H$1&$AD7, TRUE)} -> 377.4824 | I7: {=INDIRECT("'※ 재무_세부시트'!"&I$1&$AD7, TRUE)} -> 737.1983 | J7: {=INDIRECT("'※ 재무_세부시트'!"&J$1&$AD7, TRUE)} -> 368.49675 | K7: {=INDIRECT("'※ 재무_세부시트'!"&K$1&$AD7, TRUE)} -> 243.45807 | L7: {=INDIRECT("'※ 재무_세부시트'!"&L$1&$AD7, TRUE)} -> 287.03542 | M7: {=INDIRECT("'※ 재무_세부시트'!"&M$1&$AD7, TRUE)} -> 319.55447 | ... AC7: {=INDIRECT("'※ 재무_세부시트'!"&AC$1&$AD7, TRUE)} -> -775.54985 | AD7: 6 | AE7: =AE12+AE54 -> 326.19489 | AF7: =AF12+AF54 -> 526.58673 | AG7: =AG12+AG54 -> 341.83856 | AH7: =AH12+AH54 -> 294.56878 | AI7: =AI12+AI54 -> 312.07731 | AJ7: =AJ12+AJ54 -> 247.27282 | AK7: =AK12+AK54 -> 221.5312 | AL7: =AL12+AL54 -> 575.99764 | ... AP7: =AP12+AP54 -> 287.62393 | AQ7: =SUM(AE7:AP7) -> 4527.9375 | AS7: =AS12+AS54 -> 740.33425 | AT7: =AT12+AT54 -> 600.43881 | AU7: =AU12+AU54 -> 454.58784 | AV7: =AV12+AV54 -> 422.73289 | AW7: =AW12+AW54 -> 481.46189 | AX7: =AX12+AX54 -> 367.77918 | AY7: =AY12+AY54 -> 772.91137 | AZ7: =AZ12+AZ54 -> 379.60552 | ... BD7: =BD12+BD54 -> 499.73869 | BE7: =SUM(AS7:BD7) -> 6471.4818 | BG7: {=INDIRECT("'※ 재무_세부시트'!"&BG$1&$AD7, TRUE)} -> 326.19489 | BH7: {=INDIRECT("'※ 재무_세부시트'!"&BH$1&$AD7, TRUE)} -> 4527.9375 | BI7: {=INDIRECT("'※ 재무_세부시트'!"&BI$1&$AD7, TRUE)} -> 221.5312 | BJ7: {=INDIRECT("'※ 재무_세부시트'!"&BJ$1&$AD7, TRUE)} -> 431.33398 | BK7: {=INDIRECT("'※ 재무_세부시트'!"&BK$1&$AD7, TRUE)} -> 273.79615
B8: 상품원가 | F8: {=INDIRECT("'※ 재무_세부시트'!"&F$1&$AD8, TRUE)} -> 4694.0465 | G8: {=INDIRECT("'※ 재무_세부시트'!"&G$1&$AD8, TRUE)} -> 5825.5334 | H8: {=INDIRECT("'※ 재무_세부시트'!"&H$1&$AD8, TRUE)} -> 388.7483 | I8: {=INDIRECT("'※ 재무_세부시트'!"&I$1&$AD8, TRUE)} -> 790.57614 | J8: {=INDIRECT("'※ 재무_세부시트'!"&J$1&$AD8, TRUE)} -> 385.18887 | K8: {=INDIRECT("'※ 재무_세부시트'!"&K$1&$AD8, TRUE)} -> 256.63171 | L8: {=INDIRECT("'※ 재무_세부시트'!"&L$1&$AD8, TRUE)} -> 307.72262 | M8: {=INDIRECT("'※ 재무_세부시트'!"&M$1&$AD8, TRUE)} -> 324.79942 | ... AC8: {=INDIRECT("'※ 재무_세부시트'!"&AC$1&$AD8, TRUE)} -> -812.82185 | AD8: 7 | AE8: 332.61489 | AF8: 563.94445 | AG8: 347.8352 | AH8: 318.36152 | AI8: 338.16961 | AJ8: 266.59199 | AK8: 230.31367 | AL8: 636.29756 | AM8: 264.79659 | AN8: 768.34303 | AO8: 341.94122 | AP8: 284.83683 | AQ8: =SUM(AE8:AP8) -> 4694.0465 | AS8: 806.87567 | AT8: 636.89747 | AU8: 474.21819 | AV8: 449.32354 | AW8: 496.44002 | AX8: 388.97768 | AY8: 825.31508 | AZ8: 384.25014 | BA8: 530.89775 | BB8: 801.35745 | BC8: 477.91503 | BD8: 509.01538 | BE8: =SUM(AS8:BD8) -> 6781.4834 | BG8: {=INDIRECT("'※ 재무_세부시트'!"&BG$1&$AD8, TRUE)} -> 332.61489 | BH8: {=INDIRECT("'※ 재무_세부시트'!"&BH$1&$AD8, TRUE)} -> 4694.0465 | BI8: {=INDIRECT("'※ 재무_세부시트'!"&BI$1&$AD8, TRUE)} -> 230.31367 | BJ8: {=INDIRECT("'※ 재무_세부시트'!"&BJ$1&$AD8, TRUE)} -> 461.67626 | BK8: {=INDIRECT("'※ 재무_세부시트'!"&BK$1&$AD8, TRUE)} -> 264.79659
B9: 상품이익 | F9: {=INDIRECT("'※ 재무_세부시트'!"&F$1&$AD9, TRUE)} -> -166.10904 | G9: {=INDIRECT("'※ 재무_세부시트'!"&G$1&$AD9, TRUE)} -> -373.02286 | H9: {=INDIRECT("'※ 재무_세부시트'!"&H$1&$AD9, TRUE)} -> -11.265901 | I9: {=INDIRECT("'※ 재무_세부시트'!"&I$1&$AD9, TRUE)} -> -53.377835 | J9: {=INDIRECT("'※ 재무_세부시트'!"&J$1&$AD9, TRUE)} -> -16.692117 | K9: {=INDIRECT("'※ 재무_세부시트'!"&K$1&$AD9, TRUE)} -> -13.173643 | L9: {=INDIRECT("'※ 재무_세부시트'!"&L$1&$AD9, TRUE)} -> -20.6872 | M9: {=INDIRECT("'※ 재무_세부시트'!"&M$1&$AD9, TRUE)} -> -5.2449434 | ... AC9: {=INDIRECT("'※ 재무_세부시트'!"&AC$1&$AD9, TRUE)} -> 37.272008 | AD9: 8 | AE9: =AE7-AE8 -> -6.419994 | AF9: =AF7-AF8 -> -37.357717 | AG9: =AG7-AG8 -> -5.9966427 | AH9: =AH7-AH8 -> -23.792732 | AI9: =AI7-AI8 -> -26.092303 | AJ9: =AJ7-AJ8 -> -19.319165 | AK9: =AK7-AK8 -> -8.782463 | AL9: =AL7-AL8 -> -60.299919 | ... AP9: =AP7-AP8 -> 2.7870985 | AQ9: =SUM(AE9:AP9) -> -166.10904 | AS9: =AS7-AS8 -> -66.541423 | AT9: =AT7-AT8 -> -36.458657 | AU9: =AU7-AU8 -> -19.630349 | AV9: =AV7-AV8 -> -26.590648 | AW9: =AW7-AW8 -> -14.978129 | AX9: =AX7-AX8 -> -21.198494 | AY9: =AY7-AY8 -> -52.403708 | AZ9: =AZ7-AZ8 -> -4.6446264 | ... BD9: =BD7-BD8 -> -9.2766903 | BE9: =SUM(AS9:BD9) -> -310.00157 | BG9: {=INDIRECT("'※ 재무_세부시트'!"&BG$1&$AD9, TRUE)} -> -6.419994 | BH9: {=INDIRECT("'※ 재무_세부시트'!"&BH$1&$AD9, TRUE)} -> -166.10904 | BI9: {=INDIRECT("'※ 재무_세부시트'!"&BI$1&$AD9, TRUE)} -> -8.782463 | BJ9: {=INDIRECT("'※ 재무_세부시트'!"&BJ$1&$AD9, TRUE)} -> -30.342279 | BK9: {=INDIRECT("'※ 재무_세부시트'!"&BK$1&$AD9, TRUE)} -> 8.9995535
B10: * 프리할부 | F10: {=INDIRECT("'※ 재무_세부시트'!"&F$1&$AD10, TRUE)} -> 190.22446 | G10: {=INDIRECT("'※ 재무_세부시트'!"&G$1&$AD10, TRUE)} -> 353.16111 | H10: {=INDIRECT("'※ 재무_세부시트'!"&H$1&$AD10, TRUE)} -> 15.730997 | I10: {=INDIRECT("'※ 재무_세부시트'!"&I$1&$AD10, TRUE)} -> 40.752403 | J10: {=INDIRECT("'※ 재무_세부시트'!"&J$1&$AD10, TRUE)} -> 0 | K10: {=INDIRECT("'※ 재무_세부시트'!"&K$1&$AD10, TRUE)} -> 0 | L10: {=INDIRECT("'※ 재무_세부시트'!"&L$1&$AD10, TRUE)} -> 0 | M10: {=INDIRECT("'※ 재무_세부시트'!"&M$1&$AD10, TRUE)} -> 0 | ... AC10: {=INDIRECT("'※ 재무_세부시트'!"&AC$1&$AD10, TRUE)} -> -296.67771 | AD10: 9 | AE10: 8.9098142 | AF10: 21.689249 | AG10: 14.507444 | AH10: 17.838919 | AI10: 17.41659 | AJ10: 16.89778 | AK10: 11.35646 | AL10: 35.958989 | AM10: 8.879484 | AN10: 21.659157 | AO10: 9.1784308 | AP10: 5.9321402 | AQ10: =SUM(AE10:AP10) -> 190.22446 | AS10: 29.926518 | AT10: 28.159416 | AU10: 28.937265 | AV10: 28.281398 | AW10: 29.218948 | AX10: 29.443765 | AY10: 27.124195 | AZ10: 33.515021 | BA10: 27.846221 | BB10: 33.355319 | BC10: 28.624115 | BD10: 27.745943 | BE10: =SUM(AS10:BD10) -> 352.17813 | BG10: {=INDIRECT("'※ 재무_세부시트'!"&BG$1&$AD10, TRUE)} -> 8.9098142 | BH10: {=INDIRECT("'※ 재무_세부시트'!"&BH$1&$AD10, TRUE)} -> 190.22446 | BI10: {=INDIRECT("'※ 재무_세부시트'!"&BI$1&$AD10, TRUE)} -> 11.35646 | BJ10: {=INDIRECT("'※ 재무_세부시트'!"&BJ$1&$AD10, TRUE)} -> 25.559514 | BK10: {=INDIRECT("'※ 재무_세부시트'!"&BK$1&$AD10, TRUE)} -> 8.879484
B11: 통신 매출 | F11: {=INDIRECT("'※ 재무_세부시트'!"&F$1&$AD11, TRUE)} -> 6683.9912 | G11: {=INDIRECT("'※ 재무_세부시트'!"&G$1&$AD11, TRUE)} -> 7673.4989 | H11: {=INDIRECT("'※ 재무_세부시트'!"&H$1&$AD11, TRUE)} -> 533.56526 | I11: {=INDIRECT("'※ 재무_세부시트'!"&I$1&$AD11, TRUE)} -> 937.0369 | J11: {=INDIRECT("'※ 재무_세부시트'!"&J$1&$AD11, TRUE)} -> 520.82451 | K11: {=INDIRECT("'※ 재무_세부시트'!"&K$1&$AD11, TRUE)} -> 413.50723 | L11: {=INDIRECT("'※ 재무_세부시트'!"&L$1&$AD11, TRUE)} -> 474.81409 | M11: {=INDIRECT("'※ 재무_세부시트'!"&M$1&$AD11, TRUE)} -> 497.40316 | ... AC11: {=INDIRECT("'※ 재무_세부시트'!"&AC$1&$AD11, TRUE)} -> -695.50214 | AD11: 10 | AE11: =AE12+AE13 -> 455.44412 | AF11: =AF12+AF13 -> 716.63619 | AG11: =AG12+AG13 -> 514.1281 | AH11: =AH12+AH13 -> 465.41111 | AI11: =AI12+AI13 -> 466.02965 | AJ11: =AJ12+AJ13 -> 463.61065 | AK11: =AK12+AK13 -> 405.6814 | AL11: =AL12+AL13 -> 822.26186 | ... AP11: =AP12+AP13 -> 449.86678 | AQ11: =SUM(AE11:AP11) -> 6683.9912 | AS11: =AS12+AS13 -> 977.3729 | AT11: =AT12+AT13 -> 818.86189 | AU11: =AU12+AU13 -> 644.77683 | AV11: =AV12+AV13 -> 632.84223 | AW11: =AW12+AW13 -> 600.00672 | AX11: =AX12+AX13 -> 579.57717 | AY11: =AY12+AY13 -> 995.06612 | AZ11: =AZ12+AZ13 -> 561.06468 | ... BD11: =BD12+BD13 -> 669.93256 | BE11: =SUM(AS11:BD11) -> 8929.7607 | BG11: {=INDIRECT("'※ 재무_세부시트'!"&BG$1&$AD11, TRUE)} -> 455.44412 | BH11: {=INDIRECT("'※ 재무_세부시트'!"&BH$1&$AD11, TRUE)} -> 6683.9912 | BI11: {=INDIRECT("'※ 재무_세부시트'!"&BI$1&$AD11, TRUE)} -> 405.6814 | BJ11: {=INDIRECT("'※ 재무_세부시트'!"&BJ$1&$AD11, TRUE)} -> 611.33347 | BK11: {=INDIRECT("'※ 재무_세부시트'!"&BK$1&$AD11, TRUE)} -> 434.32383
B12: 상품매출(통신) ⓐ | F12: {=INDIRECT("'※ 재무_세부시트'!"&F$1&$AD12, TRUE)} -> 4264.0504 | G12: {=INDIRECT("'※ 재무_세부시트'!"&G$1&$AD12, TRUE)} -> 5103.3962 | H12: {=INDIRECT("'※ 재무_세부시트'!"&H$1&$AD12, TRUE)} -> 355.07525 | I12: {=INDIRECT("'※ 재무_세부시트'!"&I$1&$AD12, TRUE)} -> 679.23028 | J12: {=INDIRECT("'※ 재무_세부시트'!"&J$1&$AD12, TRUE)} -> 321.5338 | K12: {=INDIRECT("'※ 재무_세부시트'!"&K$1&$AD12, TRUE)} -> 213.07458 | L12: {=INDIRECT("'※ 재무_세부시트'!"&L$1&$AD12, TRUE)} -> 246.36239 | M12: {=INDIRECT("'※ 재무_세부시트'!"&M$1&$AD12, TRUE)} -> 274.80847 | ... AC12: {=INDIRECT("'※ 재무_세부시트'!"&AC$1&$AD12, TRUE)} -> -936.59388 | AD12: 11 | AE12: 307.5619 | AF12: 506.3474 | AG12: 335.51971 | AH12: 270.10871 | AI12: 267.22187 | AJ12: 238.84648 | AK12: 215.1817 | AL12: 553.17258 | AM12: 238.47596 | AN12: 746.45886 | AO12: 333.94233 | AP12: 251.21295 | AQ12: =SUM(AE12:AP12) -> 4264.0504 | AS12: 716.82329 | AT12: 582.79606 | AU12: 433.41947 | AV12: 405.09013 | AW12: 383.71296 | AX12: 343.02526 | AY12: 728.97902 | AZ12: 356.34402 | BA12: 490.0464 | BB12: 767.62525 | BC12: 440.29521 | BD12: 437.42395 | BE12: =SUM(AS12:BD12) -> 6085.581 | BG12: {=INDIRECT("'※ 재무_세부시트'!"&BG$1&$AD12, TRUE)} -> 307.5619 | BH12: {=INDIRECT("'※ 재무_세부시트'!"&BH$1&$AD12, TRUE)} -> 4264.0504 | BI12: {=INDIRECT("'※ 재무_세부시트'!"&BI$1&$AD12, TRUE)} -> 215.1817 | BJ12: {=INDIRECT("'※ 재무_세부시트'!"&BJ$1&$AD12, TRUE)} -> 424.33744 | BK12: {=INDIRECT("'※ 재무_세부시트'!"&BK$1&$AD12, TRUE)} -> 238.47596
B13: 수수료매출(통신) ⓑ | F13: {=INDIRECT("'※ 재무_세부시트'!"&F$1&$AD13, TRUE)} -> 2419.9408 | G13: {=INDIRECT("'※ 재무_세부시트'!"&G$1&$AD13, TRUE)} -> 2570.1027 | H13: {=INDIRECT("'※ 재무_세부시트'!"&H$1&$AD13, TRUE)} -> 178.49001 | I13: {=INDIRECT("'※ 재무_세부시트'!"&I$1&$AD13, TRUE)} -> 257.80661 | J13: {=INDIRECT("'※ 재무_세부시트'!"&J$1&$AD13, TRUE)} -> 199.29071 | K13: {=INDIRECT("'※ 재무_세부시트'!"&K$1&$AD13, TRUE)} -> 200.43265 | L13: {=INDIRECT("'※ 재무_세부시트'!"&L$1&$AD13, TRUE)} -> 228.4517 | M13: {=INDIRECT("'※ 재무_세부시트'!"&M$1&$AD13, TRUE)} -> 222.5947 | ... AC13: {=INDIRECT("'※ 재무_세부시트'!"&AC$1&$AD13, TRUE)} -> 241.09175 | AD13: 12 | AE13: =AE14+AE22+AE39 -> 147.88222 | AF13: =AF14+AF22+AF39 -> 210.2888 | AG13: =AG14+AG22+AG39 -> 178.60839 | AH13: =AH14+AH22+AH39 -> 195.3024 | AI13: =AI14+AI22+AI39 -> 198.80779 | AJ13: =AJ14+AJ22+AJ39 -> 224.76417 | AK13: =AK14+AK22+AK39 -> 190.4997 | AL13: =AL14+AL22+AL39 -> 269.08928 | ... AP13: =AP14+AP22+AP39 -> 198.65383 | AQ13: =SUM(AE13:AP13) -> 2419.9408 | AS13: =AS14+AS22+AS39 -> 260.54961 | AT13: =AT14+AT22+AT39 -> 236.06583 | AU13: =AU14+AU22+AU39 -> 211.35736 | AV13: =AV14+AV22+AV39 -> 227.75209 | AW13: =AW14+AW22+AW39 -> 216.29376 | AX13: =AX14+AX22+AX39 -> 236.5519 | AY13: =AY14+AY22+AY39 -> 266.0871 | AZ13: =AZ14+AZ22+AZ39 -> 204.72066 | ... BD13: =BD14+BD22+BD39 -> 232.50862 | BE13: =SUM(AS13:BD13) -> 2844.1797 | BG13: {=INDIRECT("'※ 재무_세부시트'!"&BG$1&$AD13, TRUE)} -> 147.88222 | BH13: {=INDIRECT("'※ 재무_세부시트'!"&BH$1&$AD13, TRUE)} -> 2419.9408 | BI13: {=INDIRECT("'※ 재무_세부시트'!"&BI$1&$AD13, TRUE)} -> 190.4997 | BJ13: {=INDIRECT("'※ 재무_세부시트'!"&BJ$1&$AD13, TRUE)} -> 186.99602 | BK13: {=INDIRECT("'※ 재무_세부시트'!"&BK$1&$AD13, TRUE)} -> 195.84787 | BP13: =SUM(H80:K80)/SUM(H13:K13,H51:K51) -> 0.10223774
C14: 정책수수료 | F14: {=INDIRECT("'※ 재무_세부시트'!"&F$1&$AD14, TRUE)} -> 1287.4455 | G14: {=INDIRECT("'※ 재무_세부시트'!"&G$1&$AD14, TRUE)} -> 1379.1252 | H14: {=INDIRECT("'※ 재무_세부시트'!"&H$1&$AD14, TRUE)} -> 95.784424 | I14: {=INDIRECT("'※ 재무_세부시트'!"&I$1&$AD14, TRUE)} -> 166.62482 | J14: {=INDIRECT("'※ 재무_세부시트'!"&J$1&$AD14, TRUE)} -> 110.26219 | K14: {=INDIRECT("'※ 재무_세부시트'!"&K$1&$AD14, TRUE)} -> 103.99978 | L14: {=INDIRECT("'※ 재무_세부시트'!"&L$1&$AD14, TRUE)} -> 141.27507 | M14: {=INDIRECT("'※ 재무_세부시트'!"&M$1&$AD14, TRUE)} -> 121.71604 | ... AC14: {=INDIRECT("'※ 재무_세부시트'!"&AC$1&$AD14, TRUE)} -> 349.90693 | AD14: 13 | AE14: =AE15+AE16 -> 39.929752 | AF14: =AF15+AF16 -> 126.18733 | AG14: =AG15+AG16 -> 78.487283 | AH14: =AH15+AH16 -> 106.54675 | AI14: =AI15+AI16 -> 107.44778 | AJ14: =AJ15+AJ16 -> 126.97077 | AK14: =AK15+AK16 -> 94.720605 | AL14: =AL15+AL16 -> 176.59734 | ... AP14: =AP15+AP16 -> 105.05089 | AQ14: =SUM(AE14:AP14) -> 1287.4455 | AS14: =AS15+AS16 -> 168.44609 | AT14: =AT15+AT16 -> 144.24672 | AU14: =AU15+AU16 -> 116.38592 | AV14: =AV15+AV16 -> 135.67492 | AW14: =AW15+AW16 -> 124.43375 | AX14: =AX15+AX16 -> 141.2762 | AY14: =AY15+AY16 -> 171.33586 | AZ14: =AZ15+AZ16 -> 112.74322 | ... BD14: =BD15+BD16 -> 135.06085 | BE14: =SUM(AS14:BD14) -> 1722.6336 | BG14: {=INDIRECT("'※ 재무_세부시트'!"&BG$1&$AD14, TRUE)} -> 39.929752 | BH14: {=INDIRECT("'※ 재무_세부시트'!"&BH$1&$AD14, TRUE)} -> 1287.4455 | BI14: {=INDIRECT("'※ 재무_세부시트'!"&BI$1&$AD14, TRUE)} -> 94.720605 | BJ14: {=INDIRECT("'※ 재무_세부시트'!"&BJ$1&$AD14, TRUE)} -> 90.230886 | BK14: {=INDIRECT("'※ 재무_세부시트'!"&BK$1&$AD14, TRUE)} -> 99.013855
C15: 유무선 | D15: 무선 | E15: 무선 판매관련 수수료 | F15: {=INDIRECT("'※ 재무_세부시트'!"&F$1&$AD15, TRUE)} -> 1276.91 | G15: {=INDIRECT("'※ 재무_세부시트'!"&G$1&$AD15, TRUE)} -> 1282.1047 | H15: {=INDIRECT("'※ 재무_세부시트'!"&H$1&$AD15, TRUE)} -> 90.1286 | I15: {=INDIRECT("'※ 재무_세부시트'!"&I$1&$AD15, TRUE)} -> 143.86298 | J15: {=INDIRECT("'※ 재무_세부시트'!"&J$1&$AD15, TRUE)} -> 101.90002 | K15: {=INDIRECT("'※ 재무_세부시트'!"&K$1&$AD15, TRUE)} -> 94.597902 | L15: {=INDIRECT("'※ 재무_세부시트'!"&L$1&$AD15, TRUE)} -> 123.0866 | M15: {=INDIRECT("'※ 재무_세부시트'!"&M$1&$AD15, TRUE)} -> 121.90912 | ... AC15: {=INDIRECT("'※ 재무_세부시트'!"&AC$1&$AD15, TRUE)} -> 306.86015 | AD15: 14 | AE15: =(3960.788967/100)-AE52 -> 39.60789 | AF15: =(12151.035847/100)-AF52 -> 121.51036 | AG15: =(7705.783112/100)-AG52 -> 77.057831 | AH15: =(10243.475541/100)-AH52 -> 102.43476 | AI15: =(10480.835253/100)-AI52 -> 104.80835 | AJ15: =(12702.525719/100)-AJ52 -> 127.02526 | AK15: =(9774.77105/100)-AK52 -> 97.74771 | AL15: =(17064.927391/100)-AL52 -> 170.64927 | AM15: =(10400.48971/100)-AM52 -> 104.0049 | AN15: =(14586.148137/100)-AN52 -> 145.86148 | AO15: =(8100.090309/100)-AO52 -> 81.000903 | AP15: =(10520.128683/100)-AP52 -> 105.20129 | AQ15: =SUM(AE15:AP15) -> 1276.91 | AS15: =(16674.6085308013/100)-AS52 -> 166.74609 | AT15: =(14254.6721993936/100)-AT52 -> 142.54672 | AU15: =(11468.5922982605/100)-AU52 -> 114.68592 | AV15: =(13397.4924400059/100)-AV52 -> 133.97492 | AW15: =(12273.3751631938/100)-AW52 -> 122.73375 | AX15: =(13957.6200301388/100)-AX52 -> 139.5762 | AY15: =(16963.5861593154/100)-AY52 -> 169.63586 | AZ15: =(11104.3223704168/100)-AZ52 -> 111.04322 | BA15: =(13405.5657507891/100)-BA52 -> 134.05566 | BB15: =(18571.7734130848/100)-BB52 -> 185.71773 | BC15: =(14815.6665454465/100)-BC52 -> 148.15667 | BD15: =(13336.0847840614/100)-BD52 -> 133.36085 | BE15: =SUM(AS15:BD15) -> 1702.2336 | BG15: {=INDIRECT("'※ 재무_세부시트'!"&BG$1&$AD15, TRUE)} -> 39.60789 | BH15: {=INDIRECT("'※ 재무_세부시트'!"&BH$1&$AD15, TRUE)} -> 1276.91 | BI15: {=INDIRECT("'※ 재무_세부시트'!"&BI$1&$AD15, TRUE)} -> 97.74771 | BJ15: {=INDIRECT("'※ 재무_세부시트'!"&BJ$1&$AD15, TRUE)} -> 77.151313 | BK15: {=INDIRECT("'※ 재무_세부시트'!"&BK$1&$AD15, TRUE)} -> 104.0049
D16: 유선 | E16: 유선 판매관련 수수료 | F16: {=INDIRECT("'※ 재무_세부시트'!"&F$1&$AD16, TRUE)} -> 10.535542 | G16: {=INDIRECT("'※ 재무_세부시트'!"&G$1&$AD16, TRUE)} -> 97.020432 | H16: {=INDIRECT("'※ 재무_세부시트'!"&H$1&$AD16, TRUE)} -> 5.6558239 | I16: {=INDIRECT("'※ 재무_세부시트'!"&I$1&$AD16, TRUE)} -> 22.761839 | J16: {=INDIRECT("'※ 재무_세부시트'!"&J$1&$AD16, TRUE)} -> 8.3621768 | K16: {=INDIRECT("'※ 재무_세부시트'!"&K$1&$AD16, TRUE)} -> 9.4018754 | L16: {=INDIRECT("'※ 재무_세부시트'!"&L$1&$AD16, TRUE)} -> 18.188465 | M16: {=INDIRECT("'※ 재무_세부시트'!"&M$1&$AD16, TRUE)} -> -0.19308902 | ... AC16: {=INDIRECT("'※ 재무_세부시트'!"&AC$1&$AD16, TRUE)} -> 43.046779 | AD16: 15 | AE16: 0.32186282 | AF16: 4.6769718 | AG16: 1.4294523 | AH16: 4.1119909 | AI16: 2.6394275 | AJ16: -0.05449167 | AK16: -3.0271059 | AL16: 5.9480626 | AM16: -4.9910422 | AN16: 0.14376036 | AO16: -0.51294951 | AP16: -0.15039681 | AQ16: =SUM(AE16:AP16) -> 10.535542 | AS16: 1.7 | AT16: 1.7 | AU16: 1.7 | AV16: 1.7 | AW16: 1.7 | AX16: 1.7 | AY16: 1.7 | AZ16: 1.7 | BA16: 1.7 | BB16: 1.7 | BC16: 1.7 | BD16: 1.7 | BE16: =SUM(AS16:BD16) -> 20.4 | BG16: {=INDIRECT("'※ 재무_세부시트'!"&BG$1&$AD16, TRUE)} -> 0.32186282 | BH16: {=INDIRECT("'※ 재무_세부시트'!"&BH$1&$AD16, TRUE)} -> 10.535542 | BI16: {=INDIRECT("'※ 재무_세부시트'!"&BI$1&$AD16, TRUE)} -> -3.0271059 | BJ16: {=INDIRECT("'※ 재무_세부시트'!"&BJ$1&$AD16, TRUE)} -> 13.079573 | BK16: {=INDIRECT("'※ 재무_세부시트'!"&BK$1&$AD16, TRUE)} -> -4.9910422
C17: 채널 | D17: 소매 | F17: {=INDIRECT("'※ 재무_세부시트'!"&F$1&$AD17, TRUE)} -> 983.66137 | G17: {=INDIRECT("'※ 재무_세부시트'!"&G$1&$AD17, TRUE)} -> 1062.1937 | H17: {=INDIRECT("'※ 재무_세부시트'!"&H$1&$AD17, TRUE)} -> 49.550632 | I17: {=INDIRECT("'※ 재무_세부시트'!"&I$1&$AD17, TRUE)} -> 135.13312 | J17: {=INDIRECT("'※ 재무_세부시트'!"&J$1&$AD17, TRUE)} -> 97.077539 | K17: {=INDIRECT("'※ 재무_세부시트'!"&K$1&$AD17, TRUE)} -> 93.319228 | L17: {=INDIRECT("'※ 재무_세부시트'!"&L$1&$AD17, TRUE)} -> 120.71904 | M17: {=INDIRECT("'※ 재무_세부시트'!"&M$1&$AD17, TRUE)} -> 87.744517 | ... S17: {=INDIRECT("'※ 재무_세부시트'!"&S$1&$AD17, TRUE)} -> 63.352057 | W17: {=INDIRECT("'※ 재무_세부시트'!"&W$1&$AD17, TRUE)} -> -2.8737742 | X17: {=INDIRECT("'※ 재무_세부시트'!"&X$1&$AD17, TRUE)} -> -1.3613092 | Y17: {=INDIRECT("'※ 재무_세부시트'!"&Y$1&$AD17, TRUE)} -> 0 | Z17: {=INDIRECT("'※ 재무_세부시트'!"&Z$1&$AD17, TRUE)} -> 1174.2224 | AC17: {=INDIRECT("'※ 재무_세부시트'!"&AC$1&$AD17, TRUE)} -> 112.02868 | AD17: 16 | AE17: =AE93 -> 65.196455 | AF17: =AF93 -> 101.14363 | AG17: =AG93 -> 83.760335 | AH17: =AH93 -> 86.435155 | AI17: =AI93 -> 88.062806 | AJ17: =AJ93 -> 86.666751 | AK17: =AK93 -> 68.686928 | AL17: =AL93 -> 136.5872 | ... AP17: =AP93 -> 50.376419 | AQ17: =SUM(AE17:AP17) -> 983.66137 | BG17: {=INDIRECT("'※ 재무_세부시트'!"&BG$1&$AD17, TRUE)} -> 65.196455 | BH17: {=INDIRECT("'※ 재무_세부시트'!"&BH$1&$AD17, TRUE)} -> 983.66137 | BI17: {=INDIRECT("'※ 재무_세부시트'!"&BI$1&$AD17, TRUE)} -> 68.686928 | BJ17: {=INDIRECT("'※ 재무_세부시트'!"&BJ$1&$AD17, TRUE)} -> 74.807018 | BK17: {=INDIRECT("'※ 재무_세부시트'!"&BK$1&$AD17, TRUE)} -> 53.766598
D18: 도매 | F18: {=INDIRECT("'※ 재무_세부시트'!"&F$1&$AD18, TRUE)} -> 1016.2215 | G18: {=INDIRECT("'※ 재무_세부시트'!"&G$1&$AD18, TRUE)} -> 475.92214 | H18: {=INDIRECT("'※ 재무_세부시트'!"&H$1&$AD18, TRUE)} -> 1.8922512 | I18: {=INDIRECT("'※ 재무_세부시트'!"&I$1&$AD18, TRUE)} -> 2.4818942 | J18: {=INDIRECT("'※ 재무_세부시트'!"&J$1&$AD18, TRUE)} -> 0.70588278 | K18: {=INDIRECT("'※ 재무_세부시트'!"&K$1&$AD18, TRUE)} -> 3.8676704 | L18: {=INDIRECT("'※ 재무_세부시트'!"&L$1&$AD18, TRUE)} -> 0.20809046 | M18: {=INDIRECT("'※ 재무_세부시트'!"&M$1&$AD18, TRUE)} -> 0.95145149 | ... S18: {=INDIRECT("'※ 재무_세부시트'!"&S$1&$AD18, TRUE)} -> 0.80422348 | W18: {=INDIRECT("'※ 재무_세부시트'!"&W$1&$AD18, TRUE)} -> 0.24795065 | X18: {=INDIRECT("'※ 재무_세부시트'!"&X$1&$AD18, TRUE)} -> -6.4082354 | Y18: {=INDIRECT("'※ 재무_세부시트'!"&Y$1&$AD18, TRUE)} -> 0 | Z18: {=INDIRECT("'※ 재무_세부시트'!"&Z$1&$AD18, TRUE)} -> 14.56284 | AC18: {=INDIRECT("'※ 재무_세부시트'!"&AC$1&$AD18, TRUE)} -> -461.3593 | AD18: 17 | AE18: =AE114 -> 79.726588 | AF18: =AF114 -> 101.15129 | AG18: =AG114 -> 75.106436 | AH18: =AH114 -> 81.720367 | AI18: =AI114 -> 74.699835 | AJ18: =AJ114 -> 71.695196 | AK18: =AK114 -> 88.783247 | AL18: =AL114 -> 121.17301 | ... AP18: =AP114 -> 64.490088 | AQ18: =SUM(AE18:AP18) -> 1016.2215 | BG18: {=INDIRECT("'※ 재무_세부시트'!"&BG$1&$AD18, TRUE)} -> 79.726588 | BH18: {=INDIRECT("'※ 재무_세부시트'!"&BH$1&$AD18, TRUE)} -> 1016.2215 | BI18: {=INDIRECT("'※ 재무_세부시트'!"&BI$1&$AD18, TRUE)} -> 88.783247 | BJ18: {=INDIRECT("'※ 재무_세부시트'!"&BJ$1&$AD18, TRUE)} -> 47.880171 | BK18: {=INDIRECT("'※ 재무_세부시트'!"&BK$1&$AD18, TRUE)} -> 87.086654
D19: 디지털 | F19: {=INDIRECT("'※ 재무_세부시트'!"&F$1&$AD19, TRUE)} -> 133.80859 | G19: {=INDIRECT("'※ 재무_세부시트'!"&G$1&$AD19, TRUE)} -> 188.32789 | H19: {=INDIRECT("'※ 재무_세부시트'!"&H$1&$AD19, TRUE)} -> 24.53915 | I19: {=INDIRECT("'※ 재무_세부시트'!"&I$1&$AD19, TRUE)} -> 24.976993 | J19: {=INDIRECT("'※ 재무_세부시트'!"&J$1&$AD19, TRUE)} -> 8.5582728 | K19: {=INDIRECT("'※ 재무_세부시트'!"&K$1&$AD19, TRUE)} -> 10.236852 | L19: {=INDIRECT("'※ 재무_세부시트'!"&L$1&$AD19, TRUE)} -> 13.668366 | M19: {=INDIRECT("'※ 재무_세부시트'!"&M$1&$AD19, TRUE)} -> 22.241117 | ... S19: {=INDIRECT("'※ 재무_세부시트'!"&S$1&$AD19, TRUE)} -> 42.187589 | W19: {=INDIRECT("'※ 재무_세부시트'!"&W$1&$AD19, TRUE)} -> 5.0991459 | X19: {=INDIRECT("'※ 재무_세부시트'!"&X$1&$AD19, TRUE)} -> 30.260298 | Y19: {=INDIRECT("'※ 재무_세부시트'!"&Y$1&$AD19, TRUE)} -> 0 | Z19: {=INDIRECT("'※ 재무_세부시트'!"&Z$1&$AD19, TRUE)} -> 364.0574 | AC19: {=INDIRECT("'※ 재무_세부시트'!"&AC$1&$AD19, TRUE)} -> 175.72951 | AD19: 18 | AE19: =AE136 -> 2.2492078 | AF19: =AF136 -> 15.326399 | AG19: =AG136 -> 9.9789229 | AH19: =AH136 -> 8.0602549 | AI19: =AI136 -> 10.574179 | AJ19: =AJ136 -> 11.279598 | AK19: =AK136 -> 9.417566 | AL19: =AL136 -> 22.97286 | ... AP19: =AP136 -> 10.036641 | AQ19: =SUM(AE19:AP19) -> 133.80859 | BG19: {=INDIRECT("'※ 재무_세부시트'!"&BG$1&$AD19, TRUE)} -> 2.2492078 | BH19: {=INDIRECT("'※ 재무_세부시트'!"&BH$1&$AD19, TRUE)} -> 133.80859 | BI19: {=INDIRECT("'※ 재무_세부시트'!"&BI$1&$AD19, TRUE)} -> 9.417566 | BJ19: {=INDIRECT("'※ 재무_세부시트'!"&BJ$1&$AD19, TRUE)} -> 11.711347 | BK19: {=INDIRECT("'※ 재무_세부시트'!"&BK$1&$AD19, TRUE)} -> 2.5173947
C20: 신사업 제외 | D20: 기타 | E20: B2B, 대형마트, 소상공인(25년~) 등 | F20: {=INDIRECT("'※ 재무_세부시트'!"&F$1&$AD20, TRUE)} -> 362.70517 | G20: {=INDIRECT("'※ 재무_세부시트'!"&G$1&$AD20, TRUE)} -> 212.84063 | H20: {=INDIRECT("'※ 재무_세부시트'!"&H$1&$AD20, TRUE)} -> 18.417866 | I20: {=INDIRECT("'※ 재무_세부시트'!"&I$1&$AD20, TRUE)} -> 28.322453 | J20: {=INDIRECT("'※ 재무_세부시트'!"&J$1&$AD20, TRUE)} -> 23.0726 | K20: {=INDIRECT("'※ 재무_세부시트'!"&K$1&$AD20, TRUE)} -> 21.997285 | L20: {=INDIRECT("'※ 재무_세부시트'!"&L$1&$AD20, TRUE)} -> 29.546987 | M20: {=INDIRECT("'※ 재무_세부시트'!"&M$1&$AD20, TRUE)} -> 48.038093 | ... S20: {=INDIRECT("'※ 재무_세부시트'!"&S$1&$AD20, TRUE)} -> 35.002715 | W20: {=INDIRECT("'※ 재무_세부시트'!"&W$1&$AD20, TRUE)} -> -16.908011 | X20: {=INDIRECT("'※ 재무_세부시트'!"&X$1&$AD20, TRUE)} -> 14.734211 | Y20: {=INDIRECT("'※ 재무_세부시트'!"&Y$1&$AD20, TRUE)} -> 0 | Z20: {=INDIRECT("'※ 재무_세부시트'!"&Z$1&$AD20, TRUE)} -> 394.21894 | AC20: {=INDIRECT("'※ 재무_세부시트'!"&AC$1&$AD20, TRUE)} -> 181.37831 | AD20: 19 | AE20: =AE14-AE17-AE18-AE19-AE21 -> -14.95239 | AF20: =AF14-AF17-AF18-AF19-AF21 -> 20.654254 | AG20: =AG14-AG17-AG18-AG19-AG21 -> 6.5305215 | AH20: =AH14-AH17-AH18-AH19-AH21 -> 23.230123 | AI20: =AI14-AI17-AI18-AI19-AI21 -> 26.516638 | AJ20: =AJ14-AJ17-AJ18-AJ19-AJ21 -> 49.049275 | AK20: =AK14-AK17-AK18-AK19-AK21 -> 29.098264 | AL20: =AL14-AL17-AL18-AL19-AL21 -> 40.529453 | ... AP20: =AP14-AP17-AP18-AP19-AP21 -> 58.175623 | AQ20: =SUM(AE20:AP20) -> 362.70517 | BG20: {=INDIRECT("'※ 재무_세부시트'!"&BG$1&$AD20, TRUE)} -> -14.95239 | BH20: {=INDIRECT("'※ 재무_세부시트'!"&BH$1&$AD20, TRUE)} -> 362.70517 | BI20: {=INDIRECT("'※ 재무_세부시트'!"&BI$1&$AD20, TRUE)} -> 29.098264 | BJ20: {=INDIRECT("'※ 재무_세부시트'!"&BJ$1&$AD20, TRUE)} -> 10.078795 | BK20: {=INDIRECT("'※ 재무_세부시트'!"&BK$1&$AD20, TRUE)} -> 51.771138
D21: 순액처리 | F21: {=INDIRECT("'※ 재무_세부시트'!"&F$1&$AD21, TRUE)} -> -1208.9511 | G21: {=INDIRECT("'※ 재무_세부시트'!"&G$1&$AD21, TRUE)} -> -560.1592 | H21: {=INDIRECT("'※ 재무_세부시트'!"&H$1&$AD21, TRUE)} -> 1.3845247 | I21: {=INDIRECT("'※ 재무_세부시트'!"&I$1&$AD21, TRUE)} -> -24.289645 | J21: {=INDIRECT("'※ 재무_세부시트'!"&J$1&$AD21, TRUE)} -> -19.1521 | K21: {=INDIRECT("'※ 재무_세부시트'!"&K$1&$AD21, TRUE)} -> -25.421259 | L21: {=INDIRECT("'※ 재무_세부시트'!"&L$1&$AD21, TRUE)} -> -22.867412 | M21: {=INDIRECT("'※ 재무_세부시트'!"&M$1&$AD21, TRUE)} -> -37.259143 | ... S21: {=INDIRECT("'※ 재무_세부시트'!"&S$1&$AD21, TRUE)} -> 42.385013 | W21: {=INDIRECT("'※ 재무_세부시트'!"&W$1&$AD21, TRUE)} -> 54.935215 | X21: {=INDIRECT("'※ 재무_세부시트'!"&X$1&$AD21, TRUE)} -> 33.456988 | Y21: {=INDIRECT("'※ 재무_세부시트'!"&Y$1&$AD21, TRUE)} -> 0 | Z21: {=INDIRECT("'※ 재무_세부시트'!"&Z$1&$AD21, TRUE)} -> -218.02947 | AC21: {=INDIRECT("'※ 재무_세부시트'!"&AC$1&$AD21, TRUE)} -> 342.12973 | AD21: 20 | AE21: -92.290107 | AF21: -112.08824 | AG21: -96.888933 | AH21: -92.899153 | AI21: -92.405679 | AJ21: -91.720055 | AK21: -101.2654 | AL21: -144.66518 | AM21: -96.127929 | AN21: -113.53647 | AO21: -97.03606 | AP21: -78.02788 | AQ21: =SUM(AE21:AP21) -> -1208.9511 | BG21: {=INDIRECT("'※ 재무_세부시트'!"&BG$1&$AD21, TRUE)} -> -92.290107 | BH21: {=INDIRECT("'※ 재무_세부시트'!"&BH$1&$AD21, TRUE)} -> -1208.9511 | BI21: {=INDIRECT("'※ 재무_세부시트'!"&BI$1&$AD21, TRUE)} -> -101.2654 | BJ21: {=INDIRECT("'※ 재무_세부시트'!"&BJ$1&$AD21, TRUE)} -> -54.246445 | BK21: {=INDIRECT("'※ 재무_세부시트'!"&BK$1&$AD21, TRUE)} -> -96.127929
C22: 관리수수료 | F22: {=INDIRECT("'※ 재무_세부시트'!"&F$1&$AD22, TRUE)} -> 700.35096 | G22: {=INDIRECT("'※ 재무_세부시트'!"&G$1&$AD22, TRUE)} -> 685.32327 | H22: {=INDIRECT("'※ 재무_세부시트'!"&H$1&$AD22, TRUE)} -> 49.926384 | I22: {=INDIRECT("'※ 재무_세부시트'!"&I$1&$AD22, TRUE)} -> 52.970258 | J22: {=INDIRECT("'※ 재무_세부시트'!"&J$1&$AD22, TRUE)} -> 49.264715 | K22: {=INDIRECT("'※ 재무_세부시트'!"&K$1&$AD22, TRUE)} -> 56.60334 | L22: {=INDIRECT("'※ 재무_세부시트'!"&L$1&$AD22, TRUE)} -> 46.224101 | M22: {=INDIRECT("'※ 재무_세부시트'!"&M$1&$AD22, TRUE)} -> 59.260522 | ... AC22: {=INDIRECT("'※ 재무_세부시트'!"&AC$1&$AD22, TRUE)} -> -69.680725 | AD22: 21 | AE22: 67.035032 | AF22: 50.863376 | AG22: 59.716036 | AH22: 55.567621 | AI22: 58.716059 | AJ22: 57.914679 | AK22: 60.555175 | AL22: 58.62319 | AM22: 53.750966 | AN22: 60.481486 | AO22: 55.964691 | AP22: 61.162647 | AQ22: =SUM(AE22:AP22) -> 700.35096 | AS22: 56.980025 | AT22: 56.856113 | AU22: 56.714148 | AV22: 56.60267 | AW22: 56.499211 | AX22: 56.573814 | AY22: 56.308742 | AZ22: 56.195438 | BA22: 56.070906 | BB22: 55.951718 | BC22: 55.737249 | BD22: 55.52048 | BE22: =SUM(AS22:BD22) -> 676.01051 | BG22: {=INDIRECT("'※ 재무_세부시트'!"&BG$1&$AD22, TRUE)} -> 67.035032 | BH22: {=INDIRECT("'※ 재무_세부시트'!"&BH$1&$AD22, TRUE)} -> 700.35096 | BI22: {=INDIRECT("'※ 재무_세부시트'!"&BI$1&$AD22, TRUE)} -> 60.555175 | BJ22: {=INDIRECT("'※ 재무_세부시트'!"&BJ$1&$AD22, TRUE)} -> 55.127947 | BK22: {=INDIRECT("'※ 재무_세부시트'!"&BK$1&$AD22, TRUE)} -> 53.750966
C23: 유무선 | D23: 무선 | E23: 도매 HC 포함 | F23: {=INDIRECT("'※ 재무_세부시트'!"&F$1&$AD23, TRUE)} -> 515.2506 | G23: {=INDIRECT("'※ 재무_세부시트'!"&G$1&$AD23, TRUE)} -> 504.9822 | H23: {=INDIRECT("'※ 재무_세부시트'!"&H$1&$AD23, TRUE)} -> 35.549797 | I23: {=INDIRECT("'※ 재무_세부시트'!"&I$1&$AD23, TRUE)} -> 38.023935 | J23: {=INDIRECT("'※ 재무_세부시트'!"&J$1&$AD23, TRUE)} -> 34.712852 | K23: {=INDIRECT("'※ 재무_세부시트'!"&K$1&$AD23, TRUE)} -> 42.590158 | L23: {=INDIRECT("'※ 재무_세부시트'!"&L$1&$AD23, TRUE)} -> 32.231392 | M23: {=INDIRECT("'※ 재무_세부시트'!"&M$1&$AD23, TRUE)} -> 45.135692 | ... S23: {=INDIRECT("'※ 재무_세부시트'!"&S$1&$AD23, TRUE)} -> 38.150327 | W23: {=INDIRECT("'※ 재무_세부시트'!"&W$1&$AD23, TRUE)} -> 0.7862773 | X23: {=INDIRECT("'※ 재무_세부시트'!"&X$1&$AD23, TRUE)} -> -13.807365 | Y23: {=INDIRECT("'※ 재무_세부시트'!"&Y$1&$AD23, TRUE)} -> 0 | Z23: {=INDIRECT("'※ 재무_세부시트'!"&Z$1&$AD23, TRUE)} -> 456.77828 | AC23: {=INDIRECT("'※ 재무_세부시트'!"&AC$1&$AD23, TRUE)} -> -48.203912 | AD23: 22 | AE23: =AE26+AE27+AE28 -> 45.289262 | AF23: =AF26+AF27+AF28 -> 30.587527 | AG23: =AG26+AG27+AG28 -> 37.89504 | AH23: =AH26+AH27+AH28 -> 34.921305 | AI23: =AI26+AI27+AI28 -> 37.807271 | AJ23: =AJ26+AJ27+AJ28 -> 36.979842 | AK23: =AK26+AK27+AK28 -> 39.29655 | AL23: =AL26+AL27+AL28 -> 37.691539 | ... AP23: =AP26+AP27+AP28 -> 39.85872 | AQ23: =SUM(AE23:AP23) -> 448.04183 | BG23: {=INDIRECT("'※ 재무_세부시트'!"&BG$1&$AD23, TRUE)} -> 50.94331 | BH23: {=INDIRECT("'※ 재무_세부시트'!"&BH$1&$AD23, TRUE)} -> 515.2506 | BI23: {=INDIRECT("'※ 재무_세부시트'!"&BI$1&$AD23, TRUE)} -> 44.930372 | BJ23: {=INDIRECT("'※ 재무_세부시트'!"&BJ$1&$AD23, TRUE)} -> 40.355937 | BK23: {=INDIRECT("'※ 재무_세부시트'!"&BK$1&$AD23, TRUE)} -> 38.834797
D24: 유선 | F24: {=INDIRECT("'※ 재무_세부시트'!"&F$1&$AD24, TRUE)} -> 90.192255 | G24: {=INDIRECT("'※ 재무_세부시트'!"&G$1&$AD24, TRUE)} -> 82.572907 | H24: {=INDIRECT("'※ 재무_세부시트'!"&H$1&$AD24, TRUE)} -> 5.8569293 | I24: {=INDIRECT("'※ 재무_세부시트'!"&I$1&$AD24, TRUE)} -> 6.3086738 | J24: {=INDIRECT("'※ 재무_세부시트'!"&J$1&$AD24, TRUE)} -> 6.4937648 | K24: {=INDIRECT("'※ 재무_세부시트'!"&K$1&$AD24, TRUE)} -> 5.7726904 | L24: {=INDIRECT("'※ 재무_세부시트'!"&L$1&$AD24, TRUE)} -> 5.6720753 | M24: {=INDIRECT("'※ 재무_세부시트'!"&M$1&$AD24, TRUE)} -> 5.5931315 | ... S24: {=INDIRECT("'※ 재무_세부시트'!"&S$1&$AD24, TRUE)} -> 5.1079653 | W24: {=INDIRECT("'※ 재무_세부시트'!"&W$1&$AD24, TRUE)} -> -0.023605809 | X24: {=INDIRECT("'※ 재무_세부시트'!"&X$1&$AD24, TRUE)} -> -1.4735796 | Y24: {=INDIRECT("'※ 재무_세부시트'!"&Y$1&$AD24, TRUE)} -> 0 | Z24: {=INDIRECT("'※ 재무_세부시트'!"&Z$1&$AD24, TRUE)} -> 68.278925 | AC24: {=INDIRECT("'※ 재무_세부시트'!"&AC$1&$AD24, TRUE)} -> -14.293982 | AD24: 23 | AE24: =AE30+AE31+AE32 -> 7.897109 | AF24: =AF30+AF31+AF32 -> 6.5027426 | AG24: =AG30+AG31+AG32 -> 7.9257181 | AH24: =AH30+AH31+AH32 -> 7.273413 | AI24: =AI30+AI31+AI32 -> 7.2877746 | AJ24: =AJ30+AJ31+AJ32 -> 7.2841512 | AK24: =AK30+AK31+AK32 -> 7.8168192 | AL24: =AL30+AL31+AL32 -> 7.473016 | ... AP24: =AP30+AP31+AP32 -> 8.1445389 | AQ24: =SUM(AE24:AP24) -> 90.192255 | BG24: {=INDIRECT("'※ 재무_세부시트'!"&BG$1&$AD24, TRUE)} -> 7.897109 | BH24: {=INDIRECT("'※ 재무_세부시트'!"&BH$1&$AD24, TRUE)} -> 90.192255 | BI24: {=INDIRECT("'※ 재무_세부시트'!"&BI$1&$AD24, TRUE)} -> 7.8168192 | BJ24: {=INDIRECT("'※ 재무_세부시트'!"&BJ$1&$AD24, TRUE)} -> 6.8127735 | BK24: {=INDIRECT("'※ 재무_세부시트'!"&BK$1&$AD24, TRUE)} -> 7.3596236
D25: 기타 | F25: {=INDIRECT("'※ 재무_세부시트'!"&F$1&$AD25, TRUE)} -> 94.908103 | G25: {=INDIRECT("'※ 재무_세부시트'!"&G$1&$AD25, TRUE)} -> 97.76817 | H25: {=INDIRECT("'※ 재무_세부시트'!"&H$1&$AD25, TRUE)} -> 8.5196579 | I25: {=INDIRECT("'※ 재무_세부시트'!"&I$1&$AD25, TRUE)} -> 8.6376484 | J25: {=INDIRECT("'※ 재무_세부시트'!"&J$1&$AD25, TRUE)} -> 8.0580981 | K25: {=INDIRECT("'※ 재무_세부시트'!"&K$1&$AD25, TRUE)} -> 8.2404921 | L25: {=INDIRECT("'※ 재무_세부시트'!"&L$1&$AD25, TRUE)} -> 8.3206333 | M25: {=INDIRECT("'※ 재무_세부시트'!"&M$1&$AD25, TRUE)} -> 8.5316987 | ... S25: {=INDIRECT("'※ 재무_세부시트'!"&S$1&$AD25, TRUE)} -> 7.7488725 | W25: {=INDIRECT("'※ 재무_세부시트'!"&W$1&$AD25, TRUE)} -> -0.00961416 | X25: {=INDIRECT("'※ 재무_세부시트'!"&X$1&$AD25, TRUE)} -> -0.80247936 | Y25: {=INDIRECT("'※ 재무_세부시트'!"&Y$1&$AD25, TRUE)} -> 0 | Z25: {=INDIRECT("'※ 재무_세부시트'!"&Z$1&$AD25, TRUE)} -> 90.585339 | AC25: {=INDIRECT("'※ 재무_세부시트'!"&AC$1&$AD25, TRUE)} -> -7.1828316 | AD25: 24 | AE25: =AE22-AE23-AE24 -> 13.848661 | AF25: =AF22-AF23-AF24 -> 13.773106 | AG25: =AG22-AG23-AG24 -> 13.895278 | AH25: =AH22-AH23-AH24 -> 13.372903 | AI25: =AI22-AI23-AI24 -> 13.621014 | AJ25: =AJ22-AJ23-AJ24 -> 13.650687 | AK25: =AK22-AK23-AK24 -> 13.441806 | AL25: =AL22-AL23-AL24 -> 13.458636 | ... AP25: =AP22-AP23-AP24 -> 13.159388 | AQ25: =SUM(AE25:AP25) -> 162.11687 | BG25: {=INDIRECT("'※ 재무_세부시트'!"&BG$1&$AD25, TRUE)} -> 8.1946132 | BH25: {=INDIRECT("'※ 재무_세부시트'!"&BH$1&$AD25, TRUE)} -> 94.908103 | BI25: {=INDIRECT("'※ 재무_세부시트'!"&BI$1&$AD25, TRUE)} -> 7.8079841 | BJ25: {=INDIRECT("'※ 재무_세부시트'!"&BJ$1&$AD25, TRUE)} -> 7.959237 | BK25: {=INDIRECT("'※ 재무_세부시트'!"&BK$1&$AD25, TRUE)} -> 7.5565453
C26: 수수료 항목 | D26: 무선후불 | E26: 관리수수료(6.5%)+H/C(2%) | F26: {=INDIRECT("'※ 재무_세부시트'!"&F$1&$AD26, TRUE)} -> 410.81618 | G26: {=INDIRECT("'※ 재무_세부시트'!"&G$1&$AD26, TRUE)} -> 405.4862 | H26: {=INDIRECT("'※ 재무_세부시트'!"&H$1&$AD26, TRUE)} -> 28.244298 | I26: {=INDIRECT("'※ 재무_세부시트'!"&I$1&$AD26, TRUE)} -> 30.704433 | J26: {=INDIRECT("'※ 재무_세부시트'!"&J$1&$AD26, TRUE)} -> 27.694782 | K26: {=INDIRECT("'※ 재무_세부시트'!"&K$1&$AD26, TRUE)} -> 35.633831 | L26: {=INDIRECT("'※ 재무_세부시트'!"&L$1&$AD26, TRUE)} -> 25.39898 | M26: {=INDIRECT("'※ 재무_세부시트'!"&M$1&$AD26, TRUE)} -> 38.599851 | ... S26: {=INDIRECT("'※ 재무_세부시트'!"&S$1&$AD26, TRUE)} -> 32.494026 | W26: {=INDIRECT("'※ 재무_세부시트'!"&W$1&$AD26, TRUE)} -> 0.88334037 | X26: {=INDIRECT("'※ 재무_세부시트'!"&X$1&$AD26, TRUE)} -> -11.906723 | Y26: {=INDIRECT("'※ 재무_세부시트'!"&Y$1&$AD26, TRUE)} -> 0 | Z26: {=INDIRECT("'※ 재무_세부시트'!"&Z$1&$AD26, TRUE)} -> 378.57008 | AC26: {=INDIRECT("'※ 재무_세부시트'!"&AC$1&$AD26, TRUE)} -> -26.916119 | AD26: 25 | AE26: =AE22-AE28-AE29-AE30-AE31-AE32-AE33-AE34-AE27 -> 42.066385 | AF26: =AF22-AF28-AF29-AF30-AF31-AF32-AF33-AF34-AF27 -> 27.371089 | AG26: =AG22-AG28-AG29-AG30-AG31-AG32-AG33-AG34-AG27 -> 34.751477 | AH26: =AH22-AH28-AH29-AH30-AH31-AH32-AH33-AH34-AH27 -> 31.781033 | AI26: =AI22-AI28-AI29-AI30-AI31-AI32-AI33-AI34-AI27 -> 34.715692 | AJ26: =AJ22-AJ28-AJ29-AJ30-AJ31-AJ32-AJ33-AJ34-AJ27 -> 33.89568 | AK26: =AK22-AK28-AK29-AK30-AK31-AK32-AK33-AK34-AK27 -> 36.221803 | AL26: =AL22-AL28-AL29-AL30-AL31-AL32-AL33-AL34-AL27 -> 34.629332 | ... AP26: =AP22-AP28-AP29-AP30-AP31-AP32-AP33-AP34-AP27 -> 36.82078 | AQ26: =SUM(AE26:AP26) -> 410.81618 | BE26: =SUM(AS26:BD26) -> 0 | BG26: {=INDIRECT("'※ 재무_세부시트'!"&BG$1&$AD26, TRUE)} -> 42.066385 | BH26: {=INDIRECT("'※ 재무_세부시트'!"&BH$1&$AD26, TRUE)} -> 410.81618 | BI26: {=INDIRECT("'※ 재무_세부시트'!"&BI$1&$AD26, TRUE)} -> 36.221803 | BJ26: {=INDIRECT("'※ 재무_세부시트'!"&BJ$1&$AD26, TRUE)} -> 31.993703 | BK26: {=INDIRECT("'※ 재무_세부시트'!"&BK$1&$AD26, TRUE)} -> 30.246924
D27: 2nd 등 기타단말 | E27: PAD, wearable 등 | F27: {=INDIRECT("'※ 재무_세부시트'!"&F$1&$AD27, TRUE)} -> 19.314572 | G27: {=INDIRECT("'※ 재무_세부시트'!"&G$1&$AD27, TRUE)} -> 17.795332 | H27: {=INDIRECT("'※ 재무_세부시트'!"&H$1&$AD27, TRUE)} -> 1.4180424 | I27: {=INDIRECT("'※ 재무_세부시트'!"&I$1&$AD27, TRUE)} -> 1.4337838 | J27: {=INDIRECT("'※ 재무_세부시트'!"&J$1&$AD27, TRUE)} -> 1.4274744 | K27: {=INDIRECT("'※ 재무_세부시트'!"&K$1&$AD27, TRUE)} -> 1.5287669 | L27: {=INDIRECT("'※ 재무_세부시트'!"&L$1&$AD27, TRUE)} -> 1.5329222 | M27: {=INDIRECT("'※ 재무_세부시트'!"&M$1&$AD27, TRUE)} -> 1.4180424 | ... S27: {=INDIRECT("'※ 재무_세부시트'!"&S$1&$AD27, TRUE)} -> 1.5105706 | W27: {=INDIRECT("'※ 재무_세부시트'!"&W$1&$AD27, TRUE)} -> 0.012212134 | X27: {=INDIRECT("'※ 재무_세부시트'!"&X$1&$AD27, TRUE)} -> 0.090124659 | Y27: {=INDIRECT("'※ 재무_세부시트'!"&Y$1&$AD27, TRUE)} -> 0 | Z27: {=INDIRECT("'※ 재무_세부시트'!"&Z$1&$AD27, TRUE)} -> 17.832613 | AC27: {=INDIRECT("'※ 재무_세부시트'!"&AC$1&$AD27, TRUE)} -> 0.037280938 | AD27: 26 | AE27: 1.7 | AF27: 1.683 | AG27: 1.66617 | AH27: 1.6495083 | AI27: 1.6330132 | AJ27: 1.6166831 | AK27: 1.6005163 | AL27: 1.5845111 | AM27: 1.568666 | AN27: 1.5529793 | AO27: 1.5374495 | AP27: 1.522075 | AQ27: =SUM(AE27:AP27) -> 19.314572 | BE27: =SUM(AS27:BD27) -> 0 | BG27: {=INDIRECT("'※ 재무_세부시트'!"&BG$1&$AD27, TRUE)} -> 1.7 | BH27: {=INDIRECT("'※ 재무_세부시트'!"&BH$1&$AD27, TRUE)} -> 19.314572 | BI27: {=INDIRECT("'※ 재무_세부시트'!"&BI$1&$AD27, TRUE)} -> 1.6005163 | BJ27: {=INDIRECT("'※ 재무_세부시트'!"&BJ$1&$AD27, TRUE)} -> 1.4897 | BK27: {=INDIRECT("'※ 재무_세부시트'!"&BK$1&$AD27, TRUE)} -> 1.568666
D28: IoT | E28: M2M 가입자 | F28: {=INDIRECT("'※ 재무_세부시트'!"&F$1&$AD28, TRUE)} -> 17.911081 | G28: {=INDIRECT("'※ 재무_세부시트'!"&G$1&$AD28, TRUE)} -> 20.661178 | H28: {=INDIRECT("'※ 재무_세부시트'!"&H$1&$AD28, TRUE)} -> 1.7448628 | I28: {=INDIRECT("'※ 재무_세부시트'!"&I$1&$AD28, TRUE)} -> 1.7453801 | J28: {=INDIRECT("'※ 재무_세부시트'!"&J$1&$AD28, TRUE)} -> 1.7273761 | K28: {=INDIRECT("'※ 재무_세부시트'!"&K$1&$AD28, TRUE)} -> 1.7503189 | L28: {=INDIRECT("'※ 재무_세부시트'!"&L$1&$AD28, TRUE)} -> 1.781016 | M28: {=INDIRECT("'※ 재무_세부시트'!"&M$1&$AD28, TRUE)} -> 1.7448628 | ... S28: {=INDIRECT("'※ 재무_세부시트'!"&S$1&$AD28, TRUE)} -> 1.7430904 | W28: {=INDIRECT("'※ 재무_세부시트'!"&W$1&$AD28, TRUE)} -> 0 | X28: {=INDIRECT("'※ 재무_세부시트'!"&X$1&$AD28, TRUE)} -> 0.015631056 | Y28: {=INDIRECT("'※ 재무_세부시트'!"&Y$1&$AD28, TRUE)} -> 0 | Z28: {=INDIRECT("'※ 재무_세부시트'!"&Z$1&$AD28, TRUE)} -> 20.959672 | AC28: {=INDIRECT("'※ 재무_세부시트'!"&AC$1&$AD28, TRUE)} -> 0.29849395 | AD28: 27 | AE28: 1.522877 | AF28: 1.5334383 | AG28: 1.4773935 | AH28: 1.490764 | AI28: 1.458566 | AJ28: 1.4674783 | AK28: 1.4742315 | AL28: 1.4776952 | AM28: 1.482604 | AN28: 1.4977765 | AO28: 1.5123922 | AP28: 1.5158645 | AQ28: =SUM(AE28:AP28) -> 17.911081 | BE28: =SUM(AS28:BD28) -> 0 | BG28: {=INDIRECT("'※ 재무_세부시트'!"&BG$1&$AD28, TRUE)} -> 1.522877 | BH28: {=INDIRECT("'※ 재무_세부시트'!"&BH$1&$AD28, TRUE)} -> 17.911081 | BI28: {=INDIRECT("'※ 재무_세부시트'!"&BI$1&$AD28, TRUE)} -> 1.4742315 | BJ28: {=INDIRECT("'※ 재무_세부시트'!"&BJ$1&$AD28, TRUE)} -> 1.7 | BK28: {=INDIRECT("'※ 재무_세부시트'!"&BK$1&$AD28, TRUE)} -> 1.482604
D29: 도매 H/C | E29: '21년2월이후 도매위탁 가입자 2% (무선) | F29: {=INDIRECT("'※ 재무_세부시트'!"&F$1&$AD29, TRUE)} -> 67.208766 | G29: {=INDIRECT("'※ 재무_세부시트'!"&G$1&$AD29, TRUE)} -> 61.039488 | H29: {=INDIRECT("'※ 재무_세부시트'!"&H$1&$AD29, TRUE)} -> 4.1425932 | I29: {=INDIRECT("'※ 재무_세부시트'!"&I$1&$AD29, TRUE)} -> 4.1403388 | J29: {=INDIRECT("'※ 재무_세부시트'!"&J$1&$AD29, TRUE)} -> 3.8632196 | K29: {=INDIRECT("'※ 재무_세부시트'!"&K$1&$AD29, TRUE)} -> 3.6772409 | L29: {=INDIRECT("'※ 재무_세부시트'!"&L$1&$AD29, TRUE)} -> 3.5184741 | M29: {=INDIRECT("'※ 재무_세부시트'!"&M$1&$AD29, TRUE)} -> 3.3729352 | ... S29: {=INDIRECT("'※ 재무_세부시트'!"&S$1&$AD29, TRUE)} -> 2.4026395 | W29: {=INDIRECT("'※ 재무_세부시트'!"&W$1&$AD29, TRUE)} -> -0.1092752 | X29: {=INDIRECT("'※ 재무_세부시트'!"&X$1&$AD29, TRUE)} -> -2.0063984 | Y29: {=INDIRECT("'※ 재무_세부시트'!"&Y$1&$AD29, TRUE)} -> 0 | Z29: {=INDIRECT("'※ 재무_세부시트'!"&Z$1&$AD29, TRUE)} -> 39.41592 | AC29: {=INDIRECT("'※ 재무_세부시트'!"&AC$1&$AD29, TRUE)} -> -21.623568 | AD29: 28 | AE29: 5.6540479 | AF29: 5.7012886 | AG29: 5.7383666 | AH29: 5.5275549 | AI29: 5.4801296 | AJ29: 5.4858961 | AK29: 5.6338215 | AL29: 5.6292191 | AM29: 5.5366031 | AN29: 5.6500354 | AO29: 5.5978559 | AP29: 5.5739475 | AQ29: =SUM(AE29:AP29) -> 67.208766 | BE29: =SUM(AS29:BD29) -> 0 | BG29: {=INDIRECT("'※ 재무_세부시트'!"&BG$1&$AD29, TRUE)} -> 5.6540479 | BH29: {=INDIRECT("'※ 재무_세부시트'!"&BH$1&$AD29, TRUE)} -> 67.208766 | BI29: {=INDIRECT("'※ 재무_세부시트'!"&BI$1&$AD29, TRUE)} -> 5.6338215 | BJ29: {=INDIRECT("'※ 재무_세부시트'!"&BJ$1&$AD29, TRUE)} -> 5.1725335 | BK29: {=INDIRECT("'※ 재무_세부시트'!"&BK$1&$AD29, TRUE)} -> 5.5366031
D30: 인터넷 | F30: {=INDIRECT("'※ 재무_세부시트'!"&F$1&$AD30, TRUE)} -> 56.691541 | G30: {=INDIRECT("'※ 재무_세부시트'!"&G$1&$AD30, TRUE)} -> 54.931285 | H30: {=INDIRECT("'※ 재무_세부시트'!"&H$1&$AD30, TRUE)} -> 3.8039285 | I30: {=INDIRECT("'※ 재무_세부시트'!"&I$1&$AD30, TRUE)} -> 4.1171956 | J30: {=INDIRECT("'※ 재무_세부시트'!"&J$1&$AD30, TRUE)} -> 4.3993616 | K30: {=INDIRECT("'※ 재무_세부시트'!"&K$1&$AD30, TRUE)} -> 3.7391066 | L30: {=INDIRECT("'※ 재무_세부시트'!"&L$1&$AD30, TRUE)} -> 3.6557821 | M30: {=INDIRECT("'※ 재무_세부시트'!"&M$1&$AD30, TRUE)} -> 3.5924523 | ... S30: {=INDIRECT("'※ 재무_세부시트'!"&S$1&$AD30, TRUE)} -> 3.1645737 | W30: {=INDIRECT("'※ 재무_세부시트'!"&W$1&$AD30, TRUE)} -> -0.026528455 | X30: {=INDIRECT("'※ 재무_세부시트'!"&X$1&$AD30, TRUE)} -> -1.1168895 | Y30: {=INDIRECT("'※ 재무_세부시트'!"&Y$1&$AD30, TRUE)} -> 0 | Z30: {=INDIRECT("'※ 재무_세부시트'!"&Z$1&$AD30, TRUE)} -> 43.773921 | AC30: {=INDIRECT("'※ 재무_세부시트'!"&AC$1&$AD30, TRUE)} -> -11.157363 | AD30: 29 | AE30: 5.034111 | AF30: 4.2332796 | AG30: 4.9166244 | AH30: 4.5693362 | AI30: 4.5908375 | AJ30: 4.5822825 | AK30: 4.9184787 | AL30: 4.6786445 | AM30: 4.6044434 | AN30: 4.7734635 | AO30: 4.7316571 | AP30: 5.0583823 | AQ30: =SUM(AE30:AP30) -> 56.691541 | BE30: =SUM(AS30:BD30) -> 0 | BG30: {=INDIRECT("'※ 재무_세부시트'!"&BG$1&$AD30, TRUE)} -> 5.034111 | BH30: {=INDIRECT("'※ 재무_세부시트'!"&BH$1&$AD30, TRUE)} -> 56.691541 | BI30: {=INDIRECT("'※ 재무_세부시트'!"&BI$1&$AD30, TRUE)} -> 4.9184787 | BJ30: {=INDIRECT("'※ 재무_세부시트'!"&BJ$1&$AD30, TRUE)} -> 4.5738334 | BK30: {=INDIRECT("'※ 재무_세부시트'!"&BK$1&$AD30, TRUE)} -> 4.6044434
D31: TV | F31: {=INDIRECT("'※ 재무_세부시트'!"&F$1&$AD31, TRUE)} -> 25.285031 | G31: {=INDIRECT("'※ 재무_세부시트'!"&G$1&$AD31, TRUE)} -> 26.890152 | H31: {=INDIRECT("'※ 재무_세부시트'!"&H$1&$AD31, TRUE)} -> 1.9646245 | I31: {=INDIRECT("'※ 재무_세부시트'!"&I$1&$AD31, TRUE)} -> 2.1139593 | J31: {=INDIRECT("'※ 재무_세부시트'!"&J$1&$AD31, TRUE)} -> 2.0006825 | K31: {=INDIRECT("'※ 재무_세부시트'!"&K$1&$AD31, TRUE)} -> 1.944559 | L31: {=INDIRECT("'※ 재무_세부시트'!"&L$1&$AD31, TRUE)} -> 1.9207854 | M31: {=INDIRECT("'※ 재무_세부시트'!"&M$1&$AD31, TRUE)} -> 1.9006985 | ... S31: {=INDIRECT("'※ 재무_세부시트'!"&S$1&$AD31, TRUE)} -> 1.7909318 | W31: {=INDIRECT("'※ 재무_세부시트'!"&W$1&$AD31, TRUE)} -> -0.0048486364 | X31: {=INDIRECT("'※ 재무_세부시트'!"&X$1&$AD31, TRUE)} -> -0.41620182 | Y31: {=INDIRECT("'※ 재무_세부시트'!"&Y$1&$AD31, TRUE)} -> 0 | Z31: {=INDIRECT("'※ 재무_세부시트'!"&Z$1&$AD31, TRUE)} -> 23.132791 | AC31: {=INDIRECT("'※ 재무_세부시트'!"&AC$1&$AD31, TRUE)} -> -3.7573612 | AD31: 30 | AE31: 1.9871371 | AF31: 2.190501 | AG31: 1.6563014 | AH31: 2.3826345 | AI31: 2.0444983 | AJ31: 2.0659987 | AK31: 2.0694204 | AL31: 2.2355181 | AM31: 2.1392998 | AN31: 2.1141679 | AO31: 2.1989009 | AP31: 2.2006524 | AQ31: =SUM(AE31:AP31) -> 25.285031 | BE31: =SUM(AS31:BD31) -> 0 | BG31: {=INDIRECT("'※ 재무_세부시트'!"&BG$1&$AD31, TRUE)} -> 1.9871371 | BH31: {=INDIRECT("'※ 재무_세부시트'!"&BH$1&$AD31, TRUE)} -> 25.285031 | BI31: {=INDIRECT("'※ 재무_세부시트'!"&BI$1&$AD31, TRUE)} -> 2.0694204 | BJ31: {=INDIRECT("'※ 재무_세부시트'!"&BJ$1&$AD31, TRUE)} -> 2.1981428 | BK31: {=INDIRECT("'※ 재무_세부시트'!"&BK$1&$AD31, TRUE)} -> 2.1392998
D32: 유선기타 | E32: SOIP, 기가아이즈, PSTN 등 | F32: {=INDIRECT("'※ 재무_세부시트'!"&F$1&$AD32, TRUE)} -> 8.2156837 | G32: {=INDIRECT("'※ 재무_세부시트'!"&G$1&$AD32, TRUE)} -> 0.75146973 | H32: {=INDIRECT("'※ 재무_세부시트'!"&H$1&$AD32, TRUE)} -> 0.08837641 | I32: {=INDIRECT("'※ 재무_세부시트'!"&I$1&$AD32, TRUE)} -> 0.0775189 | J32: {=INDIRECT("'※ 재무_세부시트'!"&J$1&$AD32, TRUE)} -> 0.093720582 | K32: {=INDIRECT("'※ 재무_세부시트'!"&K$1&$AD32, TRUE)} -> 0.089024718 | L32: {=INDIRECT("'※ 재무_세부시트'!"&L$1&$AD32, TRUE)} -> 0.095507827 | M32: {=INDIRECT("'※ 재무_세부시트'!"&M$1&$AD32, TRUE)} -> 0.099980718 | ... S32: {=INDIRECT("'※ 재무_세부시트'!"&S$1&$AD32, TRUE)} -> 0.15245973 | W32: {=INDIRECT("'※ 재무_세부시트'!"&W$1&$AD32, TRUE)} -> 0.0077712818 | X32: {=INDIRECT("'※ 재무_세부시트'!"&X$1&$AD32, TRUE)} -> 0.059511727 | Y32: {=INDIRECT("'※ 재무_세부시트'!"&Y$1&$AD32, TRUE)} -> 0 | Z32: {=INDIRECT("'※ 재무_세부시트'!"&Z$1&$AD32, TRUE)} -> 1.3722128 | AC32: {=INDIRECT("'※ 재무_세부시트'!"&AC$1&$AD32, TRUE)} -> 0.62074303 | AD32: 31 | AE32: 0.87586089 | AF32: 0.078961967 | AG32: 1.3527922 | AH32: 0.32144223 | AI32: 0.6524388 | AJ32: 0.63587 | AK32: 0.82892014 | AL32: 0.55885345 | AM32: 0.61588037 | AN32: 0.74195955 | AO32: 0.66719982 | AP32: 0.88550425 | AQ32: =SUM(AE32:AP32) -> 8.2156837 | BE32: =SUM(AS32:BD32) -> 0 | BG32: {=INDIRECT("'※ 재무_세부시트'!"&BG$1&$AD32, TRUE)} -> 0.87586089 | BH32: {=INDIRECT("'※ 재무_세부시트'!"&BH$1&$AD32, TRUE)} -> 8.2156837 | BI32: {=INDIRECT("'※ 재무_세부시트'!"&BI$1&$AD32, TRUE)} -> 0.82892014 | BJ32: {=INDIRECT("'※ 재무_세부시트'!"&BJ$1&$AD32, TRUE)} -> 0.040797309 | BK32: {=INDIRECT("'※ 재무_세부시트'!"&BK$1&$AD32, TRUE)} -> 0.61588037
D33: 매장성수수료 | E33: CS업무처리 수수료 | F33: {=INDIRECT("'※ 재무_세부시트'!"&F$1&$AD33, TRUE)} -> 8.3447991 | G33: {=INDIRECT("'※ 재무_세부시트'!"&G$1&$AD33, TRUE)} -> 7.9449864 | H33: {=INDIRECT("'※ 재무_세부시트'!"&H$1&$AD33, TRUE)} -> 0.58253187 | I33: {=INDIRECT("'※ 재무_세부시트'!"&I$1&$AD33, TRUE)} -> 0.66603878 | J33: {=INDIRECT("'※ 재무_세부시트'!"&J$1&$AD33, TRUE)} -> 0.63645968 | K33: {=INDIRECT("'※ 재무_세부시트'!"&K$1&$AD33, TRUE)} -> 0.59906741 | L33: {=INDIRECT("'※ 재무_세부시트'!"&L$1&$AD33, TRUE)} -> 0.69777633 | M33: {=INDIRECT("'※ 재무_세부시트'!"&M$1&$AD33, TRUE)} -> 0.75951674 | ... S33: {=INDIRECT("'※ 재무_세부시트'!"&S$1&$AD33, TRUE)} -> 0.90341731 | W33: {=INDIRECT("'※ 재무_세부시트'!"&W$1&$AD33, TRUE)} -> 0.01765857 | X33: {=INDIRECT("'※ 재무_세부시트'!"&X$1&$AD33, TRUE)} -> 0.28919146 | Y33: {=INDIRECT("'※ 재무_세부시트'!"&Y$1&$AD33, TRUE)} -> 0 | Z33: {=INDIRECT("'※ 재무_세부시트'!"&Z$1&$AD33, TRUE)} -> 9.1817721 | AC33: {=INDIRECT("'※ 재무_세부시트'!"&AC$1&$AD33, TRUE)} -> 1.2367857 | AD33: 32 | AE33: 0.69246336 | AF33: 0.73521294 | AG33: 0.74165735 | AH33: 0.6494656 | AI33: 0.6837346 | AJ33: 0.70764137 | AK33: 0.71303571 | AL33: 0.75867725 | AM33: 0.63747106 | AN33: 0.7163787 | AO33: 0.68336764 | AP33: 0.62569349 | AQ33: =SUM(AE33:AP33) -> 8.3447991 | AS33: 0.75867725 | AT33: 0.75867725 | AU33: 0.75867725 | AV33: 0.75867725 | AW33: 0.75867725 | AX33: 0.75867725 | AY33: 0.75867725 | AZ33: 0.75867725 | BA33: 0.75867725 | BB33: 0.75867725 | BC33: 0.75867725 | BD33: 0.75867725 | BE33: =SUM(AS33:BD33) -> 9.104127 | BG33: {=INDIRECT("'※ 재무_세부시트'!"&BG$1&$AD33, TRUE)} -> 0.69246336 | BH33: {=INDIRECT("'※ 재무_세부시트'!"&BH$1&$AD33, TRUE)} -> 8.3447991 | BI33: {=INDIRECT("'※ 재무_세부시트'!"&BI$1&$AD33, TRUE)} -> 0.71303571 | BJ33: {=INDIRECT("'※ 재무_세부시트'!"&BJ$1&$AD33, TRUE)} -> 0.64455618 | BK33: {=INDIRECT("'※ 재무_세부시트'!"&BK$1&$AD33, TRUE)} -> 0.63747106 | BO33: =I80/(I13+I51) -> 0.17528381 | BP33: =J80/(J13+J51) -> 0.10039511 | BQ33: =K80/(K13+K51) -> 0.11980746
D34: 프라자3.0 | E34: 플라자 인건비 지원 | F34: {=INDIRECT("'※ 재무_세부시트'!"&F$1&$AD34, TRUE)} -> 86.563304 | G34: {=INDIRECT("'※ 재무_세부시트'!"&G$1&$AD34, TRUE)} -> 89.823184 | H34: {=INDIRECT("'※ 재무_세부시트'!"&H$1&$AD34, TRUE)} -> 7.937126 | I34: {=INDIRECT("'※ 재무_세부시트'!"&I$1&$AD34, TRUE)} -> 7.9716096 | J34: {=INDIRECT("'※ 재무_세부시트'!"&J$1&$AD34, TRUE)} -> 7.4216384 | K34: {=INDIRECT("'※ 재무_세부시트'!"&K$1&$AD34, TRUE)} -> 7.6414247 | L34: {=INDIRECT("'※ 재무_세부시트'!"&L$1&$AD34, TRUE)} -> 7.622857 | M34: {=INDIRECT("'※ 재무_세부시트'!"&M$1&$AD34, TRUE)} -> 7.772182 | ... S34: {=INDIRECT("'※ 재무_세부시트'!"&S$1&$AD34, TRUE)} -> 6.8454552 | W34: {=INDIRECT("'※ 재무_세부시트'!"&W$1&$AD34, TRUE)} -> -0.02727273 | X34: {=INDIRECT("'※ 재무_세부시트'!"&X$1&$AD34, TRUE)} -> -1.0916708 | Y34: {=INDIRECT("'※ 재무_세부시트'!"&Y$1&$AD34, TRUE)} -> 0 | Z34: {=INDIRECT("'※ 재무_세부시트'!"&Z$1&$AD34, TRUE)} -> 81.403567 | AC34: {=INDIRECT("'※ 재무_세부시트'!"&AC$1&$AD34, TRUE)} -> -8.4196173 | AD34: 33 | AE34: 7.5021498 | AF34: 7.336604 | AG34: 7.4152542 | AH34: 7.1958823 | AI34: 7.4571493 | AJ34: 7.4571493 | AK34: 7.0949484 | AL34: 7.0707396 | AM34: 6.9190743 | AN34: 7.3750379 | AO34: 6.7795678 | AP34: 6.9597472 | AQ34: =SUM(AE34:AP34) -> 86.563304 | AS34: 7.030605 | AT34: 7.085747 | AU34: 7.113318 | AV34: 7.140889 | AW34: 7.196031 | AX34: 7.251173 | AY34: 7.306315 | AZ34: 7.361457 | BA34: 7.416599 | BB34: 7.526883 | BC34: 7.582025 | BD34: 7.664738 | BE34: =SUM(AS34:BD34) -> 87.67578 | BG34: {=INDIRECT("'※ 재무_세부시트'!"&BG$1&$AD34, TRUE)} -> 7.5021498 | BH34: {=INDIRECT("'※ 재무_세부시트'!"&BH$1&$AD34, TRUE)} -> 86.563304 | BI34: {=INDIRECT("'※ 재무_세부시트'!"&BI$1&$AD34, TRUE)} -> 7.0949484 | BJ34: {=INDIRECT("'※ 재무_세부시트'!"&BJ$1&$AD34, TRUE)} -> 7.3146808 | BK34: {=INDIRECT("'※ 재무_세부시트'!"&BK$1&$AD34, TRUE)} -> 6.9190743
C35: 채널 | D35: 소매 | E35: 관리수수료(점프업 제외), 매장성 수수료 | F35: {=INDIRECT("'※ 재무_세부시트'!"&F$1&$AD35, TRUE)} -> 318.78142 | G35: {=INDIRECT("'※ 재무_세부시트'!"&G$1&$AD35, TRUE)} -> 322.02978 | H35: {=INDIRECT("'※ 재무_세부시트'!"&H$1&$AD35, TRUE)} -> 24.447654 | I35: {=INDIRECT("'※ 재무_세부시트'!"&I$1&$AD35, TRUE)} -> 25.343579 | J35: {=INDIRECT("'※ 재무_세부시트'!"&J$1&$AD35, TRUE)} -> 25.657675 | K35: {=INDIRECT("'※ 재무_세부시트'!"&K$1&$AD35, TRUE)} -> 24.383282 | L35: {=INDIRECT("'※ 재무_세부시트'!"&L$1&$AD35, TRUE)} -> 24.2331 | M35: {=INDIRECT("'※ 재무_세부시트'!"&M$1&$AD35, TRUE)} -> 24.855322 | ... S35: {=INDIRECT("'※ 재무_세부시트'!"&S$1&$AD35, TRUE)} -> 24.545371 | W35: {=INDIRECT("'※ 재무_세부시트'!"&W$1&$AD35, TRUE)} -> -0.048432361 | X35: {=INDIRECT("'※ 재무_세부시트'!"&X$1&$AD35, TRUE)} -> -2.0635831 | Y35: {=INDIRECT("'※ 재무_세부시트'!"&Y$1&$AD35, TRUE)} -> 0 | Z35: {=INDIRECT("'※ 재무_세부시트'!"&Z$1&$AD35, TRUE)} -> 297.96476 | AC35: {=INDIRECT("'※ 재무_세부시트'!"&AC$1&$AD35, TRUE)} -> -32.010005 | AD35: 34 | AE35: =AE110 -> 23.465024 | AF35: =AF110 -> 24.833183 | AG35: =AG110 -> 25.754234 | AH35: =AH110 -> 25.226629 | AI35: =AI110 -> 25.718614 | AJ35: =AJ110 -> 24.953589 | AK35: =AK110 -> 26.164739 | AL35: =AL110 -> 26.688882 | ... AP35: =AP110 -> 27.376673 | BG35: {=INDIRECT("'※ 재무_세부시트'!"&BG$1&$AD35, TRUE)} -> 24.157487 | BH35: {=INDIRECT("'※ 재무_세부시트'!"&BH$1&$AD35, TRUE)} -> 318.78142 | BI35: {=INDIRECT("'※ 재무_세부시트'!"&BI$1&$AD35, TRUE)} -> 26.877775 | BJ35: {=INDIRECT("'※ 재무_세부시트'!"&BJ$1&$AD35, TRUE)} -> 27.729111 | BK35: {=INDIRECT("'※ 재무_세부시트'!"&BK$1&$AD35, TRUE)} -> 27.124463
D36: 도매 | F36: {=INDIRECT("'※ 재무_세부시트'!"&F$1&$AD36, TRUE)} -> 170.37648 | G36: {=INDIRECT("'※ 재무_세부시트'!"&G$1&$AD36, TRUE)} -> 135.42187 | H36: {=INDIRECT("'※ 재무_세부시트'!"&H$1&$AD36, TRUE)} -> 9.0666553 | I36: {=INDIRECT("'※ 재무_세부시트'!"&I$1&$AD36, TRUE)} -> 9.0830929 | J36: {=INDIRECT("'※ 재무_세부시트'!"&J$1&$AD36, TRUE)} -> 8.5529126 | K36: {=INDIRECT("'※ 재무_세부시트'!"&K$1&$AD36, TRUE)} -> 8.0079655 | L36: {=INDIRECT("'※ 재무_세부시트'!"&L$1&$AD36, TRUE)} -> 7.6013216 | M36: {=INDIRECT("'※ 재무_세부시트'!"&M$1&$AD36, TRUE)} -> 11.278029 | ... S36: {=INDIRECT("'※ 재무_세부시트'!"&S$1&$AD36, TRUE)} -> 8.7081341 | W36: {=INDIRECT("'※ 재무_세부시트'!"&W$1&$AD36, TRUE)} -> -0.10176503 | X36: {=INDIRECT("'※ 재무_세부시트'!"&X$1&$AD36, TRUE)} -> -0.91754262 | Y36: {=INDIRECT("'※ 재무_세부시트'!"&Y$1&$AD36, TRUE)} -> 0 | Z36: {=INDIRECT("'※ 재무_세부시트'!"&Z$1&$AD36, TRUE)} -> 107.70125 | AC36: {=INDIRECT("'※ 재무_세부시트'!"&AC$1&$AD36, TRUE)} -> -27.720617 | AD36: 35 | AE36: =AE128 -> 14.614718 | AF36: =AF128 -> 14.209056 | AG36: =AG128 -> 14.780466 | AH36: =AH128 -> 14.649513 | AI36: =AI128 -> 14.581836 | AJ36: =AJ128 -> 14.243939 | AK36: =AK128 -> 14.415164 | AL36: =AL128 -> 14.217451 | ... AP36: =AP128 -> 13.416322 | BG36: {=INDIRECT("'※ 재무_세부시트'!"&BG$1&$AD36, TRUE)} -> 14.614718 | BH36: {=INDIRECT("'※ 재무_세부시트'!"&BH$1&$AD36, TRUE)} -> 170.37648 | BI36: {=INDIRECT("'※ 재무_세부시트'!"&BI$1&$AD36, TRUE)} -> 14.415164 | BJ36: {=INDIRECT("'※ 재무_세부시트'!"&BJ$1&$AD36, TRUE)} -> 11.270599 | BK36: {=INDIRECT("'※ 재무_세부시트'!"&BK$1&$AD36, TRUE)} -> 13.834609
D37: 디지털 | F37: {=INDIRECT("'※ 재무_세부시트'!"&F$1&$AD37, TRUE)} -> 70.076979 | G37: {=INDIRECT("'※ 재무_세부시트'!"&G$1&$AD37, TRUE)} -> 68.735845 | H37: {=INDIRECT("'※ 재무_세부시트'!"&H$1&$AD37, TRUE)} -> 5.2481266 | I37: {=INDIRECT("'※ 재무_세부시트'!"&I$1&$AD37, TRUE)} -> 5.3671954 | J37: {=INDIRECT("'※ 재무_세부시트'!"&J$1&$AD37, TRUE)} -> 5.1954726 | K37: {=INDIRECT("'※ 재무_세부시트'!"&K$1&$AD37, TRUE)} -> 5.066248 | L37: {=INDIRECT("'※ 재무_세부시트'!"&L$1&$AD37, TRUE)} -> 4.9718197 | M37: {=INDIRECT("'※ 재무_세부시트'!"&M$1&$AD37, TRUE)} -> 5.0249524 | ... S37: {=INDIRECT("'※ 재무_세부시트'!"&S$1&$AD37, TRUE)} -> 4.6386205 | W37: {=INDIRECT("'※ 재무_세부시트'!"&W$1&$AD37, TRUE)} -> -0.04467136 | X37: {=INDIRECT("'※ 재무_세부시트'!"&X$1&$AD37, TRUE)} -> -0.85855673 | Y37: {=INDIRECT("'※ 재무_세부시트'!"&Y$1&$AD37, TRUE)} -> 0 | Z37: {=INDIRECT("'※ 재무_세부시트'!"&Z$1&$AD37, TRUE)} -> 60.125982 | AC37: {=INDIRECT("'※ 재무_세부시트'!"&AC$1&$AD37, TRUE)} -> -8.6098629 | AD37: 36 | AE37: =AE137 -> 5.7071177 | AF37: =AF137 -> 5.7489088 | AG37: =AG137 -> 5.8226918 | AH37: =AH137 -> 5.7612518 | AI37: =AI137 -> 5.7821658 | AJ37: =AJ137 -> 5.5630937 | AK37: =AK137 -> 5.8880174 | AL37: =AL137 -> 5.9146264 | ... AP37: =AP137 -> 6.0235368 | BG37: {=INDIRECT("'※ 재무_세부시트'!"&BG$1&$AD37, TRUE)} -> 5.7071177 | BH37: {=INDIRECT("'※ 재무_세부시트'!"&BH$1&$AD37, TRUE)} -> 70.076979 | BI37: {=INDIRECT("'※ 재무_세부시트'!"&BI$1&$AD37, TRUE)} -> 5.8880174 | BJ37: {=INDIRECT("'※ 재무_세부시트'!"&BJ$1&$AD37, TRUE)} -> 5.7274192 | BK37: {=INDIRECT("'※ 재무_세부시트'!"&BK$1&$AD37, TRUE)} -> 5.889442
D38: 기타 | E38: B2B, 대형마트, 지원성 관리수수료, P3.0 등 | F38: {=INDIRECT("'※ 재무_세부시트'!"&F$1&$AD38, TRUE)} -> 148.83519 | G38: {=INDIRECT("'※ 재무_세부시트'!"&G$1&$AD38, TRUE)} -> 159.13578 | H38: {=INDIRECT("'※ 재무_세부시트'!"&H$1&$AD38, TRUE)} -> 11.163948 | I38: {=INDIRECT("'※ 재무_세부시트'!"&I$1&$AD38, TRUE)} -> 13.17639 | J38: {=INDIRECT("'※ 재무_세부시트'!"&J$1&$AD38, TRUE)} -> 9.8586543 | K38: {=INDIRECT("'※ 재무_세부시트'!"&K$1&$AD38, TRUE)} -> 19.145845 | L38: {=INDIRECT("'※ 재무_세부시트'!"&L$1&$AD38, TRUE)} -> 9.4178594 | M38: {=INDIRECT("'※ 재무_세부시트'!"&M$1&$AD38, TRUE)} -> 18.102218 | ... S38: {=INDIRECT("'※ 재무_세부시트'!"&S$1&$AD38, TRUE)} -> 13.115039 | W38: {=INDIRECT("'※ 재무_세부시트'!"&W$1&$AD38, TRUE)} -> 0.94792608 | X38: {=INDIRECT("'※ 재무_세부시트'!"&X$1&$AD38, TRUE)} -> -12.243742 | Y38: {=INDIRECT("'※ 재무_세부시트'!"&Y$1&$AD38, TRUE)} -> 0 | Z38: {=INDIRECT("'※ 재무_세부시트'!"&Z$1&$AD38, TRUE)} -> 149.85056 | AC38: {=INDIRECT("'※ 재무_세부시트'!"&AC$1&$AD38, TRUE)} -> -1.34024 | AD38: 37 | AE38: =AE22-AE35-AE36-AE37 -> 23.248172 | AF38: =AF22-AF35-AF36-AF37 -> 6.0722279 | AG38: =AG22-AG35-AG36-AG37 -> 13.358644 | AH38: =AH22-AH35-AH36-AH37 -> 9.9302275 | AI38: =AI22-AI35-AI36-AI37 -> 12.633443 | AJ38: =AJ22-AJ35-AJ36-AJ37 -> 13.154058 | AK38: =AK22-AK35-AK36-AK37 -> 14.087254 | AL38: =AL22-AL35-AL36-AL37 -> 11.802231 | ... AP38: =AP22-AP35-AP36-AP37 -> 14.346115 | BG38: {=INDIRECT("'※ 재무_세부시트'!"&BG$1&$AD38, TRUE)} -> 23.248172 | BH38: {=INDIRECT("'※ 재무_세부시트'!"&BH$1&$AD38, TRUE)} -> 148.83519 | BI38: {=INDIRECT("'※ 재무_세부시트'!"&BI$1&$AD38, TRUE)} -> 14.087254 | BJ38: {=INDIRECT("'※ 재무_세부시트'!"&BJ$1&$AD38, TRUE)} -> 10.400818 | BK38: {=INDIRECT("'※ 재무_세부시트'!"&BK$1&$AD38, TRUE)} -> 7.5399231
C39: 기타수수료 | F39: {=INDIRECT("'※ 재무_세부시트'!"&F$1&$AD39, TRUE)} -> 432.1443 | G39: {=INDIRECT("'※ 재무_세부시트'!"&G$1&$AD39, TRUE)} -> 505.65747 | H39: {=INDIRECT("'※ 재무_세부시트'!"&H$1&$AD39, TRUE)} -> 32.779204 | I39: {=INDIRECT("'※ 재무_세부시트'!"&I$1&$AD39, TRUE)} -> 38.21154 | J39: {=INDIRECT("'※ 재무_세부시트'!"&J$1&$AD39, TRUE)} -> 39.763803 | K39: {=INDIRECT("'※ 재무_세부시트'!"&K$1&$AD39, TRUE)} -> 39.829534 | L39: {=INDIRECT("'※ 재무_세부시트'!"&L$1&$AD39, TRUE)} -> 40.952531 | M39: {=INDIRECT("'※ 재무_세부시트'!"&M$1&$AD39, TRUE)} -> 41.618138 | ... AC39: {=INDIRECT("'※ 재무_세부시트'!"&AC$1&$AD39, TRUE)} -> -39.137635 | AD39: 38 | AE39: =(4121.280242/100)-AE53 -> 40.917431 | AF39: =(3333.387753/100)-AF53 -> 33.238089 | AG39: =(4045.418139/100)-AG53 -> 40.405073 | AH39: =(3318.803182/100)-AH53 -> 33.188032 | AI39: =(3265.812945/100)-AI53 -> 32.643948 | AJ39: =(4011.255579/100)-AJ53 -> 39.878725 | AK39: =(3525.368812/100)-AK53 -> 35.223917 | AL39: =(3412.604221/100)-AL53 -> 33.868752 | AM39: =(4319.320147/100)-AM53 -> 43.083047 | AN39: =(3387.433582/100)-AN53 -> 33.805491 | AO39: =(3348.615816/100)-AO53 -> 33.4515 | AP39: =(3471.768056/100)-AP53 -> 32.440292 | AQ39: =SUM(AE39:AP39) -> 432.1443 | AS39: =(3644.13527339002/100)-AS53 -> 35.1235 | AT39: =(3661.00340237424/100)-AT53 -> 34.963 | AU39: =(3990.43240237424/100)-AU53 -> 38.25729 | AV39: =(3712.15340237423/100)-AV53 -> 35.4745 | AW39: =(3700.78340237423/100)-AW53 -> 35.3608 | AX39: =(4034.89240237424/100)-AX53 -> 38.70189 | AY39: =(4008.95340237423/100)-AY53 -> 38.4425 | AZ39: =(3742.90340237423/100)-AZ53 -> 35.782 | BA39: =(4072.33240237424/100)-BA53 -> 39.07629 | BB39: =(3794.05340237423/100)-BB53 -> 36.2935 | BC39: =(3778.00340237424/100)-BC53 -> 36.133 | BD39: =(4357.43240237424/100)-BD53 -> 41.92729 | BE39: =SUM(AS39:BD39) -> 445.53556 | BG39: {=INDIRECT("'※ 재무_세부시트'!"&BG$1&$AD39, TRUE)} -> 40.917431 | BH39: {=INDIRECT("'※ 재무_세부시트'!"&BH$1&$AD39, TRUE)} -> 432.1443 | BI39: {=INDIRECT("'※ 재무_세부시트'!"&BI$1&$AD39, TRUE)} -> 35.223917 | BJ39: {=INDIRECT("'※ 재무_세부시트'!"&BJ$1&$AD39, TRUE)} -> 41.637191 | BK39: {=INDIRECT("'※ 재무_세부시트'!"&BK$1&$AD39, TRUE)} -> 43.083047
