Workbook

Sheet 1Q 종합
B2: ■ '26년 조직 KPI 1Q 득점 현황
B4: 영업 기준일 | C4: 일반후불 | D4: MNP/후불신규 | E4: 유선순신규 | F4: MIT 동시판매 | G4: 전략상품 | H4: R-VOC | I4: TCSI | J4: 인프라 | K4: 판매 APRU | L4: 1G 유치율 | M4: 법인 직접영업
C5: 1~3월 | D5: 1~3월 | E5: 1~3월 | F5: 1~3월 | G5: 1~3월 | H5: 1~3월 | I5: 1~3월 | J5: 1~3월 | K5: 1~3월 | L5: 1~3월 | M5: 1~3월
B6: 이익 기준일 | C6: 정책매출 | D6: 매장이익 | E6: 영업이익/추가수익
C7: 1~3월 | D7: 1~3월 | E7: 1~3월
B8: √ 지역본부 : 소매 60% +도매 30% + 소상공인 10%
B10: 조직 | C10: KPI 득점 | D10: 순위 | E10: 소매 | H10: 도매 | K10: 소상공인
F11: 영업 | G11: 이익 | I11: 영업 | J11: 이익 | L11: 영업 | M11: 이익
E12: =SUM(F12:G12) -> 90 | F12: 75 | G12: 15 | H12: =SUM(I12:J12) -> 90 | I12: 85 | J12: 5 | K12: =SUM(L12:M12) -> 90 | L12: 70 | M12: 20
B13: 강북본부 | C13: =(E13)*0.6+(H13)*0.3+(K13)*0.1 -> 80.023937 | D13: =RANK(C13,$C$13:$C$17) -> 4 | E13: =SUM(F13:G13) -> 77.463602 | F13: ='1Q 소매'!E12 -> 61.888039 | G13: ='1Q 소매'!O12 -> 15.575563 | H13: =I13+J13 -> 91.939676 | I13: ='1Q 도매'!E12 -> 86.544941 | J13: ='1Q 도매'!N12 -> 5.3947342 | K13: =L13+M13 -> 59.638727 | L13: ='1Q 소상공인'!E25 -> 40.225496 | M13: ='1Q 소상공인'!K25 -> 19.413231
B14: 강남본부 | C14: =(E14)*0.6+(H14)*0.3+(K14)*0.1 -> 79.830811 | D14: =RANK(C14,$C$13:$C$17) -> 5 | E14: =SUM(F14:G14) -> 77.747519 | F14: ='1Q 소매'!E13 -> 62.384392 | G14: ='1Q 소매'!O13 -> 15.363127 | H14: =I14+J14 -> 94.272648 | I14: ='1Q 도매'!E13 -> 89.269737 | J14: ='1Q 도매'!N13 -> 5.0029107 | K14: =L14+M14 -> 49.005058 | L14: ='1Q 소상공인'!E26 -> 29.577321 | M14: ='1Q 소상공인'!K26 -> 19.427737
B15: 강서본부 | C15: =(E15)*0.6+(H15)*0.3+(K15)*0.1 -> 83.292676 | D15: =RANK(C15,$C$13:$C$17) -> 1 | E15: =SUM(F15:G15) -> 78.584923 | F15: ='1Q 소매'!E14 -> 62.875429 | G15: ='1Q 소매'!O14 -> 15.709495 | H15: =I15+J15 -> 96.488207 | I15: ='1Q 도매'!E14 -> 91.219695 | J15: ='1Q 도매'!N14 -> 5.2685119 | K15: =L15+M15 -> 71.952599 | L15: ='1Q 소상공인'!E27 -> 52.454039 | M15: ='1Q 소상공인'!K27 -> 19.49856
B16: 동부본부 | C16: =(E16)*0.6+(H16)*0.3+(K16)*0.1 -> 82.30466 | D16: =RANK(C16,$C$13:$C$17) -> 2 | E16: =SUM(F16:G16) -> 79.248741 | F16: ='1Q 소매'!E15 -> 63.803702 | G16: ='1Q 소매'!O15 -> 15.445039 | H16: =I16+J16 -> 96.10838 | I16: ='1Q 도매'!E15 -> 90.10838 | J16: ='1Q 도매'!N15 -> 6 | K16: =L16+M16 -> 59.229019 | L16: ='1Q 소상공인'!E28 -> 40.55119 | M16: ='1Q 소상공인'!K28 -> 18.677829
B17: 서부본부 | C17: =(E17)*0.6+(H17)*0.3+(K17)*0.1 -> 80.276515 | D17: =RANK(C17,$C$13:$C$17) -> 3 | E17: =SUM(F17:G17) -> 78.515546 | F17: ='1Q 소매'!E16 -> 63.167013 | G17: ='1Q 소매'!O16 -> 15.348533 | H17: =I17+J17 -> 88.346642 | I17: ='1Q 도매'!E16 -> 82.346642 | J17: ='1Q 도매'!N16 -> 6 | K17: =L17+M17 -> 66.631952 | L17: ='1Q 소상공인'!E29 -> 45.853513 | M17: ='1Q 소상공인'!K29 -> 20.77844
B18: 평균 | C18: =AVERAGE(C13:C17) -> 81.14572 | D18: - | E18: =AVERAGE(E13:E17) -> 78.312066 | F18: =AVERAGE(F13:F17) -> 62.823715 | G18: =AVERAGE(G13:G17) -> 15.488351 | H18: =AVERAGE(H13:H17) -> 93.43111 | I18: =AVERAGE(I13:I17) -> 87.897879 | J18: =AVERAGE(J13:J17) -> 5.5332314 | K18: =AVERAGE(K13:K17) -> 61.291471 | L18: =AVERAGE(L13:L17) -> 41.732312 | M18: =AVERAGE(M13:M17) -> 19.559159
B19: 본부별편차 | C19: =MAX(C13:C17)-MIN(C13:C17) -> 3.4618645 | D19: - | E19: =MAX(E13:E17)-MIN(E13:E17) -> 1.7851387 | F19: =MAX(F13:F17)-MIN(F13:F17) -> 1.9156635 | G19: =MAX(G13:G17)-MIN(G13:G17) -> 0.36096193 | H19: =MAX(H13:H17)-MIN(H13:H17) -> 8.1415647 | I19: =MAX(I13:I17)-MIN(I13:I17) -> 8.8730528 | J19: =MAX(J13:J17)-MIN(J13:J17) -> 0.99708926 | K19: =MAX(K13:K17)-MIN(K13:K17) -> 22.947541 | L19: =MAX(L13:L17)-MIN(L13:L17) -> 22.876718 | M19: =MAX(M13:M17)-MIN(M13:M17) -> 2.1006107

Sheet 1Q 소매
B2: ■ 26년 소매 조직별 1Q KPI 득점 현황
B4: 영업 기준일 | C4: 후불 | D4: MNP/후불신규 | E4: 유선순신규 | F4: MIT | G4: 전략상품 | H4: R-VOC | I4: TCSI | J4: 판매APRU | K4: 1G유치율
C5: 1~3월 | D5: 1~3월 | E5: 1~3월 | F5: 1~3월 | G5: 1~3월 | H5: 1~3월 | I5: 1~3월 | J5: 1~3월 | K5: 1~3월
B6: 이익 기준일 | C6: 정책매출 | D6: 매장이익
C7: 1~3월 | D7: 1~3월
T8: =SUM(O12:O16) -> 77.441756 | U8: =SUM('(이익) 소매'!G7:G11) -> 77.441756 | V8: =T8=U8 -> TRUE
B9: 본부 조직 | C9: KPI 득점 | D9: 순위 | E9: 영업 | O9: 이익 | T9: =SUM(O19:O28) -> 154.82445 | U9: =SUM('(이익) 소매'!G12:G21) -> 154.82445 | V9: =T9=U9 -> TRUE
F10: 후불 | G10: MNP/후불신규 | H10: 유선순신규 | I10: MIT | J10: 판매ARPU | K10: 전략상품 | L10: R-VOC | M10: 1G | N10: TCSI | P10: 정책 매출 | Q10: 매장 이익
E11: =SUM(F11:N11) -> 75 | F11: 15 | G11: 10 | H11: 15 | I11: 10 | J11: 7 | K11: 5 | L11: 5 | M11: 5 | N11: 3 | O11: =SUM(P11:Q11) -> 15 | P11: 10 | Q11: 5
B12: 강북본부 | C12: =SUM(E12,O12) -> 77.463602 | D12: =RANK(C12,$C$12:$C$16) -> 5 | E12: =SUM(F12:N12) -> 61.888039 | F12: =VLOOKUP($B12,'(영업)소매'!$F$7:$CZ$274,12,0) -> 14.299561 | G12: =VLOOKUP($B12,'(영업)소매'!$F$7:$CZ$274,23,0) -> 6.4937107 | H12: =VLOOKUP($B12,'(영업)소매'!$F$7:$CZ$274,42,0) -> 13.94777 | I12: =VLOOKUP($B12,'(영업)소매'!$F$7:$CZ$274,51,0) -> 8.8477366 | J12: =VLOOKUP($B12,'(영업)소매'!$F$7:$CZ$274,57,0) -> 6.0775113 | K12: =VLOOKUP($B12,'(영업)소매'!$F$7:$CZ$274,67,0) -> 1.3298969 | L12: =VLOOKUP($B12,'(영업)소매'!$F$7:$CZ$274,95,0) -> 3.0418519 | M12: =VLOOKUP($B12,'(영업)소매'!$F$7:$CZ$274,73,0) -> 5 | N12: =VLOOKUP($B12,'(영업)소매'!$F$7:$CZ$274,91,0) -> 2.85 | O12: =SUM(P12:Q12) -> 15.575563 | P12: =VLOOKUP($B12,'(이익) 소매'!$F$7:$S$21,10,0) -> 9.5755634 | Q12: =VLOOKUP($B12,'(이익) 소매'!$F$7:$S$21,14,0) -> 6
B13: 강남본부 | C13: =SUM(E13,O13) -> 77.747519 | D13: =RANK(C13,$C$12:$C$16) -> 4 | E13: =SUM(F13:N13) -> 62.384392 | F13: =VLOOKUP($B13,'(영업)소매'!$F$7:$CZ$274,12,0) -> 13.66455 | G13: =VLOOKUP($B13,'(영업)소매'!$F$7:$CZ$274,23,0) -> 5.4354839 | H13: =VLOOKUP($B13,'(영업)소매'!$F$7:$CZ$274,42,0) -> 14.468224 | I13: =VLOOKUP($B13,'(영업)소매'!$F$7:$CZ$274,51,0) -> 8.3034483 | J13: =VLOOKUP($B13,'(영업)소매'!$F$7:$CZ$274,57,0) -> 5.6532228 | K13: =VLOOKUP($B13,'(영업)소매'!$F$7:$CZ$274,67,0) -> 3.7261905 | L13: =VLOOKUP($B13,'(영업)소매'!$F$7:$CZ$274,95,0) -> 3.2832727 | M13: =VLOOKUP($B13,'(영업)소매'!$F$7:$CZ$274,73,0) -> 5 | N13: =VLOOKUP($B13,'(영업)소매'!$F$7:$CZ$274,91,0) -> 2.85 | O13: =SUM(P13:Q13) -> 15.363127 | P13: =VLOOKUP($B13,'(이익) 소매'!$F$7:$S$21,10,0) -> 9.3631269 | Q13: =VLOOKUP($B13,'(이익) 소매'!$F$7:$S$21,14,0) -> 6
B14: 강서본부 | C14: =SUM(E14,O14) -> 78.584923 | D14: =RANK(C14,$C$12:$C$16) -> 2 | E14: =SUM(F14:N14) -> 62.875429 | F14: =VLOOKUP($B14,'(영업)소매'!$F$7:$CZ$274,12,0) -> 13.490055 | G14: =VLOOKUP($B14,'(영업)소매'!$F$7:$CZ$274,23,0) -> 5.8322237 | H14: =VLOOKUP($B14,'(영업)소매'!$F$7:$CZ$274,42,0) -> 13.740941 | I14: =VLOOKUP($B14,'(영업)소매'!$F$7:$CZ$274,51,0) -> 8.4352332 | J14: =VLOOKUP($B14,'(영업)소매'!$F$7:$CZ$274,57,0) -> 5.913339 | K14: =VLOOKUP($B14,'(영업)소매'!$F$7:$CZ$274,67,0) -> 0.86363636 | L14: =VLOOKUP($B14,'(영업)소매'!$F$7:$CZ$274,95,0) -> 6 | M14: =VLOOKUP($B14,'(영업)소매'!$F$7:$CZ$274,73,0) -> 5 | N14: =VLOOKUP($B14,'(영업)소매'!$F$7:$CZ$274,91,0) -> 3.6 | O14: =SUM(P14:Q14) -> 15.709495 | P14: =VLOOKUP($B14,'(이익) 소매'!$F$7:$S$21,10,0) -> 9.7094946 | Q14: =VLOOKUP($B14,'(이익) 소매'!$F$7:$S$21,14,0) -> 6
B15: 동부본부 | C15: =SUM(E15,O15) -> 79.248741 | D15: =RANK(C15,$C$12:$C$16) -> 1 | E15: =SUM(F15:N15) -> 63.803702 | F15: =VLOOKUP($B15,'(영업)소매'!$F$7:$CZ$274,12,0) -> 13.542219 | G15: =VLOOKUP($B15,'(영업)소매'!$F$7:$CZ$274,23,0) -> 8.1413613 | H15: =VLOOKUP($B15,'(영업)소매'!$F$7:$CZ$274,42,0) -> 11.51461 | I15: =VLOOKUP($B15,'(영업)소매'!$F$7:$CZ$274,51,0) -> 8.5165326 | J15: =VLOOKUP($B15,'(영업)소매'!$F$7:$CZ$274,57,0) -> 5.7854747 | K15: =VLOOKUP($B15,'(영업)소매'!$F$7:$CZ$274,67,0) -> 4.1929825 | L15: =VLOOKUP($B15,'(영업)소매'!$F$7:$CZ$274,95,0) -> 4.4105217 | M15: =VLOOKUP($B15,'(영업)소매'!$F$7:$CZ$274,73,0) -> 5 | N15: =VLOOKUP($B15,'(영업)소매'!$F$7:$CZ$274,91,0) -> 2.7 | O15: =SUM(P15:Q15) -> 15.445039 | P15: =VLOOKUP($B15,'(이익) 소매'!$F$7:$S$21,10,0) -> 9.4450386 | Q15: =VLOOKUP($B15,'(이익) 소매'!$F$7:$S$21,14,0) -> 6
B16: 서부본부 | C16: =SUM(E16,O16) -> 78.515546 | D16: =RANK(C16,$C$12:$C$16) -> 3 | E16: =SUM(F16:N16) -> 63.167013 | F16: =VLOOKUP($B16,'(영업)소매'!$F$7:$CZ$274,12,0) -> 15.030086 | G16: =VLOOKUP($B16,'(영업)소매'!$F$7:$CZ$274,23,0) -> 6.899841 | H16: =VLOOKUP($B16,'(영업)소매'!$F$7:$CZ$274,42,0) -> 13.572108 | I16: =VLOOKUP($B16,'(영업)소매'!$F$7:$CZ$274,51,0) -> 8.5614849 | J16: =VLOOKUP($B16,'(영업)소매'!$F$7:$CZ$274,57,0) -> 5.7709108 | K16: =VLOOKUP($B16,'(영업)소매'!$F$7:$CZ$274,67,0) -> 1.3867925 | L16: =VLOOKUP($B16,'(영업)소매'!$F$7:$CZ$274,95,0) -> 4.2457895 | M16: =VLOOKUP($B16,'(영업)소매'!$F$7:$CZ$274,73,0) -> 5 | N16: =VLOOKUP($B16,'(영업)소매'!$F$7:$CZ$274,91,0) -> 2.7 | O16: =SUM(P16:Q16) -> 15.348533 | P16: =VLOOKUP($B16,'(이익) 소매'!$F$7:$S$21,10,0) -> 9.3485327 | Q16: =VLOOKUP($B16,'(이익) 소매'!$F$7:$S$21,14,0) -> 6
B17: 본부 평균 | C17: =AVERAGE(C12:C16) -> 78.312066 | D17: - | E17: =AVERAGE(E12:E16) -> 62.823715 | F17: =AVERAGE(F12:F16) -> 14.005294 | G17: =AVERAGE(G12:G16) -> 6.5605241 | H17: =AVERAGE(H12:H16) -> 13.448731 | I17: =AVERAGE(I12:I16) -> 8.5328871 | J17: =AVERAGE(J12:J16) -> 5.8400917 | K17: =AVERAGE(K12:K16) -> 2.2998997 | L17: =AVERAGE(L12:L16) -> 4.1962872 | ... Q17: =AVERAGE(Q12:Q16) -> 6
B18: 본부별편차 | C18: =MAX(C12:C16)-MIN(C12:C16) -> 1.7851387 | D18: - | E18: =MAX(E12:E16)-MIN(E12:E16) -> 1.9156635 | F18: =MAX(F12:F16)-MIN(F12:F16) -> 1.5400311 | G18: =MAX(G12:G16)-MIN(G12:G16) -> 2.7058774 | H18: =MAX(H12:H16)-MIN(H12:H16) -> 2.9536139 | I18: =MAX(I12:I16)-MIN(I12:I16) -> 0.54428835 | J18: =MAX(J12:J16)-MIN(J12:J16) -> 0.42428843 | K18: =MAX(K12:K16)-MIN(K12:K16) -> 3.3293461 | L18: =MAX(L12:L16)-MIN(L12:L16) -> 2.9581481 | ... Q18: =MAX(Q12:Q16)-MIN(Q12:Q16) -> 0
B19: 강북소매 | C19: =SUM(E19,O19) -> 76.846073 | D19: =RANK(C19,$C$19:$C$28) -> 6 | E19: =SUM(F19:N19) -> 61.145539 | F19: =VLOOKUP($B19,'(영업)소매'!$F$7:$CZ$274,12,0) -> 14.384638 | G19: =VLOOKUP($B19,'(영업)소매'!$F$7:$CZ$274,23,0) -> 6.625387 | H19: =VLOOKUP($B19,'(영업)소매'!$F$7:$CZ$274,42,0) -> 14.49817 | I19: =VLOOKUP($B19,'(영업)소매'!$F$7:$CZ$274,51,0) -> 9.2877493 | J19: =VLOOKUP($B19,'(영업)소매'!$F$7:$CZ$274,57,0) -> 6.0264181 | K19: =VLOOKUP($B19,'(영업)소매'!$F$7:$CZ$274,67,0) -> 0 | L19: =VLOOKUP($B19,'(영업)소매'!$F$7:$CZ$274,95,0) -> 2.6231765 | M19: =VLOOKUP($B19,'(영업)소매'!$F$7:$CZ$274,73,0) -> 5 | N19: =VLOOKUP($B19,'(영업)소매'!$F$7:$CZ$274,91,0) -> 2.7 | O19: =SUM(P19:Q19) -> 15.700534 | P19: =VLOOKUP($B19,'(이익) 소매'!$F$7:$S$21,10,0) -> 9.7005342 | Q19: =VLOOKUP($B19,'(이익) 소매'!$F$7:$S$21,14,0) -> 6
B20: 강동소매 | C20: =SUM(E20,O20) -> 77.912808 | D20: =RANK(C20,$C$19:$C$28) -> 5 | E20: =SUM(F20:N20) -> 62.40813 | F20: =VLOOKUP($B20,'(영업)소매'!$F$7:$CZ$274,12,0) -> 14.215572 | G20: =VLOOKUP($B20,'(영업)소매'!$F$7:$CZ$274,23,0) -> 6.3578275 | H20: =VLOOKUP($B20,'(영업)소매'!$F$7:$CZ$274,42,0) -> 13.496553 | I20: =VLOOKUP($B20,'(영업)소매'!$F$7:$CZ$274,51,0) -> 8.4391534 | J20: =VLOOKUP($B20,'(영업)소매'!$F$7:$CZ$274,57,0) -> 6.1289014 | K20: =VLOOKUP($B20,'(영업)소매'!$F$7:$CZ$274,67,0) -> 2.5294118 | L20: =VLOOKUP($B20,'(영업)소매'!$F$7:$CZ$274,95,0) -> 3.3907111 | M20: =VLOOKUP($B20,'(영업)소매'!$F$7:$CZ$274,73,0) -> 5 | N20: =VLOOKUP($B20,'(영업)소매'!$F$7:$CZ$274,91,0) -> 2.85 | O20: =SUM(P20:Q20) -> 15.504678 | P20: =VLOOKUP($B20,'(이익) 소매'!$F$7:$S$21,10,0) -> 9.5046779 | Q20: =VLOOKUP($B20,'(이익) 소매'!$F$7:$S$21,14,0) -> 6
B21: 강남소매 | C21: =SUM(E21,O21) -> 70.658267 | D21: =RANK(C21,$C$19:$C$28) -> 10 | E21: =SUM(F21:N21) -> 55.862007 | F21: =VLOOKUP($B21,'(영업)소매'!$F$7:$CZ$274,12,0) -> 12.678957 | G21: =VLOOKUP($B21,'(영업)소매'!$F$7:$CZ$274,23,0) -> 4.9477352 | H21: =VLOOKUP($B21,'(영업)소매'!$F$7:$CZ$274,42,0) -> 12.258788 | I21: =VLOOKUP($B21,'(영업)소매'!$F$7:$CZ$274,51,0) -> 7.2523962 | J21: =VLOOKUP($B21,'(영업)소매'!$F$7:$CZ$274,57,0) -> 5.557009 | K21: =VLOOKUP($B21,'(영업)소매'!$F$7:$CZ$274,67,0) -> 2.9705882 | L21: =VLOOKUP($B21,'(영업)소매'!$F$7:$CZ$274,95,0) -> 2.4965333 | M21: =VLOOKUP($B21,'(영업)소매'!$F$7:$CZ$274,73,0) -> 5 | N21: =VLOOKUP($B21,'(영업)소매'!$F$7:$CZ$274,91,0) -> 2.7 | O21: =SUM(P21:Q21) -> 14.796259 | P21: =VLOOKUP($B21,'(이익) 소매'!$F$7:$S$21,10,0) -> 8.7962595 | Q21: =VLOOKUP($B21,'(이익) 소매'!$F$7:$S$21,14,0) -> 6
B22: 남부소매 | C22: =SUM(E22,O22) -> 84.705547 | D22: =RANK(C22,$C$19:$C$28) -> 1 | E22: =SUM(F22:N22) -> 68.833249 | F22: =VLOOKUP($B22,'(영업)소매'!$F$7:$CZ$274,12,0) -> 14.4844 | G22: =VLOOKUP($B22,'(영업)소매'!$F$7:$CZ$274,23,0) -> 5.8558559 | H22: =VLOOKUP($B22,'(영업)소매'!$F$7:$CZ$274,42,0) -> 16.152517 | I22: =VLOOKUP($B22,'(영업)소매'!$F$7:$CZ$274,51,0) -> 9.1019417 | J22: =VLOOKUP($B22,'(영업)소매'!$F$7:$CZ$274,57,0) -> 5.7293921 | K22: =VLOOKUP($B22,'(영업)소매'!$F$7:$CZ$274,67,0) -> 4.24 | L22: =VLOOKUP($B22,'(영업)소매'!$F$7:$CZ$274,95,0) -> 5.2691429 | M22: =VLOOKUP($B22,'(영업)소매'!$F$7:$CZ$274,73,0) -> 5 | N22: =VLOOKUP($B22,'(영업)소매'!$F$7:$CZ$274,91,0) -> 3 | O22: =SUM(P22:Q22) -> 15.872298 | P22: =VLOOKUP($B22,'(이익) 소매'!$F$7:$S$21,10,0) -> 9.8722976 | Q22: =VLOOKUP($B22,'(이익) 소매'!$F$7:$S$21,14,0) -> 6
B23: 강서소매 | C23: =SUM(E23,O23) -> 76.17377 | D23: =RANK(C23,$C$19:$C$28) -> 8 | E23: =SUM(F23:N23) -> 60.694787 | F23: =VLOOKUP($B23,'(영업)소매'!$F$7:$CZ$274,12,0) -> 13.225431 | G23: =VLOOKUP($B23,'(영업)소매'!$F$7:$CZ$274,23,0) -> 5.4621849 | H23: =VLOOKUP($B23,'(영업)소매'!$F$7:$CZ$274,42,0) -> 13.248766 | I23: =VLOOKUP($B23,'(영업)소매'!$F$7:$CZ$274,51,0) -> 7.67642 | J23: =VLOOKUP($B23,'(영업)소매'!$F$7:$CZ$274,57,0) -> 5.8463916 | K23: =VLOOKUP($B23,'(영업)소매'!$F$7:$CZ$274,67,0) -> 0.63559322 | L23: =VLOOKUP($B23,'(영업)소매'!$F$7:$CZ$274,95,0) -> 6 | M23: =VLOOKUP($B23,'(영업)소매'!$F$7:$CZ$274,73,0) -> 5 | N23: =VLOOKUP($B23,'(영업)소매'!$F$7:$CZ$274,91,0) -> 3.6 | O23: =SUM(P23:Q23) -> 15.478983 | P23: =VLOOKUP($B23,'(이익) 소매'!$F$7:$S$21,10,0) -> 9.4789831 | Q23: =VLOOKUP($B23,'(이익) 소매'!$F$7:$S$21,14,0) -> 6
B24: 인천소매 | C24: =SUM(E24,O24) -> 81.33217 | D24: =RANK(C24,$C$19:$C$28) -> 3 | E24: =SUM(F24:N24) -> 65.468166 | F24: =VLOOKUP($B24,'(영업)소매'!$F$7:$CZ$274,12,0) -> 13.903103 | G24: =VLOOKUP($B24,'(영업)소매'!$F$7:$CZ$274,23,0) -> 6.4727273 | H24: =VLOOKUP($B24,'(영업)소매'!$F$7:$CZ$274,42,0) -> 14.447379 | I24: =VLOOKUP($B24,'(영업)소매'!$F$7:$CZ$274,51,0) -> 9.5833333 | J24: =VLOOKUP($B24,'(영업)소매'!$F$7:$CZ$274,57,0) -> 6.0116236 | K24: =VLOOKUP($B24,'(영업)소매'!$F$7:$CZ$274,67,0) -> 1.2 | L24: =VLOOKUP($B24,'(영업)소매'!$F$7:$CZ$274,95,0) -> 6 | M24: =VLOOKUP($B24,'(영업)소매'!$F$7:$CZ$274,73,0) -> 5 | N24: =VLOOKUP($B24,'(영업)소매'!$F$7:$CZ$274,91,0) -> 2.85 | O24: =SUM(P24:Q24) -> 15.864004 | P24: =VLOOKUP($B24,'(이익) 소매'!$F$7:$S$21,10,0) -> 9.8640038 | Q24: =VLOOKUP($B24,'(이익) 소매'!$F$7:$S$21,14,0) -> 6
B25: 부산소매 | C25: =SUM(E25,O25) -> 81.105621 | D25: =RANK(C25,$C$19:$C$28) -> 4 | E25: =SUM(F25:N25) -> 65.29687 | F25: =VLOOKUP($B25,'(영업)소매'!$F$7:$CZ$274,12,0) -> 13.023763 | G25: =VLOOKUP($B25,'(영업)소매'!$F$7:$CZ$274,23,0) -> 6.8973747 | H25: =VLOOKUP($B25,'(영업)소매'!$F$7:$CZ$274,42,0) -> 10.358692 | I25: =VLOOKUP($B25,'(영업)소매'!$F$7:$CZ$274,51,0) -> 9.363167 | J25: =VLOOKUP($B25,'(영업)소매'!$F$7:$CZ$274,57,0) -> 6.1227626 | K25: =VLOOKUP($B25,'(영업)소매'!$F$7:$CZ$274,67,0) -> 6 | L25: =VLOOKUP($B25,'(영업)소매'!$F$7:$CZ$274,95,0) -> 5.6811111 | M25: =VLOOKUP($B25,'(영업)소매'!$F$7:$CZ$274,73,0) -> 5 | N25: =VLOOKUP($B25,'(영업)소매'!$F$7:$CZ$274,91,0) -> 2.85 | O25: =SUM(P25:Q25) -> 15.808751 | P25: =VLOOKUP($B25,'(이익) 소매'!$F$7:$S$21,10,0) -> 9.8087506 | Q25: =VLOOKUP($B25,'(이익) 소매'!$F$7:$S$21,14,0) -> 6
B26: 대구소매 | C26: =SUM(E26,O26) -> 76.242283 | D26: =RANK(C26,$C$19:$C$28) -> 7 | E26: =SUM(F26:N26) -> 61.247415 | F26: =VLOOKUP($B26,'(영업)소매'!$F$7:$CZ$274,12,0) -> 13.953339 | G26: =VLOOKUP($B26,'(영업)소매'!$F$7:$CZ$274,23,0) -> 9.6521739 | H26: =VLOOKUP($B26,'(영업)소매'!$F$7:$CZ$274,42,0) -> 13.164873 | I26: =VLOOKUP($B26,'(영업)소매'!$F$7:$CZ$274,51,0) -> 7.6022305 | J26: =VLOOKUP($B26,'(영업)소매'!$F$7:$CZ$274,57,0) -> 5.4491779 | K26: =VLOOKUP($B26,'(영업)소매'!$F$7:$CZ$274,67,0) -> 0.25862069 | L26: =VLOOKUP($B26,'(영업)소매'!$F$7:$CZ$274,95,0) -> 3.617 | M26: =VLOOKUP($B26,'(영업)소매'!$F$7:$CZ$274,73,0) -> 5 | N26: =VLOOKUP($B26,'(영업)소매'!$F$7:$CZ$274,91,0) -> 2.55 | O26: =SUM(P26:Q26) -> 14.994868 | P26: =VLOOKUP($B26,'(이익) 소매'!$F$7:$S$21,10,0) -> 8.9948675 | Q26: =VLOOKUP($B26,'(이익) 소매'!$F$7:$S$21,14,0) -> 6
B27: 충청소매 | C27: =SUM(E27,O27) -> 75.273103 | D27: =RANK(C27,$C$19:$C$28) -> 9 | E27: =SUM(F27:N27) -> 60.352048 | F27: =VLOOKUP($B27,'(영업)소매'!$F$7:$CZ$274,12,0) -> 14.131538 | G27: =VLOOKUP($B27,'(영업)소매'!$F$7:$CZ$274,23,0) -> 6.1230769 | H27: =VLOOKUP($B27,'(영업)소매'!$F$7:$CZ$274,42,0) -> 14.134642 | I27: =VLOOKUP($B27,'(영업)소매'!$F$7:$CZ$274,51,0) -> 8.5382831 | J27: =VLOOKUP($B27,'(영업)소매'!$F$7:$CZ$274,57,0) -> 5.8767939 | K27: =VLOOKUP($B27,'(영업)소매'!$F$7:$CZ$274,67,0) -> 0.20754717 | L27: =VLOOKUP($B27,'(영업)소매'!$F$7:$CZ$274,95,0) -> 3.6401667 | M27: =VLOOKUP($B27,'(영업)소매'!$F$7:$CZ$274,73,0) -> 5 | N27: =VLOOKUP($B27,'(영업)소매'!$F$7:$CZ$274,91,0) -> 2.7 | O27: =SUM(P27:Q27) -> 14.921056 | P27: =VLOOKUP($B27,'(이익) 소매'!$F$7:$S$21,10,0) -> 8.9210557 | Q27: =VLOOKUP($B27,'(이익) 소매'!$F$7:$S$21,14,0) -> 6
B28: 호남소매 | C28: =SUM(E28,O28) -> 82.45015 | D28: =RANK(C28,$C$19:$C$28) -> 2 | E28: =SUM(F28:N28) -> 66.567126 | F28: =VLOOKUP($B28,'(영업)소매'!$F$7:$CZ$274,12,0) -> 15.95765 | G28: =VLOOKUP($B28,'(영업)소매'!$F$7:$CZ$274,23,0) -> 7.7302632 | H28: =VLOOKUP($B28,'(영업)소매'!$F$7:$CZ$274,42,0) -> 12.920702 | I28: =VLOOKUP($B28,'(영업)소매'!$F$7:$CZ$274,51,0) -> 8.5846868 | J28: =VLOOKUP($B28,'(영업)소매'!$F$7:$CZ$274,57,0) -> 5.6737868 | K28: =VLOOKUP($B28,'(영업)소매'!$F$7:$CZ$274,67,0) -> 2.5660377 | L28: =VLOOKUP($B28,'(영업)소매'!$F$7:$CZ$274,95,0) -> 5.284 | M28: =VLOOKUP($B28,'(영업)소매'!$F$7:$CZ$274,73,0) -> 5 | N28: =VLOOKUP($B28,'(영업)소매'!$F$7:$CZ$274,91,0) -> 2.85 | O28: =SUM(P28:Q28) -> 15.883024 | P28: =VLOOKUP($B28,'(이익) 소매'!$F$7:$S$21,10,0) -> 9.883024 | Q28: =VLOOKUP($B28,'(이익) 소매'!$F$7:$S$21,14,0) -> 6
B29: 지사 평균 | C29: =AVERAGE(C19:C28) -> 78.269979 | D29: - | E29: =AVERAGE(E19:E28) -> 62.787534 | F29: =AVERAGE(F19:F28) -> 13.995839 | G29: =AVERAGE(G19:G28) -> 6.6124606 | H29: =AVERAGE(H19:H28) -> 13.468108 | I29: =AVERAGE(I19:I28) -> 8.5429361 | J29: =AVERAGE(J19:J28) -> 5.8422257 | K29: =AVERAGE(K19:K28) -> 2.0607799 | L29: =AVERAGE(L19:L28) -> 4.4001842 | ... Q29: =AVERAGE(Q19:Q28) -> 6
B30: 지사별편차 | C30: =MAX(C19:C28)-MIN(C19:C28) -> 14.04728 | D30: - | E30: =MAX(E19:E28)-MIN(E19:E28) -> 12.971242 | F30: =MAX(F19:F28)-MIN(F19:F28) -> 3.2786921 | G30: =MAX(G19:G28)-MIN(G19:G28) -> 4.7044387 | H30: =MAX(H19:H28)-MIN(H19:H28) -> 5.793825 | I30: =MAX(I19:I28)-MIN(I19:I28) -> 2.3309372 | J30: =MAX(J19:J28)-MIN(J19:J28) -> 0.67972344 | K30: =MAX(K19:K28)-MIN(K19:K28) -> 6 | L30: =MAX(L19:L28)-MIN(L19:L28) -> 3.5034667 | ... Q30: =MAX(Q19:Q28)-MIN(Q19:Q28) -> 0
B31: 1 | C31: 2 | D31: 3 | E31: 4 | F31: 5 | G31: 6 | H31: 7 | I31: 8 | J31: 9 | K31: 10 | L31: 11 | M31: 12 | N31: 13 | O31: 14 | P31: 15 | Q31: 16

Sheet 1Q 도매
B2: ■ 26년 1Q 도매 조직별 KPI 득점 현황
B4: 영업 기준일 | C4: 일반후불 | D4: MNP/후불신규 | E4: 유선순신규 | F4: MIT | G4: R-VOC | H4: 판매APRU | I4: 인프라 | J4: 1G 유치율
C5: 1~3월 | D5: 1~3월 | E5: 1~3월 | F5: 1~3월 | G5: 1~3월 | H5: 1~3월 | I5: 1~3월 | J5: 1~3월
B6: 이익 기준일 | C6: 추가수익
C7: 1~3월
B9: 본부 조직 | C9: KPI 득점 | D9: 순위 | E9: 영업 | N9: 이익
F10: 후불 | G10: MNP/ 후불신규 | H10: 유선순신규 | I10: MIT | J10: R-VOC | K10: 1G | L10: 판매 ARPU | M10: 인프라 | O10: 추가 수익
E11: =SUM(F11:M11) -> 85 | F11: 20 | G11: 10 | H11: 20 | I11: 10 | J11: 5 | K11: 5 | L11: 7 | M11: 8 | N11: =SUM(O11:O11) -> 5 | O11: 5
B12: 강북본부 | C12: =E12+N12 -> 91.939676 | D12: =RANK(C12,$C$12:$C$16) -> 4 | E12: =SUM(F12:M12) -> 86.544941 | F12: =VLOOKUP($B12,'(영업)도매'!$F$7:$CZ$60,12,0) -> 24 | G12: =VLOOKUP($B12,'(영업)도매'!$F$7:$CZ$60,23,0) -> 12 | H12: =VLOOKUP($B12,'(영업)도매'!$F$7:$CZ$60,42,0) -> 16.514532 | I12: =VLOOKUP($B12,'(영업)도매'!$F$7:$CZ$60,51,0) -> 12 | J12: =VLOOKUP($B12,'(영업)도매'!$F$7:$CZ$60,95,0) -> 3.1835714 | K12: =VLOOKUP($B12,'(영업)도매'!$F$7:$CZ$60,73,0) -> 5 | L12: =VLOOKUP($B12,'(영업)도매'!$F$7:$CZ$60,57,0) -> 5.4379498 | M12: =VLOOKUP($B12,'(영업)도매'!$F$7:$CZ$60,83,0) -> 8.4088885 | N12: =SUM(O12:O12) -> 5.3947342 | O12: =VLOOKUP($B12,'(이익) 도매'!$B$8:$G$19,2,0) -> 5.3947342
B13: 강남본부 | C13: =E13+N13 -> 94.272648 | D13: =RANK(C13,$C$12:$C$16) -> 3 | E13: =SUM(F13:M13) -> 89.269737 | F13: =VLOOKUP($B13,'(영업)도매'!$F$7:$CZ$60,12,0) -> 24 | G13: =VLOOKUP($B13,'(영업)도매'!$F$7:$CZ$60,23,0) -> 12 | H13: =VLOOKUP($B13,'(영업)도매'!$F$7:$CZ$60,42,0) -> 18.434693 | I13: =VLOOKUP($B13,'(영업)도매'!$F$7:$CZ$60,51,0) -> 12 | J13: =VLOOKUP($B13,'(영업)도매'!$F$7:$CZ$60,95,0) -> 3.25104 | K13: =VLOOKUP($B13,'(영업)도매'!$F$7:$CZ$60,73,0) -> 5 | L13: =VLOOKUP($B13,'(영업)도매'!$F$7:$CZ$60,57,0) -> 5.7455872 | M13: =VLOOKUP($B13,'(영업)도매'!$F$7:$CZ$60,83,0) -> 8.8384163 | N13: =SUM(O13:O13) -> 5.0029107 | O13: =VLOOKUP($B13,'(이익) 도매'!$B$8:$G$19,2,0) -> 5.0029107
B14: 강서본부 | C14: =E14+N14 -> 96.488207 | D14: =RANK(C14,$C$12:$C$16) -> 1 | E14: =SUM(F14:M14) -> 91.219695 | F14: =VLOOKUP($B14,'(영업)도매'!$F$7:$CZ$60,12,0) -> 24 | G14: =VLOOKUP($B14,'(영업)도매'!$F$7:$CZ$60,23,0) -> 12 | H14: =VLOOKUP($B14,'(영업)도매'!$F$7:$CZ$60,42,0) -> 20.546965 | I14: =VLOOKUP($B14,'(영업)도매'!$F$7:$CZ$60,51,0) -> 12 | J14: =VLOOKUP($B14,'(영업)도매'!$F$7:$CZ$60,95,0) -> 3.2511 | K14: =VLOOKUP($B14,'(영업)도매'!$F$7:$CZ$60,73,0) -> 5 | L14: =VLOOKUP($B14,'(영업)도매'!$F$7:$CZ$60,57,0) -> 5.3926955 | M14: =VLOOKUP($B14,'(영업)도매'!$F$7:$CZ$60,83,0) -> 9.0289348 | N14: =SUM(O14:O14) -> 5.2685119 | O14: =VLOOKUP($B14,'(이익) 도매'!$B$8:$G$19,2,0) -> 5.2685119
B15: 동부본부 | C15: =E15+N15 -> 96.10838 | D15: =RANK(C15,$C$12:$C$16) -> 2 | E15: =SUM(F15:M15) -> 90.10838 | F15: =VLOOKUP($B15,'(영업)도매'!$F$7:$CZ$60,12,0) -> 24 | G15: =VLOOKUP($B15,'(영업)도매'!$F$7:$CZ$60,23,0) -> 12 | H15: =VLOOKUP($B15,'(영업)도매'!$F$7:$CZ$60,42,0) -> 18.119675 | I15: =VLOOKUP($B15,'(영업)도매'!$F$7:$CZ$60,51,0) -> 12 | J15: =VLOOKUP($B15,'(영업)도매'!$F$7:$CZ$60,95,0) -> 4.9988571 | K15: =VLOOKUP($B15,'(영업)도매'!$F$7:$CZ$60,73,0) -> 5 | L15: =VLOOKUP($B15,'(영업)도매'!$F$7:$CZ$60,57,0) -> 5.2563598 | M15: =VLOOKUP($B15,'(영업)도매'!$F$7:$CZ$60,83,0) -> 8.7334876 | N15: =SUM(O15:O15) -> 6 | O15: =VLOOKUP($B15,'(이익) 도매'!$B$8:$G$19,2,0) -> 6
B16: 서부본부 | C16: =E16+N16 -> 88.346642 | D16: =RANK(C16,$C$12:$C$16) -> 5 | E16: =SUM(F16:M16) -> 82.346642 | F16: =VLOOKUP($B16,'(영업)도매'!$F$7:$CZ$60,12,0) -> 22.938591 | G16: =VLOOKUP($B16,'(영업)도매'!$F$7:$CZ$60,23,0) -> 9.741488 | H16: =VLOOKUP($B16,'(영업)도매'!$F$7:$CZ$60,42,0) -> 14.850423 | I16: =VLOOKUP($B16,'(영업)도매'!$F$7:$CZ$60,51,0) -> 11.320451 | J16: =VLOOKUP($B16,'(영업)도매'!$F$7:$CZ$60,95,0) -> 5.003 | K16: =VLOOKUP($B16,'(영업)도매'!$F$7:$CZ$60,73,0) -> 5 | L16: =VLOOKUP($B16,'(영업)도매'!$F$7:$CZ$60,57,0) -> 5.2596237 | M16: =VLOOKUP($B16,'(영업)도매'!$F$7:$CZ$60,83,0) -> 8.2330656 | N16: =SUM(O16:O16) -> 6 | O16: =VLOOKUP($B16,'(이익) 도매'!$B$8:$G$19,2,0) -> 6
B17: 본부 평균 | C17: =AVERAGE(C12:C16) -> 93.43111 | D17: - | E17: =AVERAGE(E12:E16) -> 87.897879 | F17: =AVERAGE(F12:F16) -> 23.787718 | G17: =AVERAGE(G12:G16) -> 11.548298 | H17: =AVERAGE(H12:H16) -> 17.693258 | I17: =AVERAGE(I12:I16) -> 11.86409 | J17: =AVERAGE(J12:J16) -> 3.9375137 | K17: =AVERAGE(K12:K16) -> 5 | L17: =AVERAGE(L12:L16) -> 5.4184432 | ... O17: =AVERAGE(O12:O16) -> 5.5332314
B18: 본부별편차 | C18: =MAX(C12:C16)-MIN(C12:C16) -> 8.1415647 | E18: =MAX(E12:E16)-MIN(E12:E16) -> 8.8730528 | F18: =MAX(F12:F16)-MIN(F12:F16) -> 1.0614086 | G18: =MAX(G12:G16)-MIN(G12:G16) -> 2.258512 | H18: =MAX(H12:H16)-MIN(H12:H16) -> 5.696542 | I18: =MAX(I12:I16)-MIN(I12:I16) -> 0.67954911 | J18: =MAX(J12:J16)-MIN(J12:J16) -> 1.8194286 | K18: =MAX(K12:K16)-MIN(K12:K16) -> 0 | L18: =MAX(L12:L16)-MIN(L12:L16) -> 0.48922738 | ... O18: =MAX(O12:O16)-MIN(O12:O16) -> 0.99708926
B19: 강북도매 | C19: =E19+N19 -> 91.939676 | D19: =RANK(C19,$C$19:$C$25) -> 4 | E19: =SUM(F19:M19) -> 86.544941 | F19: =VLOOKUP($B19,'(영업)도매'!$F$7:$CZ$60,12,0) -> 24 | G19: =VLOOKUP($B19,'(영업)도매'!$F$7:$CZ$60,23,0) -> 12 | H19: =VLOOKUP($B19,'(영업)도매'!$F$7:$CZ$60,42,0) -> 16.514532 | I19: =VLOOKUP($B19,'(영업)도매'!$F$7:$CZ$60,51,0) -> 12 | J19: =VLOOKUP($B19,'(영업)도매'!$F$7:$CZ$60,95,0) -> 3.1835714 | K19: =VLOOKUP($B19,'(영업)도매'!$F$7:$CZ$60,73,0) -> 5 | L19: =VLOOKUP($B19,'(영업)도매'!$F$7:$CZ$60,57,0) -> 5.4379498 | M19: =VLOOKUP($B19,'(영업)도매'!$F$7:$CZ$60,83,0) -> 8.4088885 | N19: =SUM(O19:O19) -> 5.3947342 | O19: =VLOOKUP($B19,'(이익) 도매'!$B$8:$G$19,2,0) -> 5.3947342
B20: 강남도매 | C20: =E20+N20 -> 94.272648 | D20: =RANK(C20,$C$19:$C$25) -> 3 | E20: =SUM(F20:M20) -> 89.269737 | F20: =VLOOKUP($B20,'(영업)도매'!$F$7:$CZ$60,12,0) -> 24 | G20: =VLOOKUP($B20,'(영업)도매'!$F$7:$CZ$60,23,0) -> 12 | H20: =VLOOKUP($B20,'(영업)도매'!$F$7:$CZ$60,42,0) -> 18.434693 | I20: =VLOOKUP($B20,'(영업)도매'!$F$7:$CZ$60,51,0) -> 12 | J20: =VLOOKUP($B20,'(영업)도매'!$F$7:$CZ$60,95,0) -> 3.25104 | K20: =VLOOKUP($B20,'(영업)도매'!$F$7:$CZ$60,73,0) -> 5 | L20: =VLOOKUP($B20,'(영업)도매'!$F$7:$CZ$60,57,0) -> 5.7455872 | M20: =VLOOKUP($B20,'(영업)도매'!$F$7:$CZ$60,83,0) -> 8.8384163 | N20: =SUM(O20:O20) -> 5.0029107 | O20: =VLOOKUP($B20,'(이익) 도매'!$B$8:$G$19,2,0) -> 5.0029107
B21: 강서도매 | C21: =E21+N21 -> 96.488207 | D21: =RANK(C21,$C$19:$C$25) -> 2 | E21: =SUM(F21:M21) -> 91.219695 | F21: =VLOOKUP($B21,'(영업)도매'!$F$7:$CZ$60,12,0) -> 24 | G21: =VLOOKUP($B21,'(영업)도매'!$F$7:$CZ$60,23,0) -> 12 | H21: =VLOOKUP($B21,'(영업)도매'!$F$7:$CZ$60,42,0) -> 20.546965 | I21: =VLOOKUP($B21,'(영업)도매'!$F$7:$CZ$60,51,0) -> 12 | J21: =VLOOKUP($B21,'(영업)도매'!$F$7:$CZ$60,95,0) -> 3.2511 | K21: =VLOOKUP($B21,'(영업)도매'!$F$7:$CZ$60,73,0) -> 5 | L21: =VLOOKUP($B21,'(영업)도매'!$F$7:$CZ$60,57,0) -> 5.3926955 | M21: =VLOOKUP($B21,'(영업)도매'!$F$7:$CZ$60,83,0) -> 9.0289348 | N21: =SUM(O21:O21) -> 5.2685119 | O21: =VLOOKUP($B21,'(이익) 도매'!$B$8:$G$19,2,0) -> 5.2685119
B22: 부산도매 | C22: =E22+N22 -> 91.195432 | D22: =RANK(C22,$C$19:$C$25) -> 5 | E22: =SUM(F22:M22) -> 85.259288 | F22: =VLOOKUP($B22,'(영업)도매'!$F$7:$CZ$60,12,0) -> 24 | G22: =VLOOKUP($B22,'(영업)도매'!$F$7:$CZ$60,23,0) -> 10.93543 | H22: =VLOOKUP($B22,'(영업)도매'!$F$7:$CZ$60,42,0) -> 15.36176 | I22: =VLOOKUP($B22,'(영업)도매'!$F$7:$CZ$60,51,0) -> 12 | J22: =VLOOKUP($B22,'(영업)도매'!$F$7:$CZ$60,95,0) -> 4.6875 | K22: =VLOOKUP($B22,'(영업)도매'!$F$7:$CZ$60,73,0) -> 5 | L22: =VLOOKUP($B22,'(영업)도매'!$F$7:$CZ$60,57,0) -> 5.0247859 | M22: =VLOOKUP($B22,'(영업)도매'!$F$7:$CZ$60,83,0) -> 8.249812 | N22: =SUM(O22:O22) -> 5.936144 | O22: =VLOOKUP($B22,'(이익) 도매'!$B$8:$G$19,2,0) -> 5.936144
B23: 대구도매 | C23: =E23+N23 -> 102.81751 | D23: =RANK(C23,$C$19:$C$25) -> 1 | E23: =SUM(F23:M23) -> 96.817511 | F23: =VLOOKUP($B23,'(영업)도매'!$F$7:$CZ$60,12,0) -> 24 | G23: =VLOOKUP($B23,'(영업)도매'!$F$7:$CZ$60,23,0) -> 12 | H23: =VLOOKUP($B23,'(영업)도매'!$F$7:$CZ$60,42,0) -> 23.447368 | I23: =VLOOKUP($B23,'(영업)도매'!$F$7:$CZ$60,51,0) -> 12 | J23: =VLOOKUP($B23,'(영업)도매'!$F$7:$CZ$60,95,0) -> 5.6781818 | K23: =VLOOKUP($B23,'(영업)도매'!$F$7:$CZ$60,73,0) -> 4.757085 | L23: =VLOOKUP($B23,'(영업)도매'!$F$7:$CZ$60,57,0) -> 5.5791027 | M23: =VLOOKUP($B23,'(영업)도매'!$F$7:$CZ$60,83,0) -> 9.355773 | N23: =SUM(O23:O23) -> 6 | O23: =VLOOKUP($B23,'(이익) 도매'!$B$8:$G$19,2,0) -> 6
B24: 충청도매 | C24: =E24+N24 -> 88.321483 | D24: =RANK(C24,$C$19:$C$25) -> 6 | E24: =SUM(F24:M24) -> 82.925435 | F24: =VLOOKUP($B24,'(영업)도매'!$F$7:$CZ$60,12,0) -> 22.722874 | G24: =VLOOKUP($B24,'(영업)도매'!$F$7:$CZ$60,23,0) -> 9.4324324 | H24: =VLOOKUP($B24,'(영업)도매'!$F$7:$CZ$60,42,0) -> 15.006859 | I24: =VLOOKUP($B24,'(영업)도매'!$F$7:$CZ$60,51,0) -> 11.070461 | J24: =VLOOKUP($B24,'(영업)도매'!$F$7:$CZ$60,95,0) -> 6 | K24: =VLOOKUP($B24,'(영업)도매'!$F$7:$CZ$60,73,0) -> 5 | L24: =VLOOKUP($B24,'(영업)도매'!$F$7:$CZ$60,57,0) -> 5.5793899 | M24: =VLOOKUP($B24,'(영업)도매'!$F$7:$CZ$60,83,0) -> 8.1134188 | N24: =SUM(O24:O24) -> 5.3960475 | O24: =VLOOKUP($B24,'(이익) 도매'!$B$8:$G$19,2,0) -> 5.3960475
B25: 호남도매 | C25: =E25+N25 -> 87.85457 | D25: =RANK(C25,$C$19:$C$25) -> 7 | E25: =SUM(F25:M25) -> 81.85457 | F25: =VLOOKUP($B25,'(영업)도매'!$F$7:$CZ$60,12,0) -> 23.272525 | G25: =VLOOKUP($B25,'(영업)도매'!$F$7:$CZ$60,23,0) -> 10.173979 | H25: =VLOOKUP($B25,'(영업)도매'!$F$7:$CZ$60,42,0) -> 14.570455 | I25: =VLOOKUP($B25,'(영업)도매'!$F$7:$CZ$60,51,0) -> 11.686508 | J25: =VLOOKUP($B25,'(영업)도매'!$F$7:$CZ$60,95,0) -> 3.9470769 | K25: =VLOOKUP($B25,'(영업)도매'!$F$7:$CZ$60,73,0) -> 5 | L25: =VLOOKUP($B25,'(영업)도매'!$F$7:$CZ$60,57,0) -> 4.7641803 | M25: =VLOOKUP($B25,'(영업)도매'!$F$7:$CZ$60,83,0) -> 8.4398467 | N25: =SUM(O25:O25) -> 6 | O25: =VLOOKUP($B25,'(이익) 도매'!$B$8:$G$19,2,0) -> 6
B26: 지사 평균 | C26: =AVERAGE(C19:C25) -> 93.269932 | D26: - | E26: =AVERAGE(E19:E25) -> 87.69874 | F26: =AVERAGE(F19:F25) -> 23.713628 | G26: =AVERAGE(G19:G25) -> 11.220263 | H26: =AVERAGE(H19:H25) -> 17.697519 | I26: =AVERAGE(I19:I25) -> 11.822424 | J26: =AVERAGE(J19:J25) -> 4.2854957 | K26: =AVERAGE(K19:K25) -> 4.9652979 | L26: =AVERAGE(L19:L25) -> 5.3605273 | ... O26: =AVERAGE(O19:O25) -> 5.5711926
B27: 지사별편차 | C27: =MAX(C19:C25)-MIN(C19:C25) -> 14.962941 | D27: - | E27: =MAX(E19:E25)-MIN(E19:E25) -> 14.962941 | F27: =MAX(F19:F25)-MIN(F19:F25) -> 1.2771257 | G27: =MAX(G19:G25)-MIN(G19:G25) -> 2.5675676 | H27: =MAX(H19:H25)-MIN(H19:H25) -> 8.8769139 | I27: =MAX(I19:I25)-MIN(I19:I25) -> 0.9295393 | J27: =MAX(J19:J25)-MIN(J19:J25) -> 2.8164286 | K27: =MAX(K19:K25)-MIN(K19:K25) -> 0.24291498 | L27: =MAX(L19:L25)-MIN(L19:L25) -> 0.98140689 | ... O27: =MAX(O19:O25)-MIN(O19:O25) -> 0.99708926
B28: 1 | C28: 2 | D28: 3 | E28: 4 | F28: 5 | G28: 6 | H28: 7 | I28: 8 | J28: 9 | K28: 10 | L28: 11 | M28: 12 | N28: 13 | O28: 15

Sheet 1Q 소상공인
B2: ■ 26년 1Q 소상공인 조직별 KPI 득점 현황
B4: 영업 기준일 | C4: 일반후불 | D4: 유선 순신규 | E4: MIT 동시판매 | F4: 1G | G4: R-VOC
C5: 1~3월 | D5: 1~3월 | E5: 1~3월 | F5: 1~3월 | G5: 1~3월
B6: 이익 기준일 | C6: 영업이익
C7: 1~3월
B9: 강북소매 | C9: =SUM(E9,F9) -> #REF! | D9: =RANK(C9,$C$9:$C$18) -> #REF! | E9: =(#REF!*2/3)+(#REF!*1/3) -> #REF! | F9: =SUM(G9:G9) -> #N/A | G9: =VLOOKUP($B9,'(이익) 도매'!$B$8:$G$19,10,0) -> #N/A
B10: 강동소매 | C10: =SUM(E10,F10) -> #REF! | D10: =RANK(C10,$C$9:$C$18) -> #REF! | E10: =(#REF!*2/3)+(#REF!*1/3) -> #REF! | F10: =SUM(G10:G10) -> #N/A | G10: =VLOOKUP($B10,'(이익) 도매'!$B$8:$G$19,10,0) -> #N/A
B11: 강남소매 | C11: =SUM(E11,F11) -> #REF! | D11: =RANK(C11,$C$9:$C$18) -> #REF! | E11: =(#REF!*2/3)+(#REF!*1/3) -> #REF! | F11: =SUM(G11:G11) -> #N/A | G11: =VLOOKUP($B11,'(이익) 도매'!$B$8:$G$19,10,0) -> #N/A
B12: 강서소매 | C12: =SUM(E12,F12) -> #REF! | D12: =RANK(C12,$C$9:$C$18) -> #REF! | E12: =(#REF!*2/3)+(#REF!*1/3) -> #REF! | F12: =SUM(G12:G12) -> #N/A | G12: =VLOOKUP($B12,'(이익) 도매'!$B$8:$G$19,10,0) -> #N/A
B13: 남부소매 | C13: =SUM(E13,F13) -> #REF! | D13: =RANK(C13,$C$9:$C$18) -> #REF! | E13: =(#REF!*2/3)+(#REF!*1/3) -> #REF! | F13: =SUM(G13:G13) -> #N/A | G13: =VLOOKUP($B13,'(이익) 도매'!$B$8:$G$19,10,0) -> #N/A
B14: 인천소매 | C14: =SUM(E14,F14) -> #REF! | D14: =RANK(C14,$C$9:$C$18) -> #REF! | E14: =(#REF!*2/3)+(#REF!*1/3) -> #REF! | F14: =SUM(G14:G14) -> #N/A | G14: =VLOOKUP($B14,'(이익) 도매'!$B$8:$G$19,10,0) -> #N/A
B15: 부산소매 | C15: =SUM(E15,F15) -> #REF! | D15: =RANK(C15,$C$9:$C$18) -> #REF! | E15: =(#REF!*2/3)+(#REF!*1/3) -> #REF! | F15: =SUM(G15:G15) -> #N/A | G15: =VLOOKUP($B15,'(이익) 도매'!$B$8:$G$19,10,0) -> #N/A
B16: 대구소매 | C16: =SUM(E16,F16) -> #REF! | D16: =RANK(C16,$C$9:$C$18) -> #REF! | E16: =(#REF!*2/3)+(#REF!*1/3) -> #REF! | F16: =SUM(G16:G16) -> #N/A | G16: =VLOOKUP($B16,'(이익) 도매'!$B$8:$G$19,10,0) -> #N/A
B17: 충청소매 | C17: =SUM(E17,F17) -> #REF! | D17: =RANK(C17,$C$9:$C$18) -> #REF! | E17: =(#REF!*2/3)+(#REF!*1/3) -> #REF! | F17: =SUM(G17:G17) -> #N/A | G17: =VLOOKUP($B17,'(이익) 도매'!$B$8:$G$19,10,0) -> #N/A
B18: 호남소매 | C18: =SUM(E18,F18) -> #REF! | D18: =RANK(C18,$C$9:$C$18) -> #REF! | E18: =(#REF!*2/3)+(#REF!*1/3) -> #REF! | F18: =SUM(G18:G18) -> #N/A | G18: =VLOOKUP($B18,'(이익) 도매'!$B$8:$G$19,10,0) -> #N/A
B19: 지사 평균 | C19: =AVERAGE(C9:C18) -> #REF! | D19: - | E19: =AVERAGE(E9:E18) -> #REF! | F19: =AVERAGE(F9:F18) -> #N/A | G19: =AVERAGE(G9:G18) -> #N/A
B20: 지사별편차 | C20: =MAX(C9:C18)-MIN(C9:C18) -> #REF! | D20: - | E20: =MAX(E9:E18)-MIN(E9:E18) -> #REF! | F20: =MAX(F9:F18)-MIN(F9:F18) -> #N/A | G20: =MAX(G9:G18)-MIN(G9:G18) -> #N/A
B21: 1 | C21: 2 | D21: 3 | E21: 4 | F21: 5 | G21: 6 | H21: 7 | I21: 8 | K21: 12 | L21: 13
B22: 본부 조직 | C22: KPI 득점 | D22: 순위 | E22: 영업 | K22: 이익
F23: 일반후불 | G23: 유선 순신규 | H23: MIT | I23: 전략상품 | J23: R-VOC | L23: 영업이익
E24: =SUM(F24:J24) -> 70 | F24: 20 | G24: 20 | H24: 7 | I24: 20 | J24: 3 | K24: =SUM(L24:L24) -> 20 | L24: 20
B25: 강북본부 | C25: =SUM(E25,K25) -> 59.638727 | D25: =RANK(C25,$C$25:$C$29) -> 3 | E25: =SUM(F25:J25) -> 40.225496 | F25: =VLOOKUP($B25,'(영업)소상공인'!$F$7:$CZ$11,12,0) -> 14.615385 | G25: =VLOOKUP($B25,'(영업)소상공인'!$F$7:$CZ$11,42,0) -> 8.8791133 | H25: =VLOOKUP($B25,'(영업)소상공인'!$F$7:$CZ$11,51,0) -> 3.2958333 | I25: =VLOOKUP($B25,'(영업)소상공인'!$F$7:$CZ$11,67,0) -> 9.8351648 | J25: =VLOOKUP($B25,'(영업)소상공인'!$F$7:$CZ$11,95,0) -> 3.6 | K25: =SUM(L25:L25) -> 19.413231 | L25: =VLOOKUP($B25,'(이익)소상공인'!$C$7:$H$11,6,0) -> 19.413231
B26: 강남본부 | C26: =SUM(E26,K26) -> 49.005058 | D26: =RANK(C26,$C$25:$C$29) -> 5 | E26: =SUM(F26:J26) -> 29.577321 | F26: =VLOOKUP($B26,'(영업)소상공인'!$F$7:$CZ$11,12,0) -> 5.862069 | G26: =VLOOKUP($B26,'(영업)소상공인'!$F$7:$CZ$11,42,0) -> 8.6036238 | H26: =VLOOKUP($B26,'(영업)소상공인'!$F$7:$CZ$11,51,0) -> 1.4 | I26: =VLOOKUP($B26,'(영업)소상공인'!$F$7:$CZ$11,67,0) -> 10.111628 | J26: =VLOOKUP($B26,'(영업)소상공인'!$F$7:$CZ$11,95,0) -> 3.6 | K26: =SUM(L26:L26) -> 19.427737 | L26: =VLOOKUP($B26,'(이익)소상공인'!$C$7:$H$11,6,0) -> 19.427737
B27: 강서본부 | C27: =SUM(E27,K27) -> 71.952599 | D27: =RANK(C27,$C$25:$C$29) -> 1 | E27: =SUM(F27:J27) -> 52.454039 | F27: =VLOOKUP($B27,'(영업)소상공인'!$F$7:$CZ$11,12,0) -> 11.081081 | G27: =VLOOKUP($B27,'(영업)소상공인'!$F$7:$CZ$11,42,0) -> 11.558237 | H27: =VLOOKUP($B27,'(영업)소상공인'!$F$7:$CZ$11,51,0) -> 3.3478261 | I27: =VLOOKUP($B27,'(영업)소상공인'!$F$7:$CZ$11,67,0) -> 22.866894 | J27: =VLOOKUP($B27,'(영업)소상공인'!$F$7:$CZ$11,95,0) -> 3.6 | K27: =SUM(L27:L27) -> 19.49856 | L27: =VLOOKUP($B27,'(이익)소상공인'!$C$7:$H$11,6,0) -> 19.49856
B28: 동부본부 | C28: =SUM(E28,K28) -> 59.229019 | D28: =RANK(C28,$C$25:$C$29) -> 4 | E28: =SUM(F28:J28) -> 40.55119 | F28: =VLOOKUP($B28,'(영업)소상공인'!$F$7:$CZ$11,12,0) -> 7.5757576 | G28: =VLOOKUP($B28,'(영업)소상공인'!$F$7:$CZ$11,42,0) -> 10.380622 | H28: =VLOOKUP($B28,'(영업)소상공인'!$F$7:$CZ$11,51,0) -> 2.5277778 | I28: =VLOOKUP($B28,'(영업)소상공인'!$F$7:$CZ$11,67,0) -> 16.467033 | J28: =VLOOKUP($B28,'(영업)소상공인'!$F$7:$CZ$11,95,0) -> 3.6 | K28: =SUM(L28:L28) -> 18.677829 | L28: =VLOOKUP($B28,'(이익)소상공인'!$C$7:$H$11,6,0) -> 18.677829
B29: 서부본부 | C29: =SUM(E29,K29) -> 66.631952 | D29: =RANK(C29,$C$25:$C$29) -> 2 | E29: =SUM(F29:J29) -> 45.853513 | F29: =VLOOKUP($B29,'(영업)소상공인'!$F$7:$CZ$11,12,0) -> 12.575758 | G29: =VLOOKUP($B29,'(영업)소상공인'!$F$7:$CZ$11,42,0) -> 13.886218 | H29: =VLOOKUP($B29,'(영업)소상공인'!$F$7:$CZ$11,51,0) -> 5.5432432 | I29: =VLOOKUP($B29,'(영업)소상공인'!$F$7:$CZ$11,67,0) -> 11.439394 | J29: =VLOOKUP($B29,'(영업)소상공인'!$F$7:$CZ$11,95,0) -> 2.4089 | K29: =SUM(L29:L29) -> 20.77844 | L29: =VLOOKUP($B29,'(이익)소상공인'!$C$7:$H$11,6,0) -> 20.77844
B30: 본부 평균 | C30: =AVERAGE(C25:C29) -> 61.291471 | D30: - | E30: =AVERAGE(E25:E29) -> 41.732312 | F30: =AVERAGE(F25:F29) -> 10.34201 | G30: =AVERAGE(G25:G29) -> 10.661563 | H30: =AVERAGE(H25:H29) -> 3.2229361 | I30: =AVERAGE(I25:I29) -> 14.144023 | J30: =AVERAGE(J25:J29) -> 3.36178 | K30: =AVERAGE(K25:K29) -> 19.559159 | L30: =AVERAGE(L25:L29) -> 19.559159
B31: 본부별편차 | C31: =MAX(C25:C29)-MIN(C25:C29) -> 22.947541 | D31: - | E31: =MAX(E25:E29)-MIN(E25:E29) -> 22.876718 | F31: =MAX(F25:F29)-MIN(F25:F29) -> 8.7533156 | G31: =MAX(G25:G29)-MIN(G25:G29) -> 5.2825941 | H31: =MAX(H25:H29)-MIN(H25:H29) -> 4.1432432 | I31: =MAX(I25:I29)-MIN(I25:I29) -> 13.031729 | J31: =MAX(J25:J29)-MIN(J25:J29) -> 1.1911 | K31: =MAX(K25:K29)-MIN(K25:K29) -> 2.1006107 | L31: =MAX(L25:L29)-MIN(L25:L29) -> 2.1006107

Sheet 1Q 디지털, 법인영업
B2: ■ 26년 1Q 디지털 KPI 득점 현황
B4: 영업 기준일 | C4: 일반후불 | D4: 후불신규 | E4: 유선순신규 | F4: MIT | G4: 1G유치율
C5: 1~3월 | D5: 1~3월 | E5: 1~3월 | F5: 1~3월 | G5: 1~3월
B7: 조직 | C7: KPI 득점 | D7: 영업 | J7: 이익
E8: 일반후불 | F8: 후불신규 | G8: 유선순신규 | H8: MIT | I8: 1G유치율 | K8: 영업 이익
D9: =SUM(E9:I9) -> 80 | E9: 45 | F9: 10 | G9: 18 | H9: 5 | I9: 2 | J9: 10 | K9: 10
B10: 디지털 | C10: =D10 -> 54.193 | D10: =SUM(E10:I10) -> 54.193 | E10: =VLOOKUP($B10,'(영업)디지털 B2B'!$F$11:$DK$11,12,0) -> 38.952 | F10: =VLOOKUP($B10,'(영업)디지털 B2B'!$F$11:$DK$11,23,0) -> 12 | G10: =VLOOKUP($B10,'(영업)디지털 B2B'!$F$11:$DK$11,42,0) -> 2.856 | H10: =VLOOKUP($B10,'(영업)디지털 B2B'!$F$11:$DK$11,51,0) -> 0.385 | J10: =SUM(K10:K10) -> 7.5 | K10: ='(이익)디지털 B2B'!H6 -> 7.5
B12: ■ 25년 4Q B2B KPI 득점 현황
B14: 영업 기준일 | C14: 후불 | D14: 순신규 | E14: 동시판매 | F14: 판매ARPU 매출 | G14: 전략상품 | H14: R-VOC
C15: 10~12월 | D15: 10~12월 | E15: 10~12월 | F15: 10~12월 | G15: 10~12월 | H15: 10~12월
B16: 이익 기준일 | C16: 영업이익
C17: 10~12월
B19: 조직 | C19: KPI 득점 | D19: 영업 | L19: 이익
E20: 후불 | F20: 후불+2ND | G20: 유선순신규 | H20: 전략상품 | I20: R-VOC | J20: 판매ARPU 매출 | K20: 직접영업 | M20: 영업 이익
D21: =SUM(E21:K21) -> 55 | E21: 25 | F21: 5 | G21: 5 | H21: 5 | I21: 2 | J21: 3 | K21: 10 | L21: 35 | M21: 35
B22: B2B | C22: =D22 -> 42.594482 | D22: =SUM(E22:K22)-I22 -> 42.594482 | E22: 12.4125 | F22: 3.9068966 | G22: 6 | H22: 0 | I22: 2.4 | J22: 2.8950852 | K22: 17.38 | L22: =SUM(M22:M22) -> 0 | M22: ='(이익)디지털 B2B'!O16 -> 0

Sheet (영업)소매
F1: 1 | G1: 2 | H1: 3 | I1: 4 | J1: 5 | K1: 6 | L1: 7 | M1: 8 | N1: 9 | O1: 10 | P1: 11 | Q1: 12 | R1: 13 | S1: 14 | T1: 15 | U1: 16 | V1: 17 | W1: 18 | X1: 19 | Y1: 20 | Z1: 21 | AA1: 22 | AB1: 23 | AC1: 24 | AD1: 25 | AE1: 26 | AF1: 27 | AG1: 28 | AH1: 29 | AI1: 30 | AJ1: 31 | AK1: 32 | AL1: 33 | AM1: 34 | AN1: 35 | AO1: 36 | AP1: 37 | AQ1: 38 | AR1: 39 | AS1: 40 | AT1: 41 | AU1: 42 | AV1: 43 | AW1: 44 | AX1: 45 | AY1: 46 | AZ1: 47 | BA1: 48 | BB1: 49 | BC1: 50 | BD1: 51 | BE1: 52 | BF1: 53 | BG1: 54 | BH1: 55 | BI1: 56 | BJ1: 57 | BK1: 58 | BL1: 59 | BM1: 60 | BN1: 61 | BO1: 62 | BP1: 63 | BQ1: 64 | BR1: 65 | BS1: 66 | BT1: 67 | BU1: 68 | BV1: 69 | BW1: 70 | BX1: 71 | BY1: 72 | BZ1: 73 | CA1: 74 | CB1: 75 | CC1: 76 | CD1: 77 | CE1: 78 | CF1: 79 | CG1: 80 | CH1: 81 | CI1: 82 | CJ1: 83 | CK1: 84 | CL1: 85 | CM1: 86 | CN1: 87 | CO1: 88 | CP1: 89 | CQ1: 90 | CR1: 91 | CS1: 92 | CT1: 93 | CU1: 94 | CV1: 95 | CW1: 96 | CX1: 97 | CY1: 98 | CZ1: 99
J2: *소상공인/디지털/B2B 일반후불 1건 | K2: 1 | L2: 1 | M2: 1 | X2: *디지털 일반후불 신규 1건 | AC2: *B2B 약갱 포함(Biz제외) | AX2: *MIT에 MNP-MIT 포함됨 | BM2: 1.2 | BN2: 15 | BO2: 1 | BP2: 0.3 | BQ2: 1 | BR2: 1 | BS2: ←소상공인 | CP2: *점수 구간별 달성률 | CW2: 감점 : 불완전판매
A3: 월 | B3: 채널 | C3: 본부 | D3: 지사 | E3: 코드 | F3: 조직 | G3: 총 득점 | H3: 일반후불 | K3: 1 | L3: 1 | M3: 0.3 | N3: 0.2 | R3: B2B 무선전체 | U3: 10 | V3: 후불 신규 | X3: 1 | Y3: 1 | AC3: 유선 순신규 | AE3: 1 | AF3: 0.5 | AK3: 1 | AL3: 1 | AM3: 0.2 | AQ3: 1 | AR3: 1 | AS3: 0.2 | AV3: 동시판매 | AX3: 1 | AY3: 1 | AZ3: 1 | BA3: 0.3 | BE3: 판매 ARPU | BK3: 전략상품(소매/소상공인/B2B) | BM3: 1.2 | BN3: 5 | BO3: 0.5 | BP3: 0.3 | BQ3: 0.2 | BR3: 0.2 | BU3: 1G 유치율 | CA3: 도매 인프라(도매) | CJ3: 8 | CK3: 직접영업(B2B) | CN3: 10 | CP3: TCSI(소매) | CR3: 3 | CS3: R-VOC | CX3: 5 | CY3: 3 | DA3: 5 | DB3: 3 | DD3: 5 | DE3: 3 | DF3: 5 | DG3: 10 | DI3: 5 | DK3: 10 | DL3: 2.5
H4: 목표 | I4: 중고 목표 | J4: 실적 계 | K4: 운영후불 (소상공) 일반후불 | L4: 중고 MNP | M4: 중고 010/기변 | N4: (소매) 토탈영업 | O4: 차감점수 | P4: 달성률 Max 120% | Q4: 득점 | R4: 목표 | S4: 실적 | T4: 달성률 Max 120% | U4: 득점 | V4: 목표 | W4: 실적 계 | X4: MNP | Y4: (디지털) '010 | Z4: 차감점수 | AA4: 달성률 Max 120% | AB4: 득점 | AC4: 인터넷 목표 | AD4: 인터넷 실적 계 | AE4: 인터넷 | AF4: 선불 | AG4: 차감점수 음재 | AH4: 인터넷 달성률 | AI4: TV 목표 | AJ4: TV 실적 계 | AK4: 미디어 | AL4: 추단 | AM4: (소상공인) Biz | AN4: 차감점수 GTT무트래픽 | AO4: TV 달성률 | AP4: (B2B) 약갱 | AQ4: 인+티 | AR4: 추단 | AS4: (B2B) Biz | AT4: 달성률 Max 120% | AU4: 득점 | AV4: 목표 | AW4: 실적 계 | AX4: MIT | AY4: MNP-MIT | AZ4: ITU | BA4: (소상공인) ITB | BB4: 차감점수 | BC4: 달성률 Max 120% | BD4: 득점 | BE4: 목표 | BF4: ARPU | BG4: 매출 | BH4: 가입자 | BI4: 달성률 Max 120% | BJ4: 득점 | BK4: 목표 | BL4: 실적 계 | BM4: 하이오더 | BN4: AI로봇 | BO4: GiGAeyes | BP4: GiGAeyes 정보제공 | BQ4: AI전화 | BR4: AI링고전화 | BS4: 달성률 Max 120% | BT4: 득점 | BU4: 목표 | BV4: 유치율 | BW4: 1G | BX4: 인터넷 | BY4: 달성률 Max 100% | BZ4: 득점 | CA4: 가동점 목표 | CB4: 가동점 | CC4: 가동점 달성률 | CD4: 중형점 목표 | CE4: 중형점 | CF4: 5건~9건 발생점 | CG4: 10건↑ 발생점 | CH4: 중형점 달성률 | CI4: 달성률 Max 120% | CJ4: 득점 | CK4: 목표 | CL4: 실적 | CM4: 달성률 Max 120% | CN4: 득점 | CO4: 목표 | CP4: 실적 | CQ4: 달성률 | CR4: 득점 | CS4: R-VOC 점수 | CT4: 3대R-VOC 점수 | CU4: 대외민원 차감점수 | CV4: 득점 | CW4: 후불 SQM 차감 | CX4: 운영후불 | CY4: 중고 | CZ4: 후불 신규 SQM 차감 | DA4: 운영후불 | DB4: 중고 | DC4: MIT 차감 | DD4: SQM_운영 | DE4: SQM_중고 | DF4: 음재 | DG4: 권한남용 | DH4: 유선 차감 | DI4: 음재 | DJ4: SQM | DK4: 권한남용 | DL4: GTT 무트래픽
A5: 월 | B5: 채널 | C5: 본부 | D5: 지사 | E5: 코드 | F5: 조직 | G5: 총 득점 | H5: 목표 | I5: 중고 목표 | J5: 실적 계 | K5: 운영 후불 | L5: 중고 MNP | M5: 중고 010/기변 | N5: 토탈영업 | O5: 차감점수 | P5: 달성률 Max 120% | Q5: 득점 | R5: 목표2 | S5: 실적 | T5: 달성률 Max 120%3 | U5: 득점4 | V5: 목표5 | W5: 실적 계6 | X5: MNP | Y5: (디지털) '010 | Z5: 차감점수7 | AA5: 달성률 Max 120%8 | AB5: 득점9 | AC5: 인터넷 목표 | AD5: 인터넷 실적 계 | AE5: 인터넷 | AF5: 선불 | AG5: 차감점수 음재 | AH5: 인터넷 달성률 | AI5: TV 목표 | AJ5: TV 실적 계 | AK5: 미디어 | AL5: 추단 | AM5: (소상공인) Biz | AN5: 차감점수 GTT무트래픽 | AO5: TV 달성률 | AP5: 약갱 | AQ5: 인+티 | AR5: 추단2 | AS5: Biz2 | AT5: 달성률 Max 120%10 | AU5: 득점11 | AV5: 목표12 | AW5: 실적 계13 | AX5: MIT | AY5: MNP-MIT | AZ5: ITU | BA5: (소상공인) ITB | BB5: 차감점수14 | BC5: 달성률 Max 120%15 | BD5: 득점16 | BE5: 목표17 | BF5: ARPU | BG5: 매출 | BH5: 가입자 | BI5: 달성률 Max 120%18 | BJ5: 득점19 | BK5: 목표20 | BL5: 실적 계21 | BM5: 하이오더 | BN5: AI로봇 | BO5: GiGAeyes | BP5: GiGAeyes 정보제공 | BQ5: AI전화 | BR5: AI링고전화 | BS5: 달성률 Max 120%22 | BT5: 득점23 | BU5: 목표24 | BV5: 유치율 | BW5: 1G | BX5: 인터넷25 | BY5: 달성률 Max 120%26 | BZ5: 득점27 | CA5: 가동점 목표 | CB5: 가동점 | CC5: 가동점 달성률 | CD5: 중형점 목표 | CE5: 중형점 | CF5: 5건~9건 발생점 | CG5: 10건↑발생점 | CH5: 중형점 달성률 | CI5: 달성률 Max 120%28 | CJ5: 득점29 | CK5: 목표30 | CL5: 실적31 | CM5: 달성률 Max 120%32 | CN5: 득점33 | CO5: 목표32 | CP5: 실적33 | CQ5: 달성률34 | CR5: 득점35 | CS5: R-VOC 점수 | CT5: 3대R-VOC 점수 | CU5: 대외민원 차감점수 | CV5: 득점31 | CW5: 후불 SQM 차감 | CX5: 운영후불 | CY5: 중고 | CZ5: 후불 신규 SQM 차감 | DA5: 운영후불36 | DB5: 중고37 | DC5: MIT 차감 | DD5: SQM_운영 | DE5: SQM_중고 | DF5: 음재 | DG5: 권한남용 | DH5: 유선 차감 | DI5: 음재2 | DJ5: SQM | DK5: 권한남용3 | DL5: GTT 무트래픽
A6: 1분기 | B6: 1. 소매 | E6: 1. 소매 | F6: 1. 소매 | G6: 58.3775 | H6: 20000 | I6: 2000 | J6: 18622.8 | K6: 17997 | L6: 683 | M6: 1036 | N6: 185 | O6: 405 | P6: 0.93114 | Q6: 13.9671 | V6: 3400 | W6: 2244 | X6: 2354 | Z6: 110 | AA6: 0.66 | AB6: 6.6 | AC6: 1800 | AD6: 1379 | AE6: 1636 | AF6: 6 | AG6: 260 | AH6: 0.76611111 | AI6: 2200 | AJ6: 2213 | AK6: 1330 | AL6: 888 | AN6: 5 | AO6: 1.0059091 | AT6: 0.8860101 | AU6: 13.290152 | AV6: 4400 | AW6: 3752 | AX6: 3277 | AY6: 478 | AZ6: 177 | BB6: 180 | BC6: 0.85272727 | BD6: 8.5272727 | BE6: 65000 | BF6: 54209.777 | BG6: 1.0691252e+09 | BH6: 19722 | BI6: 0.83399657 | BJ6: 5.837976 | BK6: 500 | BL6: 230.5 | BM6: 173 | BN6: 0 | BO6: 42 | BP6: 5 | BQ6: 2 | BR6: 0 | BS6: 0.461 | BT6: 2.305 | BU6: 0.5 | BV6: 0.64311815 | BW6: 1056 | BX6: 1642 | BY6: 1 | BZ6: 5 | CP6: 98.525203 | CQ6: 0.95 | CR6: 2.85 | CW6: 405 | CX6: 81 | CY6: 0 | CZ6: 110 | DA6: 22 | DB6: 0 | DC6: 180 | DD6: 9 | DE6: 0 | DF6: 19 | DG6: 4 | DH6: 260 | DI6: 38 | DJ6: 0 | DK6: 7 | DL6: 5
A7: 1분기 | B7: 1. 소매 | C7: 강북본부 | E7: 강북본부 | F7: 강북본부 | G7: 61.888039 | H7: 3420 | I7: 414 | J7: 3260.3 | K7: 3125 | L7: 124 | M7: 199 | N7: 8 | O7: 50 | P7: 0.95330409 | Q7: 14.299561 | V7: 636 | W7: 413 | X7: 423 | Z7: 10 | AA7: 0.64937107 | AB7: 6.4937107 | AC7: 287 | AD7: 259.5 | AE7: 258 | AF7: 3 | AG7: 0 | AH7: 0.90418118 | AI7: 326 | AJ7: 311.5 | AK7: 188 | AL7: 126 | AN7: 2.5 | AO7: 0.95552147 | AT7: 0.92985133 | AU7: 13.94777 | AV7: 729 | AW7: 645 | AX7: 520 | AY7: 92 | AZ7: 38 | BB7: 5 | BC7: 0.88477366 | BD7: 8.8477366 | BE7: 65000 | BF7: 56434.033 | BG7: 1.9481028e+08 | BH7: 3452 | BI7: 0.8682159 | BJ7: 6.0775113 | BK7: 97 | BL7: 25.8 | BM7: 19 | BN7: 0 | BO7: 3 | BP7: 5 | BQ7: 0 | BR7: 0 | BS7: 0.26597938 | BT7: 1.3298969 | BU7: 0.5 | BV7: 0.63984674 | BW7: 167 | BX7: 261 | BY7: 1 | BZ7: 5 | CP7: 98.416571 | CQ7: 0.95 | CR7: 2.85 | CS7: 1.9418519 | CT7: 1.2 | CU7: -0.1 | CV7: 3.0418519 | CW7: 50 | CX7: 10 | CY7: 0 | CZ7: 10 | DA7: 2 | DB7: 0 | DC7: 5 | DD7: 1 | DE7: 0 | DF7: 0 | DG7: 0 | DH7: 0 | DI7: 0 | DJ7: 0 | DK7: 0 | DL7: 2.5
A8: 1분기 | B8: 1. 소매 | C8: 강남본부 | E8: 강남본부 | F8: 강남본부 | G8: 62.384392 | H8: 3464 | I8: 457 | J8: 3155.6 | K8: 3046 | L8: 119 | M8: 232 | N8: 30 | O8: 85 | P8: 0.91096998 | Q8: 13.66455 | V8: 620 | W8: 337 | X8: 357 | Z8: 20 | AA8: 0.54354839 | AB8: 5.4354839 | AC8: 321 | AD8: 264 | AE8: 314 | AF8: 0 | AG8: 50 | AH8: 0.82242991 | AI8: 375 | AJ8: 415 | AK8: 257 | AL8: 158 | AN8: 0 | AO8: 1.1066667 | AT8: 0.96454829 | AU8: 14.468224 | AV8: 725 | AW8: 602 | AX8: 554 | AY8: 65 | AZ8: 18 | BB8: 35 | BC8: 0.83034483 | BD8: 8.3034483 | BE8: 65000 | BF8: 52494.212 | BG8: 1.7832284e+08 | BH8: 3397 | BI8: 0.80760326 | BJ8: 5.6532228 | BK8: 84 | BL8: 62.6 | BM8: 48 | BN8: 0 | BO8: 10 | BP8: 0 | BQ8: 0 | BR8: 0 | BS8: 0.7452381 | BT8: 3.7261905 | BU8: 0.5 | BV8: 0.67197452 | BW8: 211 | BX8: 314 | BY8: 1 | BZ8: 5 | CP8: 98.606786 | CQ8: 0.95 | CR8: 2.85 | CS8: 2.3832727 | CT8: 1.2 | CU8: -0.3 | CV8: 3.2832727 | CW8: 85 | CX8: 17 | CY8: 0 | CZ8: 20 | DA8: 4 | DB8: 0 | DC8: 35 | DD8: 1 | DE8: 0 | DF8: 2 | DG8: 2 | DH8: 50 | DI8: 4 | DJ8: 0 | DK8: 3 | DL8: 0
A9: 1분기 | B9: 1. 소매 | C9: 강서본부 | E9: 강서본부 | F9: 강서본부 | G9: 62.875429 | H9: 4374 | I9: 434 | J9: 3933.7 | K9: 3868 | L9: 103 | M9: 205 | N9: 6 | O9: 100 | P9: 0.89933699 | Q9: 13.490055 | V9: 751 | W9: 438 | X9: 463 | Z9: 25 | AA9: 0.58322237 | AB9: 5.8322237 | AC9: 424 | AD9: 328.5 | AE9: 398 | AF9: 1 | AG9: 70 | AH9: 0.77476415 | AI9: 523 | AJ9: 553 | AK9: 329 | AL9: 224 | AN9: 0 | AO9: 1.0573614 | AT9: 0.91606276 | AU9: 13.740941 | AV9: 965 | AW9: 814 | AX9: 742 | AY9: 106 | AZ9: 21 | BB9: 55 | BC9: 0.84352332 | BD9: 8.4352332 | BE9: 65000 | BF9: 54909.577 | BG9: 2.2930239e+08 | BH9: 4176 | BI9: 0.84476272 | BJ9: 5.913339 | BK9: 99 | BL9: 17.1 | BM9: 8 | BN9: 0 | BO9: 15 | BP9: 0 | BQ9: 0 | BR9: 0 | BS9: 0.17272727 | BT9: 0.86363636 | BU9: 0.5 | BV9: 0.69172932 | BW9: 276 | BX9: 399 | BY9: 1 | BZ9: 5 | CP9: 99.160241 | CQ9: 1.2 | CR9: 3.6 | CS9: 4.8 | CT9: 1.2 | CU9: 0 | CV9: 6 | CW9: 100 | CX9: 20 | CY9: 0 | CZ9: 25 | DA9: 5 | DB9: 0 | DC9: 55 | DD9: 4 | DE9: 0 | DF9: 7 | DG9: 0 | DH9: 70 | DI9: 14 | DJ9: 0 | DK9: 0 | DL9: 0
A10: 1분기 | B10: 1. 소매 | C10: 동부본부 | E10: 동부본부 | F10: 동부본부 | G10: 63.803702 | H10: 4903 | I10: 361 | J10: 4426.5 | K10: 4245 | L10: 232 | M10: 279 | N10: 29 | O10: 140 | P10: 0.9028146 | Q10: 13.542219 | V10: 764 | W10: 622 | X10: 667 | Z10: 45 | AA10: 0.81413613 | AB10: 8.1413613 | AC10: 462 | AD10: 293.5 | AE10: 393 | AF10: 1 | AG10: 100 | AH10: 0.63528139 | AI10: 600 | AJ10: 540 | AK10: 348 | AL10: 192 | AN10: 0 | AO10: 0.9 | AT10: 0.76764069 | AU10: 11.51461 | AV10: 1119 | AW10: 953 | AX10: 829 | AY10: 124 | AZ10: 60 | BB10: 60 | BC10: 0.85165326 | BD10: 8.5165326 | BE10: 65000 | BF10: 53722.265 | BG10: 2.5555681e+08 | BH10: 4757 | BI10: 0.82649638 | BJ10: 5.7854747 | BK10: 114 | BL10: 95.6 | BM10: 77 | BN10: 0 | BO10: 6 | BP10: 0 | BQ10: 1 | BR10: 0 | BS10: 0.83859649 | BT10: 4.1929825 | BU10: 0.5 | BV10: 0.61167513 | BW10: 241 | BX10: 394 | BY10: 1 | BZ10: 5 | CP10: 98.152778 | CQ10: 0.9 | CR10: 2.7 | CS10: 3.3105217 | CT10: 1.2 | CU10: -0.1 | CV10: 4.4105217 | CW10: 140 | CX10: 28 | CY10: 0 | CZ10: 45 | DA10: 9 | DB10: 0 | DC10: 60 | DD10: 2 | DE10: 0 | DF10: 8 | DG10: 1 | DH10: 100 | DI10: 16 | DJ10: 0 | DK10: 2 | DL10: 0
A11: 1분기 | B11: 1. 소매 | C11: 서부본부 | E11: 서부본부 | F11: 서부본부 | G11: 63.167013 | H11: 3839 | I11: 334 | J11: 3846.7 | K11: 3713 | L11: 105 | M11: 121 | N11: 112 | O11: 30 | P11: 1.0020057 | Q11: 15.030086 | V11: 629 | W11: 434 | X11: 444 | Z11: 10 | AA11: 0.6899841 | AB11: 6.899841 | AC11: 306 | AD11: 233.5 | AE11: 273 | AF11: 1 | AG11: 40 | AH11: 0.7630719 | AI11: 376 | AJ11: 393.5 | AK11: 208 | AL11: 188 | AN11: 2.5 | AO11: 1.0465426 | AT11: 0.90480722 | AU11: 13.572108 | AV11: 862 | AW11: 738 | AX11: 632 | AY11: 91 | AZ11: 40 | BB11: 25 | BC11: 0.85614849 | BD11: 8.5614849 | BE11: 65000 | BF11: 53587.028 | BG11: 2.1113289e+08 | BH11: 3940 | BI11: 0.82441582 | BJ11: 5.7709108 | BK11: 106 | BL11: 29.4 | BM11: 21 | BN11: 0 | BO11: 8 | BP11: 0 | BQ11: 1 | BR11: 0 | BS11: 0.27735849 | BT11: 1.3867925 | BU11: 0.5 | BV11: 0.58759124 | BW11: 161 | BX11: 274 | BY11: 1 | BZ11: 5 | CP11: 98.269341 | CQ11: 0.9 | CR11: 2.7 | CS11: 3.0457895 | CT11: 1.2 | CU11: 0 | CV11: 4.2457895 | CW11: 30 | CX11: 6 | CY11: 0 | CZ11: 10 | DA11: 2 | DB11: 0 | DC11: 25 | DD11: 1 | DE11: 0 | DF11: 2 | DG11: 1 | DH11: 40 | DI11: 4 | DJ11: 0 | DK11: 2 | DL11: 2.5
A12: 1분기 | B12: 1. 소매 | C12: 강북 | D12: 강북소매 | E12: 강북소매 | F12: 강북소매 | G12: 61.145539 | H12: 1699 | I12: 239 | J12: 1629.3 | K12: 1542 | L12: 80 | M12: 105 | N12: 4 | O12: 25 | P12: 0.95897587 | Q12: 14.384638 | V12: 323 | W12: 214 | X12: 224 | Z12: 10 | AA12: 0.6625387 | AB12: 6.625387 | AC12: 144 | AD12: 129.5 | AE12: 128 | AF12: 3 | AG12: 0 | AH12: 0.89930556 | AI12: 148 | AJ12: 153 | AK12: 89 | AL12: 64 | AN12: 0 | AO12: 1.0337838 | AT12: 0.96654467 | AU12: 14.49817 | AV12: 351 | AW12: 326 | AX12: 250 | AY12: 46 | AZ12: 30 | BB12: 0 | BC12: 0.92877493 | BD12: 9.2877493 | BE12: 65000 | BF12: 55959.596 | BG12: 96866061 | BH12: 1731 | BI12: 0.86091686 | BJ12: 6.0264181 | BK12: 46 | BL12: 0 | BM12: 0 | BN12: 0 | BO12: 0 | BP12: 0 | BQ12: 0 | BR12: 0 | BS12: 0 | BT12: 0 | BU12: 0.5 | BV12: 0.66412214 | BW12: 87 | BX12: 131 | BY12: 1 | BZ12: 5 | CP12: 98.09116 | CQ12: 0.9 | CR12: 2.7 | CS12: 1.5231765 | CT12: 1.2 | CU12: -0.1 | CV12: 2.6231765 | CW12: 25 | CX12: 5 | CY12: 0 | CZ12: 10 | DA12: 2 | DB12: 0 | DC12: 0 | DD12: 0 | DE12: 0 | DF12: 0 | DG12: 0 | DH12: 0 | DI12: 0 | DJ12: 0 | DK12: 0 | DL12: 0
A13: 1분기 | B13: 1. 소매 | C13: 강북 | D13: 강동소매 | E13: 강동소매 | F13: 강동소매 | G13: 62.40813 | H13: 1721 | I13: 175 | J13: 1631 | K13: 1583 | L13: 44 | M13: 94 | N13: 4 | O13: 25 | P13: 0.94770482 | Q13: 14.215572 | V13: 313 | W13: 199 | X13: 199 | Z13: 0 | AA13: 0.63578275 | AB13: 6.3578275 | AC13: 143 | AD13: 130 | AE13: 130 | AF13: 0 | AG13: 0 | AH13: 0.90909091 | AI13: 178 | AJ13: 158.5 | AK13: 99 | AL13: 62 | AN13: 2.5 | AO13: 0.89044944 | AT13: 0.89977017 | AU13: 13.496553 | AV13: 378 | AW13: 319 | AX13: 270 | AY13: 46 | AZ13: 8 | BB13: 5 | BC13: 0.84391534 | BD13: 8.4391534 | BE13: 65000 | BF13: 56911.227 | BG13: 97944222 | BH13: 1721 | BI13: 0.87555734 | BJ13: 6.1289014 | BK13: 51 | BL13: 25.8 | BM13: 19 | BN13: 0 | BO13: 3 | BP13: 5 | BQ13: 0 | BR13: 0 | BS13: 0.50588235 | BT13: 2.5294118 | BU13: 0.5 | BV13: 0.61538462 | BW13: 80 | BX13: 130 | BY13: 1 | BZ13: 5 | CP13: 98.648915 | CQ13: 0.95 | CR13: 2.85 | CS13: 2.6536 | CT13: 0.73711111 | CU13: 0 | CV13: 3.3907111 | CW13: 25 | CX13: 5 | CY13: 0 | CZ13: 0 | DA13: 0 | DB13: 0 | DC13: 5 | DD13: 1 | DE13: 0 | DF13: 0 | DG13: 0 | DH13: 0 | DI13: 0 | DJ13: 0 | DK13: 0 | DL13: 2.5
A14: 1분기 | B14: 1. 소매 | C14: 강남 | D14: 강남소매 | E14: 강남소매 | F14: 강남소매 | G14: 55.862007 | H14: 1573 | I14: 259 | J14: 1329.6 | K14: 1287 | L14: 62 | M14: 152 | N14: 25 | O14: 70 | P14: 0.84526383 | Q14: 12.678957 | V14: 287 | W14: 142 | X14: 157 | Z14: 15 | AA14: 0.49477352 | AB14: 4.9477352 | AC14: 139 | AD14: 75 | AE14: 125 | AF14: 0 | AG14: 50 | AH14: 0.53956835 | AI14: 158 | AJ14: 173 | AK14: 100 | AL14: 73 | AN14: 0 | AO14: 1.0949367 | AT14: 0.81725253 | AU14: 12.258788 | AV14: 313 | AW14: 227 | AX14: 231 | AY14: 23 | AZ14: 8 | BB14: 35 | BC14: 0.72523962 | BD14: 7.2523962 | BE14: 65000 | BF14: 51600.798 | BG14: 77452798 | BH14: 1501 | BI14: 0.79385843 | BJ14: 5.557009 | BK14: 34 | BL14: 20.2 | BM14: 16 | BN14: 0 | BO14: 2 | BP14: 0 | BQ14: 0 | BR14: 0 | BS14: 0.59411765 | BT14: 2.9705882 | BU14: 0.5 | BV14: 0.664 | BW14: 83 | BX14: 125 | BY14: 1 | BZ14: 5 | CP14: 98.361538 | CQ14: 0.9 | CR14: 2.7 | CS14: 1.5965333 | CT14: 1.2 | CU14: -0.3 | CV14: 2.4965333 | CW14: 70 | CX14: 14 | CY14: 0 | CZ14: 15 | DA14: 3 | DB14: 0 | DC14: 35 | DD14: 1 | DE14: 0 | DF14: 2 | DG14: 2 | DH14: 50 | DI14: 4 | DJ14: 0 | DK14: 3 | DL14: 0
A15: 1분기 | B15: 1. 소매 | C15: 강남 | D15: 남부소매 | E15: 남부소매 | F15: 남부소매 | G15: 68.833249 | H15: 1891 | I15: 198 | J15: 1826 | K15: 1759 | L15: 57 | M15: 80 | N15: 5 | O15: 15 | P15: 0.96562665 | Q15: 14.4844 | V15: 333 | W15: 195 | X15: 200 | Z15: 5 | AA15: 0.58558559 | AB15: 5.8558559 | AC15: 182 | AD15: 189 | AE15: 189 | AF15: 0 | AG15: 0 | AH15: 1.0384615 | AI15: 217 | AJ15: 242 | AK15: 157 | AL15: 85 | AN15: 0 | AO15: 1.1152074 | AT15: 1.0768345 | AU15: 16.152517 | AV15: 412 | AW15: 375 | AX15: 323 | AY15: 42 | AZ15: 10 | BB15: 0 | BC15: 0.91019417 | BD15: 9.1019417 | BE15: 65000 | BF15: 53201.498 | BG15: 1.0087004e+08 | BH15: 1896 | BI15: 0.81848459 | BJ15: 5.7293921 | BK15: 50 | BL15: 42.4 | BM15: 32 | BN15: 0 | BO15: 8 | BP15: 0 | BQ15: 0 | BR15: 0 | BS15: 0.848 | BT15: 4.24 | BU15: 0.5 | BV15: 0.67724868 | BW15: 128 | BX15: 189 | BY15: 1 | BZ15: 5 | CP15: 98.871369 | CQ15: 1 | CR15: 3 | CS15: 4.0691429 | CT15: 1.2 | CU15: 0 | CV15: 5.2691429 | CW15: 15 | CX15: 3 | CY15: 0 | CZ15: 5 | DA15: 1 | DB15: 0 | DC15: 0 | DD15: 0 | DE15: 0 | DF15: 0 | DG15: 0 | DH15: 0 | DI15: 0 | DJ15: 0 | DK15: 0 | DL15: 0
A16: 1분기 | B16: 1. 소매 | C16: 강서 | D16: 강서소매 | E16: 강서소매 | F16: 강서소매 | G16: 60.694787 | H16: 2666 | I16: 285 | J16: 2350.6 | K16: 2285 | L16: 57 | M16: 142 | N16: 5 | O16: 35 | P16: 0.88169542 | Q16: 13.225431 | V16: 476 | W16: 260 | X16: 275 | Z16: 15 | AA16: 0.54621849 | AB16: 5.4621849 | AC16: 249 | AD16: 168 | AE16: 218 | AF16: 0 | AG16: 50 | AH16: 0.6746988 | AI16: 305 | AJ16: 333 | AK16: 171 | AL16: 162 | AN16: 0 | AO16: 1.0918033 | AT16: 0.88325104 | AU16: 13.248766 | AV16: 581 | AW16: 446 | AX16: 396 | AY16: 66 | AZ16: 9 | BB16: 25 | BC16: 0.767642 | BD16: 7.67642 | BE16: 65000 | BF16: 54287.922 | BG16: 1.348512e+08 | BH16: 2484 | BI16: 0.83519879 | BJ16: 5.8463916 | BK16: 59 | BL16: 7.5 | BM16: 0 | BN16: 0 | BO16: 15 | BP16: 0 | BQ16: 0 | BR16: 0 | BS16: 0.12711864 | BT16: 0.63559322 | BU16: 0.5 | BV16: 0.63761468 | BW16: 139 | BX16: 218 | BY16: 1 | BZ16: 5 | CP16: 99.374322 | CQ16: 1.2 | CR16: 3.6 | CS16: 4.8 | CT16: 1.2 | CU16: 0 | CV16: 6 | CW16: 35 | CX16: 7 | CY16: 0 | CZ16: 15 | DA16: 3 | DB16: 0 | DC16: 25 | DD16: 0 | DE16: 0 | DF16: 5 | DG16: 0 | DH16: 50 | DI16: 10 | DJ16: 0 | DK16: 0 | DL16: 0
A17: 1분기 | B17: 1. 소매 | C17: 강서 | D17: 인천소매 | E17: 인천소매 | F17: 인천소매 | G17: 65.468166 | H17: 1708 | I17: 149 | J17: 1583.1 | K17: 1583 | L17: 46 | M17: 63 | N17: 1 | O17: 65 | P17: 0.92687354 | Q17: 13.903103 | V17: 275 | W17: 178 | X17: 188 | Z17: 10 | AA17: 0.64727273 | AB17: 6.4727273 | AC17: 175 | AD17: 160.5 | AE17: 180 | AF17: 1 | AG17: 20 | AH17: 0.91714286 | AI17: 218 | AJ17: 220 | AK17: 158 | AL17: 62 | AN17: 0 | AO17: 1.0091743 | AT17: 0.96315858 | AU17: 14.447379 | AV17: 384 | AW17: 368 | AX17: 346 | AY17: 40 | AZ17: 12 | BB17: 30 | BC17: 0.95833333 | BD17: 9.5833333 | BE17: 65000 | BF17: 55822.219 | BG17: 94451195 | BH17: 1692 | BI17: 0.85880337 | BJ17: 6.0116236 | BK17: 40 | BL17: 9.6 | BM17: 8 | BN17: 0 | BO17: 0 | BP17: 0 | BQ17: 0 | BR17: 0 | BS17: 0.24 | BT17: 1.2 | BU17: 0.5 | BV17: 0.75690608 | BW17: 137 | BX17: 181 | BY17: 1 | BZ17: 5 | CP17: 98.732852 | CQ17: 0.95 | CR17: 2.85 | CS17: 4.8 | CT17: 1.2 | CU17: 0 | CV17: 6 | CW17: 65 | CX17: 13 | CY17: 0 | CZ17: 10 | DA17: 2 | DB17: 0 | DC17: 30 | DD17: 4 | DE17: 0 | DF17: 2 | DG17: 0 | DH17: 20 | DI17: 4 | DJ17: 0 | DK17: 0 | DL17: 0
A18: 1분기 | B18: 1. 소매 | C18: 동부 | D18: 부산소매 | E18: 부산소매 | F18: 부산소매 | G18: 65.29687 | H18: 2567 | I18: 208 | J18: 2228.8 | K18: 2145 | L18: 99 | M18: 130 | N18: 4 | O18: 55 | P18: 0.86825088 | Q18: 13.023763 | V18: 419 | W18: 289 | X18: 309 | Z18: 20 | AA18: 0.68973747 | AB18: 6.8973747 | AC18: 262 | AD18: 147.5 | AE18: 197 | AF18: 1 | AG18: 50 | AH18: 0.5629771 | AI18: 363 | AJ18: 297 | AK18: 178 | AL18: 119 | AN18: 0 | AO18: 0.81818182 | AT18: 0.69057946 | AU18: 10.358692 | AV18: 581 | AW18: 544 | AX18: 481 | AY18: 68 | AZ18: 30 | BB18: 35 | BC18: 0.9363167 | BD18: 9.363167 | BE18: 65000 | BF18: 56854.224 | BG18: 1.3502878e+08 | BH18: 2375 | BI18: 0.87468037 | BJ18: 6.1227626 | BK18: 56 | BL18: 92.6 | BM18: 77 | BN18: 0 | BO18: 0 | BP18: 0 | BQ18: 1 | BR18: 0 | BS18: 1.2 | BT18: 6 | BU18: 0.5 | BV18: 0.61111111 | BW18: 121 | BX18: 198 | BY18: 1 | BZ18: 5 | CP18: 98.407895 | CQ18: 0.95 | CR18: 2.85 | CS18: 4.5448889 | CT18: 1.1362222 | CU18: 0 | CV18: 5.6811111 | CW18: 55 | CX18: 11 | CY18: 0 | CZ18: 20 | DA18: 4 | DB18: 0 | DC18: 35 | DD18: 2 | DE18: 0 | DF18: 3 | DG18: 1 | DH18: 50 | DI18: 6 | DJ18: 0 | DK18: 2 | DL18: 0
A19: 1분기 | B19: 1. 소매 | C19: 동부 | D19: 대구소매 | E19: 대구소매 | F19: 대구소매 | G19: 61.247415 | H19: 2336 | I19: 153 | J19: 2173 | K19: 2100 | L19: 133 | M19: 149 | N19: 25 | O19: 85 | P19: 0.9302226 | Q19: 13.953339 | V19: 345 | W19: 333 | X19: 358 | Z19: 25 | AA19: 0.96521739 | AB19: 9.6521739 | AC19: 200 | AD19: 146 | AE19: 196 | AF19: 0 | AG19: 50 | AH19: 0.73 | AI19: 237 | AJ19: 243 | AK19: 170 | AL19: 73 | AN19: 0 | AO19: 1.0253165 | AT19: 0.87765823 | AU19: 13.164873 | AV19: 538 | AW19: 409 | AX19: 348 | AY19: 56 | AZ19: 30 | BB19: 25 | BC19: 0.76022305 | BD19: 7.6022305 | BE19: 65000 | BF19: 50599.509 | BG19: 1.2052803e+08 | BH19: 2382 | BI19: 0.77845399 | BJ19: 5.4491779 | BK19: 58 | BL19: 3 | BM19: 0 | BN19: 0 | BO19: 6 | BP19: 0 | BQ19: 0 | BR19: 0 | BS19: 0.051724138 | BT19: 0.25862069 | BU19: 0.5 | BV19: 0.6122449 | BW19: 120 | BX19: 196 | BY19: 1 | BZ19: 5 | CP19: 97.806548 | CQ19: 0.85 | CR19: 2.55 | CS19: 2.517 | CT19: 1.2 | CU19: -0.1 | CV19: 3.617 | CW19: 85 | CX19: 17 | CY19: 0 | CZ19: 25 | DA19: 5 | DB19: 0 | DC19: 25 | DD19: 0 | DE19: 0 | DF19: 5 | DG19: 0 | DH19: 50 | DI19: 10 | DJ19: 0 | DK19: 0 | DL19: 0
A20: 1분기 | B20: 1. 소매 | C20: 서부 | D20: 충청소매 | E20: 충청소매 | F20: 충청소매 | G20: 60.352048 | H20: 1950 | I20: 191 | J20: 1837.1 | K20: 1770 | L20: 59 | M20: 55 | N20: 108 | O20: 30 | P20: 0.94210256 | Q20: 14.131538 | V20: 325 | W20: 199 | X20: 209 | Z20: 10 | AA20: 0.61230769 | AB20: 6.1230769 | AC20: 166 | AD20: 133.5 | AE20: 133 | AF20: 1 | AG20: 0 | AH20: 0.80421687 | AI20: 199 | AJ20: 215 | AK20: 90 | AL20: 125 | AN20: 0 | AO20: 1.080402 | AT20: 0.94230944 | AU20: 14.134642 | AV20: 431 | AW20: 368 | AX20: 314 | AY20: 38 | AZ20: 21 | BB20: 5 | BC20: 0.85382831 | BD20: 8.5382831 | BE20: 65000 | BF20: 54570.229 | BG20: 1.0286488e+08 | BH20: 1885 | BI20: 0.83954199 | BJ20: 5.8767939 | BK20: 53 | BL20: 2.2 | BM20: 0 | BN20: 0 | BO20: 4 | BP20: 0 | BQ20: 1 | BR20: 0 | BS20: 0.041509434 | BT20: 0.20754717 | BU20: 0.5 | BV20: 0.62686567 | BW20: 84 | BX20: 134 | BY20: 1 | BZ20: 5 | CP20: 98.068966 | CQ20: 0.9 | CR20: 2.7 | CS20: 2.4401667 | CT20: 1.2 | CU20: 0 | CV20: 3.6401667 | CW20: 30 | CX20: 6 | CY20: 0 | CZ20: 10 | DA20: 2 | DB20: 0 | DC20: 5 | DD20: 1 | DE20: 0 | DF20: 0 | DG20: 0 | DH20: 0 | DI20: 0 | DJ20: 0 | DK20: 0 | DL20: 0
A21: 1분기 | B21: 1. 소매 | C21: 서부 | D21: 호남소매 | E21: 호남소매 | F21: 호남소매 | G21: 66.567126 | H21: 1889 | I21: 143 | J21: 2009.6 | K21: 1943 | L21: 46 | M21: 66 | N21: 4 | O21: 0 | P21: 1.0638433 | Q21: 15.95765 | V21: 304 | W21: 235 | X21: 235 | Z21: 0 | AA21: 0.77302632 | AB21: 7.7302632 | AC21: 140 | AD21: 100 | AE21: 140 | AF21: 0 | AG21: 40 | AH21: 0.71428571 | AI21: 177 | AJ21: 178.5 | AK21: 118 | AL21: 63 | AN21: 2.5 | AO21: 1.0084746 | AT21: 0.86138015 | AU21: 12.920702 | AV21: 431 | AW21: 370 | AX21: 318 | AY21: 53 | AZ21: 19 | BB21: 20 | BC21: 0.85846868 | BD21: 8.5846868 | BE21: 65000 | BF21: 52685.163 | BG21: 1.0826801e+08 | BH21: 2055 | BI21: 0.81054097 | BJ21: 5.6737868 | BK21: 53 | BL21: 27.2 | BM21: 21 | BN21: 0 | BO21: 4 | BP21: 0 | BQ21: 0 | BR21: 0 | BS21: 0.51320755 | BT21: 2.5660377 | BU21: 0.5 | BV21: 0.55 | BW21: 77 | BX21: 140 | BY21: 1 | BZ21: 5 | CP21: 98.504673 | CQ21: 0.95 | CR21: 2.85 | CS21: 4.084 | CT21: 1.2 | CU21: 0 | CV21: 5.284 | CW21: 0 | CX21: 0 | CY21: 0 | CZ21: 0 | DA21: 0 | DB21: 0 | DC21: 20 | DD21: 0 | DE21: 0 | DF21: 2 | DG21: 1 | DH21: 40 | DI21: 4 | DJ21: 0 | DK21: 2 | DL21: 2.5
A22: 1분기 | B22: 1. 소매 | C22: 강북 | D22: 강북소매 | E22: YC00225 | F22: 금릉역 | G22: 62.952905 | H22: 75 | I22: 11 | J22: 75 | K22: 73 | L22: 2 | M22: 0 | N22: 0 | O22: 0 | P22: 1 | Q22: 15 | V22: 14 | W22: 7 | X22: 7 | Z22: 0 | AA22: 0.5 | AB22: 5 | AC22: 6 | AD22: 9 | AE22: 9 | AF22: 0 | AG22: 0 | AH22: 1.2 | AI22: 7 | AJ22: 10 | AK22: 7 | AL22: 3 | AN22: 0 | AO22: 1.2 | AT22: 1.2 | AU22: 18 | AV22: 17 | AW22: 20 | AX22: 18 | AY22: 2 | AZ22: 0 | BB22: 0 | BC22: 1.1764706 | BD22: 11.764706 | BE22: 65000 | BF22: 53747.564 | BG22: 4031067.3 | BH22: 75 | BI22: 0.82688561 | BJ22: 5.7881992 | BL22: 0 | BM22: 0 | BN22: 0 | BO22: 0 | BP22: 0 | BQ22: 0 | BR22: 0 | BU22: 0.5 | BV22: 0.77777778 | BW22: 7 | BX22: 9 | BY22: 1 | BZ22: 5 | CP22: 97.75 | CQ22: 0.8 | CR22: 2.4 | CW22: 0 | CX22: 0 | CY22: 0 | CZ22: 0 | DA22: 0 | DB22: 0 | DC22: 0 | DD22: 0 | DE22: 0 | DF22: 0 | DG22: 0 | DH22: 0 | DI22: 0 | DJ22: 0 | DK22: 0 | DL22: 0
