Workbook

Sheet 전사손익계산서
A1: 계정명 | B1: '26년 1월
A2: 계정명
A3: 손 익 | B3: 3668676245
A4: 매 출 | B4: 77664176704
A5: 상 품 매 출 | B5: 50833630897
A6: 상품단말기매출-고객 | B6: 10693050386
A7: 상품단말기매출-판매점 | B7: 0
A8: 상품매출액-채권승계 | B8: 39406992745
A9: 상품매출액-신용카드매출 | B9: 293879884
A10: 상품매출액-부분납 | B10: 24581363
A11: 상품매출액-보험매출 | B11: 391557882
A12: 상품매출-기타 | B12: 23568637
A13: 수수료수입 | B13: 26830545807
A14: 수수료수입-KT(RDS) | B14: 15644099457
... A223: 희석주당순이익 | B223: 0

Sheet 종합
A1: 계정명 | B1: 합계 | C1: 전사 공통비 (경총) | D1: 채널공통비 (영총/영기/역강 등) | E1: 채널별 소계 | F1: 유통영업혁신단 | I1: 법인영업혁신단 | M1: 유통플랫폼 | Q1: 디지털강화 | U1: 유통플랫폼사업단
F2: 소매 | G2: 도매 | H2: 디지털 | I2: 기업/공공 | J2: IoT | K2: 법인영업 | L2: 소상공인 | Q2: 디지털(KT샵) | R2: 디지털(기타) | U2: 코코넛 | V2: 굿바이 | W2: 시연폰 | X2: AS대행 | Y2: 임대폰대행 | Z2: 리본(모바일/신촌)
A3: 매 출 | B3: =IFERROR(VLOOKUP($A3,전사손익계산서!$A:$B,2,0),0) -> 77664176704 | C3: =B3-E3-D3 -> -225340228 | D3: =IFERROR(VLOOKUP($A3,영업총괄!$A:$K,11,FALSE),0) -> 100018182 | E3: =SUM(F3:M3) -> 77789498750 | F3: =IFERROR(VLOOKUP($A3,소매!A:B,2,FALSE),0) -> 2.2953776e+10 | G3: =IFERROR(VLOOKUP($A3,도매!A:B,2,FALSE),0) -> 1.1088705e+10 | H3: =Q3+R3 -> 34659578597 | I3: =IFERROR(VLOOKUP($A3,법인영업팀!A:E,4,FALSE),0) -> 1436658674 | J3: =IFERROR(VLOOKUP($A3,법인영업팀!A:E,5,FALSE),0) -> 299991118 | K3: =IFERROR(VLOOKUP($A3,법인영업팀!$A:$E,3,FALSE),0) -> 4759402223 | L3: =IFERROR(VLOOKUP($A3,소상공인혁신팀!$A:$B,2,FALSE),0) -> 1118044701 | M3: =IFERROR(VLOOKUP($A3,'유통플랫폼사업단 IU'!$A:$F,2,FALSE),0) -> 1473342327 | O3: =B3=C3+D3+E3 -> TRUE | Q3: =IFERROR(VLOOKUP($A3,디지털강화팀!A:C,3,FALSE),0) -> 34125154074 | R3: =IFERROR(VLOOKUP($A3,디지털강화팀!A:D,4,FALSE),0) -> 534424523 | S3: =Q3+R3=H3 -> TRUE | U3: =IFERROR(VLOOKUP($A3,플랫폼1!$A:$B,2,FALSE),0) -> 262263119 | V3: =IFERROR(VLOOKUP($A3,플랫폼2!$A:$M,12,FALSE),0)+IFERROR(VLOOKUP($A3,플랫폼2!$A:$M,13,FALSE),0) -> 3.2603682e+08 | W3: =IFERROR(VLOOKUP($A3,플랫폼2!$A:$M,7,FALSE),0)+IFERROR(VLOOKUP($A3,플랫폼2!$A:$M,12,FALSE),0) -> 6.6673621e+08 | X3: =IFERROR(VLOOKUP($A3,모바일!$A:$F,5,FALSE),0) -> 30400000 | Y3: =IFERROR(VLOOKUP($A3,모바일!$A:$F,6,FALSE),0) -> 24800000 | Z3: =IFERROR(VLOOKUP(A3,플랫폼2!$A:$O,15,0),0) -> 163106182 | AA3: =M3=SUM(U3:Z3) -> TRUE
A4: 상 품 매 출 | B4: =IFERROR(VLOOKUP($A4,전사손익계산서!$A:$B,2,0),0) -> 50833630897 | C4: =B4-E4-D4 -> 107251289 | D4: =IFERROR(VLOOKUP($A4,영업총괄!$A:$K,11,FALSE),0) -> 0 | E4: =SUM(F4:M4) -> 50726379608 | F4: =IFERROR(VLOOKUP($A4,소매!A:B,2,FALSE),0) -> 10842518892 | G4: =IFERROR(VLOOKUP($A4,도매!A:B,2,FALSE),0) -> 7632998534 | H4: =Q4+R4 -> 27891641041 | I4: =IFERROR(VLOOKUP($A4,법인영업팀!A:E,4,FALSE),0) -> 834867543 | J4: =IFERROR(VLOOKUP($A4,법인영업팀!A:E,5,FALSE),0) -> 7203453 | K4: =IFERROR(VLOOKUP($A4,법인영업팀!$A:$E,3,FALSE),0) -> 2357748890 | L4: =IFERROR(VLOOKUP($A4,소상공인혁신팀!$A:$B,2,FALSE),0) -> 83412091 | M4: =IFERROR(VLOOKUP($A4,'유통플랫폼사업단 IU'!$A:$F,2,FALSE),0) -> 1075989164 | O4: =B4=C4+D4+E4 -> TRUE | Q4: =IFERROR(VLOOKUP($A4,디지털강화팀!A:C,3,FALSE),0) -> 27718939517 | R4: =IFERROR(VLOOKUP($A4,디지털강화팀!A:D,4,FALSE),0) -> 172701524 | S4: =Q4+R4=H4 -> TRUE | U4: =IFERROR(VLOOKUP($A4,플랫폼1!$A:$B,2,FALSE),0) -> 11568637 | V4: =IFERROR(VLOOKUP($A4,플랫폼2!$A:$M,12,FALSE),0)+IFERROR(VLOOKUP($A4,플랫폼2!$A:$M,13,FALSE),0) -> 260177272 | W4: =IFERROR(VLOOKUP($A4,플랫폼2!$A:$M,7,FALSE),0)+IFERROR(VLOOKUP($A4,플랫폼2!$A:$M,12,FALSE),0) -> 641137073 | X4: =IFERROR(VLOOKUP($A4,모바일!$A:$F,5,FALSE),0) -> 0 | Y4: =IFERROR(VLOOKUP($A4,모바일!$A:$F,6,FALSE),0) -> 0 | Z4: =IFERROR(VLOOKUP(A4,플랫폼2!$A:$O,15,0),0) -> 163106182 | AA4: =M4=SUM(U4:Z4) -> TRUE
A5: 상품단말기매출-고객 | B5: =IFERROR(VLOOKUP($A5,전사손익계산서!$A:$B,2,0),0) -> 10693050386 | C5: =B5-E5-D5 -> 4782200 | D5: =IFERROR(VLOOKUP($A5,영업총괄!$A:$K,11,FALSE),0) -> 0 | E5: =SUM(F5:M5) -> 10688268186 | F5: =IFERROR(VLOOKUP($A5,소매!A:B,2,FALSE),0) -> 34464139 | G5: =IFERROR(VLOOKUP($A5,도매!A:B,2,FALSE),0) -> 7629060954 | H5: =Q5+R5 -> 1197090208 | I5: =IFERROR(VLOOKUP($A5,법인영업팀!A:E,4,FALSE),0) -> 143409634 | J5: =IFERROR(VLOOKUP($A5,법인영업팀!A:E,5,FALSE),0) -> 5205000 | K5: =IFERROR(VLOOKUP($A5,법인영업팀!$A:$E,3,FALSE),0) -> 639017724 | L5: =IFERROR(VLOOKUP($A5,소상공인혁신팀!$A:$B,2,FALSE),0) -> 0 | M5: =IFERROR(VLOOKUP($A5,'유통플랫폼사업단 IU'!$A:$F,2,FALSE),0) -> 1040020527 | O5: =B5=C5+D5+E5 -> TRUE | Q5: =IFERROR(VLOOKUP($A5,디지털강화팀!A:C,3,FALSE),0) -> 1096085300 | R5: =IFERROR(VLOOKUP($A5,디지털강화팀!A:D,4,FALSE),0) -> 101004908 | S5: =Q5+R5=H5 -> TRUE | U5: =IFERROR(VLOOKUP($A5,플랫폼1!$A:$B,2,FALSE),0) -> 0 | V5: =IFERROR(VLOOKUP($A5,플랫폼2!$A:$M,12,FALSE),0)+IFERROR(VLOOKUP($A5,플랫폼2!$A:$M,13,FALSE),0) -> 260177272 | W5: =IFERROR(VLOOKUP($A5,플랫폼2!$A:$M,7,FALSE),0)+IFERROR(VLOOKUP($A5,플랫폼2!$A:$M,12,FALSE),0) -> 641137073 | X5: =IFERROR(VLOOKUP($A5,모바일!$A:$F,5,FALSE),0) -> 0 | Y5: =IFERROR(VLOOKUP($A5,모바일!$A:$F,6,FALSE),0) -> 0 | Z5: =IFERROR(VLOOKUP(A5,플랫폼2!$A:$O,15,0),0) -> 138706182 | AA5: =M5=SUM(U5:Z5) -> TRUE
A6: 상품단말기매출-판매점 | B6: =IFERROR(VLOOKUP($A6,전사손익계산서!$A:$B,2,0),0) -> 0 | C6: =B6-E6-D6 -> 0 | D6: =IFERROR(VLOOKUP($A6,영업총괄!$A:$K,11,FALSE),0) -> 0 | E6: =SUM(F6:M6) -> 0 | F6: =IFERROR(VLOOKUP($A6,소매!A:B,2,FALSE),0) -> 0 | G6: =IFERROR(VLOOKUP($A6,도매!A:B,2,FALSE),0) -> 0 | H6: =Q6+R6 -> 0 | I6: =IFERROR(VLOOKUP($A6,법인영업팀!A:E,4,FALSE),0) -> 0 | J6: =IFERROR(VLOOKUP($A6,법인영업팀!A:E,5,FALSE),0) -> 0 | K6: =IFERROR(VLOOKUP($A6,법인영업팀!$A:$E,3,FALSE),0) -> 0 | L6: =IFERROR(VLOOKUP($A6,소상공인혁신팀!$A:$B,2,FALSE),0) -> 0 | M6: =IFERROR(VLOOKUP($A6,'유통플랫폼사업단 IU'!$A:$F,2,FALSE),0) -> 0 | O6: =B6=C6+D6+E6 -> TRUE | Q6: =IFERROR(VLOOKUP($A6,디지털강화팀!A:C,3,FALSE),0) -> 0 | R6: =IFERROR(VLOOKUP($A6,디지털강화팀!A:D,4,FALSE),0) -> 0 | S6: =Q6+R6=H6 -> TRUE | U6: =IFERROR(VLOOKUP($A6,플랫폼1!$A:$B,2,FALSE),0) -> 0 | V6: =IFERROR(VLOOKUP($A6,플랫폼2!$A:$M,12,FALSE),0)+IFERROR(VLOOKUP($A6,플랫폼2!$A:$M,13,FALSE),0) -> 0 | W6: =IFERROR(VLOOKUP($A6,플랫폼2!$A:$M,7,FALSE),0)+IFERROR(VLOOKUP($A6,플랫폼2!$A:$M,12,FALSE),0) -> 0 | X6: =IFERROR(VLOOKUP($A6,모바일!$A:$F,5,FALSE),0) -> 0 | Y6: =IFERROR(VLOOKUP($A6,모바일!$A:$F,6,FALSE),0) -> 0 | Z6: =IFERROR(VLOOKUP(A6,플랫폼2!$A:$O,15,0),0) -> 0 | AA6: =M6=SUM(U6:Z6) -> TRUE
A7: 상품매출액-대형유통 | B7: =IFERROR(VLOOKUP($A7,전사손익계산서!$A:$B,2,0),0) -> 0 | C7: =B7-E7-D7 -> 0 | D7: =IFERROR(VLOOKUP($A7,영업총괄!$A:$K,11,FALSE),0) -> 0 | E7: =SUM(F7:M7) -> 0 | F7: =IFERROR(VLOOKUP($A7,소매!A:B,2,FALSE),0) -> 0 | G7: =IFERROR(VLOOKUP($A7,도매!A:B,2,FALSE),0) -> 0 | H7: =Q7+R7 -> 0 | I7: =IFERROR(VLOOKUP($A7,법인영업팀!A:E,4,FALSE),0) -> 0 | J7: =IFERROR(VLOOKUP($A7,법인영업팀!A:E,5,FALSE),0) -> 0 | K7: =IFERROR(VLOOKUP($A7,법인영업팀!$A:$E,3,FALSE),0) -> 0 | L7: =IFERROR(VLOOKUP($A7,소상공인혁신팀!$A:$B,2,FALSE),0) -> 0 | M7: =IFERROR(VLOOKUP($A7,'유통플랫폼사업단 IU'!$A:$F,2,FALSE),0) -> 0 | O7: =B7=C7+D7+E7 -> TRUE | Q7: =IFERROR(VLOOKUP($A7,디지털강화팀!A:C,3,FALSE),0) -> 0 | R7: =IFERROR(VLOOKUP($A7,디지털강화팀!A:D,4,FALSE),0) -> 0 | S7: =Q7+R7=H7 -> TRUE | U7: =IFERROR(VLOOKUP($A7,플랫폼1!$A:$B,2,FALSE),0) -> 0 | V7: =IFERROR(VLOOKUP($A7,플랫폼2!$A:$M,12,FALSE),0)+IFERROR(VLOOKUP($A7,플랫폼2!$A:$M,13,FALSE),0) -> 0 | W7: =IFERROR(VLOOKUP($A7,플랫폼2!$A:$M,7,FALSE),0)+IFERROR(VLOOKUP($A7,플랫폼2!$A:$M,12,FALSE),0) -> 0 | X7: =IFERROR(VLOOKUP($A7,모바일!$A:$F,5,FALSE),0) -> 0 | Y7: =IFERROR(VLOOKUP($A7,모바일!$A:$F,6,FALSE),0) -> 0 | Z7: =IFERROR(VLOOKUP(A7,플랫폼2!$A:$O,15,0),0) -> 0 | AA7: =M7=SUM(U7:Z7) -> TRUE
A8: 상품매출액-채권승계 | B8: =IFERROR(VLOOKUP($A8,전사손익계산서!$A:$B,2,0),0) -> 39406992745 | C8: =B8-E8-D8 -> 96761089 | D8: =IFERROR(VLOOKUP($A8,영업총괄!$A:$K,11,FALSE),0) -> 0 | E8: =SUM(F8:M8) -> 39310231656 | F8: =IFERROR(VLOOKUP($A8,소매!A:B,2,FALSE),0) -> 10221832695 | G8: =IFERROR(VLOOKUP($A8,도매!A:B,2,FALSE),0) -> 3937580 | H8: =Q8+R8 -> 26603513852 | I8: =IFERROR(VLOOKUP($A8,법인영업팀!A:E,4,FALSE),0) -> 679437909 | J8: =IFERROR(VLOOKUP($A8,법인영업팀!A:E,5,FALSE),0) -> 768000 | K8: =IFERROR(VLOOKUP($A8,법인영업팀!$A:$E,3,FALSE),0) -> 1717329529 | L8: =IFERROR(VLOOKUP($A8,소상공인혁신팀!$A:$B,2,FALSE),0) -> 83412091 | M8: =IFERROR(VLOOKUP($A8,'유통플랫폼사업단 IU'!$A:$F,2,FALSE),0) -> 0 | O8: =B8=C8+D8+E8 -> TRUE | Q8: =IFERROR(VLOOKUP($A8,디지털강화팀!A:C,3,FALSE),0) -> 26593919399 | R8: =IFERROR(VLOOKUP($A8,디지털강화팀!A:D,4,FALSE),0) -> 9594453 | S8: =Q8+R8=H8 -> TRUE | U8: =IFERROR(VLOOKUP($A8,플랫폼1!$A:$B,2,FALSE),0) -> 0 | V8: =IFERROR(VLOOKUP($A8,플랫폼2!$A:$M,12,FALSE),0)+IFERROR(VLOOKUP($A8,플랫폼2!$A:$M,13,FALSE),0) -> 0 | W8: =IFERROR(VLOOKUP($A8,플랫폼2!$A:$M,7,FALSE),0)+IFERROR(VLOOKUP($A8,플랫폼2!$A:$M,12,FALSE),0) -> 0 | X8: =IFERROR(VLOOKUP($A8,모바일!$A:$F,5,FALSE),0) -> 0 | Y8: =IFERROR(VLOOKUP($A8,모바일!$A:$F,6,FALSE),0) -> 0 | Z8: =IFERROR(VLOOKUP(A8,플랫폼2!$A:$O,15,0),0) -> 0 | AA8: =M8=SUM(U8:Z8) -> TRUE
A9: 상품매출액-신용카드매출 | B9: =IFERROR(VLOOKUP($A9,전사손익계산서!$A:$B,2,0),0) -> 293879884 | C9: =B9-E9-D9 -> 1712545 | D9: =IFERROR(VLOOKUP($A9,영업총괄!$A:$K,11,FALSE),0) -> 0 | E9: =SUM(F9:M9) -> 292167339 | F9: =IFERROR(VLOOKUP($A9,소매!A:B,2,FALSE),0) -> 260761794 | G9: =IFERROR(VLOOKUP($A9,도매!A:B,2,FALSE),0) -> 0 | H9: =Q9+R9 -> 6571181 | I9: =IFERROR(VLOOKUP($A9,법인영업팀!A:E,4,FALSE),0) -> 20000 | J9: =IFERROR(VLOOKUP($A9,법인영업팀!A:E,5,FALSE),0) -> 0 | K9: =IFERROR(VLOOKUP($A9,법인영업팀!$A:$E,3,FALSE),0) -> 414364 | L9: =IFERROR(VLOOKUP($A9,소상공인혁신팀!$A:$B,2,FALSE),0) -> 0 | M9: =IFERROR(VLOOKUP($A9,'유통플랫폼사업단 IU'!$A:$F,2,FALSE),0) -> 24400000 | O9: =B9=C9+D9+E9 -> TRUE | Q9: =IFERROR(VLOOKUP($A9,디지털강화팀!A:C,3,FALSE),0) -> 6571181 | R9: =IFERROR(VLOOKUP($A9,디지털강화팀!A:D,4,FALSE),0) -> 0 | S9: =Q9+R9=H9 -> TRUE | U9: =IFERROR(VLOOKUP($A9,플랫폼1!$A:$B,2,FALSE),0) -> 0 | V9: =IFERROR(VLOOKUP($A9,플랫폼2!$A:$M,12,FALSE),0)+IFERROR(VLOOKUP($A9,플랫폼2!$A:$M,13,FALSE),0) -> 0 | W9: =IFERROR(VLOOKUP($A9,플랫폼2!$A:$M,7,FALSE),0)+IFERROR(VLOOKUP($A9,플랫폼2!$A:$M,12,FALSE),0) -> 0 | X9: =IFERROR(VLOOKUP($A9,모바일!$A:$F,5,FALSE),0) -> 0 | Y9: =IFERROR(VLOOKUP($A9,모바일!$A:$F,6,FALSE),0) -> 0 | Z9: 24400000 | AA9: =M9=SUM(U9:Z9) -> TRUE
A10: 상품매출액-부분납 | B10: =IFERROR(VLOOKUP($A10,전사손익계산서!$A:$B,2,0),0) -> 24581363 | C10: =B10-E10-D10 -> 0 | D10: =IFERROR(VLOOKUP($A10,영업총괄!$A:$K,11,FALSE),0) -> 0 | E10: =SUM(F10:M10) -> 24581363 | F10: =IFERROR(VLOOKUP($A10,소매!A:B,2,FALSE),0) -> 0 | G10: =IFERROR(VLOOKUP($A10,도매!A:B,2,FALSE),0) -> 0 | H10: =Q10+R10 -> 22363637 | I10: =IFERROR(VLOOKUP($A10,법인영업팀!A:E,4,FALSE),0) -> 0 | J10: =IFERROR(VLOOKUP($A10,법인영업팀!A:E,5,FALSE),0) -> 1230453 | K10: =IFERROR(VLOOKUP($A10,법인영업팀!$A:$E,3,FALSE),0) -> 987273 | L10: =IFERROR(VLOOKUP($A10,소상공인혁신팀!$A:$B,2,FALSE),0) -> 0 | M10: =IFERROR(VLOOKUP($A10,'유통플랫폼사업단 IU'!$A:$F,2,FALSE),0) -> 0 | O10: =B10=C10+D10+E10 -> TRUE | Q10: =IFERROR(VLOOKUP($A10,디지털강화팀!A:C,3,FALSE),0) -> 22363637 | R10: =IFERROR(VLOOKUP($A10,디지털강화팀!A:D,4,FALSE),0) -> 0 | S10: =Q10+R10=H10 -> TRUE | U10: =IFERROR(VLOOKUP($A10,플랫폼1!$A:$B,2,FALSE),0) -> 0 | V10: =IFERROR(VLOOKUP($A10,플랫폼2!$A:$M,12,FALSE),0)+IFERROR(VLOOKUP($A10,플랫폼2!$A:$M,13,FALSE),0) -> 0 | W10: =IFERROR(VLOOKUP($A10,플랫폼2!$A:$M,7,FALSE),0)+IFERROR(VLOOKUP($A10,플랫폼2!$A:$M,12,FALSE),0) -> 0 | X10: =IFERROR(VLOOKUP($A10,모바일!$A:$F,5,FALSE),0) -> 0 | Y10: =IFERROR(VLOOKUP($A10,모바일!$A:$F,6,FALSE),0) -> 0 | Z10: =IFERROR(VLOOKUP(A10,플랫폼2!$A:$O,15,0),0) -> 0 | AA10: =M10=SUM(U10:Z10) -> TRUE
A11: 상품매출액-보험매출 | B11: =IFERROR(VLOOKUP($A11,전사손익계산서!$A:$B,2,0),0) -> 391557882 | C11: =B11-E11-D11 -> 3995455 | D11: =IFERROR(VLOOKUP($A11,영업총괄!$A:$K,11,FALSE),0) -> 0 | E11: =SUM(F11:M11) -> 387562427 | F11: =IFERROR(VLOOKUP($A11,소매!A:B,2,FALSE),0) -> 325460264 | G11: =IFERROR(VLOOKUP($A11,도매!A:B,2,FALSE),0) -> 0 | H11: =Q11+R11 -> 62102163 | I11: =IFERROR(VLOOKUP($A11,법인영업팀!A:E,4,FALSE),0) -> 0 | J11: =IFERROR(VLOOKUP($A11,법인영업팀!A:E,5,FALSE),0) -> 0 | K11: =IFERROR(VLOOKUP($A11,법인영업팀!$A:$E,3,FALSE),0) -> 0 | L11: =IFERROR(VLOOKUP($A11,소상공인혁신팀!$A:$B,2,FALSE),0) -> 0 | M11: =IFERROR(VLOOKUP($A11,'유통플랫폼사업단 IU'!$A:$F,2,FALSE),0) -> 0 | O11: =B11=C11+D11+E11 -> TRUE | Q11: =IFERROR(VLOOKUP($A11,디지털강화팀!A:C,3,FALSE),0) -> 0 | R11: =IFERROR(VLOOKUP($A11,디지털강화팀!A:D,4,FALSE),0) -> 62102163 | S11: =Q11+R11=H11 -> TRUE | U11: =IFERROR(VLOOKUP($A11,플랫폼1!$A:$B,2,FALSE),0) -> 0 | V11: =IFERROR(VLOOKUP($A11,플랫폼2!$A:$M,12,FALSE),0)+IFERROR(VLOOKUP($A11,플랫폼2!$A:$M,13,FALSE),0) -> 0 | W11: =IFERROR(VLOOKUP($A11,플랫폼2!$A:$M,7,FALSE),0)+IFERROR(VLOOKUP($A11,플랫폼2!$A:$M,12,FALSE),0) -> 0 | X11: =IFERROR(VLOOKUP($A11,모바일!$A:$F,5,FALSE),0) -> 0 | Y11: =IFERROR(VLOOKUP($A11,모바일!$A:$F,6,FALSE),0) -> 0 | Z11: =IFERROR(VLOOKUP(A11,플랫폼2!$A:$O,15,0),0) -> 0 | AA11: =M11=SUM(U11:Z11) -> TRUE
A12: 상품매출-기타 | B12: =IFERROR(VLOOKUP($A12,전사손익계산서!$A:$B,2,0),0) -> 23568637 | C12: =B12-E12-D12 -> 12000000 | D12: =IFERROR(VLOOKUP($A12,영업총괄!$A:$K,11,FALSE),0) -> 0 | E12: =SUM(F12:M12) -> 11568637 | F12: =IFERROR(VLOOKUP($A12,소매!A:B,2,FALSE),0) -> 0 | G12: =IFERROR(VLOOKUP($A12,도매!A:B,2,FALSE),0) -> 0 | H12: =Q12+R12 -> 0 | I12: =IFERROR(VLOOKUP($A12,법인영업팀!A:E,4,FALSE),0) -> 0 | J12: =IFERROR(VLOOKUP($A12,법인영업팀!A:E,5,FALSE),0) -> 0 | K12: =IFERROR(VLOOKUP($A12,법인영업팀!$A:$E,3,FALSE),0) -> 0 | L12: =IFERROR(VLOOKUP($A12,소상공인혁신팀!$A:$B,2,FALSE),0) -> 0 | M12: =IFERROR(VLOOKUP($A12,'유통플랫폼사업단 IU'!$A:$F,2,FALSE),0) -> 11568637 | O12: =B12=C12+D12+E12 -> TRUE | Q12: =IFERROR(VLOOKUP($A12,디지털강화팀!A:C,3,FALSE),0) -> 0 | R12: =IFERROR(VLOOKUP($A12,디지털강화팀!A:D,4,FALSE),0) -> 0 | S12: =Q12+R12=H12 -> TRUE | U12: =IFERROR(VLOOKUP($A12,플랫폼1!$A:$B,2,FALSE),0) -> 11568637 | V12: =IFERROR(VLOOKUP($A12,플랫폼2!$A:$M,12,FALSE),0)+IFERROR(VLOOKUP($A12,플랫폼2!$A:$M,13,FALSE),0) -> 0 | W12: =IFERROR(VLOOKUP($A12,플랫폼2!$A:$M,7,FALSE),0)+IFERROR(VLOOKUP($A12,플랫폼2!$A:$M,12,FALSE),0) -> 0 | X12: =IFERROR(VLOOKUP($A12,모바일!$A:$F,5,FALSE),0) -> 0 | Y12: =IFERROR(VLOOKUP($A12,모바일!$A:$F,6,FALSE),0) -> 0 | Z12: =IFERROR(VLOOKUP(A12,플랫폼2!$A:$O,15,0),0) -> 0 | AA12: =M12=SUM(U12:Z12) -> TRUE
A13: 수수료수입 | B13: =IFERROR(VLOOKUP($A13,전사손익계산서!$A:$B,2,0),0) -> 26830545807 | C13: =B13-E13-D13 -> -332591517 | D13: =IFERROR(VLOOKUP($A13,영업총괄!$A:$K,11,FALSE),0) -> 100018182 | E13: =SUM(F13:M13) -> 27063119142 | F13: =IFERROR(VLOOKUP($A13,소매!A:B,2,FALSE),0) -> 1.2111258e+10 | G13: =IFERROR(VLOOKUP($A13,도매!A:B,2,FALSE),0) -> 3.4557061e+09 | H13: =Q13+R13 -> 6767937556 | I13: =IFERROR(VLOOKUP($A13,법인영업팀!A:E,4,FALSE),0) -> 601791131 | J13: =IFERROR(VLOOKUP($A13,법인영업팀!A:E,5,FALSE),0) -> 292787665 | K13: =IFERROR(VLOOKUP($A13,법인영업팀!$A:$E,3,FALSE),0) -> 2401653333 | L13: =IFERROR(VLOOKUP($A13,소상공인혁신팀!$A:$B,2,FALSE),0) -> 1034632610 | M13: =IFERROR(VLOOKUP($A13,'유통플랫폼사업단 IU'!$A:$F,2,FALSE),0) -> 397353163 | O13: =B13=C13+D13+E13 -> TRUE | Q13: =IFERROR(VLOOKUP($A13,디지털강화팀!A:C,3,FALSE),0) -> 6406214557 | R13: =IFERROR(VLOOKUP($A13,디지털강화팀!A:D,4,FALSE),0) -> 361722999 | S13: =Q13+R13=H13 -> TRUE | U13: =IFERROR(VLOOKUP($A13,플랫폼1!$A:$B,2,FALSE),0) -> 250694482 | V13: =IFERROR(VLOOKUP($A13,플랫폼2!$A:$M,12,FALSE),0)+IFERROR(VLOOKUP($A13,플랫폼2!$A:$M,13,FALSE),0) -> 65859544 | W13: =IFERROR(VLOOKUP($A13,플랫폼2!$A:$M,7,FALSE),0)+IFERROR(VLOOKUP($A13,플랫폼2!$A:$M,12,FALSE),0) -> 25599136 | X13: =IFERROR(VLOOKUP($A13,모바일!$A:$F,5,FALSE),0) -> 30400000 | Y13: =IFERROR(VLOOKUP($A13,모바일!$A:$F,6,FALSE),0) -> 24800000 | Z13: =IFERROR(VLOOKUP(A13,플랫폼2!$A:$O,15,0),0) -> 0 | AA13: =M13=SUM(U13:Z13) -> TRUE
A14: 수수료수입-KT(RDS) | B14: =IFERROR(VLOOKUP($A14,전사손익계산서!$A:$B,2,0),0) -> 15644099457 | C14: =B14-E14-D14 -> 534639339 | D14: =IFERROR(VLOOKUP($A14,영업총괄!$A:$K,11,FALSE),0) -> 1818182 | E14: =SUM(F14:M14) -> 15107641936 | F14: =IFERROR(VLOOKUP($A14,소매!A:B,2,FALSE),0) -> 7440586944 | G14: =IFERROR(VLOOKUP($A14,도매!A:B,2,FALSE),0) -> 116709067 | H14: =Q14+R14 -> 4362746966 | I14: =IFERROR(VLOOKUP($A14,법인영업팀!A:E,4,FALSE),0) -> 531114212 | J14: =IFERROR(VLOOKUP($A14,법인영업팀!A:E,5,FALSE),0) -> 160986374 | K14: =IFERROR(VLOOKUP($A14,법인영업팀!$A:$E,3,FALSE),0) -> 2142994914 | L14: =IFERROR(VLOOKUP($A14,소상공인혁신팀!$A:$B,2,FALSE),0) -> 79282697 | M14: =IFERROR(VLOOKUP($A14,'유통플랫폼사업단 IU'!$A:$F,2,FALSE),0) -> 273220762 | O14: =B14=C14+D14+E14 -> TRUE | Q14: =IFERROR(VLOOKUP($A14,디지털강화팀!A:C,3,FALSE),0) -> 4368605043 | R14: =IFERROR(VLOOKUP($A14,디지털강화팀!A:D,4,FALSE),0) -> -5858077 | S14: =Q14+R14=H14 -> TRUE | U14: =IFERROR(VLOOKUP($A14,플랫폼1!$A:$B,2,FALSE),0) -> 226998035 | V14: =IFERROR(VLOOKUP($A14,플랫폼2!$A:$M,12,FALSE),0)+IFERROR(VLOOKUP($A14,플랫폼2!$A:$M,13,FALSE),0) -> 37284090 | W14: =IFERROR(VLOOKUP($A14,플랫폼2!$A:$M,7,FALSE),0)+IFERROR(VLOOKUP($A14,플랫폼2!$A:$M,12,FALSE),0) -> 8938636.5 | X14: =IFERROR(VLOOKUP($A14,모바일!$A:$F,5,FALSE),0) -> 0 | Y14: =IFERROR(VLOOKUP($A14,모바일!$A:$F,6,FALSE),0) -> 0 | Z14: =IFERROR(VLOOKUP(A14,플랫폼2!$A:$O,15,0),0) -> 0 | AA14: =M14=SUM(U14:Z14) -> TRUE
A15: 수수료수입-기타 | B15: =IFERROR(VLOOKUP($A15,전사손익계산서!$A:$B,2,0),0) -> 143644485 | C15: =B15-E15-D15 -> 76726660 | D15: =IFERROR(VLOOKUP($A15,영업총괄!$A:$K,11,FALSE),0) -> 0 | E15: =SUM(F15:M15) -> 66917825 | F15: =IFERROR(VLOOKUP($A15,소매!A:B,2,FALSE),0) -> 9603734 | G15: =IFERROR(VLOOKUP($A15,도매!A:B,2,FALSE),0) -> 0 | H15: =Q15+R15 -> 7734181 | I15: =IFERROR(VLOOKUP($A15,법인영업팀!A:E,4,FALSE),0) -> 0 | J15: =IFERROR(VLOOKUP($A15,법인영업팀!A:E,5,FALSE),0) -> 50909 | K15: =IFERROR(VLOOKUP($A15,법인영업팀!$A:$E,3,FALSE),0) -> 0 | L15: =IFERROR(VLOOKUP($A15,소상공인혁신팀!$A:$B,2,FALSE),0) -> 196600 | M15: =IFERROR(VLOOKUP($A15,'유통플랫폼사업단 IU'!$A:$F,2,FALSE),0) -> 49332401 | O15: =B15=C15+D15+E15 -> TRUE | Q15: =IFERROR(VLOOKUP($A15,디지털강화팀!A:C,3,FALSE),0) -> 0 | R15: =IFERROR(VLOOKUP($A15,디지털강화팀!A:D,4,FALSE),0) -> 7734181 | S15: =Q15+R15=H15 -> TRUE | U15: =IFERROR(VLOOKUP($A15,플랫폼1!$A:$B,2,FALSE),0) -> 23696447 | V15: =IFERROR(VLOOKUP($A15,플랫폼2!$A:$M,12,FALSE),0)+IFERROR(VLOOKUP($A15,플랫폼2!$A:$M,13,FALSE),0) -> 8975454 | W15: =IFERROR(VLOOKUP($A15,플랫폼2!$A:$M,7,FALSE),0)+IFERROR(VLOOKUP($A15,플랫폼2!$A:$M,12,FALSE),0) -> 16660500 | X15: =IFERROR(VLOOKUP($A15,모바일!$A:$F,5,FALSE),0) -> 0 | Y15: =IFERROR(VLOOKUP($A15,모바일!$A:$F,6,FALSE),0) -> 0 | Z15: =IFERROR(VLOOKUP(A15,플랫폼2!$A:$O,15,0),0) -> 0 | AA15: =M15=SUM(U15:Z15) -> TRUE
A16: 수수료수입-관리 | B16: =IFERROR(VLOOKUP($A16,전사손익계산서!$A:$B,2,0),0) -> 4208221227 | C16: =B16-E16-D16 -> 34733596 | D16: =IFERROR(VLOOKUP($A16,영업총괄!$A:$K,11,FALSE),0) -> 0 | E16: =SUM(F16:M16) -> 4173487631 | F16: =IFERROR(VLOOKUP($A16,소매!A:B,2,FALSE),0) -> 2.3531048e+09 | G16: =IFERROR(VLOOKUP($A16,도매!A:B,2,FALSE),0) -> 8.3236823e+08 | H16: =Q16+R16 -> 452588317 | I16: =IFERROR(VLOOKUP($A16,법인영업팀!A:E,4,FALSE),0) -> 78442555 | J16: =IFERROR(VLOOKUP($A16,법인영업팀!A:E,5,FALSE),0) -> 131151882 | K16: =IFERROR(VLOOKUP($A16,법인영업팀!$A:$E,3,FALSE),0) -> 212792079 | L16: =IFERROR(VLOOKUP($A16,소상공인혁신팀!$A:$B,2,FALSE),0) -> 113039742 | M16: =IFERROR(VLOOKUP($A16,'유통플랫폼사업단 IU'!$A:$F,2,FALSE),0) -> 0 | O16: =B16=C16+D16+E16 -> TRUE | Q16: =IFERROR(VLOOKUP($A16,디지털강화팀!A:C,3,FALSE),0) -> 331372064 | R16: =IFERROR(VLOOKUP($A16,디지털강화팀!A:D,4,FALSE),0) -> 121216253 | S16: =Q16+R16=H16 -> TRUE | U16: =IFERROR(VLOOKUP($A16,플랫폼1!$A:$B,2,FALSE),0) -> 0 | V16: =IFERROR(VLOOKUP($A16,플랫폼2!$A:$M,12,FALSE),0)+IFERROR(VLOOKUP($A16,플랫폼2!$A:$M,13,FALSE),0) -> 0 | W16: =IFERROR(VLOOKUP($A16,플랫폼2!$A:$M,7,FALSE),0)+IFERROR(VLOOKUP($A16,플랫폼2!$A:$M,12,FALSE),0) -> 0 | X16: =IFERROR(VLOOKUP($A16,모바일!$A:$F,5,FALSE),0) -> 0 | Y16: =IFERROR(VLOOKUP($A16,모바일!$A:$F,6,FALSE),0) -> 0 | Z16: =IFERROR(VLOOKUP(A16,플랫폼2!$A:$O,15,0),0) -> 0 | AA16: =M16=SUM(U16:Z16) -> TRUE
A17: 수수료수입-매장성 | B17: =IFERROR(VLOOKUP($A17,전사손익계산서!$A:$B,2,0),0) -> 94112511 | C17: =B17-E17-D17 -> 1486046 | D17: =IFERROR(VLOOKUP($A17,영업총괄!$A:$K,11,FALSE),0) -> 0 | E17: =SUM(F17:M17) -> 92626465 | F17: =IFERROR(VLOOKUP($A17,소매!A:B,2,FALSE),0) -> 85243674 | G17: =IFERROR(VLOOKUP($A17,도매!A:B,2,FALSE),0) -> 6601382 | H17: =Q17+R17 -> 0 | I17: =IFERROR(VLOOKUP($A17,법인영업팀!A:E,4,FALSE),0) -> 37091 | J17: =IFERROR(VLOOKUP($A17,법인영업팀!A:E,5,FALSE),0) -> 598500 | K17: =IFERROR(VLOOKUP($A17,법인영업팀!$A:$E,3,FALSE),0) -> 145818 | L17: =IFERROR(VLOOKUP($A17,소상공인혁신팀!$A:$B,2,FALSE),0) -> 0 | M17: =IFERROR(VLOOKUP($A17,'유통플랫폼사업단 IU'!$A:$F,2,FALSE),0) -> 0 | O17: =B17=C17+D17+E17 -> TRUE | Q17: =IFERROR(VLOOKUP($A17,디지털강화팀!A:C,3,FALSE),0) -> 0 | R17: =IFERROR(VLOOKUP($A17,디지털강화팀!A:D,4,FALSE),0) -> 0 | S17: =Q17+R17=H17 -> TRUE | U17: =IFERROR(VLOOKUP($A17,플랫폼1!$A:$B,2,FALSE),0) -> 0 | V17: =IFERROR(VLOOKUP($A17,플랫폼2!$A:$M,12,FALSE),0)+IFERROR(VLOOKUP($A17,플랫폼2!$A:$M,13,FALSE),0) -> 0 | W17: =IFERROR(VLOOKUP($A17,플랫폼2!$A:$M,7,FALSE),0)+IFERROR(VLOOKUP($A17,플랫폼2!$A:$M,12,FALSE),0) -> 0 | X17: =IFERROR(VLOOKUP($A17,모바일!$A:$F,5,FALSE),0) -> 0 | Y17: =IFERROR(VLOOKUP($A17,모바일!$A:$F,6,FALSE),0) -> 0 | Z17: =IFERROR(VLOOKUP(A17,플랫폼2!$A:$O,15,0),0) -> 0 | AA17: =M17=SUM(U17:Z17) -> TRUE
A18: 수수료수입-유선 | B18: =IFERROR(VLOOKUP($A18,전사손익계산서!$A:$B,2,0),0) -> 2462590379 | C18: =B18-E18-D18 -> 27668711 | D18: =IFERROR(VLOOKUP($A18,영업총괄!$A:$K,11,FALSE),0) -> 0 | E18: =SUM(F18:M18) -> 2434921668 | F18: =IFERROR(VLOOKUP($A18,소매!A:B,2,FALSE),0) -> 1524214672 | G18: =IFERROR(VLOOKUP($A18,도매!A:B,2,FALSE),0) -> 27451 | H18: =Q18+R18 -> 59828172 | I18: =IFERROR(VLOOKUP($A18,법인영업팀!A:E,4,FALSE),0) -> 1172727 | J18: =IFERROR(VLOOKUP($A18,법인영업팀!A:E,5,FALSE),0) -> 0 | K18: =IFERROR(VLOOKUP($A18,법인영업팀!$A:$E,3,FALSE),0) -> 7565075 | L18: =IFERROR(VLOOKUP($A18,소상공인혁신팀!$A:$B,2,FALSE),0) -> 842113571 | M18: =IFERROR(VLOOKUP($A18,'유통플랫폼사업단 IU'!$A:$F,2,FALSE),0) -> 0 | O18: =B18=C18+D18+E18 -> TRUE | Q18: =IFERROR(VLOOKUP($A18,디지털강화팀!A:C,3,FALSE),0) -> 53975450 | R18: =IFERROR(VLOOKUP($A18,디지털강화팀!A:D,4,FALSE),0) -> 5852722 | S18: =Q18+R18=H18 -> TRUE | U18: =IFERROR(VLOOKUP($A18,플랫폼1!$A:$B,2,FALSE),0) -> 0 | V18: =IFERROR(VLOOKUP($A18,플랫폼2!$A:$M,12,FALSE),0)+IFERROR(VLOOKUP($A18,플랫폼2!$A:$M,13,FALSE),0) -> 0 | W18: =IFERROR(VLOOKUP($A18,플랫폼2!$A:$M,7,FALSE),0)+IFERROR(VLOOKUP($A18,플랫폼2!$A:$M,12,FALSE),0) -> 0 | X18: =IFERROR(VLOOKUP($A18,모바일!$A:$F,5,FALSE),0) -> 0 | Y18: =IFERROR(VLOOKUP($A18,모바일!$A:$F,6,FALSE),0) -> 0 | Z18: =IFERROR(VLOOKUP(A18,플랫폼2!$A:$O,15,0),0) -> 0 | AA18: =M18=SUM(U18:Z18) -> TRUE
A19: 수수료수입-순액처리 | B19: =IFERROR(VLOOKUP($A19,전사손익계산서!$A:$B,2,0),0) -> -1016027688 | C19: =B19-E19-D19 -> -1016027688 | D19: =IFERROR(VLOOKUP($A19,영업총괄!$A:$K,11,FALSE),0) -> 0 | E19: =SUM(F19:M19) -> 0 | F19: =IFERROR(VLOOKUP($A19,소매!A:B,2,FALSE),0) -> 0 | G19: =IFERROR(VLOOKUP($A19,도매!A:B,2,FALSE),0) -> 0 | H19: =Q19+R19 -> 0 | I19: =IFERROR(VLOOKUP($A19,법인영업팀!A:E,4,FALSE),0) -> 0 | J19: =IFERROR(VLOOKUP($A19,법인영업팀!A:E,5,FALSE),0) -> 0 | K19: =IFERROR(VLOOKUP($A19,법인영업팀!$A:$E,3,FALSE),0) -> 0 | L19: =IFERROR(VLOOKUP($A19,소상공인혁신팀!$A:$B,2,FALSE),0) -> 0 | M19: =IFERROR(VLOOKUP($A19,'유통플랫폼사업단 IU'!$A:$F,2,FALSE),0) -> 0 | O19: =B19=C19+D19+E19 -> TRUE | Q19: =IFERROR(VLOOKUP($A19,디지털강화팀!A:C,3,FALSE),0) -> 0 | R19: =IFERROR(VLOOKUP($A19,디지털강화팀!A:D,4,FALSE),0) -> 0 | S19: =Q19+R19=H19 -> TRUE | U19: =IFERROR(VLOOKUP($A19,플랫폼1!$A:$B,2,FALSE),0) -> 0 | V19: =IFERROR(VLOOKUP($A19,플랫폼2!$A:$M,12,FALSE),0)+IFERROR(VLOOKUP($A19,플랫폼2!$A:$M,13,FALSE),0) -> 0 | W19: =IFERROR(VLOOKUP($A19,플랫폼2!$A:$M,7,FALSE),0)+IFERROR(VLOOKUP($A19,플랫폼2!$A:$M,12,FALSE),0) -> 0 | X19: =IFERROR(VLOOKUP($A19,모바일!$A:$F,5,FALSE),0) -> 0 | Y19: =IFERROR(VLOOKUP($A19,모바일!$A:$F,6,FALSE),0) -> 0 | Z19: =IFERROR(VLOOKUP(A19,플랫폼2!$A:$O,15,0),0) -> 0 | AA19: =M19=SUM(U19:Z19) -> TRUE
A20: 수수료수입-AS | B20: =IFERROR(VLOOKUP($A20,전사손익계산서!$A:$B,2,0),0) -> 0 | C20: =B20-E20-D20 -> 0 | D20: =IFERROR(VLOOKUP($A20,영업총괄!$A:$K,11,FALSE),0) -> 0 | E20: =SUM(F20:M20) -> 0 | F20: =IFERROR(VLOOKUP($A20,소매!A:B,2,FALSE),0) -> 0 | G20: =IFERROR(VLOOKUP($A20,도매!A:B,2,FALSE),0) -> 0 | H20: =Q20+R20 -> 0 | I20: =IFERROR(VLOOKUP($A20,법인영업팀!A:E,4,FALSE),0) -> 0 | J20: =IFERROR(VLOOKUP($A20,법인영업팀!A:E,5,FALSE),0) -> 0 | K20: =IFERROR(VLOOKUP($A20,법인영업팀!$A:$E,3,FALSE),0) -> 0 | L20: =IFERROR(VLOOKUP($A20,소상공인혁신팀!$A:$B,2,FALSE),0) -> 0 | M20: =IFERROR(VLOOKUP($A20,'유통플랫폼사업단 IU'!$A:$F,2,FALSE),0) -> 0 | O20: =B20=C20+D20+E20 -> TRUE | Q20: =IFERROR(VLOOKUP($A20,디지털강화팀!A:C,3,FALSE),0) -> 0 | R20: =IFERROR(VLOOKUP($A20,디지털강화팀!A:D,4,FALSE),0) -> 0 | S20: =Q20+R20=H20 -> TRUE | U20: =IFERROR(VLOOKUP($A20,플랫폼1!$A:$B,2,FALSE),0) -> 0 | V20: =IFERROR(VLOOKUP($A20,플랫폼2!$A:$M,12,FALSE),0)+IFERROR(VLOOKUP($A20,플랫폼2!$A:$M,13,FALSE),0) -> 0 | W20: =IFERROR(VLOOKUP($A20,플랫폼2!$A:$M,7,FALSE),0)+IFERROR(VLOOKUP($A20,플랫폼2!$A:$M,12,FALSE),0) -> 0 | X20: =IFERROR(VLOOKUP($A20,모바일!$A:$F,5,FALSE),0) -> 0 | Y20: =IFERROR(VLOOKUP($A20,모바일!$A:$F,6,FALSE),0) -> 0 | Z20: =IFERROR(VLOOKUP(A20,플랫폼2!$A:$O,15,0),0) -> 0 | AA20: =M20=SUM(U20:Z20) -> TRUE
A21: 수수료수입-정책 | B21: =IFERROR(VLOOKUP($A21,전사손익계산서!$A:$B,2,0),0) -> 904205387 | C21: =B21-E21-D21 -> 0 | D21: =IFERROR(VLOOKUP($A21,영업총괄!$A:$K,11,FALSE),0) -> 0 | E21: =SUM(F21:M21) -> 904205387 | F21: =IFERROR(VLOOKUP($A21,소매!A:B,2,FALSE),0) -> 19412727 | G21: =IFERROR(VLOOKUP($A21,도매!A:B,2,FALSE),0) -> 0 | H21: =Q21+R21 -> 902396000 | I21: =IFERROR(VLOOKUP($A21,법인영업팀!A:E,4,FALSE),0) -> -8975454 | J21: =IFERROR(VLOOKUP($A21,법인영업팀!A:E,5,FALSE),0) -> 0 | K21: =IFERROR(VLOOKUP($A21,법인영업팀!$A:$E,3,FALSE),0) -> -8627886 | L21: =IFERROR(VLOOKUP($A21,소상공인혁신팀!$A:$B,2,FALSE),0) -> 0 | M21: =IFERROR(VLOOKUP($A21,'유통플랫폼사업단 IU'!$A:$F,2,FALSE),0) -> 0 | O21: =B21=C21+D21+E21 -> TRUE | Q21: =IFERROR(VLOOKUP($A21,디지털강화팀!A:C,3,FALSE),0) -> 902396000 | R21: =IFERROR(VLOOKUP($A21,디지털강화팀!A:D,4,FALSE),0) -> 0 | S21: =Q21+R21=H21 -> TRUE | U21: =IFERROR(VLOOKUP($A21,플랫폼1!$A:$B,2,FALSE),0) -> 0 | V21: =IFERROR(VLOOKUP($A21,플랫폼2!$A:$M,12,FALSE),0)+IFERROR(VLOOKUP($A21,플랫폼2!$A:$M,13,FALSE),0) -> 0 | W21: =IFERROR(VLOOKUP($A21,플랫폼2!$A:$M,7,FALSE),0)+IFERROR(VLOOKUP($A21,플랫폼2!$A:$M,12,FALSE),0) -> 0 | X21: =IFERROR(VLOOKUP($A21,모바일!$A:$F,5,FALSE),0) -> 0 | Y21: =IFERROR(VLOOKUP($A21,모바일!$A:$F,6,FALSE),0) -> 0 | Z21: =IFERROR(VLOOKUP(A21,플랫폼2!$A:$O,15,0),0) -> 0 | AA21: =M21=SUM(U21:Z21) -> TRUE
... A24: 수수료수입-신사업 | B24: =IFERROR(VLOOKUP($A24,전사손익계산서!$A:$B,2,0),0) -> 0 | C24: =B24-E24-D24 -> 0 | D24: =IFERROR(VLOOKUP($A24,영업총괄!$A:$K,11,FALSE),0) -> 0 | E24: =SUM(F24:M24) -> 0 | F24: =IFERROR(VLOOKUP($A24,소매!A:B,2,FALSE),0) -> 0 | G24: =IFERROR(VLOOKUP($A24,도매!A:B,2,FALSE),0) -> 0 | H24: =Q24+R24 -> 0 | I24: =IFERROR(VLOOKUP($A24,법인영업팀!A:E,4,FALSE),0) -> 0 | J24: =IFERROR(VLOOKUP($A24,법인영업팀!A:E,5,FALSE),0) -> 0 | K24: =IFERROR(VLOOKUP($A24,법인영업팀!$A:$E,3,FALSE),0) -> 0 | L24: =IFERROR(VLOOKUP($A24,소상공인혁신팀!$A:$B,2,FALSE),0) -> 0 | M24: =IFERROR(VLOOKUP($A24,'유통플랫폼사업단 IU'!$A:$F,2,FALSE),0) -> 0 | O24: =B24=C24+D24+E24 -> TRUE | Q24: =IFERROR(VLOOKUP($A24,디지털강화팀!A:C,3,FALSE),0) -> 0 | R24: =IFERROR(VLOOKUP($A24,디지털강화팀!A:D,4,FALSE),0) -> 0 | S24: =Q24+R24=H24 -> TRUE | U24: =IFERROR(VLOOKUP($A24,플랫폼1!$A:$B,2,FALSE),0) -> 0 | V24: =IFERROR(VLOOKUP($A24,플랫폼2!$A:$M,12,FALSE),0)+IFERROR(VLOOKUP($A24,플랫폼2!$A:$M,13,FALSE),0) -> 0 | W24: =IFERROR(VLOOKUP($A24,플랫폼2!$A:$M,7,FALSE),0)+IFERROR(VLOOKUP($A24,플랫폼2!$A:$M,12,FALSE),0) -> 0 | X24: =IFERROR(VLOOKUP($A24,모바일!$A:$F,5,FALSE),0) -> 0 | Y24: =IFERROR(VLOOKUP($A24,모바일!$A:$F,6,FALSE),0) -> 0 | Z24: =IFERROR(VLOOKUP(A24,플랫폼2!$A:$O,15,0),0) -> 0 | AA24: =M24=SUM(U24:Z24) -> TRUE
A25: 매 출 원 가 | B25: =IFERROR(VLOOKUP($A25,전사손익계산서!$A:$B,2,0),0) -> 56501271076 | C25: =B25-E25-D25 -> 282778666 | D25: =IFERROR(VLOOKUP($A25,영업총괄!$A:$K,11,FALSE),0) -> 0 | E25: =SUM(F25:M25) -> 56218492410 | F25: =IFERROR(VLOOKUP($A25,소매!A:B,2,FALSE),0) -> 12676667140 | G25: =IFERROR(VLOOKUP($A25,도매!A:B,2,FALSE),0) -> 7283274766 | H25: =Q25+R25 -> 30445027703 | I25: =IFERROR(VLOOKUP($A25,법인영업팀!A:E,4,FALSE),0) -> 1231136249 | J25: =IFERROR(VLOOKUP($A25,법인영업팀!A:E,5,FALSE),0) -> -70809595 | K25: =IFERROR(VLOOKUP($A25,법인영업팀!$A:$E,3,FALSE),0) -> 3615404607 | L25: =IFERROR(VLOOKUP($A25,소상공인혁신팀!$A:$B,2,FALSE),0) -> 131198732 | M25: =IFERROR(VLOOKUP($A25,'유통플랫폼사업단 IU'!$A:$F,2,FALSE),0) -> 906592808 | O25: =B25=C25+D25+E25 -> TRUE | Q25: =IFERROR(VLOOKUP($A25,디지털강화팀!A:C,3,FALSE),0) -> 30310602604 | R25: =IFERROR(VLOOKUP($A25,디지털강화팀!A:D,4,FALSE),0) -> 134425099 | S25: =Q25+R25=H25 -> TRUE | U25: =IFERROR(VLOOKUP($A25,플랫폼1!$A:$B,2,FALSE),0) -> 5656121 | V25: =IFERROR(VLOOKUP($A25,플랫폼2!$A:$M,12,FALSE),0)+IFERROR(VLOOKUP($A25,플랫폼2!$A:$M,13,FALSE),0) -> 174648500 | W25: =IFERROR(VLOOKUP($A25,플랫폼2!$A:$M,7,FALSE),0)+IFERROR(VLOOKUP($A25,플랫폼2!$A:$M,12,FALSE),0) -> 552948187 | X25: =IFERROR(VLOOKUP($A25,모바일!$A:$S,17,FALSE),0) -> 1445000 | Y25: =IFERROR(VLOOKUP($A25,모바일!$A:$S,18,FALSE),0) -> 1445000 | Z25: =IFERROR(VLOOKUP(A25,플랫폼2!$A:$O,15,0),0) -> 170450000 | AA25: =M25=SUM(U25:Z25) -> TRUE
A26: 상 품 매 출 원 가 | B26: =IFERROR(VLOOKUP($A26,전사손익계산서!$A:$B,2,0),0) -> 56501271076 | C26: =B26-E26-D26 -> 282778666 | D26: =IFERROR(VLOOKUP($A26,영업총괄!$A:$K,11,FALSE),0) -> 0 | E26: =SUM(F26:M26) -> 56218492410 | F26: =IFERROR(VLOOKUP($A26,소매!A:B,2,FALSE),0) -> 12676667140 | G26: =IFERROR(VLOOKUP($A26,도매!A:B,2,FALSE),0) -> 7283274766 | H26: =Q26+R26 -> 30445027703 | I26: =IFERROR(VLOOKUP($A26,법인영업팀!A:E,4,FALSE),0) -> 1231136249 | J26: =IFERROR(VLOOKUP($A26,법인영업팀!A:E,5,FALSE),0) -> -70809595 | K26: =IFERROR(VLOOKUP($A26,법인영업팀!$A:$E,3,FALSE),0) -> 3615404607 | L26: =IFERROR(VLOOKUP($A26,소상공인혁신팀!$A:$B,2,FALSE),0) -> 131198732 | M26: =IFERROR(VLOOKUP($A26,'유통플랫폼사업단 IU'!$A:$F,2,FALSE),0) -> 906592808 | O26: =B26=C26+D26+E26 -> TRUE | Q26: =IFERROR(VLOOKUP($A26,디지털강화팀!A:C,3,FALSE),0) -> 30310602604 | R26: =IFERROR(VLOOKUP($A26,디지털강화팀!A:D,4,FALSE),0) -> 134425099 | S26: =Q26+R26=H26 -> TRUE | U26: =IFERROR(VLOOKUP($A26,플랫폼1!$A:$B,2,FALSE),0) -> 5656121 | V26: =IFERROR(VLOOKUP($A26,플랫폼2!$A:$M,12,FALSE),0)+IFERROR(VLOOKUP($A26,플랫폼2!$A:$M,13,FALSE),0) -> 174648500 | W26: =IFERROR(VLOOKUP($A26,플랫폼2!$A:$M,7,FALSE),0)+IFERROR(VLOOKUP($A26,플랫폼2!$A:$M,12,FALSE),0) -> 552948187 | X26: =IFERROR(VLOOKUP($A26,모바일!$A:$S,17,FALSE),0) -> 1445000 | Y26: =IFERROR(VLOOKUP($A26,모바일!$A:$S,18,FALSE),0) -> 1445000 | Z26: =IFERROR(VLOOKUP(A26,플랫폼2!$A:$O,15,0),0) -> 170450000 | AA26: =M26=SUM(U26:Z26) -> TRUE
A27: 매 출 총 이 익 | B27: =IFERROR(VLOOKUP($A27,전사손익계산서!$A:$B,2,0),0) -> 21162905628 | C27: =B27-E27-D27 -> -508118894 | D27: =IFERROR(VLOOKUP($A27,영업총괄!$A:$K,11,FALSE),0) -> 100018182 | E27: =SUM(F27:M27) -> 21571006340 | F27: =IFERROR(VLOOKUP($A27,소매!A:B,2,FALSE),0) -> 1.0277109e+10 | G27: =IFERROR(VLOOKUP($A27,도매!A:B,2,FALSE),0) -> 3.8054299e+09 | H27: =Q27+R27 -> 4214550894 | I27: =IFERROR(VLOOKUP($A27,법인영업팀!A:E,4,FALSE),0) -> 205522425 | J27: =IFERROR(VLOOKUP($A27,법인영업팀!A:E,5,FALSE),0) -> 370800713 | K27: =IFERROR(VLOOKUP($A27,법인영업팀!$A:$E,3,FALSE),0) -> 1143997616 | L27: =IFERROR(VLOOKUP($A27,소상공인혁신팀!$A:$B,2,FALSE),0) -> 986845969 | M27: =IFERROR(VLOOKUP($A27,'유통플랫폼사업단 IU'!$A:$F,2,FALSE),0) -> 566749519 | O27: =B27=C27+D27+E27 -> TRUE | Q27: =IFERROR(VLOOKUP($A27,디지털강화팀!A:C,3,FALSE),0) -> 3814551470 | R27: =IFERROR(VLOOKUP($A27,디지털강화팀!A:D,4,FALSE),0) -> 399999424 | S27: =Q27+R27=H27 -> TRUE | U27: =IFERROR(VLOOKUP($A27,플랫폼1!$A:$B,2,FALSE),0) -> 256606998 | V27: =IFERROR(VLOOKUP($A27,플랫폼2!$A:$M,12,FALSE),0)+IFERROR(VLOOKUP($A27,플랫폼2!$A:$M,13,FALSE),0) -> 1.5138832e+08 | W27: =IFERROR(VLOOKUP($A27,플랫폼2!$A:$M,7,FALSE),0)+IFERROR(VLOOKUP($A27,플랫폼2!$A:$M,12,FALSE),0) -> 1.1378802e+08 | X27: =IFERROR(VLOOKUP($A27,모바일!$A:$S,17,FALSE),0) -> 28955000 | Y27: =IFERROR(VLOOKUP($A27,모바일!$A:$S,18,FALSE),0) -> 23355000 | Z27: =IFERROR(VLOOKUP(A27,플랫폼2!$A:$O,15,0),0) -> -7343818 | AA27: =M27=SUM(U27:Z27) -> TRUE
A28: 판매비와일반관리비 | B28: =IFERROR(VLOOKUP($A28,전사손익계산서!$A:$B,2,0),0) -> 17380259391 | C28: =B28-E28-D28 -> -2.9797518e+08 | D28: =IFERROR(VLOOKUP($A28,영업총괄!$A:$K,11,FALSE),0) -> 604269852 | E28: =SUM(F28:M28) -> 1.7073965e+10 | F28: =IFERROR(VLOOKUP($A28,소매!A:B,2,FALSE),0) -> 8.4370555e+09 | G28: =IFERROR(VLOOKUP($A28,도매!A:B,2,FALSE),0) -> 2.6229872e+09 | H28: =Q28+R28 -> 3.2017358e+09 | I28: =IFERROR(VLOOKUP($A28,법인영업팀!A:E,4,FALSE),0) -> 1.0810799e+08 | J28: =IFERROR(VLOOKUP($A28,법인영업팀!A:E,5,FALSE),0) -> 3.290106e+08 | K28: =IFERROR(VLOOKUP($A28,법인영업팀!$A:$E,3,FALSE),0) -> 1.1017328e+09 | L28: =IFERROR(VLOOKUP($A28,소상공인혁신팀!$A:$B,2,FALSE),0) -> 7.586322e+08 | M28: =IFERROR(VLOOKUP($A28,'유통플랫폼사업단 IU'!$A:$F,2,FALSE),0) -> 514702584 | O28: =B28=C28+D28+E28 -> TRUE | Q28: =IFERROR(VLOOKUP($A28,디지털강화팀!A:C,3,FALSE),0) -> 2.9232582e+09 | R28: =IFERROR(VLOOKUP($A28,디지털강화팀!A:D,4,FALSE),0) -> 2.7847762e+08 | S28: =Q28+R28=H28 -> TRUE | U28: =IFERROR(VLOOKUP($A28,플랫폼1!$A:$B,2,FALSE),0) -> 293740787 | V28: =IFERROR(VLOOKUP($A28,플랫폼2!$A:$M,12,FALSE),0)+IFERROR(VLOOKUP($A28,플랫폼2!$A:$M,13,FALSE),0) -> 47945012 | W28: =IFERROR(VLOOKUP($A28,플랫폼2!$A:$M,7,FALSE),0)+IFERROR(VLOOKUP($A28,플랫폼2!$A:$M,12,FALSE),0) -> 35575539 | X28: =IFERROR(VLOOKUP($A28,모바일!$A:$S,17,FALSE),0) -> 23549611 | Y28: =IFERROR(VLOOKUP($A28,모바일!$A:$S,18,FALSE),0) -> 14823333 | Z28: =IFERROR(VLOOKUP(A28,플랫폼2!$A:$O,15,0),0) -> 99068301 | AA28: =M28=SUM(U28:Z28) -> TRUE
A29: 임 원 급 여 | B29: =IFERROR(VLOOKUP($A29,전사손익계산서!$A:$B,2,0),0) -> 107876570 | C29: =B29-E29-D29 -> 34788501 | D29: =IFERROR(VLOOKUP($A29,영업총괄!$A:$K,11,FALSE),0) -> 16220000 | E29: =SUM(F29:M29) -> 56868069 | F29: =IFERROR(VLOOKUP($A29,소매!A:B,2,FALSE),0) -> 40628274 | G29: =IFERROR(VLOOKUP($A29,도매!A:B,2,FALSE),0) -> 5548376.1 | H29: =Q29+R29 -> 0 | I29: =IFERROR(VLOOKUP($A29,법인영업팀!A:E,4,FALSE),0) -> 1307139.2 | J29: =IFERROR(VLOOKUP($A29,법인영업팀!A:E,5,FALSE),0) -> 1310341.3 | K29: =IFERROR(VLOOKUP($A29,법인영업팀!$A:$E,3,FALSE),0) -> 6596509.1 | L29: =IFERROR(VLOOKUP($A29,소상공인혁신팀!$A:$B,2,FALSE),0) -> 1477429.3 | M29: =IFERROR(VLOOKUP($A29,'유통플랫폼사업단 IU'!$A:$F,2,FALSE),0) -> 0 | O29: =B29=C29+D29+E29 -> TRUE | Q29: =IFERROR(VLOOKUP($A29,디지털강화팀!A:C,3,FALSE),0) -> 0 | R29: =IFERROR(VLOOKUP($A29,디지털강화팀!A:D,4,FALSE),0) -> 0 | S29: =Q29+R29=H29 -> TRUE | U29: =IFERROR(VLOOKUP($A29,플랫폼1!$A:$B,2,FALSE),0) -> 0 | V29: =IFERROR(VLOOKUP($A29,플랫폼2!$A:$M,12,FALSE),0)+IFERROR(VLOOKUP($A29,플랫폼2!$A:$M,13,FALSE),0) -> 0 | W29: =IFERROR(VLOOKUP($A29,플랫폼2!$A:$M,7,FALSE),0)+IFERROR(VLOOKUP($A29,플랫폼2!$A:$M,12,FALSE),0) -> 0 | X29: =IFERROR(VLOOKUP($A29,모바일!$A:$S,17,FALSE),0) -> 0 | Y29: =IFERROR(VLOOKUP($A29,모바일!$A:$S,18,FALSE),0) -> 0 | Z29: =IFERROR(VLOOKUP(A29,플랫폼2!$A:$O,15,0),0) -> 0 | AA29: =M29=SUM(U29:Z29) -> TRUE
A30: 직 원 급 여 | B30: =IFERROR(VLOOKUP($A30,전사손익계산서!$A:$B,2,0),0) -> 6535677603 | C30: =B30-E30-D30 -> 5.2512893e+08 | D30: =IFERROR(VLOOKUP($A30,영업총괄!$A:$K,11,FALSE),0) -> 177202700 | E30: =SUM(F30:M30) -> 5.833346e+09 | F30: =IFERROR(VLOOKUP($A30,소매!A:B,2,FALSE),0) -> 3.5928624e+09 | G30: =IFERROR(VLOOKUP($A30,도매!A:B,2,FALSE),0) -> 1.1742433e+09 | H30: =Q30+R30 -> 4.216996e+08 | I30: =IFERROR(VLOOKUP($A30,법인영업팀!A:E,4,FALSE),0) -> 46276690 | J30: =IFERROR(VLOOKUP($A30,법인영업팀!A:E,5,FALSE),0) -> 46390056 | K30: =IFERROR(VLOOKUP($A30,법인영업팀!$A:$E,3,FALSE),0) -> 2.3353642e+08 | L30: =IFERROR(VLOOKUP($A30,소상공인혁신팀!$A:$B,2,FALSE),0) -> 2.338562e+08 | M30: =IFERROR(VLOOKUP($A30,'유통플랫폼사업단 IU'!$A:$F,2,FALSE),0) -> 84481340 | O30: =B30=C30+D30+E30 -> TRUE | Q30: =IFERROR(VLOOKUP($A30,디지털강화팀!A:C,3,FALSE),0) -> 4.0061462e+08 | R30: =IFERROR(VLOOKUP($A30,디지털강화팀!A:D,4,FALSE),0) -> 21084980 | S30: =Q30+R30=H30 -> TRUE | U30: =IFERROR(VLOOKUP($A30,플랫폼1!$A:$B,2,FALSE),0) -> 18177100 | V30: =IFERROR(VLOOKUP($A30,플랫폼2!$A:$M,12,FALSE),0)+IFERROR(VLOOKUP($A30,플랫폼2!$A:$M,13,FALSE),0) -> 11360555 | W30: =IFERROR(VLOOKUP($A30,플랫폼2!$A:$M,7,FALSE),0)+IFERROR(VLOOKUP($A30,플랫폼2!$A:$M,12,FALSE),0) -> 11360555 | X30: =IFERROR(VLOOKUP($A30,모바일!$A:$S,17,FALSE),0) -> 2702054.2 | Y30: =IFERROR(VLOOKUP($A30,모바일!$A:$S,18,FALSE),0) -> 2702054.2 | Z30: =IFERROR(VLOOKUP(A30,플랫폼2!$A:$O,15,0),0) -> 38179022 | AA30: =M30=SUM(U30:Z30) -> TRUE
A31: 급료와임금 | B31: =IFERROR(VLOOKUP($A31,전사손익계산서!$A:$B,2,0),0) -> 747187230 | C31: =B31-E31-D31 -> 2.4895725e+08 | D31: =IFERROR(VLOOKUP($A31,영업총괄!$A:$K,11,FALSE),0) -> 64620240 | E31: =SUM(F31:M31) -> 4.3360974e+08 | F31: =IFERROR(VLOOKUP($A31,소매!A:B,2,FALSE),0) -> 2.1811076e+08 | G31: =IFERROR(VLOOKUP($A31,도매!A:B,2,FALSE),0) -> 1.0308398e+08 | H31: =Q31+R31 -> 28007229 | I31: =IFERROR(VLOOKUP($A31,법인영업팀!A:E,4,FALSE),0) -> 5484903.5 | J31: =IFERROR(VLOOKUP($A31,법인영업팀!A:E,5,FALSE),0) -> 5485554.8 | K31: =IFERROR(VLOOKUP($A31,법인영업팀!$A:$E,3,FALSE),0) -> 11522272 | L31: =IFERROR(VLOOKUP($A31,소상공인혁신팀!$A:$B,2,FALSE),0) -> 15311945 | M31: =IFERROR(VLOOKUP($A31,'유통플랫폼사업단 IU'!$A:$F,2,FALSE),0) -> 46603100 | O31: =B31=C31+D31+E31 -> TRUE | Q31: =IFERROR(VLOOKUP($A31,디지털강화팀!A:C,3,FALSE),0) -> 26606866 | R31: =IFERROR(VLOOKUP($A31,디지털강화팀!A:D,4,FALSE),0) -> 1400363 | S31: =Q31+R31=H31 -> TRUE | U31: =IFERROR(VLOOKUP($A31,플랫폼1!$A:$B,2,FALSE),0) -> 11023040 | V31: =IFERROR(VLOOKUP($A31,플랫폼2!$A:$M,12,FALSE),0)+IFERROR(VLOOKUP($A31,플랫폼2!$A:$M,13,FALSE),0) -> 7796060 | W31: =IFERROR(VLOOKUP($A31,플랫폼2!$A:$M,7,FALSE),0)+IFERROR(VLOOKUP($A31,플랫폼2!$A:$M,12,FALSE),0) -> 7796060 | X31: =IFERROR(VLOOKUP($A31,모바일!$A:$S,17,FALSE),0) -> 1665661.7 | Y31: =IFERROR(VLOOKUP($A31,모바일!$A:$S,18,FALSE),0) -> 1665661.7 | Z31: =IFERROR(VLOOKUP(A31,플랫폼2!$A:$O,15,0),0) -> 16656617 | AA31: =M31=SUM(U31:Z31) -> TRUE
A32: 초과근무수당 | B32: =IFERROR(VLOOKUP($A32,전사손익계산서!$A:$B,2,0),0) -> 137233150 | C32: =B32-E32-D32 -> 46009078 | D32: =IFERROR(VLOOKUP($A32,영업총괄!$A:$K,11,FALSE),0) -> 11898270 | E32: =SUM(F32:M32) -> 79325802 | F32: =IFERROR(VLOOKUP($A32,소매!A:B,2,FALSE),0) -> 40127133 | G32: =IFERROR(VLOOKUP($A32,도매!A:B,2,FALSE),0) -> 18543781 | H32: =Q32+R32 -> 5139895.4 | I32: =IFERROR(VLOOKUP($A32,법인영업팀!A:E,4,FALSE),0) -> 1019381.6 | J32: =IFERROR(VLOOKUP($A32,법인영업팀!A:E,5,FALSE),0) -> 1019496.5 | K32: =IFERROR(VLOOKUP($A32,법인영업팀!$A:$E,3,FALSE),0) -> 2137630.6 | L32: =IFERROR(VLOOKUP($A32,소상공인혁신팀!$A:$B,2,FALSE),0) -> 2829213.1 | M32: =IFERROR(VLOOKUP($A32,'유통플랫폼사업단 IU'!$A:$F,2,FALSE),0) -> 8509270 | O32: =B32=C32+D32+E32 -> TRUE | Q32: =IFERROR(VLOOKUP($A32,디지털강화팀!A:C,3,FALSE),0) -> 4882900.6 | R32: =IFERROR(VLOOKUP($A32,디지털강화팀!A:D,4,FALSE),0) -> 256994.77 | S32: =Q32+R32=H32 -> TRUE | U32: =IFERROR(VLOOKUP($A32,플랫폼1!$A:$B,2,FALSE),0) -> 2069480 | V32: =IFERROR(VLOOKUP($A32,플랫폼2!$A:$M,12,FALSE),0)+IFERROR(VLOOKUP($A32,플랫폼2!$A:$M,13,FALSE),0) -> 1437760 | W32: =IFERROR(VLOOKUP($A32,플랫폼2!$A:$M,7,FALSE),0)+IFERROR(VLOOKUP($A32,플랫폼2!$A:$M,12,FALSE),0) -> 1437760 | X32: =IFERROR(VLOOKUP($A32,모바일!$A:$S,17,FALSE),0) -> 297022.5 | Y32: =IFERROR(VLOOKUP($A32,모바일!$A:$S,18,FALSE),0) -> 297022.5 | Z32: =IFERROR(VLOOKUP(A32,플랫폼2!$A:$O,15,0),0) -> 2970225 | AA32: =M32=SUM(U32:Z32) -> TRUE
A33: 직책수당 | B33: =IFERROR(VLOOKUP($A33,전사손익계산서!$A:$B,2,0),0) -> 33700000 | C33: =B33-E33-D33 -> 12100000 | D33: =IFERROR(VLOOKUP($A33,영업총괄!$A:$K,11,FALSE),0) -> 2800000 | E33: =SUM(F33:M33) -> 18800000 | F33: =IFERROR(VLOOKUP($A33,소매!A:B,2,FALSE),0) -> 10158777 | G33: =IFERROR(VLOOKUP($A33,도매!A:B,2,FALSE),0) -> 3727443.7 | H33: =Q33+R33 -> 1113779.5 | I33: =IFERROR(VLOOKUP($A33,법인영업팀!A:E,4,FALSE),0) -> 350000 | J33: =IFERROR(VLOOKUP($A33,법인영업팀!A:E,5,FALSE),0) -> 350000 | K33: =IFERROR(VLOOKUP($A33,법인영업팀!$A:$E,3,FALSE),0) -> 700000 | L33: =IFERROR(VLOOKUP($A33,소상공인혁신팀!$A:$B,2,FALSE),0) -> 700000 | M33: =IFERROR(VLOOKUP($A33,'유통플랫폼사업단 IU'!$A:$F,2,FALSE),0) -> 1700000 | O33: =B33=C33+D33+E33 -> TRUE | Q33: =IFERROR(VLOOKUP($A33,디지털강화팀!A:C,3,FALSE),0) -> 1058090.5 | R33: =IFERROR(VLOOKUP($A33,디지털강화팀!A:D,4,FALSE),0) -> 55688.973 | S33: =Q33+R33=H33 -> TRUE | U33: =IFERROR(VLOOKUP($A33,플랫폼1!$A:$B,2,FALSE),0) -> 700000 | V33: =IFERROR(VLOOKUP($A33,플랫폼2!$A:$M,12,FALSE),0)+IFERROR(VLOOKUP($A33,플랫폼2!$A:$M,13,FALSE),0) -> 350000 | W33: =IFERROR(VLOOKUP($A33,플랫폼2!$A:$M,7,FALSE),0)+IFERROR(VLOOKUP($A33,플랫폼2!$A:$M,12,FALSE),0) -> 350000 | X33: =IFERROR(VLOOKUP($A33,모바일!$A:$S,17,FALSE),0) -> 25000 | Y33: =IFERROR(VLOOKUP($A33,모바일!$A:$S,18,FALSE),0) -> 25000 | Z33: =IFERROR(VLOOKUP(A33,플랫폼2!$A:$O,15,0),0) -> 250000 | AA33: =M33=SUM(U33:Z33) -> TRUE
A34: 연차수당 | B34: =IFERROR(VLOOKUP($A34,전사손익계산서!$A:$B,2,0),0) -> 24852270 | C34: =B34-E34-D34 -> 2407158.7 | D34: =IFERROR(VLOOKUP($A34,영업총괄!$A:$K,11,FALSE),0) -> 0 | E34: =SUM(F34:M34) -> 22445111 | F34: =IFERROR(VLOOKUP($A34,소매!A:B,2,FALSE),0) -> 16026475 | G34: =IFERROR(VLOOKUP($A34,도매!A:B,2,FALSE),0) -> 1913094.9 | H34: =Q34+R34 -> 0 | I34: =IFERROR(VLOOKUP($A34,법인영업팀!A:E,4,FALSE),0) -> 550850.13 | J34: =IFERROR(VLOOKUP($A34,법인영업팀!A:E,5,FALSE),0) -> 552199.57 | K34: =IFERROR(VLOOKUP($A34,법인영업팀!$A:$E,3,FALSE),0) -> 2779878.4 | L34: =IFERROR(VLOOKUP($A34,소상공인혁신팀!$A:$B,2,FALSE),0) -> 622613.22 | M34: =IFERROR(VLOOKUP($A34,'유통플랫폼사업단 IU'!$A:$F,2,FALSE),0) -> 0 | O34: =B34=C34+D34+E34 -> TRUE | Q34: =IFERROR(VLOOKUP($A34,디지털강화팀!A:C,3,FALSE),0) -> 0 | R34: =IFERROR(VLOOKUP($A34,디지털강화팀!A:D,4,FALSE),0) -> 0 | S34: =Q34+R34=H34 -> TRUE | U34: =IFERROR(VLOOKUP($A34,플랫폼1!$A:$B,2,FALSE),0) -> 0 | V34: =IFERROR(VLOOKUP($A34,플랫폼2!$A:$M,12,FALSE),0)+IFERROR(VLOOKUP($A34,플랫폼2!$A:$M,13,FALSE),0) -> 0 | W34: =IFERROR(VLOOKUP($A34,플랫폼2!$A:$M,7,FALSE),0)+IFERROR(VLOOKUP($A34,플랫폼2!$A:$M,12,FALSE),0) -> 0 | X34: =IFERROR(VLOOKUP($A34,모바일!$A:$S,17,FALSE),0) -> 0 | Y34: =IFERROR(VLOOKUP($A34,모바일!$A:$S,18,FALSE),0) -> 0 | Z34: =IFERROR(VLOOKUP(A34,플랫폼2!$A:$O,15,0),0) -> 0 | AA34: =M34=SUM(U34:Z34) -> TRUE
A35: 휴일근무수당 | B35: =IFERROR(VLOOKUP($A35,전사손익계산서!$A:$B,2,0),0) -> 10308310 | C35: =B35-E35-D35 -> 1290110 | D35: =IFERROR(VLOOKUP($A35,영업총괄!$A:$K,11,FALSE),0) -> 332140 | E35: =SUM(F35:M35) -> 8686060 | F35: =IFERROR(VLOOKUP($A35,소매!A:B,2,FALSE),0) -> 4994209 | G35: =IFERROR(VLOOKUP($A35,도매!A:B,2,FALSE),0) -> 3530971 | H35: =Q35+R35 -> 0 | I35: =IFERROR(VLOOKUP($A35,법인영업팀!A:E,4,FALSE),0) -> 0 | J35: =IFERROR(VLOOKUP($A35,법인영업팀!A:E,5,FALSE),0) -> 0 | K35: =IFERROR(VLOOKUP($A35,법인영업팀!$A:$E,3,FALSE),0) -> 0 | L35: =IFERROR(VLOOKUP($A35,소상공인혁신팀!$A:$B,2,FALSE),0) -> 0 | M35: =IFERROR(VLOOKUP($A35,'유통플랫폼사업단 IU'!$A:$F,2,FALSE),0) -> 160880 | O35: =B35=C35+D35+E35 -> TRUE | Q35: =IFERROR(VLOOKUP($A35,디지털강화팀!A:C,3,FALSE),0) -> 0 | R35: =IFERROR(VLOOKUP($A35,디지털강화팀!A:D,4,FALSE),0) -> 0 | S35: =Q35+R35=H35 -> TRUE | U35: =IFERROR(VLOOKUP($A35,플랫폼1!$A:$B,2,FALSE),0) -> 0 | V35: =IFERROR(VLOOKUP($A35,플랫폼2!$A:$M,12,FALSE),0)+IFERROR(VLOOKUP($A35,플랫폼2!$A:$M,13,FALSE),0) -> 40220 | W35: =IFERROR(VLOOKUP($A35,플랫폼2!$A:$M,7,FALSE),0)+IFERROR(VLOOKUP($A35,플랫폼2!$A:$M,12,FALSE),0) -> 40220 | X35: =IFERROR(VLOOKUP($A35,모바일!$A:$S,17,FALSE),0) -> 6703.3333 | Y35: =IFERROR(VLOOKUP($A35,모바일!$A:$S,18,FALSE),0) -> 6703.3333 | Z35: =IFERROR(VLOOKUP(A35,플랫폼2!$A:$O,15,0),0) -> 67033.333 | AA35: =M35=SUM(U35:Z35) -> TRUE
A36: 제수당기타 | B36: =IFERROR(VLOOKUP($A36,전사손익계산서!$A:$B,2,0),0) -> 19065130 | C36: =B36-E36-D36 -> 6604397.1 | D36: =IFERROR(VLOOKUP($A36,영업총괄!$A:$K,11,FALSE),0) -> 1166260 | E36: =SUM(F36:M36) -> 11294473 | F36: =IFERROR(VLOOKUP($A36,소매!A:B,2,FALSE),0) -> 4788227 | G36: =IFERROR(VLOOKUP($A36,도매!A:B,2,FALSE),0) -> 3264639.8 | H36: =Q36+R36 -> 560953.28 | I36: =IFERROR(VLOOKUP($A36,법인영업팀!A:E,4,FALSE),0) -> 114958.91 | J36: =IFERROR(VLOOKUP($A36,법인영업팀!A:E,5,FALSE),0) -> 115103.8 | K36: =IFERROR(VLOOKUP($A36,법인영업팀!$A:$E,3,FALSE),0) -> 798471.15 | L36: =IFERROR(VLOOKUP($A36,소상공인혁신팀!$A:$B,2,FALSE),0) -> 66848.999 | M36: =IFERROR(VLOOKUP($A36,'유통플랫폼사업단 IU'!$A:$F,2,FALSE),0) -> 1585270 | O36: =B36=C36+D36+E36 -> TRUE | Q36: =IFERROR(VLOOKUP($A36,디지털강화팀!A:C,3,FALSE),0) -> 532905.62 | R36: =IFERROR(VLOOKUP($A36,디지털강화팀!A:D,4,FALSE),0) -> 28047.664 | S36: =Q36+R36=H36 -> TRUE | U36: =IFERROR(VLOOKUP($A36,플랫폼1!$A:$B,2,FALSE),0) -> 500000 | V36: =IFERROR(VLOOKUP($A36,플랫폼2!$A:$M,12,FALSE),0)+IFERROR(VLOOKUP($A36,플랫폼2!$A:$M,13,FALSE),0) -> 0 | W36: =IFERROR(VLOOKUP($A36,플랫폼2!$A:$M,7,FALSE),0)+IFERROR(VLOOKUP($A36,플랫폼2!$A:$M,12,FALSE),0) -> 0 | X36: 90439.167 | Y36: 90439.167 | Z36: 904391.67 | AA36: =M36=SUM(U36:Z36) -> TRUE
A37: 급료와임금-SC직 | B37: =IFERROR(VLOOKUP($A37,전사손익계산서!$A:$B,2,0),0) -> 337560630 | C37: =B37-E37-D37 -> 25101030 | D37: =IFERROR(VLOOKUP($A37,영업총괄!$A:$K,11,FALSE),0) -> 0 | E37: =SUM(F37:M37) -> 312459600 | F37: =IFERROR(VLOOKUP($A37,소매!A:B,2,FALSE),0) -> 21551900 | G37: =IFERROR(VLOOKUP($A37,도매!A:B,2,FALSE),0) -> 0 | H37: =Q37+R37 -> 282077870 | I37: =IFERROR(VLOOKUP($A37,법인영업팀!A:E,4,FALSE),0) -> 0 | J37: =IFERROR(VLOOKUP($A37,법인영업팀!A:E,5,FALSE),0) -> 0 | K37: =IFERROR(VLOOKUP($A37,법인영업팀!$A:$E,3,FALSE),0) -> 8829830 | L37: =IFERROR(VLOOKUP($A37,소상공인혁신팀!$A:$B,2,FALSE),0) -> 0 | M37: =IFERROR(VLOOKUP($A37,'유통플랫폼사업단 IU'!$A:$F,2,FALSE),0) -> 0 | O37: =B37=C37+D37+E37 -> TRUE | Q37: =IFERROR(VLOOKUP($A37,디지털강화팀!A:C,3,FALSE),0) -> 267973977 | R37: =IFERROR(VLOOKUP($A37,디지털강화팀!A:D,4,FALSE),0) -> 14103893 | S37: =Q37+R37=H37 -> TRUE | U37: =IFERROR(VLOOKUP($A37,플랫폼1!$A:$B,2,FALSE),0) -> 0 | V37: =IFERROR(VLOOKUP($A37,플랫폼2!$A:$M,12,FALSE),0)+IFERROR(VLOOKUP($A37,플랫폼2!$A:$M,13,FALSE),0) -> 0 | W37: =IFERROR(VLOOKUP($A37,플랫폼2!$A:$M,7,FALSE),0)+IFERROR(VLOOKUP($A37,플랫폼2!$A:$M,12,FALSE),0) -> 0 | X37: =IFERROR(VLOOKUP($A37,모바일!$A:$S,17,FALSE),0) -> 0 | Y37: =IFERROR(VLOOKUP($A37,모바일!$A:$S,18,FALSE),0) -> 0 | Z37: =IFERROR(VLOOKUP(A37,플랫폼2!$A:$O,15,0),0) -> 0 | AA37: =M37=SUM(U37:Z37) -> TRUE
A38: 초과근무수당-SC직 | B38: =IFERROR(VLOOKUP($A38,전사손익계산서!$A:$B,2,0),0) -> 57264680 | C38: =B38-E38-D38 -> 4116190 | D38: =IFERROR(VLOOKUP($A38,영업총괄!$A:$K,11,FALSE),0) -> 0 | E38: =SUM(F38:M38) -> 53148490 | F38: =IFERROR(VLOOKUP($A38,소매!A:B,2,FALSE),0) -> 3647700 | G38: =IFERROR(VLOOKUP($A38,도매!A:B,2,FALSE),0) -> 0 | H38: =Q38+R38 -> 47987680 | I38: =IFERROR(VLOOKUP($A38,법인영업팀!A:E,4,FALSE),0) -> 0 | J38: =IFERROR(VLOOKUP($A38,법인영업팀!A:E,5,FALSE),0) -> 0 | K38: =IFERROR(VLOOKUP($A38,법인영업팀!$A:$E,3,FALSE),0) -> 1513110 | L38: =IFERROR(VLOOKUP($A38,소상공인혁신팀!$A:$B,2,FALSE),0) -> 0 | M38: =IFERROR(VLOOKUP($A38,'유통플랫폼사업단 IU'!$A:$F,2,FALSE),0) -> 0 | O38: =B38=C38+D38+E38 -> TRUE | Q38: =IFERROR(VLOOKUP($A38,디지털강화팀!A:C,3,FALSE),0) -> 45588296 | R38: =IFERROR(VLOOKUP($A38,디지털강화팀!A:D,4,FALSE),0) -> 2399384 | S38: =Q38+R38=H38 -> TRUE | U38: =IFERROR(VLOOKUP($A38,플랫폼1!$A:$B,2,FALSE),0) -> 0 | V38: =IFERROR(VLOOKUP($A38,플랫폼2!$A:$M,12,FALSE),0)+IFERROR(VLOOKUP($A38,플랫폼2!$A:$M,13,FALSE),0) -> 0 | W38: =IFERROR(VLOOKUP($A38,플랫폼2!$A:$M,7,FALSE),0)+IFERROR(VLOOKUP($A38,플랫폼2!$A:$M,12,FALSE),0) -> 0 | X38: =IFERROR(VLOOKUP($A38,모바일!$A:$S,17,FALSE),0) -> 0 | Y38: =IFERROR(VLOOKUP($A38,모바일!$A:$S,18,FALSE),0) -> 0 | Z38: =IFERROR(VLOOKUP(A38,플랫폼2!$A:$O,15,0),0) -> 0 | AA38: =M38=SUM(U38:Z38) -> TRUE
A39: 직책수당-SC직 | B39: =IFERROR(VLOOKUP($A39,전사손익계산서!$A:$B,2,0),0) -> 2100000 | C39: =B39-E39-D39 -> 300000 | D39: =IFERROR(VLOOKUP($A39,영업총괄!$A:$K,11,FALSE),0) -> 0 | E39: =SUM(F39:M39) -> 1800000 | F39: =IFERROR(VLOOKUP($A39,소매!A:B,2,FALSE),0) -> 0 | G39: =IFERROR(VLOOKUP($A39,도매!A:B,2,FALSE),0) -> 0 | H39: =Q39+R39 -> 1800000 | I39: =IFERROR(VLOOKUP($A39,법인영업팀!A:E,4,FALSE),0) -> 0 | J39: =IFERROR(VLOOKUP($A39,법인영업팀!A:E,5,FALSE),0) -> 0 | K39: =IFERROR(VLOOKUP($A39,법인영업팀!$A:$E,3,FALSE),0) -> 0 | L39: =IFERROR(VLOOKUP($A39,소상공인혁신팀!$A:$B,2,FALSE),0) -> 0 | M39: =IFERROR(VLOOKUP($A39,'유통플랫폼사업단 IU'!$A:$F,2,FALSE),0) -> 0 | O39: =B39=C39+D39+E39 -> TRUE | Q39: =IFERROR(VLOOKUP($A39,디지털강화팀!A:C,3,FALSE),0) -> 1710000 | R39: =IFERROR(VLOOKUP($A39,디지털강화팀!A:D,4,FALSE),0) -> 90000 | S39: =Q39+R39=H39 -> TRUE | U39: =IFERROR(VLOOKUP($A39,플랫폼1!$A:$B,2,FALSE),0) -> 0 | V39: =IFERROR(VLOOKUP($A39,플랫폼2!$A:$M,12,FALSE),0)+IFERROR(VLOOKUP($A39,플랫폼2!$A:$M,13,FALSE),0) -> 0 | W39: =IFERROR(VLOOKUP($A39,플랫폼2!$A:$M,7,FALSE),0)+IFERROR(VLOOKUP($A39,플랫폼2!$A:$M,12,FALSE),0) -> 0 | X39: =IFERROR(VLOOKUP($A39,모바일!$A:$S,17,FALSE),0) -> 0 | Y39: =IFERROR(VLOOKUP($A39,모바일!$A:$S,18,FALSE),0) -> 0 | Z39: =IFERROR(VLOOKUP(A39,플랫폼2!$A:$O,15,0),0) -> 0 | AA39: =M39=SUM(U39:Z39) -> TRUE
A40: 휴일근무수당-SC직 | B40: =IFERROR(VLOOKUP($A40,전사손익계산서!$A:$B,2,0),0) -> 0 | C40: =B40-E40-D40 -> 0 | D40: =IFERROR(VLOOKUP($A40,영업총괄!$A:$K,11,FALSE),0) -> 0 | E40: =SUM(F40:M40) -> 0 | F40: =IFERROR(VLOOKUP($A40,소매!A:B,2,FALSE),0) -> 0 | G40: =IFERROR(VLOOKUP($A40,도매!A:B,2,FALSE),0) -> 0 | H40: =Q40+R40 -> 0 | I40: =IFERROR(VLOOKUP($A40,법인영업팀!A:E,4,FALSE),0) -> 0 | J40: =IFERROR(VLOOKUP($A40,법인영업팀!A:E,5,FALSE),0) -> 0 | K40: =IFERROR(VLOOKUP($A40,법인영업팀!$A:$E,3,FALSE),0) -> 0 | L40: =IFERROR(VLOOKUP($A40,소상공인혁신팀!$A:$B,2,FALSE),0) -> 0 | M40: =IFERROR(VLOOKUP($A40,'유통플랫폼사업단 IU'!$A:$F,2,FALSE),0) -> 0 | O40: =B40=C40+D40+E40 -> TRUE | Q40: =IFERROR(VLOOKUP($A40,디지털강화팀!A:C,3,FALSE),0) -> 0 | R40: =IFERROR(VLOOKUP($A40,디지털강화팀!A:D,4,FALSE),0) -> 0 | S40: =Q40+R40=H40 -> TRUE | U40: =IFERROR(VLOOKUP($A40,플랫폼1!$A:$B,2,FALSE),0) -> 0 | V40: =IFERROR(VLOOKUP($A40,플랫폼2!$A:$M,12,FALSE),0)+IFERROR(VLOOKUP($A40,플랫폼2!$A:$M,13,FALSE),0) -> 0 | W40: =IFERROR(VLOOKUP($A40,플랫폼2!$A:$M,7,FALSE),0)+IFERROR(VLOOKUP($A40,플랫폼2!$A:$M,12,FALSE),0) -> 0 | X40: =IFERROR(VLOOKUP($A40,모바일!$A:$S,17,FALSE),0) -> 0 | Y40: =IFERROR(VLOOKUP($A40,모바일!$A:$S,18,FALSE),0) -> 0 | Z40: =IFERROR(VLOOKUP(A40,플랫폼2!$A:$O,15,0),0) -> 0 | AA40: =M40=SUM(U40:Z40) -> TRUE
A41: 연차수당-SC직 | B41: =IFERROR(VLOOKUP($A41,전사손익계산서!$A:$B,2,0),0) -> 0 | C41: =B41-E41-D41 -> 0 | D41: =IFERROR(VLOOKUP($A41,영업총괄!$A:$K,11,FALSE),0) -> 0 | E41: =SUM(F41:M41) -> 0 | F41: =IFERROR(VLOOKUP($A41,소매!A:B,2,FALSE),0) -> 0 | G41: =IFERROR(VLOOKUP($A41,도매!A:B,2,FALSE),0) -> 0 | H41: =Q41+R41 -> 0 | I41: =IFERROR(VLOOKUP($A41,법인영업팀!A:E,4,FALSE),0) -> 0 | J41: =IFERROR(VLOOKUP($A41,법인영업팀!A:E,5,FALSE),0) -> 0 | K41: =IFERROR(VLOOKUP($A41,법인영업팀!$A:$E,3,FALSE),0) -> 0 | L41: =IFERROR(VLOOKUP($A41,소상공인혁신팀!$A:$B,2,FALSE),0) -> 0 | M41: =IFERROR(VLOOKUP($A41,'유통플랫폼사업단 IU'!$A:$F,2,FALSE),0) -> 0 | O41: =B41=C41+D41+E41 -> TRUE | Q41: =IFERROR(VLOOKUP($A41,디지털강화팀!A:C,3,FALSE),0) -> 0 | R41: =IFERROR(VLOOKUP($A41,디지털강화팀!A:D,4,FALSE),0) -> 0 | S41: =Q41+R41=H41 -> TRUE | U41: =IFERROR(VLOOKUP($A41,플랫폼1!$A:$B,2,FALSE),0) -> 0 | V41: =IFERROR(VLOOKUP($A41,플랫폼2!$A:$M,12,FALSE),0)+IFERROR(VLOOKUP($A41,플랫폼2!$A:$M,13,FALSE),0) -> 0 | W41: =IFERROR(VLOOKUP($A41,플랫폼2!$A:$M,7,FALSE),0)+IFERROR(VLOOKUP($A41,플랫폼2!$A:$M,12,FALSE),0) -> 0 | X41: =IFERROR(VLOOKUP($A41,모바일!$A:$S,17,FALSE),0) -> 0 | Y41: =IFERROR(VLOOKUP($A41,모바일!$A:$S,18,FALSE),0) -> 0 | Z41: =IFERROR(VLOOKUP(A41,플랫폼2!$A:$O,15,0),0) -> 0 | AA41: =M41=SUM(U41:Z41) -> TRUE
A42: 제수당기타-기타직 | B42: =IFERROR(VLOOKUP($A42,전사손익계산서!$A:$B,2,0),0) -> 0 | C42: =B42-E42-D42 -> 0 | D42: =IFERROR(VLOOKUP($A42,영업총괄!$A:$K,11,FALSE),0) -> 0 | E42: =SUM(F42:M42) -> 0 | F42: =IFERROR(VLOOKUP($A42,소매!A:B,2,FALSE),0) -> 0 | G42: =IFERROR(VLOOKUP($A42,도매!A:B,2,FALSE),0) -> 0 | H42: =Q42+R42 -> 0 | I42: =IFERROR(VLOOKUP($A42,법인영업팀!A:E,4,FALSE),0) -> 0 | J42: =IFERROR(VLOOKUP($A42,법인영업팀!A:E,5,FALSE),0) -> 0 | K42: =IFERROR(VLOOKUP($A42,법인영업팀!$A:$E,3,FALSE),0) -> 0 | L42: =IFERROR(VLOOKUP($A42,소상공인혁신팀!$A:$B,2,FALSE),0) -> 0 | M42: =IFERROR(VLOOKUP($A42,'유통플랫폼사업단 IU'!$A:$F,2,FALSE),0) -> 0 | O42: =B42=C42+D42+E42 -> TRUE | Q42: =IFERROR(VLOOKUP($A42,디지털강화팀!A:C,3,FALSE),0) -> 0 | R42: =IFERROR(VLOOKUP($A42,디지털강화팀!A:D,4,FALSE),0) -> 0 | S42: =Q42+R42=H42 -> TRUE | U42: =IFERROR(VLOOKUP($A42,플랫폼1!$A:$B,2,FALSE),0) -> 0 | V42: =IFERROR(VLOOKUP($A42,플랫폼2!$A:$M,12,FALSE),0)+IFERROR(VLOOKUP($A42,플랫폼2!$A:$M,13,FALSE),0) -> 0 | W42: =IFERROR(VLOOKUP($A42,플랫폼2!$A:$M,7,FALSE),0)+IFERROR(VLOOKUP($A42,플랫폼2!$A:$M,12,FALSE),0) -> 0 | X42: =IFERROR(VLOOKUP($A42,모바일!$A:$S,17,FALSE),0) -> 0 | Y42: =IFERROR(VLOOKUP($A42,모바일!$A:$S,18,FALSE),0) -> 0 | Z42: =IFERROR(VLOOKUP(A42,플랫폼2!$A:$O,15,0),0) -> 0 | AA42: =M42=SUM(U42:Z42) -> TRUE
...

Sheet 소매
A1: 계정명 | B1: 합계 | C1: 유통영업혁신단 | D1: 소매 본부/파트 | E1: 소매강화팀 | F1: 현장지원팀 | G1: - | H1: 강북소매지사 | I1: 강동소매지사 | J1: 강남소매지사 | K1: 강서소매지사 | L1: 남부소매지사 | M1: 인천소매지사 | N1: 부산소매지사 | O1: 대구소매지사 | P1: 충청소매지사 | Q1: 호남소매지사 | S1: 본부별 지원TF> | T1: 강북 본부/파트 | U1: 강남 본부/파트 | V1: 강서 본부/파트 | W1: 동부 본부/파트 | X1: 서부 본부/파트
A2: 매 출 | B2: =SUM(C2:Q2) -> 2.2953776e+10 | C2: =IFERROR(VLOOKUP($A2,유통영업혁신단!$A$1:$L$254,10,FALSE),0) -> 0 | D2: =U2+W2+X2+T2+V2 -> 10515.692 | E2: =IFERROR(VLOOKUP($A2,'유통영업혁신단 IU'!$A:$G,4,FALSE),0) -> -675549571 | H2: =IFERROR(VLOOKUP($A2,강북영업본부!$A$1:$D$255,3,FALSE),0) -> 2132386788 | I2: =IFERROR(VLOOKUP($A2,강북영업본부!$A$1:$D$255,4,FALSE),0) -> 2034571274 | J2: =IFERROR(VLOOKUP($A2,강남영업본부!$A$1:$G$255,3,FALSE),0) -> 1752881877 | K2: =IFERROR(VLOOKUP($A2,강서영업본부!$A$1:$G$255,3,FALSE),0) -> 3228823195 | L2: =IFERROR(VLOOKUP($A2,강남영업본부!$A$1:$G$255,4,FALSE),0) -> 2358639866 | M2: =IFERROR(VLOOKUP($A2,강서영업본부!$A$1:$G$255,4,FALSE),0) -> 2115775055 | N2: =IFERROR(VLOOKUP($A2,동부영업본부!$A$1:$H$255,3,FALSE),0) -> 3038681723 | O2: =IFERROR(VLOOKUP($A2,동부영업본부!$A$1:$H$255,4,FALSE),0) -> 2514481059 | P2: =IFERROR(VLOOKUP($A2,서부영업본부!$A$1:$H$255,3,FALSE),0) -> 2187789434 | Q2: =IFERROR(VLOOKUP($A2,서부영업본부!$A$1:$H$255,4,FALSE),0) -> 2265285232 | T2: =IFERROR(VLOOKUP($A2,강북영업본부!$A$1:$H$254,5,FALSE),0) -> 0 | U2: =IFERROR(VLOOKUP($A2,강남영업본부!$A$1:$J$254,7,FALSE),0) -> 10515.692 | V2: =IFERROR(VLOOKUP($A2,강서영업본부!$A$1:$J$254,7,FALSE),0) -> 0 | W2: =IFERROR(VLOOKUP($A2,동부영업본부!$A$1:$H$254,5,FALSE),0) -> 0 | X2: =IFERROR(VLOOKUP($A2,서부영업본부!$A$1:$H$255,5,FALSE),0) -> 0
A3: 상 품 매 출 | B3: =SUM(C3:Q3) -> 10842518892 | C3: =IFERROR(VLOOKUP($A3,유통영업혁신단!$A$1:$L$254,10,FALSE),0) -> 0 | D3: =U3+W3+X3+T3+V3 -> 0 | E3: =IFERROR(VLOOKUP($A3,'유통영업혁신단 IU'!$A:$G,4,FALSE),0) -> 0 | H3: =IFERROR(VLOOKUP($A3,강북영업본부!$A$1:$D$255,3,FALSE),0) -> 1067896866 | I3: =IFERROR(VLOOKUP($A3,강북영업본부!$A$1:$D$255,4,FALSE),0) -> 963477491 | J3: =IFERROR(VLOOKUP($A3,강남영업본부!$A$1:$G$255,3,FALSE),0) -> 850593273 | K3: =IFERROR(VLOOKUP($A3,강서영업본부!$A$1:$G$255,3,FALSE),0) -> 1517049707 | L3: =IFERROR(VLOOKUP($A3,강남영업본부!$A$1:$G$255,4,FALSE),0) -> 1081865328 | M3: =IFERROR(VLOOKUP($A3,강서영업본부!$A$1:$G$255,4,FALSE),0) -> 915824968 | N3: =IFERROR(VLOOKUP($A3,동부영업본부!$A$1:$H$255,3,FALSE),0) -> 1349479097 | O3: =IFERROR(VLOOKUP($A3,동부영업본부!$A$1:$H$255,4,FALSE),0) -> 1128186630 | P3: =IFERROR(VLOOKUP($A3,서부영업본부!$A$1:$H$255,3,FALSE),0) -> 952855043 | Q3: =IFERROR(VLOOKUP($A3,서부영업본부!$A$1:$H$255,4,FALSE),0) -> 1015290489 | T3: =IFERROR(VLOOKUP($A3,강북영업본부!$A$1:$H$254,5,FALSE),0) -> 0 | U3: =IFERROR(VLOOKUP($A3,강남영업본부!$A$1:$J$254,7,FALSE),0) -> 0 | V3: =IFERROR(VLOOKUP($A3,강서영업본부!$A$1:$J$254,7,FALSE),0) -> 0 | W3: =IFERROR(VLOOKUP($A3,동부영업본부!$A$1:$H$254,5,FALSE),0) -> 0 | X3: =IFERROR(VLOOKUP($A3,서부영업본부!$A$1:$H$255,5,FALSE),0) -> 0
A4: 상품단말기매출-고객 | B4: =SUM(C4:Q4) -> 34464139 | C4: =IFERROR(VLOOKUP($A4,유통영업혁신단!$A$1:$L$254,10,FALSE),0) -> 0 | D4: =U4+W4+X4+T4+V4 -> 0 | E4: =IFERROR(VLOOKUP($A4,'유통영업혁신단 IU'!$A:$G,4,FALSE),0) -> 0 | H4: =IFERROR(VLOOKUP($A4,강북영업본부!$A$1:$D$255,3,FALSE),0) -> 955454 | I4: =IFERROR(VLOOKUP($A4,강북영업본부!$A$1:$D$255,4,FALSE),0) -> 1102636 | J4: =IFERROR(VLOOKUP($A4,강남영업본부!$A$1:$G$255,3,FALSE),0) -> 963909 | K4: =IFERROR(VLOOKUP($A4,강서영업본부!$A$1:$G$255,3,FALSE),0) -> 6407718 | L4: =IFERROR(VLOOKUP($A4,강남영업본부!$A$1:$G$255,4,FALSE),0) -> 1729364 | M4: =IFERROR(VLOOKUP($A4,강서영업본부!$A$1:$G$255,4,FALSE),0) -> 4518136 | N4: =IFERROR(VLOOKUP($A4,동부영업본부!$A$1:$H$255,3,FALSE),0) -> 5522545 | O4: =IFERROR(VLOOKUP($A4,동부영업본부!$A$1:$H$255,4,FALSE),0) -> 6712899 | P4: =IFERROR(VLOOKUP($A4,서부영업본부!$A$1:$H$255,3,FALSE),0) -> 2111091 | Q4: =IFERROR(VLOOKUP($A4,서부영업본부!$A$1:$H$255,4,FALSE),0) -> 4440387 | T4: =IFERROR(VLOOKUP($A4,강북영업본부!$A$1:$H$254,5,FALSE),0) -> 0 | U4: =IFERROR(VLOOKUP($A4,강남영업본부!$A$1:$J$254,7,FALSE),0) -> 0 | V4: =IFERROR(VLOOKUP($A4,강서영업본부!$A$1:$J$254,7,FALSE),0) -> 0 | W4: =IFERROR(VLOOKUP($A4,동부영업본부!$A$1:$H$254,5,FALSE),0) -> 0 | X4: =IFERROR(VLOOKUP($A4,서부영업본부!$A$1:$H$255,5,FALSE),0) -> 0
A5: 상품단말기매출-판매점 | B5: =SUM(C5:Q5) -> 0 | C5: =IFERROR(VLOOKUP($A5,유통영업혁신단!$A$1:$L$254,10,FALSE),0) -> 0 | D5: =U5+W5+X5+T5+V5 -> 0 | E5: =IFERROR(VLOOKUP($A5,'유통영업혁신단 IU'!$A:$G,4,FALSE),0) -> 0 | H5: =IFERROR(VLOOKUP($A5,강북영업본부!$A$1:$D$255,3,FALSE),0) -> 0 | I5: =IFERROR(VLOOKUP($A5,강북영업본부!$A$1:$D$255,4,FALSE),0) -> 0 | J5: =IFERROR(VLOOKUP($A5,강남영업본부!$A$1:$G$255,3,FALSE),0) -> 0 | K5: =IFERROR(VLOOKUP($A5,강서영업본부!$A$1:$G$255,3,FALSE),0) -> 0 | L5: =IFERROR(VLOOKUP($A5,강남영업본부!$A$1:$G$255,4,FALSE),0) -> 0 | M5: =IFERROR(VLOOKUP($A5,강서영업본부!$A$1:$G$255,4,FALSE),0) -> 0 | N5: =IFERROR(VLOOKUP($A5,동부영업본부!$A$1:$H$255,3,FALSE),0) -> 0 | O5: =IFERROR(VLOOKUP($A5,동부영업본부!$A$1:$H$255,4,FALSE),0) -> 0 | P5: =IFERROR(VLOOKUP($A5,서부영업본부!$A$1:$H$255,3,FALSE),0) -> 0 | Q5: =IFERROR(VLOOKUP($A5,서부영업본부!$A$1:$H$255,4,FALSE),0) -> 0 | T5: =IFERROR(VLOOKUP($A5,강북영업본부!$A$1:$H$254,5,FALSE),0) -> 0 | U5: =IFERROR(VLOOKUP($A5,강남영업본부!$A$1:$J$254,7,FALSE),0) -> 0 | V5: =IFERROR(VLOOKUP($A5,강서영업본부!$A$1:$J$254,7,FALSE),0) -> 0 | W5: =IFERROR(VLOOKUP($A5,동부영업본부!$A$1:$H$254,5,FALSE),0) -> 0 | X5: =IFERROR(VLOOKUP($A5,서부영업본부!$A$1:$H$255,5,FALSE),0) -> 0
A6: 상품매출액-대형유통 | B6: =SUM(C6:Q6) -> 0 | C6: =IFERROR(VLOOKUP($A6,유통영업혁신단!$A$1:$L$254,10,FALSE),0) -> 0 | D6: =U6+W6+X6+T6+V6 -> 0 | E6: =IFERROR(VLOOKUP($A6,'유통영업혁신단 IU'!$A:$G,4,FALSE),0) -> 0 | H6: =IFERROR(VLOOKUP($A6,강북영업본부!$A$1:$D$255,3,FALSE),0) -> 0 | I6: =IFERROR(VLOOKUP($A6,강북영업본부!$A$1:$D$255,4,FALSE),0) -> 0 | J6: =IFERROR(VLOOKUP($A6,강남영업본부!$A$1:$G$255,3,FALSE),0) -> 0 | K6: =IFERROR(VLOOKUP($A6,강서영업본부!$A$1:$G$255,3,FALSE),0) -> 0 | L6: =IFERROR(VLOOKUP($A6,강남영업본부!$A$1:$G$255,4,FALSE),0) -> 0 | M6: =IFERROR(VLOOKUP($A6,강서영업본부!$A$1:$G$255,4,FALSE),0) -> 0 | N6: =IFERROR(VLOOKUP($A6,동부영업본부!$A$1:$H$255,3,FALSE),0) -> 0 | O6: =IFERROR(VLOOKUP($A6,동부영업본부!$A$1:$H$255,4,FALSE),0) -> 0 | P6: =IFERROR(VLOOKUP($A6,서부영업본부!$A$1:$H$255,3,FALSE),0) -> 0 | Q6: =IFERROR(VLOOKUP($A6,서부영업본부!$A$1:$H$255,4,FALSE),0) -> 0 | T6: =IFERROR(VLOOKUP($A6,강북영업본부!$A$1:$H$254,5,FALSE),0) -> 0 | U6: =IFERROR(VLOOKUP($A6,강남영업본부!$A$1:$J$254,7,FALSE),0) -> 0 | V6: =IFERROR(VLOOKUP($A6,강서영업본부!$A$1:$J$254,7,FALSE),0) -> 0 | W6: =IFERROR(VLOOKUP($A6,동부영업본부!$A$1:$H$254,5,FALSE),0) -> 0 | X6: =IFERROR(VLOOKUP($A6,서부영업본부!$A$1:$H$255,5,FALSE),0) -> 0
A7: 상품매출액-채권승계 | B7: =SUM(C7:Q7) -> 10221832695 | C7: =IFERROR(VLOOKUP($A7,유통영업혁신단!$A$1:$L$254,10,FALSE),0) -> 0 | D7: =U7+W7+X7+T7+V7 -> 0 | E7: =IFERROR(VLOOKUP($A7,'유통영업혁신단 IU'!$A:$G,4,FALSE),0) -> 0 | H7: =IFERROR(VLOOKUP($A7,강북영업본부!$A$1:$D$255,3,FALSE),0) -> 1018572682 | I7: =IFERROR(VLOOKUP($A7,강북영업본부!$A$1:$D$255,4,FALSE),0) -> 917853037 | J7: =IFERROR(VLOOKUP($A7,강남영업본부!$A$1:$G$255,3,FALSE),0) -> 813215636 | K7: =IFERROR(VLOOKUP($A7,강서영업본부!$A$1:$G$255,3,FALSE),0) -> 1394211976 | L7: =IFERROR(VLOOKUP($A7,강남영업본부!$A$1:$G$255,4,FALSE),0) -> 1029411327 | M7: =IFERROR(VLOOKUP($A7,강서영업본부!$A$1:$G$255,4,FALSE),0) -> 857436331 | N7: =IFERROR(VLOOKUP($A7,동부영업본부!$A$1:$H$255,3,FALSE),0) -> 1259317185 | O7: =IFERROR(VLOOKUP($A7,동부영업본부!$A$1:$H$255,4,FALSE),0) -> 1078212721 | P7: =IFERROR(VLOOKUP($A7,서부영업본부!$A$1:$H$255,3,FALSE),0) -> 909517133 | Q7: =IFERROR(VLOOKUP($A7,서부영업본부!$A$1:$H$255,4,FALSE),0) -> 944084667 | T7: =IFERROR(VLOOKUP($A7,강북영업본부!$A$1:$H$254,5,FALSE),0) -> 0 | U7: =IFERROR(VLOOKUP($A7,강남영업본부!$A$1:$J$254,7,FALSE),0) -> 0 | V7: =IFERROR(VLOOKUP($A7,강서영업본부!$A$1:$J$254,7,FALSE),0) -> 0 | W7: =IFERROR(VLOOKUP($A7,동부영업본부!$A$1:$H$254,5,FALSE),0) -> 0 | X7: =IFERROR(VLOOKUP($A7,서부영업본부!$A$1:$H$255,5,FALSE),0) -> 0
A8: 상품매출액-신용카드매출 | B8: =SUM(C8:Q8) -> 260761794 | C8: =IFERROR(VLOOKUP($A8,유통영업혁신단!$A$1:$L$254,10,FALSE),0) -> 0 | D8: =U8+W8+X8+T8+V8 -> 0 | E8: =IFERROR(VLOOKUP($A8,'유통영업혁신단 IU'!$A:$G,4,FALSE),0) -> 0 | H8: =IFERROR(VLOOKUP($A8,강북영업본부!$A$1:$D$255,3,FALSE),0) -> 22032790 | I8: =IFERROR(VLOOKUP($A8,강북영업본부!$A$1:$D$255,4,FALSE),0) -> 19719489 | J8: =IFERROR(VLOOKUP($A8,강남영업본부!$A$1:$G$255,3,FALSE),0) -> 20506682 | K8: =IFERROR(VLOOKUP($A8,강서영업본부!$A$1:$G$255,3,FALSE),0) -> 48869385 | L8: =IFERROR(VLOOKUP($A8,강남영업본부!$A$1:$G$255,4,FALSE),0) -> 22121199 | M8: =IFERROR(VLOOKUP($A8,강서영업본부!$A$1:$G$255,4,FALSE),0) -> 18984969 | N8: =IFERROR(VLOOKUP($A8,동부영업본부!$A$1:$H$255,3,FALSE),0) -> 41274436 | O8: =IFERROR(VLOOKUP($A8,동부영업본부!$A$1:$H$255,4,FALSE),0) -> 17077382 | P8: =IFERROR(VLOOKUP($A8,서부영업본부!$A$1:$H$255,3,FALSE),0) -> 19804521 | Q8: =IFERROR(VLOOKUP($A8,서부영업본부!$A$1:$H$255,4,FALSE),0) -> 30370941 | T8: =IFERROR(VLOOKUP($A8,강북영업본부!$A$1:$H$254,5,FALSE),0) -> 0 | U8: =IFERROR(VLOOKUP($A8,강남영업본부!$A$1:$J$254,7,FALSE),0) -> 0 | V8: =IFERROR(VLOOKUP($A8,강서영업본부!$A$1:$J$254,7,FALSE),0) -> 0 | W8: =IFERROR(VLOOKUP($A8,동부영업본부!$A$1:$H$254,5,FALSE),0) -> 0 | X8: =IFERROR(VLOOKUP($A8,서부영업본부!$A$1:$H$255,5,FALSE),0) -> 0
