Workbook

Sheet 종합
A1: 계정명 | B1: 합계 | C1: 전사 공통비 (경총) | D1: 채널공통비 (영총/영기/역강 등) | E1: 채널별 소계 | F1: 유통영업혁신단 | I1: 법인영업혁신단 | M1: 유통플랫폼 | O1: 유통플랫폼사업단 | V1: 계정명 | W1: 유통플랫폼사업단
F2: 소매 | G2: 도매 | H2: 디지털 | I2: 기업/공공 | J2: IoT | K2: 법인영업 | L2: 소상공인 | O2: 코코넛 | P2: 굿바이 | Q2: 시연폰 | R2: AS대행 | S2: 임대폰대행 | T2: 리본(모바일/신촌) | W2: 코코넛 | X2: 굿바이 | Y2: 시연폰 | Z2: 리본(모바일+신촌) | AA2: 기타(AS대행/임대폰)
A3: 매 출 | B3: ='1월'!B3+'2월'!B3+'3월'!B3+'4월'!B3+'5월'!B3+'6월'!B3+'7월'!B3+'8월'!B3+'9월'!B3+'10월'!B3+'11월'!B3+'12월'!B3 -> 753458029468 | C3: ='1월'!C3+'2월'!C3+'3월'!C3+'4월'!C3+'5월'!C3+'6월'!C3+'7월'!C3+'8월'!C3+'9월'!C3+'10월'!C3+'11월'!C3+'12월'!C3 -> -20632121414 | D3: ='1월'!D3+'2월'!D3+'3월'!D3+'4월'!D3+'5월'!D3+'6월'!D3+'7월'!D3+'8월'!D3+'9월'!D3+'10월'!D3+'11월'!D3+'12월'!D3 -> 2370259975 | E3: ='1월'!E3+'2월'!E3+'3월'!E3+'4월'!E3+'5월'!E3+'6월'!E3+'7월'!E3+'8월'!E3+'9월'!E3+'10월'!E3+'11월'!E3+'12월'!E3 -> 771719890907 | F3: ='1월'!F3+'2월'!F3+'3월'!F3+'4월'!F3+'5월'!F3+'6월'!F3+'7월'!F3+'8월'!F3+'9월'!F3+'10월'!F3+'11월'!F3+'12월'!F3 -> 3.3494819e+11 | G3: ='1월'!H3+'2월'!G3+'3월'!G3+'4월'!G3+'5월'!G3+'6월'!G3+'7월'!G3+'8월'!G3+'9월'!G3+'10월'!G3+'11월'!G3+'12월'!G3 -> 4.6718302e+10 | H3: ='1월'!J3+'2월'!H3+'3월'!H3+'4월'!H3+'5월'!H3+'6월'!H3+'7월'!H3+'8월'!H3+'9월'!H3+'10월'!H3+'11월'!H3+'12월'!H3 -> 197616419350 | I3: ='1월'!K3+'2월'!I3+'3월'!I3+'4월'!I3+'5월'!I3+'6월'!I3+'7월'!I3+'8월'!I3+'9월'!I3+'10월'!I3+'11월'!I3+'12월'!I3 -> 13381087574 | J3: ='1월'!L3+'2월'!J3+'3월'!J3+'4월'!J3+'5월'!J3+'6월'!J3+'7월'!J3+'8월'!J3+'9월'!J3+'10월'!J3+'11월'!J3+'12월'!J3 -> 9138411901 | K3: ='1월'!M3+'2월'!K3+'3월'!K3+'4월'!K3+'5월'!K3+'6월'!K3+'7월'!K3+'8월'!K3+'9월'!K3+'10월'!K3+'11월'!K3+'12월'!K3 -> 97967838290 | L3: ='1월'!N3+'2월'!L3+'3월'!L3+'4월'!L3+'5월'!L3+'6월'!L3+'7월'!L3+'8월'!L3+'9월'!L3+'10월'!L3+'11월'!L3+'12월'!L3 -> 16291219584 | M3: ='1월'!O3+'2월'!M3+'3월'!M3+'4월'!M3+'5월'!M3+'6월'!M3+'7월'!M3+'8월'!M3+'9월'!M3+'10월'!M3+'11월'!M3+'12월'!M3 -> 55658424026 | O3: =IFERROR(VLOOKUP($A3,[1]플랫폼1!$A:$B,2,FALSE),0) -> 6682762318 | P3: =IFERROR(VLOOKUP($A3,[1]플랫폼2!$A:$M,12,FALSE),0)+IFERROR(VLOOKUP($A3,[1]플랫폼2!$A:$M,13,FALSE),0) -> 10165249491 | Q3: =IFERROR(VLOOKUP($A3,[1]플랫폼2!$A:$M,7,FALSE),0)+IFERROR(VLOOKUP($A3,[1]플랫폼2!$A:$M,12,FALSE),0) -> 37119426563 | R3: =IFERROR(VLOOKUP($A3,[1]모바일!$A:$S,17,FALSE),0) -> 357710000 | S3: =IFERROR(VLOOKUP($A3,[1]모바일!$A:$S,18,FALSE),0) -> 441954966 | T3: =IFERROR(VLOOKUP(A3,[1]플랫폼2!$A:$O,15,0),0) -> 891320688 | V3: 매 출 | W3: =VLOOKUP(V3,$A:$S,15,0) -> 6682762318 | X3: =VLOOKUP(V3,$A:$S,16,0) -> 10165249491 | Y3: =VLOOKUP(V3,$A:$S,17,0) -> 37119426563 | Z3: =VLOOKUP(V3,$A:$S,18,0) -> 357710000 | AA3: =VLOOKUP(V3,$A:$S,19,0) -> 441954966
A4: 상 품 매 출 | B4: ='1월'!B4+'2월'!B4+'3월'!B4+'4월'!B4+'5월'!B4+'6월'!B4+'7월'!B4+'8월'!B4+'9월'!B4+'10월'!B4+'11월'!B4+'12월'!B4 -> 467696067414 | C4: ='1월'!C4+'2월'!C4+'3월'!C4+'4월'!C4+'5월'!C4+'6월'!C4+'7월'!C4+'8월'!C4+'9월'!C4+'10월'!C4+'11월'!C4+'12월'!C4 -> 1582917344 | D4: ='1월'!D4+'2월'!D4+'3월'!D4+'4월'!D4+'5월'!D4+'6월'!D4+'7월'!D4+'8월'!D4+'9월'!D4+'10월'!D4+'11월'!D4+'12월'!D4 -> 794310339 | E4: ='1월'!E4+'2월'!E4+'3월'!E4+'4월'!E4+'5월'!E4+'6월'!E4+'7월'!E4+'8월'!E4+'9월'!E4+'10월'!E4+'11월'!E4+'12월'!E4 -> 465318839731 | F4: ='1월'!F4+'2월'!F4+'3월'!F4+'4월'!F4+'5월'!F4+'6월'!F4+'7월'!F4+'8월'!F4+'9월'!F4+'10월'!F4+'11월'!F4+'12월'!F4 -> 177125950486 | G4: ='1월'!H4+'2월'!G4+'3월'!G4+'4월'!G4+'5월'!G4+'6월'!G4+'7월'!G4+'8월'!G4+'9월'!G4+'10월'!G4+'11월'!G4+'12월'!G4 -> 3752066349 | H4: ='1월'!J4+'2월'!H4+'3월'!H4+'4월'!H4+'5월'!H4+'6월'!H4+'7월'!H4+'8월'!H4+'9월'!H4+'10월'!H4+'11월'!H4+'12월'!H4 -> 144601540733 | I4: ='1월'!K4+'2월'!I4+'3월'!I4+'4월'!I4+'5월'!I4+'6월'!I4+'7월'!I4+'8월'!I4+'9월'!I4+'10월'!I4+'11월'!I4+'12월'!I4 -> 4342427594 | J4: ='1월'!L4+'2월'!J4+'3월'!J4+'4월'!J4+'5월'!J4+'6월'!J4+'7월'!J4+'8월'!J4+'9월'!J4+'10월'!J4+'11월'!J4+'12월'!J4 -> 168737180 | K4: ='1월'!M4+'2월'!K4+'3월'!K4+'4월'!K4+'5월'!K4+'6월'!K4+'7월'!K4+'8월'!K4+'9월'!K4+'10월'!K4+'11월'!K4+'12월'!K4 -> 83027784583 | L4: ='1월'!N4+'2월'!L4+'3월'!L4+'4월'!L4+'5월'!L4+'6월'!L4+'7월'!L4+'8월'!L4+'9월'!L4+'10월'!L4+'11월'!L4+'12월'!L4 -> 1284494654 | M4: ='1월'!O4+'2월'!M4+'3월'!M4+'4월'!M4+'5월'!M4+'6월'!M4+'7월'!M4+'8월'!M4+'9월'!M4+'10월'!M4+'11월'!M4+'12월'!M4 -> 51015838152 | O4: =IFERROR(VLOOKUP($A4,[1]플랫폼1!$A:$B,2,FALSE),0) -> 4557133512 | P4: =IFERROR(VLOOKUP($A4,[1]플랫폼2!$A:$M,12,FALSE),0)+IFERROR(VLOOKUP($A4,[1]플랫폼2!$A:$M,13,FALSE),0) -> 9035257470 | Q4: =IFERROR(VLOOKUP($A4,[1]플랫폼2!$A:$M,7,FALSE),0)+IFERROR(VLOOKUP($A4,[1]플랫폼2!$A:$M,12,FALSE),0) -> 36850308300 | R4: =IFERROR(VLOOKUP($A4,[1]모바일!$A:$S,17,FALSE),0) -> 0 | S4: =IFERROR(VLOOKUP($A4,[1]모바일!$A:$S,18,FALSE),0) -> 0 | T4: =IFERROR(VLOOKUP(A4,[1]플랫폼2!$A:$O,15,0),0) -> 573138870 | V4: 상 품 매 출 | W4: =VLOOKUP(V4,$A:$S,15,0) -> 4557133512 | X4: =VLOOKUP(V4,$A:$S,16,0) -> 9035257470 | Y4: =VLOOKUP(V4,$A:$S,17,0) -> 36850308300 | Z4: =VLOOKUP(V4,$A:$S,18,0) -> 0 | AA4: =VLOOKUP(V4,$A:$S,19,0) -> 0
A5: 상품단말기매출-고객 | B5: ='1월'!B5+'2월'!B5+'3월'!B5+'4월'!B5+'5월'!B5+'6월'!B5+'7월'!B5+'8월'!B5+'9월'!B5+'10월'!B5+'11월'!B5+'12월'!B5 -> 154445609578 | C5: ='1월'!C5+'2월'!C5+'3월'!C5+'4월'!C5+'5월'!C5+'6월'!C5+'7월'!C5+'8월'!C5+'9월'!C5+'10월'!C5+'11월'!C5+'12월'!C5 -> 978744394 | D5: ='1월'!D5+'2월'!D5+'3월'!D5+'4월'!D5+'5월'!D5+'6월'!D5+'7월'!D5+'8월'!D5+'9월'!D5+'10월'!D5+'11월'!D5+'12월'!D5 -> 776398697 | E5: ='1월'!E5+'2월'!E5+'3월'!E5+'4월'!E5+'5월'!E5+'6월'!E5+'7월'!E5+'8월'!E5+'9월'!E5+'10월'!E5+'11월'!E5+'12월'!E5 -> 152690466487 | F5: ='1월'!F5+'2월'!F5+'3월'!F5+'4월'!F5+'5월'!F5+'6월'!F5+'7월'!F5+'8월'!F5+'9월'!F5+'10월'!F5+'11월'!F5+'12월'!F5 -> 692356879 | G5: ='1월'!H5+'2월'!G5+'3월'!G5+'4월'!G5+'5월'!G5+'6월'!G5+'7월'!G5+'8월'!G5+'9월'!G5+'10월'!G5+'11월'!G5+'12월'!G5 -> 3450105232 | H5: ='1월'!J5+'2월'!H5+'3월'!H5+'4월'!H5+'5월'!H5+'6월'!H5+'7월'!H5+'8월'!H5+'9월'!H5+'10월'!H5+'11월'!H5+'12월'!H5 -> 27510540057 | I5: ='1월'!K5+'2월'!I5+'3월'!I5+'4월'!I5+'5월'!I5+'6월'!I5+'7월'!I5+'8월'!I5+'9월'!I5+'10월'!I5+'11월'!I5+'12월'!I5 -> 759926064 | J5: ='1월'!L5+'2월'!J5+'3월'!J5+'4월'!J5+'5월'!J5+'6월'!J5+'7월'!J5+'8월'!J5+'9월'!J5+'10월'!J5+'11월'!J5+'12월'!J5 -> 110690400 | K5: ='1월'!M5+'2월'!K5+'3월'!K5+'4월'!K5+'5월'!K5+'6월'!K5+'7월'!K5+'8월'!K5+'9월'!K5+'10월'!K5+'11월'!K5+'12월'!K5 -> 74124783411 | L5: ='1월'!N5+'2월'!L5+'3월'!L5+'4월'!L5+'5월'!L5+'6월'!L5+'7월'!L5+'8월'!L5+'9월'!L5+'10월'!L5+'11월'!L5+'12월'!L5 -> 510364 | M5: ='1월'!O5+'2월'!M5+'3월'!M5+'4월'!M5+'5월'!M5+'6월'!M5+'7월'!M5+'8월'!M5+'9월'!M5+'10월'!M5+'11월'!M5+'12월'!M5 -> 46041554080 | O5: =IFERROR(VLOOKUP($A5,[1]플랫폼1!$A:$B,2,FALSE),0) -> 0 | P5: =IFERROR(VLOOKUP($A5,[1]플랫폼2!$A:$M,12,FALSE),0)+IFERROR(VLOOKUP($A5,[1]플랫폼2!$A:$M,13,FALSE),0) -> 9035257470 | Q5: =IFERROR(VLOOKUP($A5,[1]플랫폼2!$A:$M,7,FALSE),0)+IFERROR(VLOOKUP($A5,[1]플랫폼2!$A:$M,12,FALSE),0) -> 36840381032 | R5: =IFERROR(VLOOKUP($A5,[1]모바일!$A:$S,17,FALSE),0) -> 0 | S5: =IFERROR(VLOOKUP($A5,[1]모바일!$A:$S,18,FALSE),0) -> 0 | T5: =IFERROR(VLOOKUP(A5,[1]플랫폼2!$A:$O,15,0),0) -> 165915578 | V5: 수수료수입 | W5: =VLOOKUP(V5,$A:$S,15,0) -> 2125628806 | X5: =VLOOKUP(V5,$A:$S,16,0) -> 1129992021 | Y5: =VLOOKUP(V5,$A:$S,17,0) -> 269118263 | Z5: =VLOOKUP(V5,$A:$S,18,0) -> 357710000 | AA5: =VLOOKUP(V5,$A:$S,19,0) -> 441954966
A6: 상품단말기매출-판매점 | B6: ='1월'!B6+'2월'!B6+'3월'!B6+'4월'!B6+'5월'!B6+'6월'!B6+'7월'!B6+'8월'!B6+'9월'!B6+'10월'!B6+'11월'!B6+'12월'!B6 -> 4935000 | C6: ='1월'!C6+'2월'!C6+'3월'!C6+'4월'!C6+'5월'!C6+'6월'!C6+'7월'!C6+'8월'!C6+'9월'!C6+'10월'!C6+'11월'!C6+'12월'!C6 -> 0 | D6: ='1월'!D6+'2월'!D6+'3월'!D6+'4월'!D6+'5월'!D6+'6월'!D6+'7월'!D6+'8월'!D6+'9월'!D6+'10월'!D6+'11월'!D6+'12월'!D6 -> 0 | E6: ='1월'!E6+'2월'!E6+'3월'!E6+'4월'!E6+'5월'!E6+'6월'!E6+'7월'!E6+'8월'!E6+'9월'!E6+'10월'!E6+'11월'!E6+'12월'!E6 -> 4935000 | F6: ='1월'!F6+'2월'!F6+'3월'!F6+'4월'!F6+'5월'!F6+'6월'!F6+'7월'!F6+'8월'!F6+'9월'!F6+'10월'!F6+'11월'!F6+'12월'!F6 -> 0 | G6: ='1월'!H6+'2월'!G6+'3월'!G6+'4월'!G6+'5월'!G6+'6월'!G6+'7월'!G6+'8월'!G6+'9월'!G6+'10월'!G6+'11월'!G6+'12월'!G6 -> 4935000 | H6: ='1월'!J6+'2월'!H6+'3월'!H6+'4월'!H6+'5월'!H6+'6월'!H6+'7월'!H6+'8월'!H6+'9월'!H6+'10월'!H6+'11월'!H6+'12월'!H6 -> 0 | I6: ='1월'!K6+'2월'!I6+'3월'!I6+'4월'!I6+'5월'!I6+'6월'!I6+'7월'!I6+'8월'!I6+'9월'!I6+'10월'!I6+'11월'!I6+'12월'!I6 -> 0 | J6: ='1월'!L6+'2월'!J6+'3월'!J6+'4월'!J6+'5월'!J6+'6월'!J6+'7월'!J6+'8월'!J6+'9월'!J6+'10월'!J6+'11월'!J6+'12월'!J6 -> 0 | K6: ='1월'!M6+'2월'!K6+'3월'!K6+'4월'!K6+'5월'!K6+'6월'!K6+'7월'!K6+'8월'!K6+'9월'!K6+'10월'!K6+'11월'!K6+'12월'!K6 -> 0 | L6: ='1월'!N6+'2월'!L6+'3월'!L6+'4월'!L6+'5월'!L6+'6월'!L6+'7월'!L6+'8월'!L6+'9월'!L6+'10월'!L6+'11월'!L6+'12월'!L6 -> 0 | M6: ='1월'!O6+'2월'!M6+'3월'!M6+'4월'!M6+'5월'!M6+'6월'!M6+'7월'!M6+'8월'!M6+'9월'!M6+'10월'!M6+'11월'!M6+'12월'!M6 -> 0 | O6: =IFERROR(VLOOKUP($A6,[1]플랫폼1!$A:$B,2,FALSE),0) -> 0 | P6: =IFERROR(VLOOKUP($A6,[1]플랫폼2!$A:$M,12,FALSE),0)+IFERROR(VLOOKUP($A6,[1]플랫폼2!$A:$M,13,FALSE),0) -> 0 | Q6: =IFERROR(VLOOKUP($A6,[1]플랫폼2!$A:$M,7,FALSE),0)+IFERROR(VLOOKUP($A6,[1]플랫폼2!$A:$M,12,FALSE),0) -> 0 | R6: =IFERROR(VLOOKUP($A6,[1]모바일!$A:$S,17,FALSE),0) -> 0 | S6: =IFERROR(VLOOKUP($A6,[1]모바일!$A:$S,18,FALSE),0) -> 0 | T6: =IFERROR(VLOOKUP(A6,[1]플랫폼2!$A:$O,15,0),0) -> 0 | V6: 정책수수료 | W6: =O14 -> 1870069164 | X6: =P14 -> 905442987 | Y6: =Q14 -> 220883899 | Z6: =R14 -> 0 | AA6: =S14 -> 0
A7: 상품매출액-대형유통 | B7: ='1월'!B7+'2월'!B7+'3월'!B7+'4월'!B7+'5월'!B7+'6월'!B7+'7월'!B7+'8월'!B7+'9월'!B7+'10월'!B7+'11월'!B7+'12월'!B7 -> 0 | C7: ='1월'!C7+'2월'!C7+'3월'!C7+'4월'!C7+'5월'!C7+'6월'!C7+'7월'!C7+'8월'!C7+'9월'!C7+'10월'!C7+'11월'!C7+'12월'!C7 -> 0 | D7: ='1월'!D7+'2월'!D7+'3월'!D7+'4월'!D7+'5월'!D7+'6월'!D7+'7월'!D7+'8월'!D7+'9월'!D7+'10월'!D7+'11월'!D7+'12월'!D7 -> 0 | E7: ='1월'!E7+'2월'!E7+'3월'!E7+'4월'!E7+'5월'!E7+'6월'!E7+'7월'!E7+'8월'!E7+'9월'!E7+'10월'!E7+'11월'!E7+'12월'!E7 -> 0 | F7: ='1월'!F7+'2월'!F7+'3월'!F7+'4월'!F7+'5월'!F7+'6월'!F7+'7월'!F7+'8월'!F7+'9월'!F7+'10월'!F7+'11월'!F7+'12월'!F7 -> 0 | G7: ='1월'!H7+'2월'!G7+'3월'!G7+'4월'!G7+'5월'!G7+'6월'!G7+'7월'!G7+'8월'!G7+'9월'!G7+'10월'!G7+'11월'!G7+'12월'!G7 -> 0 | H7: ='1월'!J7+'2월'!H7+'3월'!H7+'4월'!H7+'5월'!H7+'6월'!H7+'7월'!H7+'8월'!H7+'9월'!H7+'10월'!H7+'11월'!H7+'12월'!H7 -> 0 | I7: ='1월'!K7+'2월'!I7+'3월'!I7+'4월'!I7+'5월'!I7+'6월'!I7+'7월'!I7+'8월'!I7+'9월'!I7+'10월'!I7+'11월'!I7+'12월'!I7 -> 0 | J7: ='1월'!L7+'2월'!J7+'3월'!J7+'4월'!J7+'5월'!J7+'6월'!J7+'7월'!J7+'8월'!J7+'9월'!J7+'10월'!J7+'11월'!J7+'12월'!J7 -> 0 | K7: ='1월'!M7+'2월'!K7+'3월'!K7+'4월'!K7+'5월'!K7+'6월'!K7+'7월'!K7+'8월'!K7+'9월'!K7+'10월'!K7+'11월'!K7+'12월'!K7 -> 0 | L7: ='1월'!N7+'2월'!L7+'3월'!L7+'4월'!L7+'5월'!L7+'6월'!L7+'7월'!L7+'8월'!L7+'9월'!L7+'10월'!L7+'11월'!L7+'12월'!L7 -> 0 | M7: ='1월'!O7+'2월'!M7+'3월'!M7+'4월'!M7+'5월'!M7+'6월'!M7+'7월'!M7+'8월'!M7+'9월'!M7+'10월'!M7+'11월'!M7+'12월'!M7 -> 0 | O7: =IFERROR(VLOOKUP($A7,[1]플랫폼1!$A:$B,2,FALSE),0) -> 0 | P7: =IFERROR(VLOOKUP($A7,[1]플랫폼2!$A:$M,12,FALSE),0)+IFERROR(VLOOKUP($A7,[1]플랫폼2!$A:$M,13,FALSE),0) -> 0 | Q7: =IFERROR(VLOOKUP($A7,[1]플랫폼2!$A:$M,7,FALSE),0)+IFERROR(VLOOKUP($A7,[1]플랫폼2!$A:$M,12,FALSE),0) -> 0 | R7: =IFERROR(VLOOKUP($A7,[1]모바일!$A:$S,17,FALSE),0) -> 0 | S7: =IFERROR(VLOOKUP($A7,[1]모바일!$A:$S,18,FALSE),0) -> 0 | T7: =IFERROR(VLOOKUP(A7,[1]플랫폼2!$A:$O,15,0),0) -> 0 | V7: 관리수수료 | W7: =O16 -> 0 | X7: =P16 -> 0 | Y7: =Q16 -> 0 | Z7: =R16 -> 0 | AA7: =S16 -> 0
A8: 상품매출액-채권승계 | B8: ='1월'!B8+'2월'!B8+'3월'!B8+'4월'!B8+'5월'!B8+'6월'!B8+'7월'!B8+'8월'!B8+'9월'!B8+'10월'!B8+'11월'!B8+'12월'!B8 -> 298850591023 | C8: ='1월'!C8+'2월'!C8+'3월'!C8+'4월'!C8+'5월'!C8+'6월'!C8+'7월'!C8+'8월'!C8+'9월'!C8+'10월'!C8+'11월'!C8+'12월'!C8 -> 605789315 | D8: ='1월'!D8+'2월'!D8+'3월'!D8+'4월'!D8+'5월'!D8+'6월'!D8+'7월'!D8+'8월'!D8+'9월'!D8+'10월'!D8+'11월'!D8+'12월'!D8 -> 0 | E8: ='1월'!E8+'2월'!E8+'3월'!E8+'4월'!E8+'5월'!E8+'6월'!E8+'7월'!E8+'8월'!E8+'9월'!E8+'10월'!E8+'11월'!E8+'12월'!E8 -> 298244801708 | F8: ='1월'!F8+'2월'!F8+'3월'!F8+'4월'!F8+'5월'!F8+'6월'!F8+'7월'!F8+'8월'!F8+'9월'!F8+'10월'!F8+'11월'!F8+'12월'!F8 -> 169990202006 | G8: ='1월'!H8+'2월'!G8+'3월'!G8+'4월'!G8+'5월'!G8+'6월'!G8+'7월'!G8+'8월'!G8+'9월'!G8+'10월'!G8+'11월'!G8+'12월'!G8 -> 294294662 | H8: ='1월'!J8+'2월'!H8+'3월'!H8+'4월'!H8+'5월'!H8+'6월'!H8+'7월'!H8+'8월'!H8+'9월'!H8+'10월'!H8+'11월'!H8+'12월'!H8 -> 114400243123 | I8: ='1월'!K8+'2월'!I8+'3월'!I8+'4월'!I8+'5월'!I8+'6월'!I8+'7월'!I8+'8월'!I8+'9월'!I8+'10월'!I8+'11월'!I8+'12월'!I8 -> 3568957613 | J8: ='1월'!L8+'2월'!J8+'3월'!J8+'4월'!J8+'5월'!J8+'6월'!J8+'7월'!J8+'8월'!J8+'9월'!J8+'10월'!J8+'11월'!J8+'12월'!J8 -> 13329998 | K8: ='1월'!M8+'2월'!K8+'3월'!K8+'4월'!K8+'5월'!K8+'6월'!K8+'7월'!K8+'8월'!K8+'9월'!K8+'10월'!K8+'11월'!K8+'12월'!K8 -> 8706214016 | L8: ='1월'!N8+'2월'!L8+'3월'!L8+'4월'!L8+'5월'!L8+'6월'!L8+'7월'!L8+'8월'!L8+'9월'!L8+'10월'!L8+'11월'!L8+'12월'!L8 -> 1271560290 | M8: ='1월'!O8+'2월'!M8+'3월'!M8+'4월'!M8+'5월'!M8+'6월'!M8+'7월'!M8+'8월'!M8+'9월'!M8+'10월'!M8+'11월'!M8+'12월'!M8 -> 0 | O8: =IFERROR(VLOOKUP($A8,[1]플랫폼1!$A:$B,2,FALSE),0) -> 0 | P8: =IFERROR(VLOOKUP($A8,[1]플랫폼2!$A:$M,12,FALSE),0)+IFERROR(VLOOKUP($A8,[1]플랫폼2!$A:$M,13,FALSE),0) -> 0 | Q8: =IFERROR(VLOOKUP($A8,[1]플랫폼2!$A:$M,7,FALSE),0)+IFERROR(VLOOKUP($A8,[1]플랫폼2!$A:$M,12,FALSE),0) -> 0 | R8: =IFERROR(VLOOKUP($A8,[1]모바일!$A:$S,17,FALSE),0) -> 0 | S8: =IFERROR(VLOOKUP($A8,[1]모바일!$A:$S,18,FALSE),0) -> 0 | T8: =IFERROR(VLOOKUP(A8,[1]플랫폼2!$A:$O,15,0),0) -> 0 | V8: 기타수수료 | W8: =O15 -> 255559642 | X8: =P15+P22 -> 224549034 | Y8: =Q15 -> 48234364 | Z8: =R15 -> 0 | AA8: =S22 -> 441954966
A9: 상품매출액-신용카드매출 | B9: ='1월'!B9+'2월'!B9+'3월'!B9+'4월'!B9+'5월'!B9+'6월'!B9+'7월'!B9+'8월'!B9+'9월'!B9+'10월'!B9+'11월'!B9+'12월'!B9 -> 3607447906 | C9: ='1월'!C9+'2월'!C9+'3월'!C9+'4월'!C9+'5월'!C9+'6월'!C9+'7월'!C9+'8월'!C9+'9월'!C9+'10월'!C9+'11월'!C9+'12월'!C9 -> -7737093 | D9: ='1월'!D9+'2월'!D9+'3월'!D9+'4월'!D9+'5월'!D9+'6월'!D9+'7월'!D9+'8월'!D9+'9월'!D9+'10월'!D9+'11월'!D9+'12월'!D9 -> 17911642 | E9: ='1월'!E9+'2월'!E9+'3월'!E9+'4월'!E9+'5월'!E9+'6월'!E9+'7월'!E9+'8월'!E9+'9월'!E9+'10월'!E9+'11월'!E9+'12월'!E9 -> 3597273357 | F9: ='1월'!F9+'2월'!F9+'3월'!F9+'4월'!F9+'5월'!F9+'6월'!F9+'7월'!F9+'8월'!F9+'9월'!F9+'10월'!F9+'11월'!F9+'12월'!F9 -> 3011229218 | G9: ='1월'!H9+'2월'!G9+'3월'!G9+'4월'!G9+'5월'!G9+'6월'!G9+'7월'!G9+'8월'!G9+'9월'!G9+'10월'!G9+'11월'!G9+'12월'!G9 -> 2731455 | H9: ='1월'!J9+'2월'!H9+'3월'!H9+'4월'!H9+'5월'!H9+'6월'!H9+'7월'!H9+'8월'!H9+'9월'!H9+'10월'!H9+'11월'!H9+'12월'!H9 -> 141399046 | I9: ='1월'!K9+'2월'!I9+'3월'!I9+'4월'!I9+'5월'!I9+'6월'!I9+'7월'!I9+'8월'!I9+'9월'!I9+'10월'!I9+'11월'!I9+'12월'!I9 -> 11694091 | J9: ='1월'!L9+'2월'!J9+'3월'!J9+'4월'!J9+'5월'!J9+'6월'!J9+'7월'!J9+'8월'!J9+'9월'!J9+'10월'!J9+'11월'!J9+'12월'!J9 -> 0 | K9: ='1월'!M9+'2월'!K9+'3월'!K9+'4월'!K9+'5월'!K9+'6월'!K9+'7월'!K9+'8월'!K9+'9월'!K9+'10월'!K9+'11월'!K9+'12월'!K9 -> 10572255 | L9: ='1월'!N9+'2월'!L9+'3월'!L9+'4월'!L9+'5월'!L9+'6월'!L9+'7월'!L9+'8월'!L9+'9월'!L9+'10월'!L9+'11월'!L9+'12월'!L9 -> 12424000 | M9: ='1월'!O9+'2월'!M9+'3월'!M9+'4월'!M9+'5월'!M9+'6월'!M9+'7월'!M9+'8월'!M9+'9월'!M9+'10월'!M9+'11월'!M9+'12월'!M9 -> 407223292 | O9: =IFERROR(VLOOKUP($A9,[1]플랫폼1!$A:$B,2,FALSE),0) -> 0 | P9: =IFERROR(VLOOKUP($A9,[1]플랫폼2!$A:$M,12,FALSE),0)+IFERROR(VLOOKUP($A9,[1]플랫폼2!$A:$M,13,FALSE),0) -> 0 | Q9: =IFERROR(VLOOKUP($A9,[1]플랫폼2!$A:$M,7,FALSE),0)+IFERROR(VLOOKUP($A9,[1]플랫폼2!$A:$M,12,FALSE),0) -> 0 | R9: =IFERROR(VLOOKUP($A9,[1]모바일!$A:$S,17,FALSE),0) -> 0 | S9: =IFERROR(VLOOKUP($A9,[1]모바일!$A:$S,18,FALSE),0) -> 0 | T9: 407223292 | V9: 매 출 원 가 | W9: =VLOOKUP(V9,$A:$S,15,0) -> 4110141099 | X9: =VLOOKUP(V9,$A:$S,16,0) -> 7894223749 | Y9: =VLOOKUP(V9,$A:$S,17,0) -> 29895506448 | Z9: =VLOOKUP(V9,$A:$S,18,0) -> 728333.33 | AA9: =VLOOKUP(V9,$A:$S,19,0) -> 728333.33
A10: 상품매출액-부분납 | B10: ='1월'!B10+'2월'!B10+'3월'!B10+'4월'!B10+'5월'!B10+'6월'!B10+'7월'!B10+'8월'!B10+'9월'!B10+'10월'!B10+'11월'!B10+'12월'!B10 -> 2073581510 | C10: ='1월'!C10+'2월'!C10+'3월'!C10+'4월'!C10+'5월'!C10+'6월'!C10+'7월'!C10+'8월'!C10+'9월'!C10+'10월'!C10+'11월'!C10+'12월'!C10 -> 0 | D10: ='1월'!D10+'2월'!D10+'3월'!D10+'4월'!D10+'5월'!D10+'6월'!D10+'7월'!D10+'8월'!D10+'9월'!D10+'10월'!D10+'11월'!D10+'12월'!D10 -> 0 | E10: ='1월'!E10+'2월'!E10+'3월'!E10+'4월'!E10+'5월'!E10+'6월'!E10+'7월'!E10+'8월'!E10+'9월'!E10+'10월'!E10+'11월'!E10+'12월'!E10 -> 2073581510 | F10: ='1월'!F10+'2월'!F10+'3월'!F10+'4월'!F10+'5월'!F10+'6월'!F10+'7월'!F10+'8월'!F10+'9월'!F10+'10월'!F10+'11월'!F10+'12월'!F10 -> 0 | G10: ='1월'!H10+'2월'!G10+'3월'!G10+'4월'!G10+'5월'!G10+'6월'!G10+'7월'!G10+'8월'!G10+'9월'!G10+'10월'!G10+'11월'!G10+'12월'!G10 -> 0 | H10: ='1월'!J10+'2월'!H10+'3월'!H10+'4월'!H10+'5월'!H10+'6월'!H10+'7월'!H10+'8월'!H10+'9월'!H10+'10월'!H10+'11월'!H10+'12월'!H10 -> 1840800001 | I10: ='1월'!K10+'2월'!I10+'3월'!I10+'4월'!I10+'5월'!I10+'6월'!I10+'7월'!I10+'8월'!I10+'9월'!I10+'10월'!I10+'11월'!I10+'12월'!I10 -> 1849826 | J10: ='1월'!L10+'2월'!J10+'3월'!J10+'4월'!J10+'5월'!J10+'6월'!J10+'7월'!J10+'8월'!J10+'9월'!J10+'10월'!J10+'11월'!J10+'12월'!J10 -> 44716782 | K10: ='1월'!M10+'2월'!K10+'3월'!K10+'4월'!K10+'5월'!K10+'6월'!K10+'7월'!K10+'8월'!K10+'9월'!K10+'10월'!K10+'11월'!K10+'12월'!K10 -> 186214901 | L10: ='1월'!N10+'2월'!L10+'3월'!L10+'4월'!L10+'5월'!L10+'6월'!L10+'7월'!L10+'8월'!L10+'9월'!L10+'10월'!L10+'11월'!L10+'12월'!L10 -> 0 | M10: ='1월'!O10+'2월'!M10+'3월'!M10+'4월'!M10+'5월'!M10+'6월'!M10+'7월'!M10+'8월'!M10+'9월'!M10+'10월'!M10+'11월'!M10+'12월'!M10 -> 0 | O10: =IFERROR(VLOOKUP($A10,[1]플랫폼1!$A:$B,2,FALSE),0) -> 0 | P10: =IFERROR(VLOOKUP($A10,[1]플랫폼2!$A:$M,12,FALSE),0)+IFERROR(VLOOKUP($A10,[1]플랫폼2!$A:$M,13,FALSE),0) -> 0 | Q10: =IFERROR(VLOOKUP($A10,[1]플랫폼2!$A:$M,7,FALSE),0)+IFERROR(VLOOKUP($A10,[1]플랫폼2!$A:$M,12,FALSE),0) -> 0 | R10: =IFERROR(VLOOKUP($A10,[1]모바일!$A:$S,17,FALSE),0) -> 0 | S10: =IFERROR(VLOOKUP($A10,[1]모바일!$A:$S,18,FALSE),0) -> 0 | T10: =IFERROR(VLOOKUP(A10,[1]플랫폼2!$A:$O,15,0),0) -> 0 | V10: 매 출 총 이 익 | W10: =VLOOKUP(V10,$A:$S,15,0) -> 2572621219 | X10: =VLOOKUP(V10,$A:$S,16,0) -> 2271025742 | Y10: =VLOOKUP(V10,$A:$S,17,0) -> 7223920115 | Z10: =VLOOKUP(V10,$A:$S,18,0) -> 3.5698167e+08 | AA10: =VLOOKUP(V10,$A:$S,19,0) -> 4.4122663e+08
A11: 상품매출액-보험매출 | B11: ='1월'!B11+'2월'!B11+'3월'!B11+'4월'!B11+'5월'!B11+'6월'!B11+'7월'!B11+'8월'!B11+'9월'!B11+'10월'!B11+'11월'!B11+'12월'!B11 -> 4144008217 | C11: ='1월'!C11+'2월'!C11+'3월'!C11+'4월'!C11+'5월'!C11+'6월'!C11+'7월'!C11+'8월'!C11+'9월'!C11+'10월'!C11+'11월'!C11+'12월'!C11 -> 2850728 | D11: ='1월'!D11+'2월'!D11+'3월'!D11+'4월'!D11+'5월'!D11+'6월'!D11+'7월'!D11+'8월'!D11+'9월'!D11+'10월'!D11+'11월'!D11+'12월'!D11 -> 0 | E11: ='1월'!E11+'2월'!E11+'3월'!E11+'4월'!E11+'5월'!E11+'6월'!E11+'7월'!E11+'8월'!E11+'9월'!E11+'10월'!E11+'11월'!E11+'12월'!E11 -> 4141157489 | F11: ='1월'!F11+'2월'!F11+'3월'!F11+'4월'!F11+'5월'!F11+'6월'!F11+'7월'!F11+'8월'!F11+'9월'!F11+'10월'!F11+'11월'!F11+'12월'!F11 -> 3432162383 | G11: ='1월'!H11+'2월'!G11+'3월'!G11+'4월'!G11+'5월'!G11+'6월'!G11+'7월'!G11+'8월'!G11+'9월'!G11+'10월'!G11+'11월'!G11+'12월'!G11 -> 0 | H11: ='1월'!J11+'2월'!H11+'3월'!H11+'4월'!H11+'5월'!H11+'6월'!H11+'7월'!H11+'8월'!H11+'9월'!H11+'10월'!H11+'11월'!H11+'12월'!H11 -> 708995106 | I11: ='1월'!K11+'2월'!I11+'3월'!I11+'4월'!I11+'5월'!I11+'6월'!I11+'7월'!I11+'8월'!I11+'9월'!I11+'10월'!I11+'11월'!I11+'12월'!I11 -> 0 | J11: ='1월'!L11+'2월'!J11+'3월'!J11+'4월'!J11+'5월'!J11+'6월'!J11+'7월'!J11+'8월'!J11+'9월'!J11+'10월'!J11+'11월'!J11+'12월'!J11 -> 0 | K11: ='1월'!M11+'2월'!K11+'3월'!K11+'4월'!K11+'5월'!K11+'6월'!K11+'7월'!K11+'8월'!K11+'9월'!K11+'10월'!K11+'11월'!K11+'12월'!K11 -> 0 | L11: ='1월'!N11+'2월'!L11+'3월'!L11+'4월'!L11+'5월'!L11+'6월'!L11+'7월'!L11+'8월'!L11+'9월'!L11+'10월'!L11+'11월'!L11+'12월'!L11 -> 0 | M11: ='1월'!O11+'2월'!M11+'3월'!M11+'4월'!M11+'5월'!M11+'6월'!M11+'7월'!M11+'8월'!M11+'9월'!M11+'10월'!M11+'11월'!M11+'12월'!M11 -> 0 | O11: =IFERROR(VLOOKUP($A11,[1]플랫폼1!$A:$B,2,FALSE),0) -> 0 | P11: =IFERROR(VLOOKUP($A11,[1]플랫폼2!$A:$M,12,FALSE),0)+IFERROR(VLOOKUP($A11,[1]플랫폼2!$A:$M,13,FALSE),0) -> 0 | Q11: =IFERROR(VLOOKUP($A11,[1]플랫폼2!$A:$M,7,FALSE),0)+IFERROR(VLOOKUP($A11,[1]플랫폼2!$A:$M,12,FALSE),0) -> 0 | R11: =IFERROR(VLOOKUP($A11,[1]모바일!$A:$S,17,FALSE),0) -> 0 | S11: =IFERROR(VLOOKUP($A11,[1]모바일!$A:$S,18,FALSE),0) -> 0 | T11: =IFERROR(VLOOKUP(A11,[1]플랫폼2!$A:$O,15,0),0) -> 0 | V11: 판매비와일반관리비 | W11: =VLOOKUP(V11,$A:$S,15,0) -> 2870898509 | X11: =VLOOKUP(V11,$A:$S,16,0) -> 1864003365 | Y11: =VLOOKUP(V11,$A:$S,17,0) -> 1362120999 | Z11: =VLOOKUP(V11,$A:$S,18,0) -> 3.1150064e+08 | AA11: =VLOOKUP(V11,$A:$S,19,0) -> 1.7168388e+08
A12: 상품매출-기타 | B12: ='1월'!B12+'2월'!B12+'3월'!B12+'4월'!B12+'5월'!B12+'6월'!B12+'7월'!B12+'8월'!B12+'9월'!B12+'10월'!B12+'11월'!B12+'12월'!B12 -> 4569894180 | C12: ='1월'!C12+'2월'!C12+'3월'!C12+'4월'!C12+'5월'!C12+'6월'!C12+'7월'!C12+'8월'!C12+'9월'!C12+'10월'!C12+'11월'!C12+'12월'!C12 -> 2833400 | D12: ='1월'!D12+'2월'!D12+'3월'!D12+'4월'!D12+'5월'!D12+'6월'!D12+'7월'!D12+'8월'!D12+'9월'!D12+'10월'!D12+'11월'!D12+'12월'!D12 -> 0 | E12: ='1월'!E12+'2월'!E12+'3월'!E12+'4월'!E12+'5월'!E12+'6월'!E12+'7월'!E12+'8월'!E12+'9월'!E12+'10월'!E12+'11월'!E12+'12월'!E12 -> 4567060780 | F12: ='1월'!F12+'2월'!F12+'3월'!F12+'4월'!F12+'5월'!F12+'6월'!F12+'7월'!F12+'8월'!F12+'9월'!F12+'10월'!F12+'11월'!F12+'12월'!F12 -> 0 | G12: ='1월'!H12+'2월'!G12+'3월'!G12+'4월'!G12+'5월'!G12+'6월'!G12+'7월'!G12+'8월'!G12+'9월'!G12+'10월'!G12+'11월'!G12+'12월'!G12 -> 0 | H12: ='1월'!J12+'2월'!H12+'3월'!H12+'4월'!H12+'5월'!H12+'6월'!H12+'7월'!H12+'8월'!H12+'9월'!H12+'10월'!H12+'11월'!H12+'12월'!H12 -> 0 | I12: ='1월'!K12+'2월'!I12+'3월'!I12+'4월'!I12+'5월'!I12+'6월'!I12+'7월'!I12+'8월'!I12+'9월'!I12+'10월'!I12+'11월'!I12+'12월'!I12 -> 0 | J12: ='1월'!L12+'2월'!J12+'3월'!J12+'4월'!J12+'5월'!J12+'6월'!J12+'7월'!J12+'8월'!J12+'9월'!J12+'10월'!J12+'11월'!J12+'12월'!J12 -> 0 | K12: ='1월'!M12+'2월'!K12+'3월'!K12+'4월'!K12+'5월'!K12+'6월'!K12+'7월'!K12+'8월'!K12+'9월'!K12+'10월'!K12+'11월'!K12+'12월'!K12 -> 0 | L12: ='1월'!N12+'2월'!L12+'3월'!L12+'4월'!L12+'5월'!L12+'6월'!L12+'7월'!L12+'8월'!L12+'9월'!L12+'10월'!L12+'11월'!L12+'12월'!L12 -> 0 | M12: ='1월'!O12+'2월'!M12+'3월'!M12+'4월'!M12+'5월'!M12+'6월'!M12+'7월'!M12+'8월'!M12+'9월'!M12+'10월'!M12+'11월'!M12+'12월'!M12 -> 4567060780 | O12: =IFERROR(VLOOKUP($A12,[1]플랫폼1!$A:$B,2,FALSE),0) -> 4557133512 | P12: =IFERROR(VLOOKUP($A12,[1]플랫폼2!$A:$M,12,FALSE),0)+IFERROR(VLOOKUP($A12,[1]플랫폼2!$A:$M,13,FALSE),0) -> 0 | Q12: =IFERROR(VLOOKUP($A12,[1]플랫폼2!$A:$M,7,FALSE),0)+IFERROR(VLOOKUP($A12,[1]플랫폼2!$A:$M,12,FALSE),0) -> 9927268 | R12: =IFERROR(VLOOKUP($A12,[1]모바일!$A:$S,17,FALSE),0) -> 0 | S12: =IFERROR(VLOOKUP($A12,[1]모바일!$A:$S,18,FALSE),0) -> 0 | T12: =IFERROR(VLOOKUP(A12,[1]플랫폼2!$A:$O,15,0),0) -> 0 | V12: 인건비 | W12: =O29+O30+O63+O70+O71+O73+O74 -> 362867576 | X12: =P29+P30+P63+P70+P71+P73+P74 -> 2.6140635e+08 | Y12: =Q29+Q30+Q63+Q70+Q71+Q73+Q74 -> 2.6140635e+08 | Z12: =R29+R30+R63+R70+R71+R73+R74 -> 37300458 | AA12: =S29+S30+S63+S70+S71+S73+S74 -> 37300458
A13: 수수료수입 | B13: ='1월'!B13+'2월'!B13+'3월'!B13+'4월'!B13+'5월'!B13+'6월'!B13+'7월'!B13+'8월'!B13+'9월'!B13+'10월'!B13+'11월'!B13+'12월'!B13 -> 285761962054 | C13: ='1월'!C13+'2월'!C13+'3월'!C13+'4월'!C13+'5월'!C13+'6월'!C13+'7월'!C13+'8월'!C13+'9월'!C13+'10월'!C13+'11월'!C13+'12월'!C13 -> -22215038758 | D13: ='1월'!D13+'2월'!D13+'3월'!D13+'4월'!D13+'5월'!D13+'6월'!D13+'7월'!D13+'8월'!D13+'9월'!D13+'10월'!D13+'11월'!D13+'12월'!D13 -> 1575949636 | E13: ='1월'!E13+'2월'!E13+'3월'!E13+'4월'!E13+'5월'!E13+'6월'!E13+'7월'!E13+'8월'!E13+'9월'!E13+'10월'!E13+'11월'!E13+'12월'!E13 -> 306401051176 | F13: ='1월'!F13+'2월'!F13+'3월'!F13+'4월'!F13+'5월'!F13+'6월'!F13+'7월'!F13+'8월'!F13+'9월'!F13+'10월'!F13+'11월'!F13+'12월'!F13 -> 1.5782224e+11 | G13: ='1월'!H13+'2월'!G13+'3월'!G13+'4월'!G13+'5월'!G13+'6월'!G13+'7월'!G13+'8월'!G13+'9월'!G13+'10월'!G13+'11월'!G13+'12월'!G13 -> 4.2966236e+10 | H13: ='1월'!J13+'2월'!H13+'3월'!H13+'4월'!H13+'5월'!H13+'6월'!H13+'7월'!H13+'8월'!H13+'9월'!H13+'10월'!H13+'11월'!H13+'12월'!H13 -> 53014878617 | I13: ='1월'!K13+'2월'!I13+'3월'!I13+'4월'!I13+'5월'!I13+'6월'!I13+'7월'!I13+'8월'!I13+'9월'!I13+'10월'!I13+'11월'!I13+'12월'!I13 -> 9038659980 | J13: ='1월'!L13+'2월'!J13+'3월'!J13+'4월'!J13+'5월'!J13+'6월'!J13+'7월'!J13+'8월'!J13+'9월'!J13+'10월'!J13+'11월'!J13+'12월'!J13 -> 8969674721 | K13: ='1월'!M13+'2월'!K13+'3월'!K13+'4월'!K13+'5월'!K13+'6월'!K13+'7월'!K13+'8월'!K13+'9월'!K13+'10월'!K13+'11월'!K13+'12월'!K13 -> 14940053707 | L13: ='1월'!N13+'2월'!L13+'3월'!L13+'4월'!L13+'5월'!L13+'6월'!L13+'7월'!L13+'8월'!L13+'9월'!L13+'10월'!L13+'11월'!L13+'12월'!L13 -> 15006724930 | M13: ='1월'!O13+'2월'!M13+'3월'!M13+'4월'!M13+'5월'!M13+'6월'!M13+'7월'!M13+'8월'!M13+'9월'!M13+'10월'!M13+'11월'!M13+'12월'!M13 -> 4642585874 | O13: =IFERROR(VLOOKUP($A13,[1]플랫폼1!$A:$B,2,FALSE),0) -> 2125628806 | P13: =IFERROR(VLOOKUP($A13,[1]플랫폼2!$A:$M,12,FALSE),0)+IFERROR(VLOOKUP($A13,[1]플랫폼2!$A:$M,13,FALSE),0) -> 1129992021 | Q13: =IFERROR(VLOOKUP($A13,[1]플랫폼2!$A:$M,7,FALSE),0)+IFERROR(VLOOKUP($A13,[1]플랫폼2!$A:$M,12,FALSE),0) -> 269118263 | R13: =IFERROR(VLOOKUP($A13,[1]모바일!$A:$S,17,FALSE),0) -> 357710000 | S13: =IFERROR(VLOOKUP($A13,[1]모바일!$A:$S,18,FALSE),0) -> 441954966 | T13: =IFERROR(VLOOKUP(A13,[1]플랫폼2!$A:$O,15,0),0) -> 318181818 | V13: 마케팅비 | W13: =O217+O215+O229 -> 142022820 | X13: =P217+P215+P229 -> 1.3802355e+08 | Y13: =Q217+Q215+Q229 -> 1.4117993e+08 | Z13: =R217+R215+R229 -> 2167737 | AA13: =S217+S215+S229 -> 2167737
A14: 수수료수입-KT(RDS) | B14: ='1월'!B14+'2월'!B14+'3월'!B14+'4월'!B14+'5월'!B14+'6월'!B14+'7월'!B14+'8월'!B14+'9월'!B14+'10월'!B14+'11월'!B14+'12월'!B14 -> 159859732685 | C14: ='1월'!C14+'2월'!C14+'3월'!C14+'4월'!C14+'5월'!C14+'6월'!C14+'7월'!C14+'8월'!C14+'9월'!C14+'10월'!C14+'11월'!C14+'12월'!C14 -> 217903319 | D14: ='1월'!D14+'2월'!D14+'3월'!D14+'4월'!D14+'5월'!D14+'6월'!D14+'7월'!D14+'8월'!D14+'9월'!D14+'10월'!D14+'11월'!D14+'12월'!D14 -> 16381820 | E14: ='1월'!E14+'2월'!E14+'3월'!E14+'4월'!E14+'5월'!E14+'6월'!E14+'7월'!E14+'8월'!E14+'9월'!E14+'10월'!E14+'11월'!E14+'12월'!E14 -> 159625447546 | F14: ='1월'!F14+'2월'!F14+'3월'!F14+'4월'!F14+'5월'!F14+'6월'!F14+'7월'!F14+'8월'!F14+'9월'!F14+'10월'!F14+'11월'!F14+'12월'!F14 -> 9.7276205e+10 | G14: ='1월'!H14+'2월'!G14+'3월'!G14+'4월'!G14+'5월'!G14+'6월'!G14+'7월'!G14+'8월'!G14+'9월'!G14+'10월'!G14+'11월'!G14+'12월'!G14 -> 1.4486641e+09 | H14: ='1월'!J14+'2월'!H14+'3월'!H14+'4월'!H14+'5월'!H14+'6월'!H14+'7월'!H14+'8월'!H14+'9월'!H14+'10월'!H14+'11월'!H14+'12월'!H14 -> 32359921971 | I14: ='1월'!K14+'2월'!I14+'3월'!I14+'4월'!I14+'5월'!I14+'6월'!I14+'7월'!I14+'8월'!I14+'9월'!I14+'10월'!I14+'11월'!I14+'12월'!I14 -> 6296962972 | J14: ='1월'!L14+'2월'!J14+'3월'!J14+'4월'!J14+'5월'!J14+'6월'!J14+'7월'!J14+'8월'!J14+'9월'!J14+'10월'!J14+'11월'!J14+'12월'!J14 -> 7108576733 | K14: ='1월'!M14+'2월'!K14+'3월'!K14+'4월'!K14+'5월'!K14+'6월'!K14+'7월'!K14+'8월'!K14+'9월'!K14+'10월'!K14+'11월'!K14+'12월'!K14 -> 10924392547 | L14: ='1월'!N14+'2월'!L14+'3월'!L14+'4월'!L14+'5월'!L14+'6월'!L14+'7월'!L14+'8월'!L14+'9월'!L14+'10월'!L14+'11월'!L14+'12월'!L14 -> 896146592 | M14: ='1월'!O14+'2월'!M14+'3월'!M14+'4월'!M14+'5월'!M14+'6월'!M14+'7월'!M14+'8월'!M14+'9월'!M14+'10월'!M14+'11월'!M14+'12월'!M14 -> 3314577868 | O14: =IFERROR(VLOOKUP($A14,[1]플랫폼1!$A:$B,2,FALSE),0) -> 1870069164 | P14: =IFERROR(VLOOKUP($A14,[1]플랫폼2!$A:$M,12,FALSE),0)+IFERROR(VLOOKUP($A14,[1]플랫폼2!$A:$M,13,FALSE),0) -> 905442987 | Q14: =IFERROR(VLOOKUP($A14,[1]플랫폼2!$A:$M,7,FALSE),0)+IFERROR(VLOOKUP($A14,[1]플랫폼2!$A:$M,12,FALSE),0) -> 220883899 | R14: =IFERROR(VLOOKUP($A14,[1]모바일!$A:$S,17,FALSE),0) -> 0 | S14: =IFERROR(VLOOKUP($A14,[1]모바일!$A:$S,18,FALSE),0) -> 0 | T14: =IFERROR(VLOOKUP(A14,[1]플랫폼2!$A:$O,15,0),0) -> 318181818 | V14: 임차관리비 | W14: =O142+O133 -> 0 | X14: =P142+P133 -> 17929443 | Y14: =Q142+Q133 -> 32369094 | Z14: =R142+R133 -> 18795740 | AA14: =S142+S133 -> 26627313
A15: 수수료수입-기타 | B15: ='1월'!B15+'2월'!B15+'3월'!B15+'4월'!B15+'5월'!B15+'6월'!B15+'7월'!B15+'8월'!B15+'9월'!B15+'10월'!B15+'11월'!B15+'12월'!B15 -> 2592202339 | C15: ='1월'!C15+'2월'!C15+'3월'!C15+'4월'!C15+'5월'!C15+'6월'!C15+'7월'!C15+'8월'!C15+'9월'!C15+'10월'!C15+'11월'!C15+'12월'!C15 -> 1030531090 | D15: ='1월'!D15+'2월'!D15+'3월'!D15+'4월'!D15+'5월'!D15+'6월'!D15+'7월'!D15+'8월'!D15+'9월'!D15+'10월'!D15+'11월'!D15+'12월'!D15 -> -15158638 | E15: ='1월'!E15+'2월'!E15+'3월'!E15+'4월'!E15+'5월'!E15+'6월'!E15+'7월'!E15+'8월'!E15+'9월'!E15+'10월'!E15+'11월'!E15+'12월'!E15 -> 1576829887 | F15: ='1월'!F15+'2월'!F15+'3월'!F15+'4월'!F15+'5월'!F15+'6월'!F15+'7월'!F15+'8월'!F15+'9월'!F15+'10월'!F15+'11월'!F15+'12월'!F15 -> 218321943 | G15: ='1월'!H15+'2월'!G15+'3월'!G15+'4월'!G15+'5월'!G15+'6월'!G15+'7월'!G15+'8월'!G15+'9월'!G15+'10월'!G15+'11월'!G15+'12월'!G15 -> 6272727 | H15: ='1월'!J15+'2월'!H15+'3월'!H15+'4월'!H15+'5월'!H15+'6월'!H15+'7월'!H15+'8월'!H15+'9월'!H15+'10월'!H15+'11월'!H15+'12월'!H15 -> 157286169 | I15: ='1월'!K15+'2월'!I15+'3월'!I15+'4월'!I15+'5월'!I15+'6월'!I15+'7월'!I15+'8월'!I15+'9월'!I15+'10월'!I15+'11월'!I15+'12월'!I15 -> 0 | J15: ='1월'!L15+'2월'!J15+'3월'!J15+'4월'!J15+'5월'!J15+'6월'!J15+'7월'!J15+'8월'!J15+'9월'!J15+'10월'!J15+'11월'!J15+'12월'!J15 -> 27989232 | K15: ='1월'!M15+'2월'!K15+'3월'!K15+'4월'!K15+'5월'!K15+'6월'!K15+'7월'!K15+'8월'!K15+'9월'!K15+'10월'!K15+'11월'!K15+'12월'!K15 -> 0 | L15: ='1월'!N15+'2월'!L15+'3월'!L15+'4월'!L15+'5월'!L15+'6월'!L15+'7월'!L15+'8월'!L15+'9월'!L15+'10월'!L15+'11월'!L15+'12월'!L15 -> 861071810 | M15: ='1월'!O15+'2월'!M15+'3월'!M15+'4월'!M15+'5월'!M15+'6월'!M15+'7월'!M15+'8월'!M15+'9월'!M15+'10월'!M15+'11월'!M15+'12월'!M15 -> 305888006 | O15: =IFERROR(VLOOKUP($A15,[1]플랫폼1!$A:$B,2,FALSE),0) -> 255559642 | P15: =IFERROR(VLOOKUP($A15,[1]플랫폼2!$A:$M,12,FALSE),0)+IFERROR(VLOOKUP($A15,[1]플랫폼2!$A:$M,13,FALSE),0) -> 2094000 | Q15: =IFERROR(VLOOKUP($A15,[1]플랫폼2!$A:$M,7,FALSE),0)+IFERROR(VLOOKUP($A15,[1]플랫폼2!$A:$M,12,FALSE),0) -> 48234364 | R15: =IFERROR(VLOOKUP($A15,[1]모바일!$A:$S,17,FALSE),0) -> 0 | S15: =IFERROR(VLOOKUP($A15,[1]모바일!$A:$S,18,FALSE),0) -> 0 | T15: =IFERROR(VLOOKUP(A15,[1]플랫폼2!$A:$O,15,0),0) -> 0 | V15: 감가상각비 | W15: =O141+O238 -> 30000000 | X15: =P141+P238 -> 319799989 | Y15: =Q141+Q238 -> 0 | Z15: =R141+R238 -> 0 | AA15: =S141+S238 -> 0
A16: 수수료수입-관리 | B16: ='1월'!B16+'2월'!B16+'3월'!B16+'4월'!B16+'5월'!B16+'6월'!B16+'7월'!B16+'8월'!B16+'9월'!B16+'10월'!B16+'11월'!B16+'12월'!B16 -> 52505720873 | C16: ='1월'!C16+'2월'!C16+'3월'!C16+'4월'!C16+'5월'!C16+'6월'!C16+'7월'!C16+'8월'!C16+'9월'!C16+'10월'!C16+'11월'!C16+'12월'!C16 -> -135643018 | D16: ='1월'!D16+'2월'!D16+'3월'!D16+'4월'!D16+'5월'!D16+'6월'!D16+'7월'!D16+'8월'!D16+'9월'!D16+'10월'!D16+'11월'!D16+'12월'!D16 -> 0 | E16: ='1월'!E16+'2월'!E16+'3월'!E16+'4월'!E16+'5월'!E16+'6월'!E16+'7월'!E16+'8월'!E16+'9월'!E16+'10월'!E16+'11월'!E16+'12월'!E16 -> 52641363891 | F16: ='1월'!F16+'2월'!F16+'3월'!F16+'4월'!F16+'5월'!F16+'6월'!F16+'7월'!F16+'8월'!F16+'9월'!F16+'10월'!F16+'11월'!F16+'12월'!F16 -> 2.9908803e+10 | G16: ='1월'!H16+'2월'!G16+'3월'!G16+'4월'!G16+'5월'!G16+'6월'!G16+'7월'!G16+'8월'!G16+'9월'!G16+'10월'!G16+'11월'!G16+'12월'!G16 -> 9.8731705e+09 | H16: ='1월'!J16+'2월'!H16+'3월'!H16+'4월'!H16+'5월'!H16+'6월'!H16+'7월'!H16+'8월'!H16+'9월'!H16+'10월'!H16+'11월'!H16+'12월'!H16 -> 5984211784 | I16: ='1월'!K16+'2월'!I16+'3월'!I16+'4월'!I16+'5월'!I16+'6월'!I16+'7월'!I16+'8월'!I16+'9월'!I16+'10월'!I16+'11월'!I16+'12월'!I16 -> 936586111 | J16: ='1월'!L16+'2월'!J16+'3월'!J16+'4월'!J16+'5월'!J16+'6월'!J16+'7월'!J16+'8월'!J16+'9월'!J16+'10월'!J16+'11월'!J16+'12월'!J16 -> 1558828667 | K16: ='1월'!M16+'2월'!K16+'3월'!K16+'4월'!K16+'5월'!K16+'6월'!K16+'7월'!K16+'8월'!K16+'9월'!K16+'10월'!K16+'11월'!K16+'12월'!K16 -> 2917135810 | L16: ='1월'!N16+'2월'!L16+'3월'!L16+'4월'!L16+'5월'!L16+'6월'!L16+'7월'!L16+'8월'!L16+'9월'!L16+'10월'!L16+'11월'!L16+'12월'!L16 -> 1462628020 | M16: ='1월'!O16+'2월'!M16+'3월'!M16+'4월'!M16+'5월'!M16+'6월'!M16+'7월'!M16+'8월'!M16+'9월'!M16+'10월'!M16+'11월'!M16+'12월'!M16 -> 0 | O16: =IFERROR(VLOOKUP($A16,[1]플랫폼1!$A:$B,2,FALSE),0) -> 0 | P16: =IFERROR(VLOOKUP($A16,[1]플랫폼2!$A:$M,12,FALSE),0)+IFERROR(VLOOKUP($A16,[1]플랫폼2!$A:$M,13,FALSE),0) -> 0 | Q16: =IFERROR(VLOOKUP($A16,[1]플랫폼2!$A:$M,7,FALSE),0)+IFERROR(VLOOKUP($A16,[1]플랫폼2!$A:$M,12,FALSE),0) -> 0 | R16: =IFERROR(VLOOKUP($A16,[1]모바일!$A:$S,17,FALSE),0) -> 0 | S16: =IFERROR(VLOOKUP($A16,[1]모바일!$A:$S,18,FALSE),0) -> 0 | T16: =IFERROR(VLOOKUP(A16,[1]플랫폼2!$A:$O,15,0),0) -> 0 | V16: 기타운영비 | W16: =O115+O122+O126+O136+O151+O156+O164+O171+O178+O181+O193+O199 -> 2336008113 | X16: =P115+P122+P126+P136+P151+P156+P164+P171+P178+P181+P193+P199 -> 1126844035 | Y16: =Q115+Q122+Q126+Q136+Q151+Q156+Q164+Q171+Q178+Q181+Q193+Q199 -> 927165627 | Z16: =R115+R122+R126+R136+R151+R156+R164+R171+R178+R181+R193+R199 -> 2.532367e+08 | AA16: =S115+S122+S126+S136+S151+S156+S164+S171+S178+S181+S193+S199 -> 1.0558838e+08
A17: 수수료수입-매장성 | B17: ='1월'!B17+'2월'!B17+'3월'!B17+'4월'!B17+'5월'!B17+'6월'!B17+'7월'!B17+'8월'!B17+'9월'!B17+'10월'!B17+'11월'!B17+'12월'!B17 -> 918177211 | C17: ='1월'!C17+'2월'!C17+'3월'!C17+'4월'!C17+'5월'!C17+'6월'!C17+'7월'!C17+'8월'!C17+'9월'!C17+'10월'!C17+'11월'!C17+'12월'!C17 -> 79291398 | D17: ='1월'!D17+'2월'!D17+'3월'!D17+'4월'!D17+'5월'!D17+'6월'!D17+'7월'!D17+'8월'!D17+'9월'!D17+'10월'!D17+'11월'!D17+'12월'!D17 -> 0 | E17: ='1월'!E17+'2월'!E17+'3월'!E17+'4월'!E17+'5월'!E17+'6월'!E17+'7월'!E17+'8월'!E17+'9월'!E17+'10월'!E17+'11월'!E17+'12월'!E17 -> 838885813 | F17: ='1월'!F17+'2월'!F17+'3월'!F17+'4월'!F17+'5월'!F17+'6월'!F17+'7월'!F17+'8월'!F17+'9월'!F17+'10월'!F17+'11월'!F17+'12월'!F17 -> 777172701 | G17: ='1월'!H17+'2월'!G17+'3월'!G17+'4월'!G17+'5월'!G17+'6월'!G17+'7월'!G17+'8월'!G17+'9월'!G17+'10월'!G17+'11월'!G17+'12월'!G17 -> 15747028 | H17: ='1월'!J17+'2월'!H17+'3월'!H17+'4월'!H17+'5월'!H17+'6월'!H17+'7월'!H17+'8월'!H17+'9월'!H17+'10월'!H17+'11월'!H17+'12월'!H17 -> 28386448 | I17: ='1월'!K17+'2월'!I17+'3월'!I17+'4월'!I17+'5월'!I17+'6월'!I17+'7월'!I17+'8월'!I17+'9월'!I17+'10월'!I17+'11월'!I17+'12월'!I17 -> 790000 | J17: ='1월'!L17+'2월'!J17+'3월'!J17+'4월'!J17+'5월'!J17+'6월'!J17+'7월'!J17+'8월'!J17+'9월'!J17+'10월'!J17+'11월'!J17+'12월'!J17 -> 14287909 | K17: ='1월'!M17+'2월'!K17+'3월'!K17+'4월'!K17+'5월'!K17+'6월'!K17+'7월'!K17+'8월'!K17+'9월'!K17+'10월'!K17+'11월'!K17+'12월'!K17 -> 2501727 | L17: ='1월'!N17+'2월'!L17+'3월'!L17+'4월'!L17+'5월'!L17+'6월'!L17+'7월'!L17+'8월'!L17+'9월'!L17+'10월'!L17+'11월'!L17+'12월'!L17 -> 0 | M17: ='1월'!O17+'2월'!M17+'3월'!M17+'4월'!M17+'5월'!M17+'6월'!M17+'7월'!M17+'8월'!M17+'9월'!M17+'10월'!M17+'11월'!M17+'12월'!M17 -> 0 | O17: =IFERROR(VLOOKUP($A17,[1]플랫폼1!$A:$B,2,FALSE),0) -> 0 | P17: =IFERROR(VLOOKUP($A17,[1]플랫폼2!$A:$M,12,FALSE),0)+IFERROR(VLOOKUP($A17,[1]플랫폼2!$A:$M,13,FALSE),0) -> 0 | Q17: =IFERROR(VLOOKUP($A17,[1]플랫폼2!$A:$M,7,FALSE),0)+IFERROR(VLOOKUP($A17,[1]플랫폼2!$A:$M,12,FALSE),0) -> 0 | R17: =IFERROR(VLOOKUP($A17,[1]모바일!$A:$S,17,FALSE),0) -> 0 | S17: =IFERROR(VLOOKUP($A17,[1]모바일!$A:$S,18,FALSE),0) -> 0 | T17: =IFERROR(VLOOKUP(A17,[1]플랫폼2!$A:$O,15,0),0) -> 0 | V17: 영 업 이 익 | W17: =VLOOKUP(V17,$A:$S,15,0) -> -298277290 | X17: =VLOOKUP(V17,$A:$S,16,0) -> 407022377 | Y17: =VLOOKUP(V17,$A:$S,17,0) -> 5861799116 | Z17: =VLOOKUP(V17,$A:$S,18,0) -> 45481029 | AA17: =VLOOKUP(V17,$A:$S,19,0) -> 2.6954275e+08
A18: 수수료수입-유선 | B18: ='1월'!B18+'2월'!B18+'3월'!B18+'4월'!B18+'5월'!B18+'6월'!B18+'7월'!B18+'8월'!B18+'9월'!B18+'10월'!B18+'11월'!B18+'12월'!B18 -> 31133304661 | C18: ='1월'!C18+'2월'!C18+'3월'!C18+'4월'!C18+'5월'!C18+'6월'!C18+'7월'!C18+'8월'!C18+'9월'!C18+'10월'!C18+'11월'!C18+'12월'!C18 -> -1293610322 | D18: ='1월'!D18+'2월'!D18+'3월'!D18+'4월'!D18+'5월'!D18+'6월'!D18+'7월'!D18+'8월'!D18+'9월'!D18+'10월'!D18+'11월'!D18+'12월'!D18 -> 14545454 | E18: ='1월'!E18+'2월'!E18+'3월'!E18+'4월'!E18+'5월'!E18+'6월'!E18+'7월'!E18+'8월'!E18+'9월'!E18+'10월'!E18+'11월'!E18+'12월'!E18 -> 32412369529 | F18: ='1월'!F18+'2월'!F18+'3월'!F18+'4월'!F18+'5월'!F18+'6월'!F18+'7월'!F18+'8월'!F18+'9월'!F18+'10월'!F18+'11월'!F18+'12월'!F18 -> 1.9968208e+10 | G18: ='1월'!H18+'2월'!G18+'3월'!G18+'4월'!G18+'5월'!G18+'6월'!G18+'7월'!G18+'8월'!G18+'9월'!G18+'10월'!G18+'11월'!G18+'12월'!G18 -> 2913760.5 | H18: ='1월'!J18+'2월'!H18+'3월'!H18+'4월'!H18+'5월'!H18+'6월'!H18+'7월'!H18+'8월'!H18+'9월'!H18+'10월'!H18+'11월'!H18+'12월'!H18 -> 479447248 | I18: ='1월'!K18+'2월'!I18+'3월'!I18+'4월'!I18+'5월'!I18+'6월'!I18+'7월'!I18+'8월'!I18+'9월'!I18+'10월'!I18+'11월'!I18+'12월'!I18 -> 18745461 | J18: ='1월'!L18+'2월'!J18+'3월'!J18+'4월'!J18+'5월'!J18+'6월'!J18+'7월'!J18+'8월'!J18+'9월'!J18+'10월'!J18+'11월'!J18+'12월'!J18 -> 0 | K18: ='1월'!M18+'2월'!K18+'3월'!K18+'4월'!K18+'5월'!K18+'6월'!K18+'7월'!K18+'8월'!K18+'9월'!K18+'10월'!K18+'11월'!K18+'12월'!K18 -> 156176906 | L18: ='1월'!N18+'2월'!L18+'3월'!L18+'4월'!L18+'5월'!L18+'6월'!L18+'7월'!L18+'8월'!L18+'9월'!L18+'10월'!L18+'11월'!L18+'12월'!L18 -> 11786878508 | M18: ='1월'!O18+'2월'!M18+'3월'!M18+'4월'!M18+'5월'!M18+'6월'!M18+'7월'!M18+'8월'!M18+'9월'!M18+'10월'!M18+'11월'!M18+'12월'!M18 -> 0 | O18: =IFERROR(VLOOKUP($A18,[1]플랫폼1!$A:$B,2,FALSE),0) -> 0 | P18: =IFERROR(VLOOKUP($A18,[1]플랫폼2!$A:$M,12,FALSE),0)+IFERROR(VLOOKUP($A18,[1]플랫폼2!$A:$M,13,FALSE),0) -> 0 | Q18: =IFERROR(VLOOKUP($A18,[1]플랫폼2!$A:$M,7,FALSE),0)+IFERROR(VLOOKUP($A18,[1]플랫폼2!$A:$M,12,FALSE),0) -> 0 | R18: =IFERROR(VLOOKUP($A18,[1]모바일!$A:$S,17,FALSE),0) -> 0 | S18: =IFERROR(VLOOKUP($A18,[1]모바일!$A:$S,18,FALSE),0) -> 0 | T18: =IFERROR(VLOOKUP(A18,[1]플랫폼2!$A:$O,15,0),0) -> 0
A19: 수수료수입-순액처리 | B19: ='1월'!B19+'2월'!B19+'3월'!B19+'4월'!B19+'5월'!B19+'6월'!B19+'7월'!B19+'8월'!B19+'9월'!B19+'10월'!B19+'11월'!B19+'12월'!B19 -> -20803985180 | C19: ='1월'!C19+'2월'!C19+'3월'!C19+'4월'!C19+'5월'!C19+'6월'!C19+'7월'!C19+'8월'!C19+'9월'!C19+'10월'!C19+'11월'!C19+'12월'!C19 -> -20803985180 | D19: ='1월'!D19+'2월'!D19+'3월'!D19+'4월'!D19+'5월'!D19+'6월'!D19+'7월'!D19+'8월'!D19+'9월'!D19+'10월'!D19+'11월'!D19+'12월'!D19 -> 0 | E19: ='1월'!E19+'2월'!E19+'3월'!E19+'4월'!E19+'5월'!E19+'6월'!E19+'7월'!E19+'8월'!E19+'9월'!E19+'10월'!E19+'11월'!E19+'12월'!E19 -> 0 | F19: ='1월'!F19+'2월'!F19+'3월'!F19+'4월'!F19+'5월'!F19+'6월'!F19+'7월'!F19+'8월'!F19+'9월'!F19+'10월'!F19+'11월'!F19+'12월'!F19 -> 0 | G19: ='1월'!H19+'2월'!G19+'3월'!G19+'4월'!G19+'5월'!G19+'6월'!G19+'7월'!G19+'8월'!G19+'9월'!G19+'10월'!G19+'11월'!G19+'12월'!G19 -> 0 | H19: ='1월'!J19+'2월'!H19+'3월'!H19+'4월'!H19+'5월'!H19+'6월'!H19+'7월'!H19+'8월'!H19+'9월'!H19+'10월'!H19+'11월'!H19+'12월'!H19 -> 0 | I19: ='1월'!K19+'2월'!I19+'3월'!I19+'4월'!I19+'5월'!I19+'6월'!I19+'7월'!I19+'8월'!I19+'9월'!I19+'10월'!I19+'11월'!I19+'12월'!I19 -> 0 | J19: ='1월'!L19+'2월'!J19+'3월'!J19+'4월'!J19+'5월'!J19+'6월'!J19+'7월'!J19+'8월'!J19+'9월'!J19+'10월'!J19+'11월'!J19+'12월'!J19 -> 0 | K19: ='1월'!M19+'2월'!K19+'3월'!K19+'4월'!K19+'5월'!K19+'6월'!K19+'7월'!K19+'8월'!K19+'9월'!K19+'10월'!K19+'11월'!K19+'12월'!K19 -> 0 | L19: ='1월'!N19+'2월'!L19+'3월'!L19+'4월'!L19+'5월'!L19+'6월'!L19+'7월'!L19+'8월'!L19+'9월'!L19+'10월'!L19+'11월'!L19+'12월'!L19 -> 0 | M19: ='1월'!O19+'2월'!M19+'3월'!M19+'4월'!M19+'5월'!M19+'6월'!M19+'7월'!M19+'8월'!M19+'9월'!M19+'10월'!M19+'11월'!M19+'12월'!M19 -> 0 | O19: =IFERROR(VLOOKUP($A19,[1]플랫폼1!$A:$B,2,FALSE),0) -> 0 | P19: =IFERROR(VLOOKUP($A19,[1]플랫폼2!$A:$M,12,FALSE),0)+IFERROR(VLOOKUP($A19,[1]플랫폼2!$A:$M,13,FALSE),0) -> 0 | Q19: =IFERROR(VLOOKUP($A19,[1]플랫폼2!$A:$M,7,FALSE),0)+IFERROR(VLOOKUP($A19,[1]플랫폼2!$A:$M,12,FALSE),0) -> 0 | R19: =IFERROR(VLOOKUP($A19,[1]모바일!$A:$S,17,FALSE),0) -> 0 | S19: =IFERROR(VLOOKUP($A19,[1]모바일!$A:$S,18,FALSE),0) -> 0 | T19: =IFERROR(VLOOKUP(A19,[1]플랫폼2!$A:$O,15,0),0) -> 0
A20: 수수료수입-AS | B20: ='1월'!B20+'2월'!B20+'3월'!B20+'4월'!B20+'5월'!B20+'6월'!B20+'7월'!B20+'8월'!B20+'9월'!B20+'10월'!B20+'11월'!B20+'12월'!B20 -> 0 | C20: ='1월'!C20+'2월'!C20+'3월'!C20+'4월'!C20+'5월'!C20+'6월'!C20+'7월'!C20+'8월'!C20+'9월'!C20+'10월'!C20+'11월'!C20+'12월'!C20 -> 0 | D20: ='1월'!D20+'2월'!D20+'3월'!D20+'4월'!D20+'5월'!D20+'6월'!D20+'7월'!D20+'8월'!D20+'9월'!D20+'10월'!D20+'11월'!D20+'12월'!D20 -> 0 | E20: ='1월'!E20+'2월'!E20+'3월'!E20+'4월'!E20+'5월'!E20+'6월'!E20+'7월'!E20+'8월'!E20+'9월'!E20+'10월'!E20+'11월'!E20+'12월'!E20 -> 0 | F20: ='1월'!F20+'2월'!F20+'3월'!F20+'4월'!F20+'5월'!F20+'6월'!F20+'7월'!F20+'8월'!F20+'9월'!F20+'10월'!F20+'11월'!F20+'12월'!F20 -> 0 | G20: ='1월'!H20+'2월'!G20+'3월'!G20+'4월'!G20+'5월'!G20+'6월'!G20+'7월'!G20+'8월'!G20+'9월'!G20+'10월'!G20+'11월'!G20+'12월'!G20 -> 0 | H20: ='1월'!J20+'2월'!H20+'3월'!H20+'4월'!H20+'5월'!H20+'6월'!H20+'7월'!H20+'8월'!H20+'9월'!H20+'10월'!H20+'11월'!H20+'12월'!H20 -> 0 | I20: ='1월'!K20+'2월'!I20+'3월'!I20+'4월'!I20+'5월'!I20+'6월'!I20+'7월'!I20+'8월'!I20+'9월'!I20+'10월'!I20+'11월'!I20+'12월'!I20 -> 0 | J20: ='1월'!L20+'2월'!J20+'3월'!J20+'4월'!J20+'5월'!J20+'6월'!J20+'7월'!J20+'8월'!J20+'9월'!J20+'10월'!J20+'11월'!J20+'12월'!J20 -> 0 | K20: ='1월'!M20+'2월'!K20+'3월'!K20+'4월'!K20+'5월'!K20+'6월'!K20+'7월'!K20+'8월'!K20+'9월'!K20+'10월'!K20+'11월'!K20+'12월'!K20 -> 0 | L20: ='1월'!N20+'2월'!L20+'3월'!L20+'4월'!L20+'5월'!L20+'6월'!L20+'7월'!L20+'8월'!L20+'9월'!L20+'10월'!L20+'11월'!L20+'12월'!L20 -> 0 | M20: ='1월'!O20+'2월'!M20+'3월'!M20+'4월'!M20+'5월'!M20+'6월'!M20+'7월'!M20+'8월'!M20+'9월'!M20+'10월'!M20+'11월'!M20+'12월'!M20 -> 0 | O20: =IFERROR(VLOOKUP($A20,[1]플랫폼1!$A:$B,2,FALSE),0) -> 0 | P20: =IFERROR(VLOOKUP($A20,[1]플랫폼2!$A:$M,12,FALSE),0)+IFERROR(VLOOKUP($A20,[1]플랫폼2!$A:$M,13,FALSE),0) -> 0 | Q20: =IFERROR(VLOOKUP($A20,[1]플랫폼2!$A:$M,7,FALSE),0)+IFERROR(VLOOKUP($A20,[1]플랫폼2!$A:$M,12,FALSE),0) -> 0 | R20: =IFERROR(VLOOKUP($A20,[1]모바일!$A:$S,17,FALSE),0) -> 0 | S20: =IFERROR(VLOOKUP($A20,[1]모바일!$A:$S,18,FALSE),0) -> 0 | T20: =IFERROR(VLOOKUP(A20,[1]플랫폼2!$A:$O,15,0),0) -> 0
A21: 수수료수입-정책 | B21: ='1월'!B21+'2월'!B21+'3월'!B21+'4월'!B21+'5월'!B21+'6월'!B21+'7월'!B21+'8월'!B21+'9월'!B21+'10월'!B21+'11월'!B21+'12월'!B21 -> 6028736368 | C21: ='1월'!C21+'2월'!C21+'3월'!C21+'4월'!C21+'5월'!C21+'6월'!C21+'7월'!C21+'8월'!C21+'9월'!C21+'10월'!C21+'11월'!C21+'12월'!C21 -> 45818182 | D21: ='1월'!D21+'2월'!D21+'3월'!D21+'4월'!D21+'5월'!D21+'6월'!D21+'7월'!D21+'8월'!D21+'9월'!D21+'10월'!D21+'11월'!D21+'12월'!D21 -> 0 | E21: ='1월'!E21+'2월'!E21+'3월'!E21+'4월'!E21+'5월'!E21+'6월'!E21+'7월'!E21+'8월'!E21+'9월'!E21+'10월'!E21+'11월'!E21+'12월'!E21 -> 5982918186 | F21: ='1월'!F21+'2월'!F21+'3월'!F21+'4월'!F21+'5월'!F21+'6월'!F21+'7월'!F21+'8월'!F21+'9월'!F21+'10월'!F21+'11월'!F21+'12월'!F21 -> 1.7782662e+08 | G21: ='1월'!H21+'2월'!G21+'3월'!G21+'4월'!G21+'5월'!G21+'6월'!G21+'7월'!G21+'8월'!G21+'9월'!G21+'10월'!G21+'11월'!G21+'12월'!G21 -> 4706119.6 | H21: ='1월'!J21+'2월'!H21+'3월'!H21+'4월'!H21+'5월'!H21+'6월'!H21+'7월'!H21+'8월'!H21+'9월'!H21+'10월'!H21+'11월'!H21+'12월'!H21 -> 3566370717 | I21: ='1월'!K21+'2월'!I21+'3월'!I21+'4월'!I21+'5월'!I21+'6월'!I21+'7월'!I21+'8월'!I21+'9월'!I21+'10월'!I21+'11월'!I21+'12월'!I21 -> 1769020436 | J21: ='1월'!L21+'2월'!J21+'3월'!J21+'4월'!J21+'5월'!J21+'6월'!J21+'7월'!J21+'8월'!J21+'9월'!J21+'10월'!J21+'11월'!J21+'12월'!J21 -> 8890909 | K21: ='1월'!M21+'2월'!K21+'3월'!K21+'4월'!K21+'5월'!K21+'6월'!K21+'7월'!K21+'8월'!K21+'9월'!K21+'10월'!K21+'11월'!K21+'12월'!K21 -> 456103387 | L21: ='1월'!N21+'2월'!L21+'3월'!L21+'4월'!L21+'5월'!L21+'6월'!L21+'7월'!L21+'8월'!L21+'9월'!L21+'10월'!L21+'11월'!L21+'12월'!L21 -> 0 | M21: ='1월'!O21+'2월'!M21+'3월'!M21+'4월'!M21+'5월'!M21+'6월'!M21+'7월'!M21+'8월'!M21+'9월'!M21+'10월'!M21+'11월'!M21+'12월'!M21 -> 0 | O21: =IFERROR(VLOOKUP($A21,[1]플랫폼1!$A:$B,2,FALSE),0) -> 0 | P21: =IFERROR(VLOOKUP($A21,[1]플랫폼2!$A:$M,12,FALSE),0)+IFERROR(VLOOKUP($A21,[1]플랫폼2!$A:$M,13,FALSE),0) -> 0 | Q21: =IFERROR(VLOOKUP($A21,[1]플랫폼2!$A:$M,7,FALSE),0)+IFERROR(VLOOKUP($A21,[1]플랫폼2!$A:$M,12,FALSE),0) -> 0 | R21: =IFERROR(VLOOKUP($A21,[1]모바일!$A:$S,17,FALSE),0) -> 0 | S21: =IFERROR(VLOOKUP($A21,[1]모바일!$A:$S,18,FALSE),0) -> 0 | T21: =IFERROR(VLOOKUP(A21,[1]플랫폼2!$A:$O,15,0),0) -> 0
A22: 수수료수입-용역 | B22: ='1월'!B22+'2월'!B22+'3월'!B22+'4월'!B22+'5월'!B22+'6월'!B22+'7월'!B22+'8월'!B22+'9월'!B22+'10월'!B22+'11월'!B22+'12월'!B22 -> 45387716427 | C22: ='1월'!C22+'2월'!C22+'3월'!C22+'4월'!C22+'5월'!C22+'6월'!C22+'7월'!C22+'8월'!C22+'9월'!C22+'10월'!C22+'11월'!C22+'12월'!C22 -> -720606000 | D22: ='1월'!D22+'2월'!D22+'3월'!D22+'4월'!D22+'5월'!D22+'6월'!D22+'7월'!D22+'8월'!D22+'9월'!D22+'10월'!D22+'11월'!D22+'12월'!D22 -> 1560181000 | E22: ='1월'!E22+'2월'!E22+'3월'!E22+'4월'!E22+'5월'!E22+'6월'!E22+'7월'!E22+'8월'!E22+'9월'!E22+'10월'!E22+'11월'!E22+'12월'!E22 -> 44548141427 | F22: ='1월'!F22+'2월'!F22+'3월'!F22+'4월'!F22+'5월'!F22+'6월'!F22+'7월'!F22+'8월'!F22+'9월'!F22+'10월'!F22+'11월'!F22+'12월'!F22 -> 720606000 | G22: ='1월'!H22+'2월'!G22+'3월'!G22+'4월'!G22+'5월'!G22+'6월'!G22+'7월'!G22+'8월'!G22+'9월'!G22+'10월'!G22+'11월'!G22+'12월'!G22 -> 31614761546 | H22: ='1월'!J22+'2월'!H22+'3월'!H22+'4월'!H22+'5월'!H22+'6월'!H22+'7월'!H22+'8월'!H22+'9월'!H22+'10월'!H22+'11월'!H22+'12월'!H22 -> 10439254280 | I22: ='1월'!K22+'2월'!I22+'3월'!I22+'4월'!I22+'5월'!I22+'6월'!I22+'7월'!I22+'8월'!I22+'9월'!I22+'10월'!I22+'11월'!I22+'12월'!I22 -> 16555000 | J22: ='1월'!L22+'2월'!J22+'3월'!J22+'4월'!J22+'5월'!J22+'6월'!J22+'7월'!J22+'8월'!J22+'9월'!J22+'10월'!J22+'11월'!J22+'12월'!J22 -> 251101271 | K22: ='1월'!M22+'2월'!K22+'3월'!K22+'4월'!K22+'5월'!K22+'6월'!K22+'7월'!K22+'8월'!K22+'9월'!K22+'10월'!K22+'11월'!K22+'12월'!K22 -> 483743330 | L22: ='1월'!N22+'2월'!L22+'3월'!L22+'4월'!L22+'5월'!L22+'6월'!L22+'7월'!L22+'8월'!L22+'9월'!L22+'10월'!L22+'11월'!L22+'12월'!L22 -> 0 | M22: ='1월'!O22+'2월'!M22+'3월'!M22+'4월'!M22+'5월'!M22+'6월'!M22+'7월'!M22+'8월'!M22+'9월'!M22+'10월'!M22+'11월'!M22+'12월'!M22 -> 1022120000 | O22: =IFERROR(VLOOKUP($A22,[1]플랫폼1!$A:$B,2,FALSE),0) -> 0 | P22: =IFERROR(VLOOKUP($A22,[1]플랫폼2!$A:$M,12,FALSE),0)+IFERROR(VLOOKUP($A22,[1]플랫폼2!$A:$M,13,FALSE),0) -> 222455034 | Q22: =IFERROR(VLOOKUP($A22,[1]플랫폼2!$A:$M,7,FALSE),0)+IFERROR(VLOOKUP($A22,[1]플랫폼2!$A:$M,12,FALSE),0) -> 0 | R22: =IFERROR(VLOOKUP($A22,[1]모바일!$A:$S,17,FALSE),0) -> 357710000 | S22: =IFERROR(VLOOKUP($A22,[1]모바일!$A:$S,18,FALSE),0) -> 441954966 | T22: =IFERROR(VLOOKUP(A22,[1]플랫폼2!$A:$O,15,0),0) -> 0
A23: 수수료수입-P3.0 | B23: ='1월'!B23+'2월'!B23+'3월'!B23+'4월'!B23+'5월'!B23+'6월'!B23+'7월'!B23+'8월'!B23+'9월'!B23+'10월'!B23+'11월'!B23+'12월'!B23 -> 8140356670 | C23: ='1월'!C23+'2월'!C23+'3월'!C23+'4월'!C23+'5월'!C23+'6월'!C23+'7월'!C23+'8월'!C23+'9월'!C23+'10월'!C23+'11월'!C23+'12월'!C23 -> -634738227 | D23: ='1월'!D23+'2월'!D23+'3월'!D23+'4월'!D23+'5월'!D23+'6월'!D23+'7월'!D23+'8월'!D23+'9월'!D23+'10월'!D23+'11월'!D23+'12월'!D23 -> 0 | E23: ='1월'!E23+'2월'!E23+'3월'!E23+'4월'!E23+'5월'!E23+'6월'!E23+'7월'!E23+'8월'!E23+'9월'!E23+'10월'!E23+'11월'!E23+'12월'!E23 -> 8775094897 | F23: ='1월'!F23+'2월'!F23+'3월'!F23+'4월'!F23+'5월'!F23+'6월'!F23+'7월'!F23+'8월'!F23+'9월'!F23+'10월'!F23+'11월'!F23+'12월'!F23 -> 8775094897 | G23: ='1월'!H23+'2월'!G23+'3월'!G23+'4월'!G23+'5월'!G23+'6월'!G23+'7월'!G23+'8월'!G23+'9월'!G23+'10월'!G23+'11월'!G23+'12월'!G23 -> 0 | H23: ='1월'!J23+'2월'!H23+'3월'!H23+'4월'!H23+'5월'!H23+'6월'!H23+'7월'!H23+'8월'!H23+'9월'!H23+'10월'!H23+'11월'!H23+'12월'!H23 -> 0 | I23: ='1월'!K23+'2월'!I23+'3월'!I23+'4월'!I23+'5월'!I23+'6월'!I23+'7월'!I23+'8월'!I23+'9월'!I23+'10월'!I23+'11월'!I23+'12월'!I23 -> 0 | J23: ='1월'!L23+'2월'!J23+'3월'!J23+'4월'!J23+'5월'!J23+'6월'!J23+'7월'!J23+'8월'!J23+'9월'!J23+'10월'!J23+'11월'!J23+'12월'!J23 -> 0 | K23: ='1월'!M23+'2월'!K23+'3월'!K23+'4월'!K23+'5월'!K23+'6월'!K23+'7월'!K23+'8월'!K23+'9월'!K23+'10월'!K23+'11월'!K23+'12월'!K23 -> 0 | L23: ='1월'!N23+'2월'!L23+'3월'!L23+'4월'!L23+'5월'!L23+'6월'!L23+'7월'!L23+'8월'!L23+'9월'!L23+'10월'!L23+'11월'!L23+'12월'!L23 -> 0 | M23: ='1월'!O23+'2월'!M23+'3월'!M23+'4월'!M23+'5월'!M23+'6월'!M23+'7월'!M23+'8월'!M23+'9월'!M23+'10월'!M23+'11월'!M23+'12월'!M23 -> 0 | O23: =IFERROR(VLOOKUP($A23,[1]플랫폼1!$A:$B,2,FALSE),0) -> 0 | P23: =IFERROR(VLOOKUP($A23,[1]플랫폼2!$A:$M,12,FALSE),0)+IFERROR(VLOOKUP($A23,[1]플랫폼2!$A:$M,13,FALSE),0) -> 0 | Q23: =IFERROR(VLOOKUP($A23,[1]플랫폼2!$A:$M,7,FALSE),0)+IFERROR(VLOOKUP($A23,[1]플랫폼2!$A:$M,12,FALSE),0) -> 0 | R23: =IFERROR(VLOOKUP($A23,[1]모바일!$A:$S,17,FALSE),0) -> 0 | S23: =IFERROR(VLOOKUP($A23,[1]모바일!$A:$S,18,FALSE),0) -> 0 | T23: =IFERROR(VLOOKUP(A23,[1]플랫폼2!$A:$O,15,0),0) -> 0
A24: 수수료수입-신사업 | B24: ='1월'!B24+'2월'!B24+'3월'!B24+'4월'!B24+'5월'!B24+'6월'!B24+'7월'!B24+'8월'!B24+'9월'!B24+'10월'!B24+'11월'!B24+'12월'!B24 -> 0 | C24: ='1월'!C24+'2월'!C24+'3월'!C24+'4월'!C24+'5월'!C24+'6월'!C24+'7월'!C24+'8월'!C24+'9월'!C24+'10월'!C24+'11월'!C24+'12월'!C24 -> 0 | D24: ='1월'!D24+'2월'!D24+'3월'!D24+'4월'!D24+'5월'!D24+'6월'!D24+'7월'!D24+'8월'!D24+'9월'!D24+'10월'!D24+'11월'!D24+'12월'!D24 -> 0 | E24: ='1월'!E24+'2월'!E24+'3월'!E24+'4월'!E24+'5월'!E24+'6월'!E24+'7월'!E24+'8월'!E24+'9월'!E24+'10월'!E24+'11월'!E24+'12월'!E24 -> 0 | F24: ='1월'!F24+'2월'!F24+'3월'!F24+'4월'!F24+'5월'!F24+'6월'!F24+'7월'!F24+'8월'!F24+'9월'!F24+'10월'!F24+'11월'!F24+'12월'!F24 -> 0 | G24: ='1월'!H24+'2월'!G24+'3월'!G24+'4월'!G24+'5월'!G24+'6월'!G24+'7월'!G24+'8월'!G24+'9월'!G24+'10월'!G24+'11월'!G24+'12월'!G24 -> 0 | H24: ='1월'!J24+'2월'!H24+'3월'!H24+'4월'!H24+'5월'!H24+'6월'!H24+'7월'!H24+'8월'!H24+'9월'!H24+'10월'!H24+'11월'!H24+'12월'!H24 -> 0 | I24: ='1월'!K24+'2월'!I24+'3월'!I24+'4월'!I24+'5월'!I24+'6월'!I24+'7월'!I24+'8월'!I24+'9월'!I24+'10월'!I24+'11월'!I24+'12월'!I24 -> 0 | J24: ='1월'!L24+'2월'!J24+'3월'!J24+'4월'!J24+'5월'!J24+'6월'!J24+'7월'!J24+'8월'!J24+'9월'!J24+'10월'!J24+'11월'!J24+'12월'!J24 -> 0 | K24: ='1월'!M24+'2월'!K24+'3월'!K24+'4월'!K24+'5월'!K24+'6월'!K24+'7월'!K24+'8월'!K24+'9월'!K24+'10월'!K24+'11월'!K24+'12월'!K24 -> 0 | L24: ='1월'!N24+'2월'!L24+'3월'!L24+'4월'!L24+'5월'!L24+'6월'!L24+'7월'!L24+'8월'!L24+'9월'!L24+'10월'!L24+'11월'!L24+'12월'!L24 -> 0 | M24: ='1월'!O24+'2월'!M24+'3월'!M24+'4월'!M24+'5월'!M24+'6월'!M24+'7월'!M24+'8월'!M24+'9월'!M24+'10월'!M24+'11월'!M24+'12월'!M24 -> 0 | O24: =IFERROR(VLOOKUP($A24,[1]플랫폼1!$A:$B,2,FALSE),0) -> 0 | P24: =IFERROR(VLOOKUP($A24,[1]플랫폼2!$A:$M,12,FALSE),0)+IFERROR(VLOOKUP($A24,[1]플랫폼2!$A:$M,13,FALSE),0) -> 0 | Q24: =IFERROR(VLOOKUP($A24,[1]플랫폼2!$A:$M,7,FALSE),0)+IFERROR(VLOOKUP($A24,[1]플랫폼2!$A:$M,12,FALSE),0) -> 0 | R24: =IFERROR(VLOOKUP($A24,[1]모바일!$A:$S,17,FALSE),0) -> 0 | S24: =IFERROR(VLOOKUP($A24,[1]모바일!$A:$S,18,FALSE),0) -> 0 | T24: =IFERROR(VLOOKUP(A24,[1]플랫폼2!$A:$O,15,0),0) -> 0
A25: 매 출 원 가 | B25: ='1월'!B25+'2월'!B25+'3월'!B25+'4월'!B25+'5월'!B25+'6월'!B25+'7월'!B25+'8월'!B25+'9월'!B25+'10월'!B25+'11월'!B25+'12월'!B25 -> 501271152573 | C25: ='1월'!C25+'2월'!C25+'3월'!C25+'4월'!C25+'5월'!C25+'6월'!C25+'7월'!C25+'8월'!C25+'9월'!C25+'10월'!C25+'11월'!C25+'12월'!C25 -> 1534112483 | D25: ='1월'!D25+'2월'!D25+'3월'!D25+'4월'!D25+'5월'!D25+'6월'!D25+'7월'!D25+'8월'!D25+'9월'!D25+'10월'!D25+'11월'!D25+'12월'!D25 -> 0 | E25: ='1월'!E25+'2월'!E25+'3월'!E25+'4월'!E25+'5월'!E25+'6월'!E25+'7월'!E25+'8월'!E25+'9월'!E25+'10월'!E25+'11월'!E25+'12월'!E25 -> 499737040090 | F25: ='1월'!F25+'2월'!F25+'3월'!F25+'4월'!F25+'5월'!F25+'6월'!F25+'7월'!F25+'8월'!F25+'9월'!F25+'10월'!F25+'11월'!F25+'12월'!F25 -> 202129592685 | G25: ='1월'!H25+'2월'!G25+'3월'!G25+'4월'!G25+'5월'!G25+'6월'!G25+'7월'!G25+'8월'!G25+'9월'!G25+'10월'!G25+'11월'!G25+'12월'!G25 -> 1993607273 | H25: ='1월'!J25+'2월'!H25+'3월'!H25+'4월'!H25+'5월'!H25+'6월'!H25+'7월'!H25+'8월'!H25+'9월'!H25+'10월'!H25+'11월'!H25+'12월'!H25 -> 156462654054 | I25: ='1월'!K25+'2월'!I25+'3월'!I25+'4월'!I25+'5월'!I25+'6월'!I25+'7월'!I25+'8월'!I25+'9월'!I25+'10월'!I25+'11월'!I25+'12월'!I25 -> 7909686446 | J25: ='1월'!L25+'2월'!J25+'3월'!J25+'4월'!J25+'5월'!J25+'6월'!J25+'7월'!J25+'8월'!J25+'9월'!J25+'10월'!J25+'11월'!J25+'12월'!J25 -> -2042112539 | K25: ='1월'!M25+'2월'!K25+'3월'!K25+'4월'!K25+'5월'!K25+'6월'!K25+'7월'!K25+'8월'!K25+'9월'!K25+'10월'!K25+'11월'!K25+'12월'!K25 -> 89200802536 | L25: ='1월'!N25+'2월'!L25+'3월'!L25+'4월'!L25+'5월'!L25+'6월'!L25+'7월'!L25+'8월'!L25+'9월'!L25+'10월'!L25+'11월'!L25+'12월'!L25 -> 1734628341 | M25: ='1월'!O25+'2월'!M25+'3월'!M25+'4월'!M25+'5월'!M25+'6월'!M25+'7월'!M25+'8월'!M25+'9월'!M25+'10월'!M25+'11월'!M25+'12월'!M25 -> 42348181294 | O25: =IFERROR(VLOOKUP($A25,[1]플랫폼1!$A:$B,2,FALSE),0) -> 4110141099 | P25: =IFERROR(VLOOKUP($A25,[1]플랫폼2!$A:$M,12,FALSE),0)+IFERROR(VLOOKUP($A25,[1]플랫폼2!$A:$M,13,FALSE),0) -> 7894223749 | Q25: =IFERROR(VLOOKUP($A25,[1]플랫폼2!$A:$M,7,FALSE),0)+IFERROR(VLOOKUP($A25,[1]플랫폼2!$A:$M,12,FALSE),0) -> 29895506448 | R25: =IFERROR(VLOOKUP($A25,[1]모바일!$A:$S,17,FALSE),0) -> 728333.33 | S25: =IFERROR(VLOOKUP($A25,[1]모바일!$A:$S,18,FALSE),0) -> 728333.33 | T25: =IFERROR(VLOOKUP(A25,[1]플랫폼2!$A:$O,15,0),0) -> 4.4685333e+08
A26: 상 품 매 출 원 가 | B26: ='1월'!B26+'2월'!B26+'3월'!B26+'4월'!B26+'5월'!B26+'6월'!B26+'7월'!B26+'8월'!B26+'9월'!B26+'10월'!B26+'11월'!B26+'12월'!B26 -> 501271152573 | C26: ='1월'!C26+'2월'!C26+'3월'!C26+'4월'!C26+'5월'!C26+'6월'!C26+'7월'!C26+'8월'!C26+'9월'!C26+'10월'!C26+'11월'!C26+'12월'!C26 -> 1534112483 | D26: ='1월'!D26+'2월'!D26+'3월'!D26+'4월'!D26+'5월'!D26+'6월'!D26+'7월'!D26+'8월'!D26+'9월'!D26+'10월'!D26+'11월'!D26+'12월'!D26 -> 0 | E26: ='1월'!E26+'2월'!E26+'3월'!E26+'4월'!E26+'5월'!E26+'6월'!E26+'7월'!E26+'8월'!E26+'9월'!E26+'10월'!E26+'11월'!E26+'12월'!E26 -> 499737040090 | F26: ='1월'!F26+'2월'!F26+'3월'!F26+'4월'!F26+'5월'!F26+'6월'!F26+'7월'!F26+'8월'!F26+'9월'!F26+'10월'!F26+'11월'!F26+'12월'!F26 -> 202129592685 | G26: ='1월'!H26+'2월'!G26+'3월'!G26+'4월'!G26+'5월'!G26+'6월'!G26+'7월'!G26+'8월'!G26+'9월'!G26+'10월'!G26+'11월'!G26+'12월'!G26 -> 1993607273 | H26: ='1월'!J26+'2월'!H26+'3월'!H26+'4월'!H26+'5월'!H26+'6월'!H26+'7월'!H26+'8월'!H26+'9월'!H26+'10월'!H26+'11월'!H26+'12월'!H26 -> 156462654054 | I26: ='1월'!K26+'2월'!I26+'3월'!I26+'4월'!I26+'5월'!I26+'6월'!I26+'7월'!I26+'8월'!I26+'9월'!I26+'10월'!I26+'11월'!I26+'12월'!I26 -> 7909686446 | J26: ='1월'!L26+'2월'!J26+'3월'!J26+'4월'!J26+'5월'!J26+'6월'!J26+'7월'!J26+'8월'!J26+'9월'!J26+'10월'!J26+'11월'!J26+'12월'!J26 -> -2042112539 | K26: ='1월'!M26+'2월'!K26+'3월'!K26+'4월'!K26+'5월'!K26+'6월'!K26+'7월'!K26+'8월'!K26+'9월'!K26+'10월'!K26+'11월'!K26+'12월'!K26 -> 89200802536 | L26: ='1월'!N26+'2월'!L26+'3월'!L26+'4월'!L26+'5월'!L26+'6월'!L26+'7월'!L26+'8월'!L26+'9월'!L26+'10월'!L26+'11월'!L26+'12월'!L26 -> 1734628341 | M26: ='1월'!O26+'2월'!M26+'3월'!M26+'4월'!M26+'5월'!M26+'6월'!M26+'7월'!M26+'8월'!M26+'9월'!M26+'10월'!M26+'11월'!M26+'12월'!M26 -> 42348181294 | O26: =IFERROR(VLOOKUP($A26,[1]플랫폼1!$A:$B,2,FALSE),0) -> 4110141099 | P26: =IFERROR(VLOOKUP($A26,[1]플랫폼2!$A:$M,12,FALSE),0)+IFERROR(VLOOKUP($A26,[1]플랫폼2!$A:$M,13,FALSE),0) -> 7894223749 | Q26: =IFERROR(VLOOKUP($A26,[1]플랫폼2!$A:$M,7,FALSE),0)+IFERROR(VLOOKUP($A26,[1]플랫폼2!$A:$M,12,FALSE),0) -> 29895506448 | R26: =IFERROR(VLOOKUP($A26,[1]모바일!$A:$S,17,FALSE),0) -> 728333.33 | S26: =IFERROR(VLOOKUP($A26,[1]모바일!$A:$S,18,FALSE),0) -> 728333.33 | T26: =IFERROR(VLOOKUP(A26,[1]플랫폼2!$A:$O,15,0),0) -> 4.4685333e+08
A27: 매 출 총 이 익 | B27: ='1월'!B27+'2월'!B27+'3월'!B27+'4월'!B27+'5월'!B27+'6월'!B27+'7월'!B27+'8월'!B27+'9월'!B27+'10월'!B27+'11월'!B27+'12월'!B27 -> 252186876895 | C27: ='1월'!C27+'2월'!C27+'3월'!C27+'4월'!C27+'5월'!C27+'6월'!C27+'7월'!C27+'8월'!C27+'9월'!C27+'10월'!C27+'11월'!C27+'12월'!C27 -> -22166233897 | D27: ='1월'!D27+'2월'!D27+'3월'!D27+'4월'!D27+'5월'!D27+'6월'!D27+'7월'!D27+'8월'!D27+'9월'!D27+'10월'!D27+'11월'!D27+'12월'!D27 -> 2370259975 | E27: ='1월'!E27+'2월'!E27+'3월'!E27+'4월'!E27+'5월'!E27+'6월'!E27+'7월'!E27+'8월'!E27+'9월'!E27+'10월'!E27+'11월'!E27+'12월'!E27 -> 271982850817 | F27: ='1월'!F27+'2월'!F27+'3월'!F27+'4월'!F27+'5월'!F27+'6월'!F27+'7월'!F27+'8월'!F27+'9월'!F27+'10월'!F27+'11월'!F27+'12월'!F27 -> 1.328186e+11 | G27: ='1월'!H27+'2월'!G27+'3월'!G27+'4월'!G27+'5월'!G27+'6월'!G27+'7월'!G27+'8월'!G27+'9월'!G27+'10월'!G27+'11월'!G27+'12월'!G27 -> 4.4724695e+10 | H27: ='1월'!J27+'2월'!H27+'3월'!H27+'4월'!H27+'5월'!H27+'6월'!H27+'7월'!H27+'8월'!H27+'9월'!H27+'10월'!H27+'11월'!H27+'12월'!H27 -> 41153765296 | I27: ='1월'!K27+'2월'!I27+'3월'!I27+'4월'!I27+'5월'!I27+'6월'!I27+'7월'!I27+'8월'!I27+'9월'!I27+'10월'!I27+'11월'!I27+'12월'!I27 -> 5471401128 | J27: ='1월'!L27+'2월'!J27+'3월'!J27+'4월'!J27+'5월'!J27+'6월'!J27+'7월'!J27+'8월'!J27+'9월'!J27+'10월'!J27+'11월'!J27+'12월'!J27 -> 11180524440 | K27: ='1월'!M27+'2월'!K27+'3월'!K27+'4월'!K27+'5월'!K27+'6월'!K27+'7월'!K27+'8월'!K27+'9월'!K27+'10월'!K27+'11월'!K27+'12월'!K27 -> 8767035754 | L27: ='1월'!N27+'2월'!L27+'3월'!L27+'4월'!L27+'5월'!L27+'6월'!L27+'7월'!L27+'8월'!L27+'9월'!L27+'10월'!L27+'11월'!L27+'12월'!L27 -> 14556591243 | M27: ='1월'!O27+'2월'!M27+'3월'!M27+'4월'!M27+'5월'!M27+'6월'!M27+'7월'!M27+'8월'!M27+'9월'!M27+'10월'!M27+'11월'!M27+'12월'!M27 -> 13310242732 | O27: =IFERROR(VLOOKUP($A27,[1]플랫폼1!$A:$B,2,FALSE),0) -> 2572621219 | P27: =IFERROR(VLOOKUP($A27,[1]플랫폼2!$A:$M,12,FALSE),0)+IFERROR(VLOOKUP($A27,[1]플랫폼2!$A:$M,13,FALSE),0) -> 2271025742 | Q27: =IFERROR(VLOOKUP($A27,[1]플랫폼2!$A:$M,7,FALSE),0)+IFERROR(VLOOKUP($A27,[1]플랫폼2!$A:$M,12,FALSE),0) -> 7223920115 | R27: =IFERROR(VLOOKUP($A27,[1]모바일!$A:$S,17,FALSE),0) -> 3.5698167e+08 | S27: =IFERROR(VLOOKUP($A27,[1]모바일!$A:$S,18,FALSE),0) -> 4.4122663e+08 | T27: =IFERROR(VLOOKUP(A27,[1]플랫폼2!$A:$O,15,0),0) -> 4.4446736e+08
A28: 판매비와일반관리비 | B28: ='1월'!B28+'2월'!B28+'3월'!B28+'4월'!B28+'5월'!B28+'6월'!B28+'7월'!B28+'8월'!B28+'9월'!B28+'10월'!B28+'11월'!B28+'12월'!B28 -> 235845461647 | C28: ='1월'!C28+'2월'!C28+'3월'!C28+'4월'!C28+'5월'!C28+'6월'!C28+'7월'!C28+'8월'!C28+'9월'!C28+'10월'!C28+'11월'!C28+'12월'!C28 -> -3.1615557e+08 | D28: ='1월'!D28+'2월'!D28+'3월'!D28+'4월'!D28+'5월'!D28+'6월'!D28+'7월'!D28+'8월'!D28+'9월'!D28+'10월'!D28+'11월'!D28+'12월'!D28 -> 7754690736 | E28: ='1월'!E28+'2월'!E28+'3월'!E28+'4월'!E28+'5월'!E28+'6월'!E28+'7월'!E28+'8월'!E28+'9월'!E28+'10월'!E28+'11월'!E28+'12월'!E28 -> 2.2840693e+11 | F28: ='1월'!F28+'2월'!F28+'3월'!F28+'4월'!F28+'5월'!F28+'6월'!F28+'7월'!F28+'8월'!F28+'9월'!F28+'10월'!F28+'11월'!F28+'12월'!F28 -> 1.1417634e+11 | G28: ='1월'!H28+'2월'!G28+'3월'!G28+'4월'!G28+'5월'!G28+'6월'!G28+'7월'!G28+'8월'!G28+'9월'!G28+'10월'!G28+'11월'!G28+'12월'!G28 -> 3.1804172e+10 | H28: ='1월'!J28+'2월'!H28+'3월'!H28+'4월'!H28+'5월'!H28+'6월'!H28+'7월'!H28+'8월'!H28+'9월'!H28+'10월'!H28+'11월'!H28+'12월'!H28 -> 3.30393e+10 | I28: ='1월'!K28+'2월'!I28+'3월'!I28+'4월'!I28+'5월'!I28+'6월'!I28+'7월'!I28+'8월'!I28+'9월'!I28+'10월'!I28+'11월'!I28+'12월'!I28 -> 4.9290773e+09 | J28: ='1월'!L28+'2월'!J28+'3월'!J28+'4월'!J28+'5월'!J28+'6월'!J28+'7월'!J28+'8월'!J28+'9월'!J28+'10월'!J28+'11월'!J28+'12월'!J28 -> 1.0183082e+10 | K28: ='1월'!M28+'2월'!K28+'3월'!K28+'4월'!K28+'5월'!K28+'6월'!K28+'7월'!K28+'8월'!K28+'9월'!K28+'10월'!K28+'11월'!K28+'12월'!K28 -> 7.738158e+09 | L28: ='1월'!N28+'2월'!L28+'3월'!L28+'4월'!L28+'5월'!L28+'6월'!L28+'7월'!L28+'8월'!L28+'9월'!L28+'10월'!L28+'11월'!L28+'12월'!L28 -> 1.8821416e+10 | M28: ='1월'!O28+'2월'!M28+'3월'!M28+'4월'!M28+'5월'!M28+'6월'!M28+'7월'!M28+'8월'!M28+'9월'!M28+'10월'!M28+'11월'!M28+'12월'!M28 -> 7715380593 | O28: =IFERROR(VLOOKUP($A28,[1]플랫폼1!$A:$B,2,FALSE),0) -> 2870898509 | P28: =IFERROR(VLOOKUP($A28,[1]플랫폼2!$A:$M,12,FALSE),0)+IFERROR(VLOOKUP($A28,[1]플랫폼2!$A:$M,13,FALSE),0) -> 1864003365 | Q28: =IFERROR(VLOOKUP($A28,[1]플랫폼2!$A:$M,7,FALSE),0)+IFERROR(VLOOKUP($A28,[1]플랫폼2!$A:$M,12,FALSE),0) -> 1362120999 | R28: =IFERROR(VLOOKUP($A28,[1]모바일!$A:$S,17,FALSE),0) -> 3.1150064e+08 | S28: =IFERROR(VLOOKUP($A28,[1]모바일!$A:$S,18,FALSE),0) -> 1.7168388e+08 | T28: =IFERROR(VLOOKUP(A28,[1]플랫폼2!$A:$O,15,0),0) -> 1135188061
A29: 임 원 급 여 | B29: ='1월'!B29+'2월'!B29+'3월'!B29+'4월'!B29+'5월'!B29+'6월'!B29+'7월'!B29+'8월'!B29+'9월'!B29+'10월'!B29+'11월'!B29+'12월'!B29 -> 1305190900 | C29: ='1월'!C29+'2월'!C29+'3월'!C29+'4월'!C29+'5월'!C29+'6월'!C29+'7월'!C29+'8월'!C29+'9월'!C29+'10월'!C29+'11월'!C29+'12월'!C29 -> 4.1946261e+08 | D29: ='1월'!D29+'2월'!D29+'3월'!D29+'4월'!D29+'5월'!D29+'6월'!D29+'7월'!D29+'8월'!D29+'9월'!D29+'10월'!D29+'11월'!D29+'12월'!D29 -> 194526450 | E29: ='1월'!E29+'2월'!E29+'3월'!E29+'4월'!E29+'5월'!E29+'6월'!E29+'7월'!E29+'8월'!E29+'9월'!E29+'10월'!E29+'11월'!E29+'12월'!E29 -> 6.9120184e+08 | F29: ='1월'!F29+'2월'!F29+'3월'!F29+'4월'!F29+'5월'!F29+'6월'!F29+'7월'!F29+'8월'!F29+'9월'!F29+'10월'!F29+'11월'!F29+'12월'!F29 -> 5.667791e+08 | G29: ='1월'!H29+'2월'!G29+'3월'!G29+'4월'!G29+'5월'!G29+'6월'!G29+'7월'!G29+'8월'!G29+'9월'!G29+'10월'!G29+'11월'!G29+'12월'!G29 -> 67539468 | H29: ='1월'!J29+'2월'!H29+'3월'!H29+'4월'!H29+'5월'!H29+'6월'!H29+'7월'!H29+'8월'!H29+'9월'!H29+'10월'!H29+'11월'!H29+'12월'!H29 -> 0 | I29: ='1월'!K29+'2월'!I29+'3월'!I29+'4월'!I29+'5월'!I29+'6월'!I29+'7월'!I29+'8월'!I29+'9월'!I29+'10월'!I29+'11월'!I29+'12월'!I29 -> 6804987.6 | J29: ='1월'!L29+'2월'!J29+'3월'!J29+'4월'!J29+'5월'!J29+'6월'!J29+'7월'!J29+'8월'!J29+'9월'!J29+'10월'!J29+'11월'!J29+'12월'!J29 -> 8031578.8 | K29: ='1월'!M29+'2월'!K29+'3월'!K29+'4월'!K29+'5월'!K29+'6월'!K29+'7월'!K29+'8월'!K29+'9월'!K29+'10월'!K29+'11월'!K29+'12월'!K29 -> 34524521 | L29: ='1월'!N29+'2월'!L29+'3월'!L29+'4월'!L29+'5월'!L29+'6월'!L29+'7월'!L29+'8월'!L29+'9월'!L29+'10월'!L29+'11월'!L29+'12월'!L29 -> 7522183.5 | M29: ='1월'!O29+'2월'!M29+'3월'!M29+'4월'!M29+'5월'!M29+'6월'!M29+'7월'!M29+'8월'!M29+'9월'!M29+'10월'!M29+'11월'!M29+'12월'!M29 -> 0 | O29: =IFERROR(VLOOKUP($A29,[1]플랫폼1!$A:$B,2,FALSE),0) -> 0 | P29: =IFERROR(VLOOKUP($A29,[1]플랫폼2!$A:$M,12,FALSE),0)+IFERROR(VLOOKUP($A29,[1]플랫폼2!$A:$M,13,FALSE),0) -> 0 | Q29: =IFERROR(VLOOKUP($A29,[1]플랫폼2!$A:$M,7,FALSE),0)+IFERROR(VLOOKUP($A29,[1]플랫폼2!$A:$M,12,FALSE),0) -> 0 | R29: =IFERROR(VLOOKUP($A29,[1]모바일!$A:$S,17,FALSE),0) -> 0 | S29: =IFERROR(VLOOKUP($A29,[1]모바일!$A:$S,18,FALSE),0) -> 0 | T29: =IFERROR(VLOOKUP(A29,[1]플랫폼2!$A:$O,15,0),0) -> 0
... A49: 초과근무수당-영업직 | B49: ='1월'!B49+'2월'!B49+'3월'!B49+'4월'!B49+'5월'!B49+'6월'!B49+'7월'!B49+'8월'!B49+'9월'!B49+'10월'!B49+'11월'!B49+'12월'!B49 -> 8301326610 | C49: ='1월'!C49+'2월'!C49+'3월'!C49+'4월'!C49+'5월'!C49+'6월'!C49+'7월'!C49+'8월'!C49+'9월'!C49+'10월'!C49+'11월'!C49+'12월'!C49 -> 172517450 | D49: ='1월'!D49+'2월'!D49+'3월'!D49+'4월'!D49+'5월'!D49+'6월'!D49+'7월'!D49+'8월'!D49+'9월'!D49+'10월'!D49+'11월'!D49+'12월'!D49 -> 135145870 | E49: ='1월'!E49+'2월'!E49+'3월'!E49+'4월'!E49+'5월'!E49+'6월'!E49+'7월'!E49+'8월'!E49+'9월'!E49+'10월'!E49+'11월'!E49+'12월'!E49 -> 7993663290 | F49: ='1월'!F49+'2월'!F49+'3월'!F49+'4월'!F49+'5월'!F49+'6월'!F49+'7월'!F49+'8월'!F49+'9월'!F49+'10월'!F49+'11월'!F49+'12월'!F49 -> 5.3244382e+09 | G49: ='1월'!H49+'2월'!G49+'3월'!G49+'4월'!G49+'5월'!G49+'6월'!G49+'7월'!G49+'8월'!G49+'9월'!G49+'10월'!G49+'11월'!G49+'12월'!G49 -> 1.7064268e+09 | H49: ='1월'!J49+'2월'!H49+'3월'!H49+'4월'!H49+'5월'!H49+'6월'!H49+'7월'!H49+'8월'!H49+'9월'!H49+'10월'!H49+'11월'!H49+'12월'!H49 -> 51606420 | I49: ='1월'!K49+'2월'!I49+'3월'!I49+'4월'!I49+'5월'!I49+'6월'!I49+'7월'!I49+'8월'!I49+'9월'!I49+'10월'!I49+'11월'!I49+'12월'!I49 -> 52664296 | J49: ='1월'!L49+'2월'!J49+'3월'!J49+'4월'!J49+'5월'!J49+'6월'!J49+'7월'!J49+'8월'!J49+'9월'!J49+'10월'!J49+'11월'!J49+'12월'!J49 -> 55185064 | K49: ='1월'!M49+'2월'!K49+'3월'!K49+'4월'!K49+'5월'!K49+'6월'!K49+'7월'!K49+'8월'!K49+'9월'!K49+'10월'!K49+'11월'!K49+'12월'!K49 -> 259778170 | L49: ='1월'!N49+'2월'!L49+'3월'!L49+'4월'!L49+'5월'!L49+'6월'!L49+'7월'!L49+'8월'!L49+'9월'!L49+'10월'!L49+'11월'!L49+'12월'!L49 -> 507816300 | M49: ='1월'!O49+'2월'!M49+'3월'!M49+'4월'!M49+'5월'!M49+'6월'!M49+'7월'!M49+'8월'!M49+'9월'!M49+'10월'!M49+'11월'!M49+'12월'!M49 -> 35747970 | O49: =IFERROR(VLOOKUP($A49,[1]플랫폼1!$A:$B,2,FALSE),0) -> 4378510 | P49: =IFERROR(VLOOKUP($A49,[1]플랫폼2!$A:$M,12,FALSE),0)+IFERROR(VLOOKUP($A49,[1]플랫폼2!$A:$M,13,FALSE),0) -> 3004925 | Q49: =IFERROR(VLOOKUP($A49,[1]플랫폼2!$A:$M,7,FALSE),0)+IFERROR(VLOOKUP($A49,[1]플랫폼2!$A:$M,12,FALSE),0) -> 3004925 | R49: =IFERROR(VLOOKUP($A49,[1]모바일!$A:$S,17,FALSE),0) -> 837272.5 | S49: =IFERROR(VLOOKUP($A49,[1]모바일!$A:$S,18,FALSE),0) -> 837272.5 | T49: =IFERROR(VLOOKUP(A49,[1]플랫폼2!$A:$O,15,0),0) -> 23685065
