Workbook

Sheet 전사 손익계산서
E1: =E98+E99 -> 0 | F1: =F98+F99 -> 0 | G1: =G98+G99 -> 0 | H1: =H98+H99 -> 0 | I1: =I98+I99 -> 0 | J1: =J98+J99 -> 0 | K1: =K98+K99 -> 0 | L1: =L98+L99 -> 0 | ... P1: =P98+P99 -> 0
Q3: =Q18/Q13 -> 1.0013413 | AD3: =AD18/AD13 -> 1.0333495 | AQ3: =AQ18/AQ13 -> 1.0271018 | BD3: =BD18/BD13 -> 1.0366854 | BQ3: =BQ18/BQ13 -> 1.068413 | BR3: =BR18/BR13 -> 1.0617113 | BS3: =BS18/BS13 -> 1.0270574 | BT3: =BT18/BT13 -> 1.0409872 | BU3: =BU18/BU13 -> 1.0965794 | BV3: =BV18/BV13 -> 1.1162294 | BW3: =BW18/BW13 -> 1.0703452 | BX3: =BX18/BX13 -> 1.1450079 | ... DC3: =DC18/DC13 -> 1.0185691
Q4: =Q19/Q12 -> 0.26799292 | AD4: =AD19/AD12 -> 0.26130211 | AQ4: =AQ19/AQ12 -> 0.29832719 | BD4: =BD19/BD12 -> 0.32472827 | BQ4: =BQ19/BQ12 -> 0.27839985 | CD4: =CD19/CD12 -> 0.33470594 | CQ4: =CQ19/CQ12 -> 0.31952592
Q5: =Q21/Q12 -> 0.16395303 | AD5: =AD21/AD12 -> 0.14922173 | AQ5: =AQ21/AQ12 -> 0.16024207 | BD5: =BD21/BD12 -> 0.17412556 | BQ5: =BQ21/BQ12 -> 0.15745109 | CD5: =CD21/CD12 -> 0.18685103 | CQ5: =CQ21/CQ12 -> 0.18104565
Q6: =Q52/Q12 -> 0.0026108559 | AD6: =AD52/AD12 -> 0.006368339 | AQ6: =AQ52/AQ12 -> 0.01042894 | BD6: =BD52/BD12 -> 0.013014291 | BQ6: =BQ52/BQ12 -> 0.01792258 | CD6: =CD52/CD12 -> 0.021688554 | CQ6: =CQ52/CQ12 -> 0.021011004
Q7: =Q52/Q14 -> 0.0097067429 | AD7: =AD52/AD14 -> 0.022333903 | AQ7: =AQ52/AQ14 -> 0.03291527 | BD7: =BD52/BD14 -> 0.037330425 | BQ7: =BQ52/BQ14 -> 0.055213397 | CD7: =CD52/CD14 -> 0.057185411 | CQ7: =CQ52/CQ14 -> 0.059928557 | CR7: =무선!CF8 -> 58967.317 | CS7: =무선!CG8 -> 48000.171 | CT7: =무선!CH8 -> 63707.181 | CU7: =무선!CI8 -> 51132.05 | CV7: =무선!CJ8 -> 51074.399 | CW7: =무선!CK8 -> 50463.683 | CX7: =무선!CL8 -> 66509.988 | CY7: =무선!CM8 -> 52643.601 | ... DC7: =무선!CQ8 -> 46517.929
CR8: =무선!CF8-무선!CF9 -> 30548.317 | CS8: =무선!CG8-무선!CG9 -> 27156 | CT8: =무선!CH8-무선!CH9 -> 38419.625 | CU8: =무선!CI8-무선!CI9 -> 28049.463 | CV8: =무선!CJ8-무선!CJ9 -> 28056.134 | CW8: =무선!CK8-무선!CK9 -> 27128.952 | CX8: =무선!CL8-무선!CL9 -> 38583.931 | CY8: =무선!CM8-무선!CM9 -> 30335.454 | ... DC8: =무선!CQ8-무선!CQ9 -> 26273.673
B9: ■ 손익계산서 (종합) | AR9: =AR18/AR13 -> 1.0695813 | AS9: =AS18/AS13 -> 1.0344985 | AT9: =AT18/AT13 -> 0.92617687 | AU9: =AU18/AU13 -> 1.0373586 | AV9: =AV18/AV13 -> 1.0382671 | AW9: =AW18/AW13 -> 1.0679305 | AX9: =AX18/AX13 -> 1.0583605 | AY9: =AY18/AY13 -> 1.0719394 | ... BC9: =BC18/BC13 -> 1.0026155 | BQ9: =BQ18/BQ13 -> 1.068413 | CD9: =CD18/CD13 -> 1.0717883 | CQ9: =CQ18/CQ13 -> 1.0478518 | CR9: =CR18-CR13 -> 1710.9393 | CS9: =CS18-CS13 -> 1570.9131 | CT9: =CT18-CT13 -> 3521.1976 | CU9: =CU18-CU13 -> 1732.3448 | CV9: =CV18-CV13 -> 1870.6799 | CW9: =CW18-CW13 -> 482.1977 | CX9: =CX18-CX13 -> 4274.7813 | CY9: =CY18-CY13 -> 2315.7856 | ... DC9: =DC18-DC13 -> 690.6862
B10: 구분 | Q10: 2020년 | AD10: 2021년 | AQ10: 2022년 | BD10: 2023년 | BQ10: 2024년 | CD10: 2025년 | CQ10: 2026년(E)
E11: 1월 | F11: 2월 | G11: 3월 | H11: 4월 | I11: 5월 | J11: 6월 | K11: 7월 | L11: 8월 | M11: 9월 | N11: 10월 | O11: 11월 | P11: 12월 | Q11: Total | R11: 1월 | S11: 2월 | T11: 3월 | U11: 4월 | V11: 5월 | W11: 6월 | X11: 7월 | Y11: 8월 | Z11: 9월 | AA11: 10월 | AB11: 11월 | AC11: 12월 | AD11: Total | AE11: 1월 | AF11: 2월 | AG11: 3월 | AH11: 4월 | AI11: 5월 | AJ11: 6월 | AK11: 7월 | AL11: 8월 | AM11: 9월 | AN11: 10월 | AO11: 11월 | AP11: 12월 | AQ11: Total | AR11: 1월 | AS11: 2월 | AT11: 3월 | AU11: 4월 | AV11: 5월 | AW11: 6월 | AX11: 7월 | AY11: 8월 | AZ11: 9월 | BA11: 10월 | BB11: 11월 | BC11: 12월 | BD11: Total | BE11: 1월 | BF11: 2월 | BG11: 3월 | BH11: 4월 | BI11: 5월 | BJ11: 6월 | BK11: 7월 | BL11: 8월 | BM11: 9월 | BN11: 10월 | BO11: 11월 | BP11: 12월 | BQ11: Total | BR11: 1월 | BS11: 2월 | BT11: 3월 | BU11: 4월 | BV11: 5월 | BW11: 6월 | BX11: 7월 | BY11: 8월 | BZ11: 9월 | CA11: 10월 | CB11: 11월 | CC11: 12월 | CD11: Total | CE11: 1월 | CF11: 2월 | CG11: 3월 | CH11: 4월 | CI11: 5월 | CJ11: 6월 | CK11: 7월 | CL11: 8월 | CM11: 9월 | CN11: 10월 | CO11: 11월 | CP11: 12월 | CQ11: Total | CR11: 1월(E) | CS11: 2월(E) | CT11: 3월(E) | CU11: 4월(E) | CV11: 5월(E) | CW11: 6월(E) | CX11: 7월(E) | CY11: 8월(E) | CZ11: 9월(E) | DA11: 10월(E) | DB11: 11월(E) | DC11: 12월(E) | DG11: 24-23년 | DH11: 25-24년 | DI11: 26-25년
B12: I. 매 출 | Q12: =Q88 -> 661195.77 | R12: =R88 -> 56951.147 | S12: =S88 -> 57834.212 | T12: =T88 -> 56802.299 | U12: =U88 -> 50295.011 | V12: =V88 -> 52424.927 | W12: =W88 -> 45226.849 | X12: =X88 -> 44122.264 | ... AC12: =AC88 -> 56164.881 | AD12: 710172.82 | AE12: =AE88 -> 56726.566 | AF12: =AF88 -> 50697.736 | AG12: =AG88 -> 50960.981 | AH12: =AH88 -> 53482.951 | AI12: =AI88 -> 51104.428 | AJ12: =AJ88 -> 53063.681 | AK12: =AK88 -> 49589.41 | AL12: =AL88 -> 72113.129 | ... AP12: =AP88 -> 61693.194 | AQ12: 728532.37 | AR12: 46598.749 | AS12: 68677.032 | AT12: 51885.609 | AU12: 51535.706 | AV12: 56235.965 | AW12: 60907.419 | AX12: 48634.172 | AY12: 76486.15 | AZ12: 52965.776 | BA12: 95854.637 | BB12: 58244.032 | BC12: 60507.12 | BD12: =BD13+BD14 -> 695134.47 | BE12: =BE13+BE14 -> 47437.248 | BF12: =BF13+BF14 -> 73697.131 | BG12: =BG13+BG14 -> 52049.606 | BH12: =BH13+BH14 -> 48987.118 | BI12: =BI13+BI14 -> 51089.928 | BJ12: =BJ13+BJ14 -> 47227.082 | BK12: =BK13+BK14 -> 41206.067 | ... DC12: =DC13+DC14 -> 60008.2 | DG12: =BQ12/BD12-1 -> 0.16136907 | DH12: =CD12/BQ12-1 -> -0.06670275 | DI12: =CQ12/CD12-1 -> 0.083386912 | DJ12: =BQ12-BD12 -> 112173.2 | DK12: =CD12-BQ12 -> -53849.642 | DL12: =CQ12-CD12 -> 62828.538
B13: 상품매출 | Q13: =Q89 -> 483351.68 | R13: =R89 -> 42512.58 | S13: =S89 -> 43559.137 | T13: =T89 -> 41706.116 | U13: =U89 -> 36208.61 | V13: =V89 -> 37676.339 | W13: =W89 -> 31112.636 | X13: =X89 -> 29844.903 | ... AC13: =AC89 -> 42178.799 | AD13: 507672.56 | AE13: =AE89 -> 42730.275 | AF13: =AF89 -> 35995.056 | AG13: =AG89 -> 37313.117 | AH13: =AH89 -> 39255.811 | AI13: =AI89 -> 35017.421 | AJ13: =AJ89 -> 35584.186 | AK13: =AK89 -> 32718.949 | AL13: =AL89 -> 53393.26 | ... AP13: =AP89 -> 37154.045 | AQ13: 497702.72 | AR13: 31407.969 | AS13: 51050.982 | AT13: 36369.041 | AU13: 33767.39 | AV13: 36709.363 | AW13: 39852.305 | AX13: 29267.989 | AY13: 54467.727 | AZ13: 34249.629 | BA13: 76985.844 | BB13: 41474.087 | BC13: 32100.398 | BD13: =SUM(BE13:BP13) -> 452793.75 | BE13: =무선!AS196 -> 32619.489 | BF13: =무선!AT196 -> 52658.673 | BG13: =무선!AU196 -> 34183.856 | BH13: =무선!AV196 -> 29456.878 | BI13: =무선!AW196 -> 31207.731 | BJ13: =무선!AX196 -> 24727.282 | BK13: =무선!AY196 -> 22153.12 | BL13: =무선!AZ196 -> 57599.764 | ... BP13: =무선!BD196 -> 28762.393 | BQ13: =SUM(BR13:CC13) -> 545251.05 | BR13: =무선!BF196 -> 94006.422 | BS13: =무선!BG196 -> 42755.354 | BT13: =무선!BH196 -> 36705.735 | BU13: =무선!BI196 -> 28788.902 | BV13: =무선!BJ196 -> 23800.012 | BW13: =무선!BK196 -> 43133.398 | BX13: =무선!BL196 -> 49263.717 | BY13: =무선!BM196 -> 36122.709 | ... CC13: =무선!BQ196 -> 29083.169 | CD13: =SUM(CE13:CP13) -> 467696.07 | CE13: =무선!BS196 -> 37748.24 | CF13: =무선!BT196 -> 73719.83 | CG13: =무선!BU196 -> 36849.675 | CH13: =무선!BV196 -> 24345.807 | CI13: =무선!BW196 -> 28703.542 | CJ13: =무선!BX196 -> 31955.447 | CK13: =무선!BY196 -> 49341.569 | CL13: =무선!BZ196 -> 31317.966 | ... CP13: =무선!CD196 -> 22284.258 | CQ13: =SUM(CR13:DC13) -> 530095.8 | CR13: =CR89+CR137 -> 35875.873 | CS13: =CS89+CS137 -> 34959.748 | CT13: =CT89+CT137 -> 69109.645 | CU13: =CU89+CU137 -> 39703.572 | CV13: =CV89+CV137 -> 39800.23 | CW13: =CW89+CW137 -> 36518.977 | CX13: =CX89+CX137 -> 51929.963 | CY13: =CY89+CY137 -> 40476.296 | ... DC13: =DC89+DC137 -> 37195.511 | DG13: =BQ13/BD13-1 -> 0.20419297 | DH13: =CD13/BQ13-1 -> -0.1422372 | DI13: =CQ13/CD13-1 -> 0.1334194 | DJ13: =BQ13-BD13 -> 92457.302 | DK13: =CD13-BQ13 -> -77554.985 | DL13: =CQ13-CD13 -> 62399.728
B14: 수수료수입 | Q14: =Q90 -> 177844.09 | R14: =R90 -> 14438.567 | S14: =S90 -> 14275.075 | T14: =T90 -> 15096.183 | U14: =U90 -> 14086.401 | V14: =V90 -> 14748.588 | W14: =W90 -> 14114.213 | X14: =X90 -> 14277.361 | ... AC14: =AC90 -> 13986.082 | AD14: 202500.26 | AE14: =AE90 -> 13996.291 | AF14: =AF90 -> 14702.679 | AG14: =AG90 -> 13647.864 | AH14: =AH90 -> 14227.14 | AI14: =AI90 -> 16087.007 | AJ14: =AJ90 -> 17479.495 | AK14: =AK90 -> 16870.461 | AL14: =AL90 -> 18719.869 | ... AP14: =AP90 -> 24539.148 | AQ14: 230829.64 | AR14: 15190.779 | AS14: 17626.05 | AT14: 15516.568 | AU14: 17768.316 | AV14: 19526.602 | AW14: 21055.114 | AX14: 19366.183 | AY14: 22018.424 | AZ14: 18716.146 | BA14: 18868.793 | BB14: 16769.945 | BC14: 28406.722 | BD14: =SUM(BE14:BP14) -> 242340.72 | BE14: =SUM(BE15:BE17) -> 14817.759 | BF14: =SUM(BF15:BF17) -> 21038.458 | BG14: =SUM(BG15:BG17) -> 17865.75 | BH14: =SUM(BH15:BH17) -> 19530.24 | BI14: =SUM(BI15:BI17) -> 19882.197 | BJ14: =SUM(BJ15:BJ17) -> 22499.8 | BK14: =SUM(BK15:BK17) -> 19052.947 | BL14: =SUM(BL15:BL17) -> 26934.657 | ... BP14: =SUM(BP15:BP17) -> 20093.122 | BQ14: =SUM(BR14:CC14) -> 262056.62 | BR14: =SUM(BR15:BR17) -> 24999.382 | BS14: =SUM(BS15:BS17) -> 18730.84 | BT14: =SUM(BT15:BT17) -> 19062.473 | BU14: =SUM(BU15:BU17) -> 21262.775 | BV14: =SUM(BV15:BV17) -> 19196.818 | BW14: =SUM(BW15:BW17) -> 18824.601 | BX14: =SUM(BX15:BX17) -> 26971.789 | BY14: =SUM(BY15:BY17) -> 20680.222 | ... CC14: =SUM(CC15:CC17) -> 22619.437 | CD14: =SUM(CE14:CP14) -> 285761.96 | CE14: =SUM(CE15:CE17) -> 18315.593 | CF14: =SUM(CF15:CF17) -> 26609.562 | CG14: =SUM(CG15:CG17) -> 20073.38 | CH14: =SUM(CH15:CH17) -> 20606.008 | CI14: =SUM(CI15:CI17) -> 23032.64 | CJ14: =SUM(CJ15:CJ17) -> 22540.5 | CK14: =SUM(CK15:CK17) -> 31679.269 | CL14: =SUM(CL15:CL17) -> 22437.498 | ... CP14: =SUM(CP15:CP17) -> 28432.737 | CQ14: =SUM(CR14:DC14) -> 286190.77 | CR14: =SUM(CR15:CR17) -> 22261.175 | CS14: =SUM(CS15:CS17) -> 21499.229 | CT14: =SUM(CT15:CT17) -> 26403.046 | CU14: =SUM(CU15:CU17) -> 22807.339 | CV14: =SUM(CV15:CV17) -> 22779.577 | CW14: =SUM(CW15:CW17) -> 22249.484 | CX14: =SUM(CX15:CX17) -> 28144.783 | CY14: =SUM(CY15:CY17) -> 23267.045 | ... DC14: =SUM(DC15:DC17) -> 22812.689 | DG14: =BQ14/BD14-1 -> 0.081356122 | DH14: =CD14/BQ14-1 -> 0.090458859 | DI14: =CQ14/CD14-1 -> 0.0015005839 | DJ14: =BQ14-BD14 -> 19715.901 | DK14: =CD14-BQ14 -> 23705.343 | DL14: =CQ14-CD14 -> 428.80981
B15: 정책수수료 | Q15: =Q91 -> 85819.2 | R15: =R91 -> 6650.5846 | S15: =S91 -> 6165.532 | T15: =T91 -> 6765.5568 | U15: =U91 -> 6273.3708 | V15: =V91 -> 7173.6811 | W15: =W91 -> 6740.7589 | X15: =X91 -> 6615.3399 | ... AC15: =AC91 -> 6533.2407 | AD15: 106845.74 | AE15: =AE91 -> 6775.9317 | AF15: =AF91 -> 7000.7579 | AG15: =AG91 -> 6248.7498 | AH15: =AH91 -> 5643.6671 | AI15: =AI91 -> 8252.1391 | AJ15: =AJ91 -> 9604.1539 | AK15: =AK91 -> 8850.5993 | AL15: =AL91 -> 10662.665 | ... AP15: =AP91 -> 16232.011 | AQ15: 124108.54 | AR15: 6767.705 | AS15: 9334.1094 | AT15: 6668.6359 | AU15: 9655.179 | AV15: 10201.928 | AW15: 10770.27 | AX15: 10429.413 | AY15: 12880.382 | AZ15: 9115.4754 | BA15: 10884.66 | BB15: 7591.0748 | BC15: 19809.71 | BD15: =SUM(BE15:BP15) -> 128744.55 | BE15: =무선!AS253+유선!AS42 -> 3992.9752 | BF15: =무선!AT253+유선!AT42 -> 12618.733 | BG15: =무선!AU253+유선!AU42 -> 7848.7283 | BH15: =무선!AV253+유선!AV42 -> 10654.675 | BI15: =무선!AW253+유선!AW42 -> 10744.778 | BJ15: =무선!AX253+유선!AX42 -> 12697.077 | BK15: =무선!AY253+유선!AY42 -> 9472.0605 | BL15: =무선!AZ253+유선!AZ42 -> 17659.734 | ... BP15: =무선!BD253+유선!BD42 -> 10505.089 | BQ15: =SUM(BR15:CC15) -> 142104.79 | BR15: =무선!BF253+유선!BF42 -> 14954.501 | BS15: =무선!BG253+유선!BG42 -> 9055.1532 | BT15: =무선!BH253+유선!BH42 -> 9936.2416 | BU15: =무선!BI253+유선!BI42 -> 10836.779 | BV15: =무선!BJ253+유선!BJ42 -> 10013.736 | BW15: =무선!BK253+유선!BK42 -> 9104.286 | BX15: =무선!BL253+유선!BL42 -> 16880.276 | BY15: =무선!BM253+유선!BM42 -> 10283.88 | ... CC15: =무선!BQ253+유선!BQ42 -> 11833.703 | CD15: =SUM(CE15:CP15) -> 176217.79 | CE15: =무선!BS253+유선!BS42 -> 9981.5813 | CF15: =무선!BT253+유선!BT42 -> 17442.115 | CG15: =무선!BU253+유선!BU42 -> 11113.885 | CH15: =무선!BV253+유선!BV42 -> 10634.724 | CI15: =무선!BW253+유선!BW42 -> 14265.01 | CJ15: =무선!BX253+유선!BX42 -> 12407.777 | CK15: =무선!BY253+유선!BY42 -> 22463.79 | CL15: =무선!BZ253+유선!BZ42 -> 13585.284 | ... CP15: =무선!CD253+유선!CD42 -> 18546.09 | CQ15: =SUM(CR15:DC15) -> 180215.47 | CR15: =CR91+CR139 -> 13390.153 | CS15: =CS91+CS139 -> 12679.196 | CT15: =CT91+CT139 -> 17591.425 | CU15: =CU91+CU139 -> 13807.486 | CV15: =CV91+CV139 -> 14001.157 | CW15: =CW91+CW139 -> 13490.296 | CX15: =CX91+CX139 -> 19273.97 | CY15: =CY91+CY139 -> 14451.701 | ... DC15: =DC91+DC139 -> 14010.608 | DG15: =BQ15/BD15-1 -> 0.10377324 | DH15: =CD15/BQ15-1 -> 0.2400552 | DI15: =CQ15/CD15-1 -> 0.022686015 | DJ15: =BQ15-BD15 -> 13360.24 | DK15: =CD15-BQ15 -> 34112.995 | DL15: =CQ15-CD15 -> 3997.6795
B16: 관리수수료 | Q16: =Q92 -> 50046.036 | R16: =R92 -> 3887.3879 | S16: =S92 -> 4031.233 | T16: =T92 -> 4225.2128 | U16: =U92 -> 3943.9889 | V16: =V92 -> 4359.426 | W16: =W92 -> 4087.7616 | X16: =X92 -> 4106.5562 | ... AC16: =AC92 -> 4217.4853 | AD16: 56993.082 | AE16: =AE92 -> 4118.1559 | AF16: =AF92 -> 4617.9168 | AG16: =AG92 -> 4356.2214 | AH16: =AH92 -> 5291.949 | AI16: =AI92 -> 4656.8344 | AJ16: =AJ92 -> 4758.5661 | AK16: =AK92 -> 4675.3641 | AL16: =AL92 -> 4966.5687 | ... AP16: =AP92 -> 4895.5665 | AQ16: 62536.304 | AR16: 5046.8873 | AS16: 5231.6195 | AT16: 5232.0335 | AU16: 4976.926 | AV16: 5254.8349 | AW16: 5262.2964 | AX16: 5492.9105 | AY16: 5558.836 | AZ16: 5405.2959 | BA16: 4517.0608 | BB16: 5690.0435 | BC16: 4867.5597 | BD16: =SUM(BE16:BP16) -> 70035.096 | BE16: =무선!AS116+무선!AS181+유선!AS32+무선!AS129+무선!AS126 -> 6703.5032 | BF16: =무선!AT116+무선!AT181+유선!AT32+무선!AT129+무선!AT126 -> 5086.3376 | BG16: =무선!AU116+무선!AU181+유선!AU32+무선!AU129+무선!AU126 -> 5971.6036 | BH16: =무선!AV116+무선!AV181+유선!AV32+무선!AV129+무선!AV126 -> 5556.7621 | BI16: =무선!AW116+무선!AW181+유선!AW32+무선!AW129+무선!AW126 -> 5871.6059 | BJ16: =무선!AX116+무선!AX181+유선!AX32+무선!AX129+무선!AX126 -> 5791.4679 | BK16: =무선!AY116+무선!AY181+유선!AY32+무선!AY129+무선!AY126 -> 6055.5175 | BL16: =무선!AZ116+무선!AZ181+유선!AZ32+무선!AZ129+무선!AZ126 -> 5862.319 | ... BP16: =무선!BD116+무선!BD181+유선!BD32+무선!BD129+무선!BD126 -> 6116.2647 | BQ16: =SUM(BR16:CC16) -> 68532.327 | BR16: =무선!BF116+무선!BF181+유선!BF32+무선!BF129+무선!BF126+무선!BF127 -> 5982.5449 | BS16: =무선!BG116+무선!BG181+유선!BG32+무선!BG129+무선!BG126+무선!BG127 -> 5820.4345 | BT16: =무선!BH116+무선!BH181+유선!BH32+무선!BH129+무선!BH126+무선!BH127 -> 5775.5821 | BU16: =무선!BI116+무선!BI181+유선!BI32+무선!BI129+무선!BI126+무선!BI127 -> 5544.5384 | BV16: =무선!BJ116+무선!BJ181+유선!BJ32+무선!BJ129+무선!BJ126+무선!BJ127 -> 5535.8037 | BW16: =무선!BK116+무선!BK181+유선!BK32+무선!BK129+무선!BK126+무선!BK127 -> 5512.7947 | BX16: =무선!BL116+무선!BL181+유선!BL32+무선!BL129+무선!BL126+무선!BL127 -> 5700.9085 | BY16: =무선!BM116+무선!BM181+유선!BM32+무선!BM129+무선!BM126+무선!BM127 -> 5518.8602 | ... CC16: =무선!BQ116+무선!BQ181+유선!BQ32+무선!BQ129+무선!BQ126+무선!BQ127 -> 6709.0589 | CD16: =SUM(CE16:CP16) -> 61564.255 | CE16: =무선!BS116+무선!BS181+유선!BS32+무선!BS126+무선!BS127+무선!BS129+무선!BS128 -> 4992.6384 | CF16: =무선!BT116+무선!BT181+유선!BT32+무선!BT126+무선!BT127+무선!BT129+무선!BT128 -> 5297.0258 | CG16: =무선!BU116+무선!BU181+유선!BU32+무선!BU126+무선!BU127+무선!BU129+무선!BU128 -> 4926.4715 | CH16: =무선!BV116+무선!BV181+유선!BV32+무선!BV126+무선!BV127+무선!BV129+무선!BV128 -> 5660.334 | CI16: =무선!BW116+무선!BW181+유선!BW32+무선!BW126+무선!BW127+무선!BW129+무선!BW128 -> 4622.4101 | CJ16: =무선!BX116+무선!BX181+유선!BX32+무선!BX126+무선!BX127+무선!BX129+무선!BX128 -> 5926.0522 | CK16: =무선!BY116+무선!BY181+유선!BY32+무선!BY126+무선!BY127+무선!BY129+무선!BY128 -> 5327.6578 | CL16: =무선!BZ116+무선!BZ181+유선!BZ32+무선!BZ126+무선!BZ127+무선!BZ129+무선!BZ128 -> 5029.3206 | ... CP16: =무선!CD116+무선!CD181+유선!CD32+무선!CD126+무선!CD127+무선!CD129+무선!CD128 -> 5100.7165 | CQ16: =SUM(CR16:DC16) -> 57976.257 | CR16: =CR92+CR140 -> 4899.5889 | CS16: =CS92+CS140 -> 4874.7797 | CT16: =CT92+CT140 -> 4864.4676 | CU16: =CU92+CU140 -> 4847.5685 | CV16: =CV92+CV140 -> 4831.4468 | CW16: =CW92+CW140 -> 4812.2151 | CX16: =CX92+CX140 -> 4816.1959 | CY16: =CY92+CY140 -> 4808.5714 | ... DC16: =DC92+DC140 -> 4795.1138 | DG16: =BQ16/BD16-1 -> -0.021457365 | DH16: =CD16/BQ16-1 -> -0.1016757 | DI16: =CQ16/CD16-1 -> -0.058280533 | DJ16: =BQ16-BD16 -> -1502.7686 | DK16: =CD16-BQ16 -> -6968.0725 | DL16: =CQ16-CD16 -> -3587.9976
B17: 기타수수료 | Q17: =Q93 -> 41978.852 | R17: =R93 -> 3900.5945 | S17: =S93 -> 4078.3099 | T17: =T93 -> 4105.4136 | U17: =U93 -> 3869.0418 | V17: =V93 -> 3215.4814 | W17: =W93 -> 3285.6923 | X17: =X93 -> 3555.4653 | ... AC17: =AC93 -> 3235.3559 | AD17: 38661.44 | AE17: =AE93 -> 3102.2035 | AF17: =AF93 -> 3084.0044 | AG17: =AG93 -> 3042.8932 | AH17: =AH93 -> 3291.524 | AI17: =AI93 -> 3178.0335 | AJ17: =AJ93 -> 3116.7747 | AK17: =AK93 -> 3344.498 | AL17: =AL93 -> 3090.6358 | ... AP17: =AP93 -> 3411.5707 | AQ17: 44184.794 | AR17: 3376.1872 | AS17: 3060.3212 | AT17: 3615.8984 | AU17: 3136.2113 | AV17: 4069.8383 | AW17: 5022.5481 | AX17: 3443.859 | AY17: 3579.2051 | AZ17: 4195.3751 | BA17: 3467.0723 | BB17: 3488.8265 | BC17: 3729.4518 | BD17: =SUM(BE17:BP17) -> 43561.068 | BE17: =기타수익!AQ37+기타수익!AQ40+기타수익!AQ44 -> 4121.2802 | BF17: =기타수익!AR37+기타수익!AR40+기타수익!AR44 -> 3333.3878 | BG17: =기타수익!AS37+기타수익!AS40+기타수익!AS44 -> 4045.4181 | BH17: =기타수익!AT37+기타수익!AT40+기타수익!AT44 -> 3318.8032 | BI17: =기타수익!AU37+기타수익!AU40+기타수익!AU44 -> 3265.8129 | BJ17: =기타수익!AV37+기타수익!AV40+기타수익!AV44 -> 4011.2556 | BK17: =기타수익!AW37+기타수익!AW40+기타수익!AW44 -> 3525.3688 | BL17: =기타수익!AX37+기타수익!AX40+기타수익!AX44 -> 3412.6042 | ... BP17: =기타수익!BB37+기타수익!BB40+기타수익!BB44 -> 3471.7681 | BQ17: =SUM(BR17:CC17) -> 51419.498 | BR17: =기타수익!BD37+기타수익!BD40+기타수익!BD44 -> 4062.3361 | BS17: =기타수익!BE37+기타수익!BE40+기타수익!BE44 -> 3855.2525 | BT17: =기타수익!BF37+기타수익!BF40+기타수익!BF44 -> 3350.6491 | BU17: =기타수익!BG37+기타수익!BG40+기타수익!BG44 -> 4881.4574 | BV17: =기타수익!BH37+기타수익!BH40+기타수익!BH44 -> 3647.2777 | BW17: =기타수익!BI37+기타수익!BI40+기타수익!BI44 -> 4207.52 | BX17: =기타수익!BJ37+기타수익!BJ40+기타수익!BJ44 -> 4390.6043 | BY17: =기타수익!BK37+기타수익!BK40+기타수익!BK44 -> 4877.4818 | ... CC17: =기타수익!BO37+기타수익!BO40+기타수익!BO44 -> 4076.6749 | CD17: =SUM(CE17:CP17) -> 47979.919 | CE17: =기타수익!BQ37+기타수익!BQ40+기타수익!BQ44 -> 3341.3731 | CF17: =기타수익!BR37+기타수익!BR40+기타수익!BR44 -> 3870.4216 | CG17: =기타수익!BS37+기타수익!BS40+기타수익!BS44 -> 4033.0243 | CH17: =기타수익!BT37+기타수익!BT40+기타수익!BT44 -> 4310.9498 | CI17: =기타수익!BU37+기타수익!BU40+기타수익!BU44 -> 4145.2192 | CJ17: =기타수익!BV37+기타수익!BV40+기타수익!BV44 -> 4206.6708 | CK17: =기타수익!BW37+기타수익!BW40+기타수익!BW44 -> 3887.8212 | CL17: =기타수익!BX37+기타수익!BX40+기타수익!BX44 -> 3822.894 | ... CP17: =기타수익!CB37+기타수익!CB40+기타수익!CB44 -> 4785.9303 | CQ17: =SUM(CR17:DC17) -> 47999.047 | CR17: =CR93+CR141 -> 3971.4331 | CS17: =CS93+CS141 -> 3945.2531 | CT17: =CT93+CT141 -> 3947.1531 | CU17: =CU93+CU141 -> 4152.2844 | CV17: =CV93+CV141 -> 3946.9731 | CW17: =CW93+CW141 -> 3946.9731 | CX17: =CX93+CX141 -> 4054.6169 | CY17: =CY93+CY141 -> 4006.7731 | ... DC17: =DC93+DC141 -> 4006.9671 | DG17: =BQ17/BD17-1 -> 0.1804003 | DH17: =CD17/BQ17-1 -> -0.066892517 | DI17: =CQ17/CD17-1 -> 0.00039866606 | DJ17: =BQ17-BD17 -> 7858.43 | DK17: =CD17-BQ17 -> -3439.5797 | DL17: =CQ17-CD17 -> 19.127965
B18: II. 매 출 원 가 | Q18: =Q94 -> 483999.99 | R18: =R94 -> 43105.112 | S18: =S94 -> 43998.351 | T18: =T94 -> 41806.972 | U18: =U94 -> 35584.579 | V18: =V94 -> 37648.167 | W18: =W94 -> 30523.117 | X18: =X94 -> 29757.59 | ... AC18: =AC94 -> 42127.194 | AD18: =524725.166543-122 -> 524603.17 | AE18: =AE94 -> 43031.8 | AF18: =AF94 -> 36204.686 | AG18: =AG94 -> 36678.754 | AH18: =AH94 -> 39733.485 | AI18: =AI94 -> 36132.01 | AJ18: =AJ94 -> 37457.079 | AK18: =AK94 -> 34547.228 | AL18: =AL94 -> 57208.191 | ... AP18: =AP94 -> 40314.611 | AQ18: 511191.35 | AR18: 33593.378 | AS18: 52812.165 | AT18: 33684.164 | AU18: 35028.893 | AV18: 38114.122 | AW18: 42559.492 | AX18: 30976.084 | AY18: 58386.101 | AZ18: 34089.587 | BA18: 77774.195 | BB18: 41988.816 | BC18: 32184.356 | BD18: =SUM(BE18:BP18) -> 469404.65 | BE18: =무선!AS220 -> 33261.489 | BF18: =무선!AT220 -> 56394.445 | BG18: =무선!AU220 -> 34783.52 | BH18: =무선!AV220 -> 31836.152 | BI18: =무선!AW220 -> 33816.961 | BJ18: =무선!AX220 -> 26659.199 | BK18: =무선!AY220 -> 23031.367 | BL18: =무선!AZ220 -> 63629.756 | ... BP18: =무선!BD220 -> 28483.683 | BQ18: =SUM(BR18:CC18) -> 582553.34 | BR18: =무선!BF220 -> 99807.68 | BS18: =무선!BG220 -> 43912.202 | BT18: =무선!BH220 -> 38210.2 | BU18: =무선!BI220 -> 31569.318 | BV18: =무선!BJ220 -> 26566.272 | BW18: =무선!BK220 -> 46167.626 | BX18: =무선!BL220 -> 56407.347 | BY18: =무선!BM220 -> 38993.011 | ... CC18: =무선!BQ220 -> 32568.991 | CD18: =SUM(CE18:CP18) -> 501271.15 | CE18: =무선!BS220 -> 38874.83 | CF18: =무선!BT220 -> 79057.614 | CG18: =무선!BU220 -> 38518.887 | CH18: =무선!BV220 -> 25663.171 | CI18: =무선!BW220 -> 30772.262 | CJ18: =무선!BX220 -> 32479.942 | CK18: =무선!BY220 -> 56204.739 | CL18: =무선!BZ220 -> 35789.969 | ... CP18: =무선!CD220 -> 25439.444 | CQ18: =SUM(CR18:DC18) -> 555461.85 | CR18: =CR94+CR142 -> 37586.813 | CS18: =CS94+CS142 -> 36530.661 | CT18: =CT94+CT142 -> 72630.842 | CU18: =CU94+CU142 -> 41435.917 | CV18: =CV94+CV142 -> 41670.91 | CW18: =CW94+CW142 -> 37001.175 | CX18: =CX94+CX142 -> 56204.744 | CY18: =CY94+CY142 -> 42792.081 | ... DC18: =DC94+DC142 -> 37886.197 | DG18: =BQ18/BD18-1 -> 0.24104721 | DH18: =CD18/BQ18-1 -> -0.13952746 | DI18: =CQ18/CD18-1 -> 0.10810656 | DJ18: =BQ18-BD18 -> 113148.68 | DK18: =CD18-BQ18 -> -81282.185 | DL18: =CQ18-CD18 -> 54190.701
B19: III. 매 출 총 이 익 | Q19: =Q95 -> 177195.78 | R19: =R95 -> 13846.035 | S19: =S95 -> 13835.861 | T19: =T95 -> 14995.327 | U19: =U95 -> 14710.432 | V19: =V95 -> 14776.76 | W19: =W95 -> 14703.732 | X19: =X95 -> 14364.675 | ... AC19: =AC95 -> 14037.686 | AD19: =AD12-AD18 -> 185569.66 | AE19: =AE95 -> 13694.766 | AF19: =AF95 -> 14493.05 | AG19: =AG95 -> 14282.227 | AH19: =AH95 -> 13749.466 | AI19: =AI95 -> 14972.417 | AJ19: =AJ95 -> 15606.602 | AK19: =AK95 -> 15042.183 | AL19: =AL95 -> 14904.937 | ... AP19: =AP95 -> 21378.582 | AQ19: 217341.01 | AR19: 13005.371 | AS19: 15864.867 | AT19: 18201.444 | AU19: 16506.813 | AV19: 18121.842 | AW19: 18347.928 | AX19: 17658.087 | AY19: 18100.049 | AZ19: 18876.188 | BA19: 18080.442 | BB19: 16255.216 | BC19: 28322.764 | BD19: =SUM(BE19:BP19) -> 225729.81 | BE19: =BE12-BE18 -> 14175.759 | BF19: =BF12-BF18 -> 17302.687 | BG19: =BG12-BG18 -> 17266.086 | BH19: =BH12-BH18 -> 17150.967 | BI19: =BI12-BI18 -> 17272.967 | BJ19: =BJ12-BJ18 -> 20567.884 | BK19: =BK12-BK18 -> 18174.7 | BL19: =BL12-BL18 -> 20904.665 | ... BP19: =BP12-BP18 -> 20371.832 | BQ19: =SUM(BR19:CC19) -> 224754.33 | BR19: =BR12-BR18 -> 19198.124 | BS19: =BS12-BS18 -> 17573.992 | BT19: =BT12-BT18 -> 17558.008 | BU19: =BU12-BU18 -> 18482.359 | BV19: =BV12-BV18 -> 16430.557 | BW19: =BW12-BW18 -> 15790.373 | BX19: =BX12-BX18 -> 19828.159 | BY19: =BY12-BY18 -> 17809.92 | ... CC19: =CC12-CC18 -> 19133.614 | CD19: =SUM(CE19:CP19) -> 252186.88 | CE19: =CE12-CE18 -> 17189.003 | CF19: =CF12-CF18 -> 21271.779 | CG19: =CG12-CG18 -> 18404.169 | CH19: =CH12-CH18 -> 19288.643 | CI19: =CI12-CI18 -> 20963.92 | CJ19: =CJ12-CJ18 -> 22016.006 | CK19: =CK12-CK18 -> 24816.098 | CL19: =CL12-CL18 -> 17965.496 | ... CP19: =CP12-CP18 -> 25277.551 | CQ19: =SUM(CR19:DC19) -> 260824.71 | CR19: =CR12-CR18 -> 20550.236 | CS19: =CS12-CS18 -> 19928.316 | CT19: =CT12-CT18 -> 22881.848 | CU19: =CU12-CU18 -> 21074.994 | CV19: =CV12-CV18 -> 20908.897 | CW19: =CW12-CW18 -> 21767.287 | CX19: =CX12-CX18 -> 23870.001 | CY19: =CY12-CY18 -> 20951.26 | ... DC19: =DC12-DC18 -> 22122.003 | DG19: =BQ19/BD19-1 -> -0.0043214521 | DH19: =CD19/BQ19-1 -> 0.12205568 | DI19: =CQ19/CD19-1 -> 0.034251734 | DJ19: =BQ19-BD19 -> -975.48058 | DK19: =CD19-BQ19 -> 27432.544 | DL19: =CQ19-CD19 -> 8637.8377
B20: IV. 판매비와일반관리비 | Q20: =Q96 -> 175469.5 | R20: =R96 -> 14387.761 | S20: =S96 -> 13118.332 | T20: =T96 -> 15581.362 | U20: =U96 -> 13668.868 | V20: =V96 -> 13749.405 | W20: =W96 -> 15634.151 | X20: =X96 -> 13568.583 | ... AC20: =AC96 -> 18143.559 | AD20: =AD21+AD28+AD32+AD35+AD38 -> 181047.04 | AE20: =AE96 -> 14106.043 | AF20: =AF96 -> 13982.146 | AG20: =AG96 -> 13548.619 | AH20: =AH96 -> 13541.366 | AI20: =AI96 -> 14192.745 | AJ20: =AJ96 -> 14888.626 | AK20: =AK96 -> 14643.289 | AL20: =AL96 -> 14154.864 | ... AP20: =AP96 -> 21529.371 | AQ20: 209743.19 | AR20: 12705.676 | AS20: 15040.74 | AT20: 15851.27 | AU20: 15762.413 | AV20: 16152.971 | AW20: 16101.163 | AX20: 17114.714 | AY20: 17056.677 | AZ20: 18677.538 | BA20: 16613.841 | BB20: 19259.267 | BC20: 29406.921 | BD20: =BD21+BD28+BD32+BD35+BD38 -> 216683.13 | BE20: =BE21+BE28+BE32+BE35+BE38 -> 13914.345 | BF20: =BF21+BF28+BF32+BF35+BF38 -> 16065.397 | BG20: =BG21+BG28+BG32+BG35+BG38 -> 16130.594 | BH20: =BH21+BH28+BH32+BH35+BH38 -> 16114.569 | BI20: =BI21+BI28+BI32+BI35+BI38 -> 15622.468 | BJ20: =BJ21+BJ28+BJ32+BJ35+BJ38 -> 19236.783 | BK20: =BK21+BK28+BK32+BK35+BK38 -> 17388.291 | ... DC20: =DC21+DC28+DC32+DC35+DC38 -> 25952.225 | DG20: =BQ20/BD20-1 -> -0.029526224 | DH20: =CD20/BQ20-1 -> 0.12154994 | DI20: =CQ20/CD20-1 -> 0.033192299 | DJ20: =BQ20-BD20 -> -6397.8346 | DK20: =CD20-BQ20 -> 25560.165 | DL20: =CQ20-CD20 -> 7828.253
B21: 인건비 | Q21: =Q97 -> 108405.05 | R21: =R97 -> 8697.2388 | S21: =S97 -> 8477.4466 | T21: =T97 -> 10852.852 | U21: =U97 -> 8928.2044 | V21: =V97 -> 8528.3799 | W21: =W97 -> 10500.92 | X21: =X97 -> 7916.4886 | ... AC21: =AC97 -> 10886.925 | AD21: 105973.22 | AE21: =AE97 -> 8335.8859 | AF21: =AF97 -> 8667.1014 | AG21: =AG97 -> 8382.5463 | AH21: =AH97 -> 8596.4489 | AI21: =AI97 -> 8631.5302 | AJ21: =AJ97 -> 9137.5867 | AK21: =AK97 -> 8536.4691 | AL21: =AL97 -> 8721.6811 | ... AP21: =AP97 -> 10496.705 | AQ21: 116741.54 | AR21: 8472.4803 | AS21: 8666.7535 | AT21: 8803.9768 | AU21: 8916.7538 | AV21: 9398.0741 | AW21: 9580.8536 | AX21: 9741.7821 | AY21: 9370.2486 | AZ21: 10521.706 | BA21: 9447.6431 | BB21: 13231.429 | BC21: 10589.835 | BD21: =SUM(BD22:BD27) -> 121040.68 | BE21: =SUM(BE22:BE27) -> 9509.1648 | BF21: =SUM(BF22:BF27) -> 9474.3659 | BG21: =SUM(BG22:BG27) -> 9914.9542 | BH21: =SUM(BH22:BH27) -> 10362.955 | BI21: =SUM(BI22:BI27) -> 9783.7382 | BJ21: =SUM(BJ22:BJ27) -> 9541.7563 | BK21: =SUM(BK22:BK27) -> 9855.4298 | ... DC21: =SUM(DC22:DC27) -> 16549.736 | DG21: =BQ21/BD21-1 -> 0.050155 | DH21: =CD21/BQ21-1 -> 0.10756647 | DI21: =CQ21/CD21-1 -> 0.049726593 | DJ21: =BQ21-BD21 -> 6070.7952 | DK21: =CD21-BQ21 -> 13672.933 | DL21: =CQ21-CD21 -> 7000.7289
B22: 일반직 | Q22: =Q98 -> 13079.928 | R22: =R98 -> 732.41953 | S22: =S98 -> 792.56667 | T22: =T98 -> 1863.2813 | U22: =U98 -> 782.00269 | V22: =V98 -> 795.40254 | W22: =W98 -> 1574.1421 | X22: =X98 -> 782.30636 | ... AC22: =AC98 -> 1852.8762 | AD22: 13537.894 | AE22: =AE98 -> 1091.4124 | AF22: =AF98 -> 1134.5268 | AG22: =AG98 -> 994.25002 | AH22: =AH98 -> 1102.3353 | AI22: =AI98 -> 1109.3112 | AJ22: =AJ98 -> 1089.9074 | AK22: =AK98 -> 1053.5704 | AL22: =AL98 -> 1091.3762 | ... AP22: =AP98 -> 1517.4129 | AQ22: 13620.727 | AR22: 1116.5375 | AS22: 1103.2753 | AT22: 699.43366 | AU22: 1097.807 | AV22: 1104.3066 | AW22: 1108.644 | AX22: 1069.0607 | AY22: 1082.2471 | AZ22: 1100.57 | BA22: 1073.569 | BB22: 1480.1339 | BC22: 1585.1419 | BD22: =SUM(BE22:BP22) -> 14910.462 | BE22: =인건비!AT29 -> 1155.562 | BF22: =인건비!AU29 -> 1154.9587 | BG22: =인건비!AV29 -> 896.16154 | BH22: =인건비!AW29 -> 1157.8665 | BI22: =인건비!AX29 -> 1177.5984 | BJ22: =인건비!AY29 -> 1169.5173 | BK22: =인건비!AZ29 -> 1459.0689 | BL22: =인건비!BA29 -> 1177.6673 | ... BP22: =인건비!BE29 -> 1889.379 | BQ22: =SUM(BR22:CC22) -> 14763.338 | BR22: =인건비!BG29 -> 1324.7113 | BS22: =인건비!BH29 -> 1351.2225 | BT22: =인건비!BI29 -> 688.47386 | BU22: =인건비!BJ29 -> 1308.6767 | BV22: =인건비!BK29 -> 1312.292 | BW22: =인건비!BL29 -> 1306.9142 | BX22: =인건비!BM29 -> 1215.1461 | BY22: =인건비!BN29 -> 1228.1722 | ... CC22: =인건비!BR29 -> 1172.2298 | CD22: =SUM(CE22:CP22) -> 17537.096 | CE22: =인건비!BT29 -> 1258.4461 | CF22: =인건비!BU29 -> 1311.4976 | CG22: =인건비!BV29 -> 1665.1473 | CH22: =인건비!BW29 -> 1332.2244 | CI22: =인건비!BX29 -> 1320.5953 | CJ22: =인건비!BY29 -> 1333.4174 | CK22: =인건비!BZ29 -> 1353.3149 | CL22: =인건비!CA29 -> 1329.2281 | ... CP22: =인건비!CE29 -> 2226.2618 | CQ22: =SUM(CR22:DC22) -> 18912.698 | CR22: =CR98+CR146 -> 1390.8657 | CS22: =CS98+CS146 -> 1425.4747 | CT22: =CT98+CT146 -> 1801.3358 | CU22: =CU98+CU146 -> 1441.184 | CV22: =CV98+CV146 -> 1428.6038 | CW22: =CW98+CW146 -> 1442.4746 | CX22: =CX98+CX146 -> 1503.8565 | CY22: =CY98+CY146 -> 1503.8565 | ... DC22: =DC98+DC146 -> 2423.8565 | DG22: =BQ22/BD22-1 -> -0.0098671765 | DH22: =CD22/BQ22-1 -> 0.18788148 | DI22: =CQ22/CD22-1 -> 0.07843957 | DJ22: =BQ22-BD22 -> -147.12416 | DK22: =CD22-BQ22 -> 2773.7577 | DL22: =CQ22-CD22 -> 1375.6022
B23: 영업직군 | Q23: =Q99 -> 67307.359 | R23: =R99 -> 5521.9264 | S23: =S99 -> 5484.5403 | T23: =T99 -> 6874.0138 | U23: =U99 -> 5470.7391 | V23: =V99 -> 5286.5701 | W23: =W99 -> 6568.0286 | X23: =X99 -> 4989.1525 | ... AC23: =AC99 -> 5886.4633 | AD23: 63250.941 | AE23: =AE99 -> 5319.6061 | AF23: =AF99 -> 5500.1339 | AG23: =AG99 -> 5382.3584 | AH23: =AH99 -> 5460.427 | AI23: =AI99 -> 5330.5585 | AJ23: =AJ99 -> 5296.3631 | AK23: =AK99 -> 5262.6073 | AL23: =AL99 -> 5254.8808 | ... AP23: =AP99 -> 4896.3903 | AQ23: 65842.602 | AR23: 5186.8304 | AS23: 5285.8339 | AT23: 5317.0178 | AU23: 5213.2142 | AV23: 5197.2661 | AW23: 5206.8878 | AX23: 5195.6852 | AY23: 5244.8745 | AZ23: 5256.64 | BA23: 5252.9707 | BB23: 7567.8116 | BC23: 5917.5693 | BD23: =SUM(BE23:BP23) -> 67415.662 | BE23: =인건비!AT30 -> 5524.7868 | BF23: =인건비!AU30 -> 5575.3812 | BG23: =인건비!AV30 -> 5547.5005 | BH23: =인건비!AW30 -> 5745.7359 | BI23: =인건비!AX30 -> 5548.9957 | BJ23: =인건비!AY30 -> 5526.7988 | BK23: =인건비!AZ30 -> 5462.6341 | BL23: =인건비!BA30 -> 5519.4558 | ... BP23: =인건비!BE30 -> 5481.1175 | BQ23: =SUM(BR23:CC23) -> 70814.33 | BR23: =인건비!BG30+인건비!BG31 -> 5530.9239 | BS23: =인건비!BH30+인건비!BH31 -> 5641.2531 | BT23: =인건비!BI30+인건비!BI31 -> 5588.7795 | BU23: =인건비!BJ30+인건비!BJ31 -> 5728.7208 | BV23: =인건비!BK30+인건비!BK31 -> 5712.7678 | BW23: =인건비!BL30+인건비!BL31 -> 5710.7293 | BX23: =인건비!BM30+인건비!BM31 -> 5701.9205 | BY23: =인건비!BN30+인건비!BN31 -> 5789.4881 | ... CC23: =인건비!BR30+인건비!BR31 -> 6595.1968 | CD23: =SUM(CE23:CP23) -> 75411.307 | CE23: =인건비!BT30+인건비!BT31 -> 6133.5573 | CF23: =인건비!BU30+인건비!BU31 -> 6253.0501 | CG23: =인건비!BV30+인건비!BV31 -> 6264.889 | CH23: =인건비!BW30+인건비!BW31 -> 6301.6876 | CI23: =인건비!BX30+인건비!BX31 -> 6206.6479 | CJ23: =인건비!BY30+인건비!BY31 -> 6162.3233 | CK23: =인건비!BZ30+인건비!BZ31 -> 6110.6272 | CL23: =인건비!CA30+인건비!CA31 -> 6095.6246 | ... CP23: =인건비!CE30+인건비!CE31 -> 6179.6695 | CQ23: =SUM(CR23:DC23) -> 78841.412 | CR23: =CR99+CR147 -> 6405.4959 | CS23: =CS99+CS147 -> 6349.1689 | CT23: =CT99+CT147 -> 6376.7619 | CU23: =CU99+CU147 -> 6343.4948 | CV23: =CV99+CV147 -> 6357.9446 | CW23: =CW99+CW147 -> 6362.847 | CX23: =CX99+CX147 -> 6426.9049 | CY23: =CY99+CY147 -> 6412.2024 | ... DC23: =DC99+DC147 -> 6565.174 | DG23: =BQ23/BD23-1 -> 0.050413625 | DH23: =CD23/BQ23-1 -> 0.064915915 | DI23: =CQ23/CD23-1 -> 0.045485286 | DJ23: =BQ23-BD23 -> 3398.6679 | DK23: =CD23-BQ23 -> 4596.977 | DL23: =CQ23-CD23 -> 3430.1049
B24: 특별격려금 | Q24: =SUM(R24:AC24) -> 0 | AD24: =SUM(AE24:AP24) -> 0 | AQ24: 1840 | AR24: 0 | AS24: 0 | AT24: 0 | AU24: 0 | AV24: 0 | AW24: 0 | AX24: 0 | AY24: 0 | AZ24: 0 | BA24: 0 | BB24: 1840 | BC24: 0 | BD24: =SUM(BE24:BP24) -> 2363.4 | BE24: =인건비!AT32 -> 0 | BF24: =인건비!AU32 -> 0 | BG24: =인건비!AV32 -> 0 | BH24: =인건비!AW32 -> 0 | BI24: =인건비!AX32 -> 0 | BJ24: =인건비!AY32 -> 0 | BK24: =인건비!AZ32 -> 0 | BL24: =인건비!BA32 -> 0 | ... BP24: =인건비!BE32 -> 0 | BQ24: =SUM(BR24:CC24) -> 2357.4 | BR24: =인건비!BG32 -> 0 | BS24: =인건비!BH32 -> 0 | BT24: =인건비!BI32 -> 0 | BU24: =인건비!BJ32 -> 0 | BV24: =인건비!BK32 -> 0 | BW24: =인건비!BL32 -> 578.4 | BX24: =인건비!BM32 -> 0 | BY24: =인건비!BN32 -> 0 | ... CC24: =인건비!BR32 -> 0 | CD24: =SUM(CE24:CP24) -> 2896.5 | CE24: =인건비!BT32 -> 0 | CF24: =인건비!BU32 -> 0 | CG24: =인건비!BV32 -> 0 | CH24: =인건비!BW32 -> 0 | CI24: =인건비!BX32 -> 0 | CJ24: =인건비!BY32 -> 0 | CK24: =인건비!BZ32 -> 0 | CL24: =인건비!CA32 -> 0 | ... CP24: =인건비!CE32 -> 0 | CQ24: =SUM(CR24:DC24) -> 3000 | CR24: =CR100+CR148 -> 0 | CS24: =CS100+CS148 -> 0 | CT24: =CT100+CT148 -> 0 | CU24: =CU100+CU148 -> 0 | CV24: =CV100+CV148 -> 0 | CW24: =CW100+CW148 -> 0 | CX24: =CX100+CX148 -> 0 | CY24: =CY100+CY148 -> 0 | ... DC24: =DC100+DC148 -> 0 | DG24: =BQ24/BD24-1 -> -0.0025387154 | DH24: =CD24/BQ24-1 -> 0.22868414 | DI24: =CQ24/CD24-1 -> 0.035732781 | DJ24: =BQ24-BD24 -> -6 | DK24: =CD24-BQ24 -> 539.1 | DL24: =CQ24-CD24 -> 103.5
B25: 포상비 | Q25: =Q101 -> 317.3251 | R25: =R101 -> 0 | S25: =S101 -> 0 | T25: =T101 -> 13.675269 | U25: =U101 -> 0 | V25: =V101 -> 0 | W25: =W101 -> 15.875269 | X25: =X101 -> 1.3 | ... AC25: =AC101 -> 271.65217 | AD25: 396.97132 | AE25: =AE101 -> 8.802136 | AF25: =AF101 -> 8.802136 | AG25: =AG101 -> 10.602136 | AH25: =AH101 -> 10.962136 | AI25: =AI101 -> 10.602136 | AJ25: =AJ101 -> 12.282136 | AK25: =AK101 -> 10.362136 | AL25: =AL101 -> 10.122136 | ... AP25: =AP101 -> 31.899594 | AQ25: 741.52123 | AR25: 8.759362 | AS25: 160.15936 | AT25: 16.739362 | AU25: 22.444362 | AV25: 13.679362 | AW25: 11.039362 | AX25: 11.039362 | AY25: 96.358536 | AZ25: 10.439362 | BA25: 216.57812 | BB25: 14.279362 | BC25: 160.00532 | BD25: =SUM(BE25:BP25) -> 806.35911 | BE25: =인건비!AT34 -> 9.037043 | BF25: =인건비!AU34 -> 135.26564 | BG25: =인건비!AV34 -> 11.977043 | BH25: =인건비!AW34 -> 131.93752 | BI25: =인건비!AX34 -> 10.357043 | BJ25: =인건비!AY34 -> 10.597043 | BK25: =인건비!AZ34 -> 10.477043 | BL25: =인건비!BA34 -> 82.647043 | ... BP25: =인건비!BE34 -> 219.43183 | BQ25: =SUM(BR25:CC25) -> 707.79863 | BR25: =인건비!BG34 -> 10.320023 | BS25: =인건비!BH34 -> 15.840023 | BT25: =인건비!BI34 -> 15.840023 | BU25: =인건비!BJ34 -> 136.7782 | BV25: =인건비!BK34 -> 15.840023 | BW25: =인건비!BL34 -> 16.240023 | BX25: =인건비!BM34 -> 8.640023 | BY25: =인건비!BN34 -> 32.833488 | ... CC25: =인건비!BR34 -> 141.86274 | CD25: =SUM(CE25:CP25) -> 699.44121 | CE25: =인건비!BT34 -> 115.60305 | CF25: =인건비!BU34 -> 11.543053 | CG25: =인건비!BV34 -> 9.743053 | CH25: =인건비!BW34 -> 30.543053 | CI25: =인건비!BX34 -> 8.643053 | CJ25: =인건비!BY34 -> 21.243053 | CK25: =인건비!BZ34 -> 10.143053 | CL25: =인건비!CA34 -> 8.543053 | ... CP25: =인건비!CE34 -> 396.05763 | CQ25: =SUM(CR25:DC25) -> 710.47574 | CR25: =CR101+CR149 -> 19.904478 | CS25: =CS101+CS149 -> 71.522678 | CT25: =CT101+CT149 -> 69.668678 | CU25: =CU101+CU149 -> 41.092678 | CV25: =CV101+CV149 -> 38.535678 | CW25: =CW101+CW149 -> 31.513678 | CX25: =CX101+CX149 -> 43.506311 | CY25: =CY101+CY149 -> 43.506311 | ... DC25: =DC101+DC149 -> 220.70631 | DG25: =BQ25/BD25-1 -> -0.12222901 | DH25: =CD25/BQ25-1 -> -0.011807624 | DI25: =CQ25/CD25-1 -> 0.015776199 | DJ25: =BQ25-BD25 -> -98.560475 | DK25: =CD25-BQ25 -> -8.35742 | DL25: =CQ25-CD25 -> 11.034524
B26: 퇴직급여충당금 | Q26: =Q102 -> 7981.6239 | R26: =R102 -> 711.13695 | S26: =S102 -> 711.13695 | T26: =T102 -> 561.13695 | U26: =U102 -> 661.13695 | V26: =V102 -> 661.13695 | W26: =W102 -> 661.13695 | X26: =X102 -> 661.13695 | ... AC26: =AC102 -> 709.11742 | AD26: 8056.1611 | AE26: =AE102 -> 639.63321 | AF26: =AF102 -> 639.63321 | AG26: =AG102 -> 639.63321 | AH26: =AH102 -> 639.63321 | AI26: =AI102 -> 639.63321 | AJ26: =AJ102 -> 639.63321 | AK26: =AK102 -> 639.63321 | AL26: =AL102 -> 639.63321 | ... AP26: =AP102 -> 1020.1959 | AQ26: 7904.7271 | AR26: 677.14462 | AS26: 677.14462 | AT26: 677.14462 | AU26: 677.14462 | AV26: 677.14462 | AW26: 677.14462 | AX26: 677.14462 | AY26: 677.14462 | AZ26: 677.14462 | BA26: 677.14462 | BB26: 677.14462 | BC26: 456.13623 | BD26: =SUM(BE26:BP26) -> 7219.9387 | BE26: =인건비!AT36 -> 668.26682 | BF26: =인건비!AU36 -> 668.26682 | BG26: =인건비!AV36 -> 668.26682 | BH26: =인건비!AW36 -> 668.26682 | BI26: =인건비!AX36 -> 668.26682 | BJ26: =인건비!AY36 -> 668.26682 | BK26: =인건비!AZ36 -> 668.26682 | BL26: =인건비!BA36 -> 668.26682 | ... BP26: =인건비!BE36 -> -130.99632 | BQ26: =SUM(BR26:CC26) -> 8364.709 | BR26: =인건비!BG36 -> 646.57752 | BS26: =인건비!BH36 -> 646.57752 | BT26: =인건비!BI36 -> 646.57752 | BU26: =인건비!BJ36 -> 646.57752 | BV26: =인건비!BK36 -> 646.57752 | BW26: =인건비!BL36 -> 646.57752 | BX26: =인건비!BM36 -> 646.57752 | BY26: =인건비!BN36 -> 646.57752 | ... CC26: =인건비!BR36 -> 1252.3563 | CD26: =SUM(CE26:CP26) -> 10263.998 | CE26: =인건비!BT36 -> 743.62771 | CF26: =인건비!BU36 -> 743.62771 | CG26: =인건비!BV36 -> 743.62771 | CH26: =인건비!BW36 -> 743.62771 | CI26: =인건비!BX36 -> 743.62771 | CJ26: =인건비!BY36 -> 743.62771 | CK26: =인건비!BZ36 -> 743.62771 | CL26: =인건비!CA36 -> 743.62771 | ... CP26: =인건비!CE36 -> 2084.0936 | CQ26: =SUM(CR26:DC26) -> 11914 | CR26: =CR102+CR150 -> 729 | CS26: =CS102+CS150 -> 729 | CT26: =CT102+CT150 -> 729 | CU26: =CU102+CU150 -> 729 | CV26: =CV102+CV150 -> 729 | CW26: =CW102+CW150 -> 729 | CX26: =CX102+CX150 -> 729 | CY26: =CY102+CY150 -> 729 | ... DC26: =DC102+DC150 -> 3895 | DG26: =BQ26/BD26-1 -> 0.15855678 | DH26: =CD26/BQ26-1 -> 0.22705982 | DI26: =CQ26/CD26-1 -> 0.16075622 | DJ26: =BQ26-BD26 -> 1144.7703 | DK26: =CD26-BQ26 -> 1899.2894 | DL26: =CQ26-CD26 -> 1650.0016
B27: 복리후생비 | Q27: =Q103 -> 19718.814 | R27: =R103 -> 1731.7559 | S27: =S103 -> 1489.2027 | T27: =T103 -> 1540.7449 | U27: =U103 -> 2014.3257 | V27: =V103 -> 1785.2702 | W27: =W103 -> 1681.7369 | X27: =X103 -> 1482.5928 | ... AC27: =AC103 -> 2166.8159 | AD27: 20731.25 | AE27: =AE103 -> 1276.4321 | AF27: =AF103 -> 1384.0053 | AG27: =AG103 -> 1355.7025 | AH27: =AH103 -> 1383.0912 | AI27: =AI103 -> 1541.4252 | AJ27: =AJ103 -> 2099.4008 | AK27: =AK103 -> 1570.2961 | AL27: =AL103 -> 1725.6688 | ... AP27: =AP103 -> 3030.8062 | AQ27: 26791.96 | AR27: 1483.2085 | AS27: 1440.3403 | AT27: 2093.6414 | AU27: 1906.1436 | AV27: 2405.6773 | AW27: 2577.1377 | AX27: 2788.8522 | AY27: 2269.6239 | AZ27: 3476.9123 | BA27: 2227.3806 | BB27: 1652.0596 | BC27: 2470.9824 | BD27: =SUM(BE27:BP27) -> 28324.856 | BE27: =인건비!AT37 -> 2151.5121 | BF27: =인건비!AU37 -> 1940.4936 | BG27: =인건비!AV37 -> 2791.0483 | BH27: =인건비!AW37 -> 2659.1481 | BI27: =인건비!AX37 -> 2378.5202 | BJ27: =인건비!AY37 -> 2166.5763 | BK27: =인건비!AZ37 -> 2254.983 | BL27: =인건비!BA37 -> 2017.634 | ... BP27: =인건비!BE37 -> 2497.2385 | BQ27: =SUM(BR27:CC27) -> 30103.897 | BR27: =인건비!BG37 -> 1671.1529 | BS27: =인건비!BH37 -> 2642.0654 | BT27: =인건비!BI37 -> 2323.5422 | BU27: =인건비!BJ37 -> 2294.2253 | BV27: =인건비!BK37 -> 2207.0231 | BW27: =인건비!BL37 -> 2448.7784 | BX27: =인건비!BM37 -> 2255.7873 | BY27: =인건비!BN37 -> 2703.7428 | ... CC27: =인건비!BR37 -> 3545.3843 | CD27: =SUM(CE27:CP27) -> 33976.063 | CE27: =인건비!BT37 -> 2119.9558 | CF27: =인건비!BU37 -> 1860.3786 | CG27: =인건비!BV37 -> 2792.8682 | CH27: =인건비!BW37 -> 2584.7024 | CI27: =인건비!BX37 -> 2536.1255 | CJ27: =인건비!BY37 -> 4013.8688 | CK27: =인건비!BZ37 -> 2992.8871 | CL27: =인건비!CA37 -> 3387.017 | ... CP27: =인건비!CE37 -> 3470.5973 | CQ27: =SUM(CR27:DC27) -> 34406.549 | CR27: =CR103+CR151 -> 2483.668 | CS27: =CS103+CS151 -> 2654.4944 | CT27: =CT103+CT151 -> 2583.7796 | CU27: =CU103+CU151 -> 2731.5078 | CV27: =CV103+CV151 -> 2587.6193 | CW27: =CW103+CW151 -> 3759.677 | CX27: =CX103+CX151 -> 2660.4305 | CY27: =CY103+CY151 -> 3039.0647 | ... DC27: =DC103+DC151 -> 3444.999 | DG27: =BQ27/BD27-1 -> 0.062808498 | DH27: =CD27/BQ27-1 -> 0.12862673 | DI27: =CQ27/CD27-1 -> 0.012670262 | DJ27: =BQ27-BD27 -> 1779.0416 | DK27: =CD27-BQ27 -> 3872.166 | DL27: =CQ27-CD27 -> 430.48562
B28: 마케팅비용 | Q28: =Q104 -> 30979.457 | R28: =R104 -> 1580.7569 | S28: =S104 -> 1565.6174 | T28: =T104 -> 1829.9156 | U28: =U104 -> 1901.1032 | V28: =V104 -> 2366.7804 | W28: =W104 -> 2287.7366 | X28: =X104 -> 2724.1441 | ... AC28: =AC104 -> 4022.9439 | AD28: 35947.571 | AE28: =AE104 -> 2180.0728 | AF28: =AF104 -> 2591.9361 | AG28: =AG104 -> 2608.6665 | AH28: =AH104 -> 2188.2347 | AI28: =AI104 -> 2948.9549 | AJ28: =AJ104 -> 2680.0679 | AK28: =AK104 -> 2442.3402 | AL28: =AL104 -> 2435.8798 | ... AP28: =AP104 -> 5702.6608 | AQ28: 52287.223 | AR28: 1411.1972 | AS28: 3479.7991 | AT28: 4042.2042 | AU28: 3415.4928 | AV28: 3614.9873 | AW28: 3588.5015 | AX28: 3419.5826 | AY28: 4084.1606 | AZ28: 4816.7538 | BA28: 3587.409 | BB28: 2626.9001 | BC28: 14200.235 | BD28: =SUM(BD29:BD31) -> 52196.061 | BE28: =SUM(BE29:BE31) -> 1067.9466 | BF28: =SUM(BF29:BF31) -> 3184.1216 | BG28: =SUM(BG29:BG31) -> 2951.2413 | BH28: =SUM(BH29:BH31) -> 2336.4959 | BI28: =SUM(BI29:BI31) -> 2660.2807 | BJ28: =SUM(BJ29:BJ31) -> 6279.9808 | BK28: =SUM(BK29:BK31) -> 3964.0826 | ... DC28: =SUM(DC29:DC31) -> 4318.8914 | DG28: =BQ28/BD28-1 -> -0.33822185 | DH28: =CD28/BQ28-1 -> 0.29794727 | DI28: =CQ28/CD28-1 -> 0.016802257 | DJ28: =BQ28-BD28 -> -17653.848 | DK28: =CD28-BQ28 -> 10291.758 | DL28: =CQ28-CD28 -> 753.31188
B29: 판매수수료 | Q29: =Q105 -> 19775.607 | R29: =R105 -> 992.55164 | S29: =S105 -> 907.36839 | T29: =T105 -> 1008.5404 | U29: =U105 -> 1187.8642 | V29: =V105 -> 1466.1984 | W29: =W105 -> 1422.3798 | X29: =X105 -> 2068.8051 | ... AC29: =AC105 -> 1780.1145 | AD29: 26739.311 | AE29: =AE105 -> 1725.4342 | AF29: =AF105 -> 2200.7861 | AG29: =AG105 -> 1987.5193 | AH29: =AH105 -> 1658.054 | AI29: =AI105 -> 2379.6793 | AJ29: =AJ105 -> 2060.4544 | AK29: =AK105 -> 1953.91 | AL29: =AL105 -> 1580.5624 | ... AP29: =AP105 -> 4190.5963 | AQ29: 39025.756 | AR29: 950.99256 | AS29: 2719.1556 | AT29: 3408.1603 | AU29: 2843.7597 | AV29: 2826.8426 | AW29: 2925.5939 | AX29: 2968.5657 | AY29: 2986.1494 | AZ29: 3940.2311 | BA29: 2627.4668 | BB29: 1930.7553 | BC29: 8898.083 | BD29: =SUM(BE29:BP29) -> 32305.885 | BE29: =무선!AS282 -> 684.52379 | BF29: =무선!AT282 -> 2521.5926 | BG29: =무선!AU282 -> 2332.9442 | BH29: =무선!AV282 -> 1847.3232 | BI29: =무선!AW282 -> 2126.155 | BJ29: =무선!AX282 -> 3651.0204 | BK29: =무선!AY282 -> 3186.521 | BL29: =무선!AZ282 -> 2814.6494 | ... BP29: =무선!BD282 -> 1934.1758 | BQ29: =SUM(BR29:CC29) -> 16745.85 | BR29: =무선!BF282 -> 1536.6758 | BS29: =무선!BG282 -> 820.50925 | BT29: =무선!BH282 -> 1104.2471 | BU29: =무선!BI282 -> 990.16139 | BV29: =무선!BJ282 -> 928.17297 | BW29: =무선!BK282 -> 685.54462 | BX29: =무선!BL282 -> 1789.2586 | BY29: =무선!BM282 -> 1087.8145 | ... CC29: =무선!BQ282 -> 1384.9412 | CD29: =SUM(CE29:CP29) -> 15427.886 | CE29: =무선!BS282 -> 609.35523 | CF29: =무선!BT282 -> 1030.4066 | CG29: =무선!BU282 -> 907.80226 | CH29: =무선!BV282 -> 765.68158 | CI29: =무선!BW282 -> 1584.6036 | CJ29: =무선!BX282 -> 1587.8933 | CK29: =무선!BY282 -> 746.60656 | CL29: =무선!BZ282 -> 535.27087 | ... CP29: =무선!CD282 -> 1744.4953 | CQ29: =SUM(CR29:DC29) -> 16897.314 | CR29: =CR105+CR153 -> 1224.3714 | CS29: =CS105+CS153 -> 952.34434 | CT29: =CT105+CT153 -> 1376.5924 | CU29: =CU105+CU153 -> 1489.7275 | CV29: =CV105+CV153 -> 1509.5894 | CW29: =CW105+CW153 -> 1516.2354 | CX29: =CX105+CX153 -> 1546.2511 | CY29: =CY105+CY153 -> 1416.2354 | ... DC29: =DC105+DC153 -> 942.37088 | DG29: =BQ29/BD29-1 -> -0.48164708 | DH29: =CD29/BQ29-1 -> -0.078703937 | DI29: =CQ29/CD29-1 -> 0.095244948 | DJ29: =BQ29-BD29 -> -15560.035 | DK29: =CD29-BQ29 -> -1317.9643 | DL29: =CQ29-CD29 -> 1469.4282
B30: 판매촉진비 | Q30: =Q106 -> 10894.413 | R30: =R106 -> 583.32224 | S30: =S106 -> 652.25816 | T30: =T106 -> 783.46397 | U30: =U106 -> 701.94219 | V30: =V106 -> 891.49316 | W30: =W106 -> 818.2007 | X30: =X106 -> 644.93925 | ... AC30: =AC106 -> 2155.3454 | AD30: 7152.4172 | AE30: =AE106 -> 426.19736 | AF30: =AF106 -> 378.2073 | AG30: =AG106 -> 578.27761 | AH30: =AH106 -> 522.95593 | AI30: =AI106 -> 593.16883 | AJ30: =AJ106 -> 584.62416 | AK30: =AK106 -> 487.12611 | AL30: =AL106 -> 838.31738 | ... AP30: =AP106 -> 1233.5645 | AQ30: 13200.522 | AR30: 460.20462 | AS30: 760.64352 | AT30: 618.44386 | AU30: 571.73312 | AV30: 788.14468 | AW30: 650.30755 | AX30: 450.47145 | AY30: 1098.0112 | AZ30: 863.92265 | BA30: 952.94223 | BB30: 696.14487 | BC30: 5289.5519 | BD30: =SUM(BE30:BP30) -> 19765.911 | BE30: =무선!AS289+무선!AS294+유선!AS72+유선!AS74+무선!AS295 -> 383.42282 | BF30: =무선!AT289+무선!AT294+유선!AT72+유선!AT74+무선!AT295 -> 662.52907 | BG30: =무선!AU289+무선!AU294+유선!AU72+유선!AU74+무선!AU295 -> 615.48808 | BH30: =무선!AV289+무선!AV294+유선!AV72+유선!AV74+무선!AV295 -> 488.17269 | BI30: =무선!AW289+무선!AW294+유선!AW72+유선!AW74+무선!AW295 -> 533.14391 | BJ30: =무선!AX289+무선!AX294+유선!AX72+유선!AX74+무선!AX295 -> 2628.124 | BK30: =무선!AY289+무선!AY294+유선!AY72+유선!AY74+무선!AY295 -> 745.41615 | BL30: =무선!AZ289+무선!AZ294+유선!AZ72+유선!AZ74+무선!AZ295 -> 902.24237 | ... BP30: =무선!BD289+무선!BD294+유선!BD72+유선!BD74+무선!BD295 -> 5708.4023 | BQ30: =SUM(BR30:CC30) -> 17547.417 | BR30: =무선!BF289+무선!BF294+유선!BF72+유선!BF74 -> 3088.1655 | BS30: =무선!BG289+무선!BG294+유선!BG72+유선!BG74+무선!BG295 -> 771.05125 | BT30: =무선!BH289+무선!BH294+유선!BH72+유선!BH74+무선!BH295 -> 589.9621 | BU30: =무선!BI289+무선!BI294+유선!BI72+유선!BI74+무선!BI295 -> 1074.0221 | BV30: =무선!BJ289+무선!BJ294+유선!BJ72+유선!BJ74+무선!BJ295 -> 641.47133 | BW30: =무선!BK289+무선!BK294+유선!BK72+유선!BK74+무선!BK295 -> 859.98171 | BX30: =무선!BL289+무선!BL294+유선!BL72+유선!BL74+무선!BL295 -> 1276.934 | BY30: =무선!BM289+무선!BM294+유선!BM72+유선!BM74+무선!BM295 -> 1189.6321 | BZ30: =무선!BN289+무선!BN294+유선!BN72+유선!BN74+무선!BN295 -> 3311.7933 | ... CC30: =무선!BQ289+무선!BQ294+유선!BQ72+유선!BQ74+무선!BQ295 -> 993.83545 | CD30: =SUM(CE30:CP30) -> 28784.266 | CE30: =무선!BS289+무선!BS294+유선!BS72+유선!BS74 -> 2828.5798 | CF30: =무선!BT289+무선!BT294+유선!BT72+유선!BT74 -> 1297.5017 | CG30: =무선!BU289+무선!BU294+유선!BU72+유선!BU74 -> 673.45115 | CH30: =무선!BV289+무선!BV294+유선!BV72+유선!BV74 -> 1150.281 | CI30: =무선!BW289+무선!BW294+유선!BW72+유선!BW74 -> 1247.7606 | CJ30: =무선!BX289+무선!BX294+유선!BX72+유선!BX74 -> 1847.9929 | CK30: =무선!BY289+무선!BY294+유선!BY72+유선!BY74 -> 3969.3809 | CL30: =무선!BZ289+무선!BZ294+유선!BZ72+유선!BZ74 -> 1549.3479 | ... CP30: =무선!CD289+무선!CD294+유선!CD72+유선!CD74 -> 5257.8218 | CQ30: =SUM(CR30:DC30) -> 28059.804 | CR30: =CR106+CR154 -> 2005.6336 | CS30: =CS106+CS154 -> 1919.3487 | CT30: =CT106+CT154 -> 2072.1392 | CU30: =CU106+CU154 -> 1851.1161 | CV30: =CV106+CV154 -> 1854.0695 | CW30: =CW106+CW154 -> 2539.6819 | CX30: =CX106+CX154 -> 2474.866 | CY30: =CY106+CY154 -> 1899.3135 | ... DC30: =DC106+DC154 -> 3324.0068 | DG30: =BQ30/BD30-1 -> -0.11223836 | DH30: =CD30/BQ30-1 -> 0.64037051 | DI30: =CQ30/CD30-1 -> -0.025168691 | DJ30: =BQ30-BD30 -> -2218.4935 | DK30: =CD30-BQ30 -> 11236.849 | DL30: =CQ30-CD30 -> -724.46228
B31: 광고선전비 | Q31: =Q107 -> 309.43682 | R31: =R107 -> 4.883 | S31: =S107 -> 5.99085 | T31: =T107 -> 37.91125 | U31: =U107 -> 11.29675 | V31: =V107 -> 9.08886 | W31: =W107 -> 47.15605 | X31: =X107 -> 10.39968 | ... AC31: =AC107 -> 87.483998 | AD31: 2055.8424 | AE31: =AE107 -> 28.441258 | AF31: =AF107 -> 12.942661 | AG31: =AG107 -> 42.869608 | AH31: =AH107 -> 7.22482 | AI31: =AI107 -> -23.89329 | AJ31: =AJ107 -> 34.98932 | AK31: =AK107 -> 1.30402 | AL31: =AL107 -> 17 | ... AP31: =AP107 -> 278.5 | AQ31: 60.945455 | AR31: 0 | AS31: 0 | AT31: 15.6 | AU31: 0 | AV31: 0 | AW31: 12.6 | AX31: 0.545455 | AY31: 0 | AZ31: 12.6 | BA31: 7 | BB31: 0 | BC31: 12.6 | BD31: =SUM(BE31:BP31) -> 124.26436 | BE31: =무선!AS298 -> 0 | BF31: =무선!AT298 -> 0 | BG31: =무선!AU298 -> 2.809091 | BH31: =무선!AV298 -> 1 | BI31: =무선!AW298 -> 0.981818 | BJ31: =무선!AX298 -> 0.836364 | BK31: =무선!AY298 -> 32.145454 | BL31: =무선!AZ298 -> 29.818 | ... BP31: =무선!BD298 -> 12.229454 | BQ31: =SUM(BR31:CC31) -> 248.94518 | BR31: =무선!BF298 -> 20.4 | BS31: =무선!BG298 -> 27.135909 | BT31: =무선!BH298 -> 0.381818 | BU31: =무선!BI298 -> 37.081818 | BV31: =무선!BJ298 -> 2.509091 | BW31: =무선!BK298 -> 2.922727 | BX31: =무선!BL298 -> 26.463636 | BY31: =무선!BM298 -> 12.990909 | ... CC31: =무선!BQ298 -> 32.849546 | CD31: =SUM(CE31:CP31) -> 621.81873 | CE31: =무선!BS297 -> 28.159 | CF31: =무선!BT297 -> 40.013727 | CG31: =무선!BU297 -> 18.813 | CH31: =무선!BV297 -> 38.266 | CI31: =무선!BW297 -> 27.242 | CJ31: =무선!BX297 -> 39.037 | CK31: =무선!BY297 -> 116.037 | CL31: =무선!BZ297 -> 72.41 | ... CP31: =무선!CD297 -> 98.89 | CQ31: =SUM(CR31:DC31) -> 630.16472 | CR31: =CR107+CR155 -> 52.513727 | CS31: =CS107+CS155 -> 52.513727 | CT31: =CT107+CT155 -> 52.513727 | CU31: =CU107+CU155 -> 52.513727 | CV31: =CV107+CV155 -> 52.513727 | CW31: =CW107+CW155 -> 52.513727 | CX31: =CX107+CX155 -> 52.513727 | CY31: =CY107+CY155 -> 52.513727 | ... DC31: =DC107+DC155 -> 52.513727 | DG31: =BQ31/BD31-1 -> 1.0033514 | DH31: =CD31/BQ31-1 -> 1.4978139 | DI31: =CQ31/CD31-1 -> 0.0134219 | DJ31: =BQ31-BD31 -> 124.68082 | DK31: =CD31-BQ31 -> 372.87355 | DL31: =CQ31-CD31 -> 8.345989
B32: 임차관리비 | Q32: =Q108 -> 5615.1741 | R32: =R108 -> 1159.7407 | S32: =S108 -> 1047.4318 | T32: =T108 -> -605.85149 | U32: =U108 -> 984.27788 | V32: =V108 -> 987.62554 | W32: =W108 -> -610.23281 | X32: =X108 -> 993.09551 | ... AC32: =AC108 -> -626.04693 | AD32: 5137.7624 | AE32: =AE108 -> 959.96665 | AF32: =AF108 -> 942.77649 | AG32: =AG108 -> -527.64109 | AH32: =AH108 -> 879.69588 | AI32: =AI108 -> 853.7728 | AJ32: =AJ108 -> -538.79821 | AK32: =AK108 -> 888.99098 | AL32: =AL108 -> 897.29632 | ... AP32: =AP108 -> -443.52125 | AQ32: 6060.2939 | AR32: 886.95041 | AS32: 875.13991 | AT32: -377.94869 | AU32: 850.71564 | AV32: 863.27472 | AW32: -386.60054 | AX32: 854.33068 | AY32: 973.183 | AZ32: -266.17801 | BA32: 1032.735 | BB32: 1031.551 | BC32: -276.85929 | BD32: =SUM(BE32:BP32) -> 6422.9032 | BE32: =SUM(BE33:BE34) -> 1092.4286 | BF32: =SUM(BF33:BF34) -> 1102.049 | BG32: =SUM(BG33:BG34) -> -580.464 | BH32: =SUM(BH33:BH34) -> 1021.9751 | BI32: =SUM(BI33:BI34) -> 1016.9357 | BJ32: =SUM(BJ33:BJ34) -> -404.39472 | BK32: =SUM(BK33:BK34) -> 1029.5732 | BL32: =SUM(BL33:BL34) -> 1111.4838 | ... BP32: =SUM(BP33:BP34) -> -526.18351 | BQ32: =SUM(BR32:CC32) -> 6090.3768 | BR32: =SUM(BR33:BR34) -> 1057.9903 | BS32: =SUM(BS33:BS34) -> 1085.0542 | BT32: =SUM(BT33:BT34) -> -410.60644 | BU32: =SUM(BU33:BU34) -> 1030.6897 | BV32: =SUM(BV33:BV34) -> 1020.3262 | BW32: =SUM(BW33:BW34) -> -475.55993 | BX32: =SUM(BX33:BX34) -> 1116.7045 | BY32: =SUM(BY33:BY34) -> 1086.8685 | ... CC32: =SUM(CC33:CC34) -> -666.29302 | CD32: =SUM(CE32:CP32) -> 5315.1674 | CE32: =SUM(CE33:CE34) -> 971.51188 | CF32: =SUM(CF33:CF34) -> 963.81851 | CG32: =SUM(CG33:CG34) -> -592.14587 | CH32: =SUM(CH33:CH34) -> 921.80414 | CI32: =SUM(CI33:CI34) -> 914.81608 | CJ32: =SUM(CJ33:CJ34) -> -652.23599 | CK32: =SUM(CK33:CK34) -> 952.83527 | CL32: =SUM(CL33:CL34) -> 999.40479 | ... CP32: =SUM(CP33:CP34) -> -593.32801 | CQ32: =SUM(CR32:DC32) -> 5474.1124 | CR32: =SUM(CR33:CR34) -> 992.49668 | CS32: =SUM(CS33:CS34) -> 998.27844 | CT32: =SUM(CT33:CT34) -> -626.41547 | CU32: =SUM(CU33:CU34) -> 997.93306 | CV32: =SUM(CV33:CV34) -> 998.6559 | CW32: =SUM(CW33:CW34) -> -633.51769 | CX32: =SUM(CX33:CX34) -> 997.76159 | CY32: =SUM(CY33:CY34) -> 998.40839 | ... DC32: =SUM(DC33:DC34) -> -629.65967 | DG32: =BQ32/BD32-1 -> -0.051771978 | DH32: =CD32/BQ32-1 -> -0.12728431 | DI32: =CQ32/CD32-1 -> 0.029904052 | DJ32: =BQ32-BD32 -> -332.5264 | DK32: =CD32-BQ32 -> -775.20941 | DL32: =CQ32-CD32 -> 158.94504
B33: 임차료 | Q33: =Q109 -> 4785.5893 | R33: =R109 -> 1077.1939 | S33: =S109 -> 968.50991 | T33: =T109 -> -681.5833 | U33: =U109 -> 922.98003 | V33: =V109 -> 930.22236 | W33: =W109 -> -666.88316 | X33: =X109 -> 922.60433 | ... AC33: =AC109 -> -696.86132 | AD33: 4401.4293 | AE33: =AE109 -> 883.57936 | AF33: =AF109 -> 859.0187 | AG33: =AG109 -> -593.34228 | AH33: =AH109 -> 830.42421 | AI33: =AI109 -> 810.32144 | AJ33: =AJ109 -> -587.47841 | AK33: =AK109 -> 821.27809 | AL33: =AL109 -> 819.52794 | ... AP33: =AP109 -> -502.61335 | AQ33: 5303.6947 | AR33: 816.26683 | AS33: 796.30424 | AT33: -446.08008 | AU33: 801.09305 | AV33: 814.70825 | AW33: -436.2109 | AX33: 788.6626 | AY33: 897.21021 | AZ33: -337.53263 | BA33: 974.63419 | BB33: 974.46555 | BC33: -339.82667 | BD33: =SUM(BE33:BP33) -> 5542.3486 | BE33: =인프라!AS25 -> 1006.7227 | BF33: =인프라!AT25 -> 1007.9497 | BG33: =인프라!AU25 -> -659.7504 | BH33: =인프라!AV25 -> 961.63084 | BI33: =인프라!AW25 -> 962.99869 | BJ33: =인프라!AX25 -> -466.77411 | BK33: =인프라!AY25 -> 956.11005 | BL33: =인프라!AZ25 -> 1015.3815 | ... BP33: =인프라!BD25 -> -596.12164 | BQ33: =SUM(BR33:CC33) -> 5190.9478 | BR33: =인프라!BF25 -> 976.62714 | BS33: =인프라!BG25 -> 991.95291 | BT33: =인프라!BH25 -> -485.25514 | BU33: =인프라!BI25 -> 969.43936 | BV33: =인프라!BJ25 -> 962.87926 | BW33: =인프라!BK25 -> -536.36932 | BX33: =인프라!BL25 -> 1038.1918 | BY33: =인프라!BM25 -> 988.43124 | ... CC33: =인프라!BQ25 -> -738.61428 | CD33: =SUM(CE33:CP33) -> 4488.5558 | CE33: =인프라!BS25 -> 889.45883 | CF33: =인프라!BT25 -> 875.80791 | CG33: =인프라!BU25 -> -674.42279 | CH33: =인프라!BV25 -> 863.68534 | CI33: =인프라!BW25 -> 861.79002 | CJ33: =인프라!BX25 -> -709.25131 | CK33: =인프라!BY25 -> 880.66315 | CL33: =인프라!BZ25 -> 916.12363 | ... CP33: =인프라!CD25 -> -650.82548 | CQ33: =SUM(CR33:DC33) -> 4578.0936 | CR33: =CR109+CR157 -> 923.46979 | CS33: =CS109+CS157 -> 923.58194 | CT33: =CT109+CT157 -> -701.11197 | CU33: =CU109+CU157 -> 923.23656 | CV33: =CV109+CV157 -> 923.9594 | CW33: =CW109+CW157 -> -708.21419 | CX33: =CX109+CX157 -> 923.06509 | CY33: =CY109+CY157 -> 923.71189 | ... DC33: =DC109+DC157 -> -703.68656 | DG33: =BQ33/BD33-1 -> -0.063402871 | DH33: =CD33/BQ33-1 -> -0.13531093 | DI33: =CQ33/CD33-1 -> 0.019948021 | DJ33: =BQ33-BD33 -> -351.40082 | DK33: =CD33-BQ33 -> -702.39195 | DL33: =CQ33-CD33 -> 89.537807
B34: 수도광열비 | Q34: =Q110 -> 829.58481 | R34: =R110 -> 82.546761 | S34: =S110 -> 78.921929 | T34: =T110 -> 75.731809 | U34: =U110 -> 61.297843 | V34: =V110 -> 57.403175 | W34: =W110 -> 56.650343 | X34: =X110 -> 70.491185 | ... AC34: =AC110 -> 70.814392 | AD34: 736.33307 | AE34: =AE110 -> 76.387294 | AF34: =AF110 -> 83.757787 | AG34: =AG110 -> 65.701191 | AH34: =AH110 -> 49.271671 | AI34: =AI110 -> 43.451366 | AJ34: =AJ110 -> 48.680199 | AK34: =AK110 -> 67.712889 | AL34: =AL110 -> 77.768382 | ... AP34: =AP110 -> 59.092102 | AQ34: 756.59927 | AR34: 70.683579 | AS34: 78.835669 | AT34: 68.131388 | AU34: 49.622595 | AV34: 48.566465 | AW34: 49.610357 | AX34: 65.668082 | AY34: 75.97279 | AZ34: 71.354616 | BA34: 58.100857 | BB34: 57.085496 | BC34: 62.967375 | BD34: =SUM(BE34:BP34) -> 880.55462 | BE34: =인프라!AS32 -> 85.705912 | BF34: =인프라!AT32 -> 94.099297 | BG34: =인프라!AU32 -> 79.2864 | BH34: =인프라!AV32 -> 60.344215 | BI34: =인프라!AW32 -> 53.936983 | BJ34: =인프라!AX32 -> 62.379388 | BK34: =인프라!AY32 -> 73.463151 | BL34: =인프라!AZ32 -> 96.102294 | ... BP34: =인프라!BD32 -> 69.938127 | BQ34: =SUM(BR34:CC34) -> 899.42904 | BR34: =인프라!BF32 -> 81.363117 | BS34: =인프라!BG32 -> 93.101247 | BT34: =인프라!BH32 -> 74.648701 | BU34: =인프라!BI32 -> 61.250384 | BV34: =인프라!BJ32 -> 57.446894 | BW34: =인프라!BK32 -> 60.809388 | BX34: =인프라!BL32 -> 78.512665 | BY34: =인프라!BM32 -> 98.43731 | ... CC34: =인프라!BQ32 -> 72.321263 | CD34: =SUM(CE34:CP34) -> 826.61158 | CE34: =인프라!BS32 -> 82.053048 | CF34: =인프라!BT32 -> 88.010606 | CG34: =인프라!BU32 -> 82.276914 | CH34: =인프라!BV32 -> 58.118793 | CI34: =인프라!BW32 -> 53.026055 | CJ34: =인프라!BX32 -> 57.015319 | CK34: =인프라!BY32 -> 72.172119 | CL34: =인프라!BZ32 -> 83.281161 | ... CP34: =인프라!CD32 -> 57.49747 | CQ34: =SUM(CR34:DC34) -> 896.01881 | CR34: =CR110+CR158 -> 69.026894 | CS34: =CS110+CS158 -> 74.696502 | CT34: =CT110+CT158 -> 74.696502 | CU34: =CU110+CU158 -> 74.696502 | CV34: =CV110+CV158 -> 74.696502 | CW34: =CW110+CW158 -> 74.696502 | CX34: =CX110+CX158 -> 74.696502 | CY34: =CY110+CY158 -> 74.696502 | ... DC34: =DC110+DC158 -> 74.026894 | DG34: =BQ34/BD34-1 -> 0.021434687 | DH34: =CD34/BQ34-1 -> -0.080959651 | DI34: =CQ34/CD34-1 -> 0.083965962 | DJ34: =BQ34-BD34 -> 18.874413 | DK34: =CD34-BQ34 -> -72.817461 | DL34: =CQ34-CD34 -> 69.407236
B35: 감가상각비 | Q35: =Q111 -> 7701.4169 | R35: =R111 -> 184.4195 | S35: =S111 -> 179.0879 | T35: =T111 -> 1757.2635 | U35: =U111 -> 169.22991 | V35: =V111 -> 163.72881 | W35: =W111 -> 1647.3229 | X35: =X111 -> 156.14584 | ... AC35: =AC111 -> 1482.0513 | AD35: 6408.2964 | AE35: =AE111 -> 122.0677 | AF35: =AF111 -> 121.3347 | AG35: =AG111 -> 1454.0483 | AH35: =AH111 -> 119.72864 | AI35: =AI111 -> 117.01975 | AJ35: =AJ111 -> 1409.0149 | AK35: =AK111 -> 113.79749 | AL35: =AL111 -> 113.43646 | ... AP35: =AP111 -> 1257.087 | AQ35: 6129.8075 | AR35: 109.30769 | AS35: 109.18753 | AT35: 1263.7526 | AU35: 112.92596 | AV35: 111.94171 | AW35: 1227.2413 | AX35: 111.20828 | AY35: 110.80226 | AZ35: 1378.101 | BA35: 69.966214 | BB35: 70.322174 | BC35: 1455.0508 | BD35: =SUM(BE35:BP35) -> 6436.8374 | BE35: =SUM(BE36:BE37) -> 74.262207 | BF35: =SUM(BF36:BF37) -> 77.44554 | BG35: =SUM(BG36:BG37) -> 1441.6924 | BH35: =SUM(BH36:BH37) -> 78.998683 | BI35: =SUM(BI36:BI37) -> 79.131074 | BJ35: =SUM(BJ36:BJ37) -> 1450.3236 | BK35: =SUM(BK36:BK37) -> 90.104267 | BL35: =SUM(BL36:BL37) -> 88.435212 | ... BP35: =SUM(BP36:BP37) -> 1415.6612 | BQ35: =SUM(BR35:CC35) -> 6365.9272 | BR35: =SUM(BR36:BR37) -> 87.261594 | BS35: =SUM(BS36:BS37) -> 67.63382 | BT35: =SUM(BT36:BT37) -> 1419.3982 | BU35: =SUM(BU36:BU37) -> 68.55932 | BV35: =SUM(BV36:BV37) -> 68.502802 | BW35: =SUM(BW36:BW37) -> 1431.3232 | BX35: =SUM(BX36:BX37) -> 66.797169 | BY35: =SUM(BY36:BY37) -> 66.797169 | ... CC35: =SUM(CC36:CC37) -> 1458.2854 | CD35: =SUM(CE35:CP35) -> 6388.1613 | CE35: =SUM(CE36:CE37) -> 65.42659 | CF35: =SUM(CF36:CF37) -> 65.42659 | CG35: =SUM(CG36:CG37) -> 1460.6177 | CH35: =SUM(CH36:CH37) -> 64.824418 | CI35: =SUM(CI36:CI37) -> 64.533783 | CJ35: =SUM(CJ36:CJ37) -> 1450.0262 | CK35: =SUM(CK36:CK37) -> 64.204667 | CL35: =SUM(CL36:CL37) -> 64.204667 | ... CP35: =SUM(CP36:CP37) -> 1484.5402 | CQ35: =SUM(CR35:DC35) -> 6035.7089 | CR35: =SUM(CR36:CR37) -> 38.483934 | CS35: =SUM(CS36:CS37) -> 38.483934 | CT35: =SUM(CT36:CT37) -> 1382.5054 | CU35: =SUM(CU36:CU37) -> 43.483934 | CV35: =SUM(CV36:CV37) -> 43.483934 | CW35: =SUM(CW36:CW37) -> 1387.5054 | CX35: =SUM(CX36:CX37) -> 43.483934 | CY35: =SUM(CY36:CY37) -> 43.483934 | ... DC35: =SUM(DC36:DC37) -> 1430.6662 | DG35: =BQ35/BD35-1 -> -0.011016309 | DH35: =CD35/BQ35-1 -> 0.0034926842 | DI35: =CQ35/CD35-1 -> -0.055172754 | DJ35: =BQ35-BD35 -> -70.91019 | DK35: =CD35-BQ35 -> 22.234173 | DL35: =CQ35-CD35 -> -352.45245
